Workbook
Name Baumart_: [1]!Baumart[Baumart]
Name Baumart_: [2]!Baumart[Baumart]
Name Cluster_: [1]!Cluster[Cluster]
Name Cluster_: [2]!Cluster[Cluster]
Name einheit: [1]!Tabelle14[Einheit]
Name einheit: [2]!Tabelle14[Einheit]
Name Erhebungsart_: [1]!Erhebungsart[Erhebungsart]
Name Erhebungsart_: [2]!Erhebungsart[Erhebungsart]
Name Herkunft_: [1]!Herkunft[Herkunft]
Name Herkunft_: [2]!Herkunft[Herkunft]
Name Holzstrom_: [1]!Holzstrom[Holzstrom]
Name Holzstrom_: [2]!Holzstrom[Holzstrom]
Name In_Out_: [1]!Tabelleinput[In/Out]
Name In_Out_: [2]!Tabelleinput[In/Out]
Name Inhaltsverzeichnis: "MTRANS(ERSETZEN(Inhalt;1;FINDEN(""]"";Inhalt);""))"
Name Klassifizierung: [1]!Tabelle9[Klassifizierung]
Name Klassifizierung: [2]!Tabelle9[Klassifizierung]
Name Ort_: [1]!Ort[Ort]
Name Ort_: [2]!Ort[Ort]
Name Ziel_: [1]!Ziel[Ziel]
Name Ziel_: [2]!Ziel[Ziel]

Sheet Intro
B3: Der angehängte Datensatz beinhalten Informationen über Materialflüsse, Prozesse sowie Lager in der Region Brandenburg. Der Datensatz bezieht sich dabei auf verschiedene Quellen und Dokumente.
B5: Definition der Systemgrenzen:
C6: Beobachtungszeitraum: | F6: 2010 - 2020
C7: Beobachtungsgebiet: | F7: Berlin
F8: Brandenburg
F9: Berlin + Brandenburg
B11: Für die Anfertigung der Materialflussanalyse werden die folgenden Daten benötigt. Die Daten werden in seperaten Tabellenblättern dargestellt. Für jeden Datensatz werden spezifische Anforderungen definiert. Diese lassen sich einem Systemübergreifenden Fließbild zuordnen. Dieses Fließbild beinhaltet die relevanten Flüsse, Prozesse und Lager.
B14: Prozesse bilden die Grundlage für das System. Prozesse können Transferkoefizienten und Lager beinhalten. Prozesse haben einen oder mehrere Flüsse als Input sowie einen oder mehrere Flüsse als Output.
B21: Flüsse:
C23: Flüsse müssen in Mg umgerechnet werden
B32: Prozesse:
B33: Lager
B34: Transferkoeffizienten
B35: Umrechnungsfaktoren:
B36: Codelisten:

Sheet dynamic stock model
B1: 2022 | C1: 2023 | D1: 2024 | E1: 2025 | F1: 2026 | G1: 2027 | H1: 2028 | I1: 2029 | J1: 2030 | K1: 2031 | L1: 2032 | M1: 2033 | N1: 2034 | O1: 2035 | P1: 2036
A2: MBC_long_in | B2: =Solution_material!B9*0.2 -> 10.843543 | C2: =Solution_material!C9*0.2 -> 11.060414 | D2: =Solution_material!D9*0.2 -> 11.281622 | E2: =Solution_material!E9*0.2 -> 11.507255 | F2: =Solution_material!F9*0.2 -> 11.7374 | G2: =Solution_material!G9*0.2 -> 11.972148 | H2: =Solution_material!H9*0.2 -> 12.211591 | I2: =Solution_material!I9*0.2 -> 12.455823 | ... P2: =Solution_material!P9*0.2 -> 14.307825
A3: MBC_medium_in | B3: =Solution_material!B9*0.2 -> 10.843543 | C3: =Solution_material!C9*0.2 -> 11.060414 | D3: =Solution_material!D9*0.2 -> 11.281622 | E3: =Solution_material!E9*0.2 -> 11.507255 | F3: =Solution_material!F9*0.2 -> 11.7374 | G3: =Solution_material!G9*0.2 -> 11.972148 | H3: =Solution_material!H9*0.2 -> 12.211591 | I3: =Solution_material!I9*0.2 -> 12.455823 | ... P3: =Solution_material!P9*0.2 -> 14.307825
A4: MBC_short_in | B4: =Solution_material!B9*0.6 -> 32.53063 | C4: =Solution_material!C9*0.6 -> 33.181242 | D4: =Solution_material!D9*0.6 -> 33.844867 | E4: =Solution_material!E9*0.6 -> 34.521764 | F4: =Solution_material!F9*0.6 -> 35.2122 | G4: =Solution_material!G9*0.6 -> 35.916444 | H4: =Solution_material!H9*0.6 -> 36.634773 | I4: =Solution_material!I9*0.6 -> 37.367468 | ... P4: =Solution_material!P9*0.6 -> 42.923475
A5: MBC_long_dS | B5: 10.84354 | C5: 11.060377 | D5: 11.281278 | E5: 11.504725 | F5: 11.722704 | G5: 11.904461 | H5: 11.963193 | I5: 11.724722 | J5: 10.963258 | K5: 9.5572682 | L5: 7.6722821 | M5: 5.7495963 | N5: 4.2393332 | O5: 3.3281615 | P5: 2.91699
A6: MBC_medium_dS | B6: 10.84354 | C6: 11.060071 | D6: 11.266978 | E6: 11.260263 | F6: 10.011775 | G6: 6.5106241 | H6: 2.9394501 | I6: 1.5245461 | J6: 1.3229826 | K6: 1.335148 | L6: 1.3615107 | M6: 1.3887378 | N6: 1.4165125 | O6: 1.4448428 | P6: 1.4737396
A7: MBC_short_dS | B7: 32.53062 | C7: 16.915927 | D7: 0.98894027 | E7: 1.0087098 | F7: 1.028884 | G7: 1.0494616 | H7: 1.0704509 | I7: 1.0918599 | J7: 1.1136971 | K7: 1.135971 | L7: 1.1586904 | M7: 1.1818642 | N7: 1.2055015 | O7: 1.2296116 | P7: 1.2542038
A8: MBC_long_out | B8: =B2-B5 -> 3.1083187e-06 | C8: =C2-C5 -> 3.6904982e-05 | D8: =D2-D5 -> 0.00034422875 | E8: =E2-E5 -> 0.0025302083 | F8: =F2-F5 -> 0.014695967 | G8: =G2-G5 -> 0.067686983 | H8: =H2-H5 -> 0.24839799 | I8: =I2-I5 -> 0.73110068 | ... P8: =P2-P5 -> 11.390835
A9: MBC_medium_out | B9: =B3-B6 -> 3.1083187e-06 | C9: =C3-C6 -> 0.00034349065 | D9: =D3-D6 -> 0.01464461 | E9: =E3-E6 -> 0.24699186 | F9: =F3-F6 -> 1.7256248 | G9: =G3-G6 -> 5.4615238 | H9: =H3-H6 -> 9.2721407 | I9: =I3-I6 -> 10.931277 | ... P9: =P3-P6 -> 12.834085
A10: MBC_short_out | B10: =B4-B7 -> 9.3249561e-06 | C10: =C4-C7 -> 16.265315 | D10: =D4-D7 -> 32.855927 | E10: =E4-E7 -> 33.513055 | F10: =F4-F7 -> 34.183316 | G10: =G4-G7 -> 34.866982 | H10: =H4-H7 -> 35.564322 | I10: =I4-I7 -> 36.275608 | ... P10: =P4-P7 -> 41.669271
A14: Stock MBC long | B14: 2022 | C14: 2023 | D14: 2024 | E14: 2025 | F14: 2026 | G14: 2027 | H14: 2028 | I14: 2029 | J14: 2030 | K14: 2031 | L14: 2032 | M14: 2033 | N14: 2034 | O14: 2035 | P14: 2036 | R14: Stock MBC long | S14: dS
A15: 2022 | B15: =B$2*'survival functions'!B2 -> 10.84354 | C15: =C$2*'survival functions'!C2 -> 0 | D15: =D$2*'survival functions'!D2 -> 0 | E15: =E$2*'survival functions'!E2 -> 0 | F15: =F$2*'survival functions'!F2 -> 0 | G15: =G$2*'survival functions'!G2 -> 0 | H15: =H$2*'survival functions'!H2 -> 0 | I15: =I$2*'survival functions'!I2 -> 0 | ... P15: =P$2*'survival functions'!P2 -> 0 | R15: =SUM(B15:P15) -> 10.84354 | S15: =R15 -> 10.84354
A16: 2023 | B16: =B$2*'survival functions'!B3 -> 10.843506 | C16: =C$2*'survival functions'!C3 -> 11.060411 | D16: =D$2*'survival functions'!D3 -> 0 | E16: =E$2*'survival functions'!E3 -> 0 | F16: =F$2*'survival functions'!F3 -> 0 | G16: =G$2*'survival functions'!G3 -> 0 | H16: =H$2*'survival functions'!H3 -> 0 | I16: =I$2*'survival functions'!I3 -> 0 | ... P16: =P$2*'survival functions'!P3 -> 0 | R16: =SUM(B16:P16) -> 21.903917 | S16: =R16-R15 -> 11.060377
A17: 2024 | B17: =B$2*'survival functions'!B4 -> 10.8432 | C17: =C$2*'survival functions'!C4 -> 11.060376 | D17: =D$2*'survival functions'!D4 -> 11.281619 | E17: =E$2*'survival functions'!E4 -> 0 | F17: =F$2*'survival functions'!F4 -> 0 | G17: =G$2*'survival functions'!G4 -> 0 | H17: =H$2*'survival functions'!H4 -> 0 | I17: =I$2*'survival functions'!I4 -> 0 | ... P17: =P$2*'survival functions'!P4 -> 0 | R17: =SUM(B17:P17) -> 33.185195 | S17: =R17-R16 -> 11.281278
A18: 2025 | B18: =B$2*'survival functions'!B5 -> 10.841021 | C18: =C$2*'survival functions'!C5 -> 11.060064 | D18: =D$2*'survival functions'!D5 -> 11.281584 | E18: =E$2*'survival functions'!E5 -> 11.507251 | F18: =F$2*'survival functions'!F5 -> 0 | G18: =G$2*'survival functions'!G5 -> 0 | H18: =H$2*'survival functions'!H5 -> 0 | I18: =I$2*'survival functions'!I5 -> 0 | ... P18: =P$2*'survival functions'!P5 -> 0 | R18: =SUM(B18:P18) -> 44.68992 | S18: =R18-R17 -> 11.504725
A19: 2026 | B19: =B$2*'survival functions'!B6 -> 10.828906 | C19: =C$2*'survival functions'!C6 -> 11.057841 | D19: =D$2*'survival functions'!D6 -> 11.281265 | E19: =E$2*'survival functions'!E6 -> 11.507216 | F19: =F$2*'survival functions'!F6 -> 11.737397 | G19: =G$2*'survival functions'!G6 -> 0 | H19: =H$2*'survival functions'!H6 -> 0 | I19: =I$2*'survival functions'!I6 -> 0 | ... P19: =P$2*'survival functions'!P6 -> 0 | R19: =SUM(B19:P19) -> 56.412624 | S19: =R19-R18 -> 11.722704
A20: 2027 | B20: =B$2*'survival functions'!B7 -> 10.776208 | C20: =C$2*'survival functions'!C7 -> 11.045484 | D20: =D$2*'survival functions'!D7 -> 11.278998 | E20: =E$2*'survival functions'!E7 -> 11.50689 | F20: =F$2*'survival functions'!F7 -> 11.73736 | G20: =G$2*'survival functions'!G7 -> 11.972144 | H20: =H$2*'survival functions'!H7 -> 0 | I20: =I$2*'survival functions'!I7 -> 0 | ... P20: =P$2*'survival functions'!P7 -> 0 | R20: =SUM(B20:P20) -> 68.317085 | S20: =R20-R19 -> 11.904461
A21: 2028 | B21: =B$2*'survival functions'!B8 -> 10.596851 | C21: =C$2*'survival functions'!C8 -> 10.991733 | D21: =D$2*'survival functions'!D8 -> 11.266393 | E21: =E$2*'survival functions'!E8 -> 11.504578 | F21: =F$2*'survival functions'!F8 -> 11.737028 | G21: =G$2*'survival functions'!G8 -> 11.972107 | H21: =H$2*'survival functions'!H8 -> 12.211587 | I21: =I$2*'survival functions'!I8 -> 0 | ... P21: =P$2*'survival functions'!P8 -> 0 | R21: =SUM(B21:P21) -> 80.280278 | S21: =R21-R20 -> 11.963193
A22: 2029 | B22: =B$2*'survival functions'!B9 -> 10.119116 | C22: =C$2*'survival functions'!C9 -> 10.808788 | D22: =D$2*'survival functions'!D9 -> 11.211567 | E22: =E$2*'survival functions'!E9 -> 11.491721 | F22: =F$2*'survival functions'!F9 -> 11.734669 | G22: =G$2*'survival functions'!G9 -> 11.971769 | H22: =H$2*'survival functions'!H9 -> 12.211549 | I22: =I$2*'survival functions'!I9 -> 12.455819 | ... P22: =P$2*'survival functions'!P9 -> 0 | R22: =SUM(B22:P22) -> 92.005 | S22: =R22-R21 -> 11.724722
A23: 2030 | B23: =B$2*'survival functions'!B10 -> 9.1231581 | C23: =C$2*'survival functions'!C10 -> 10.321499 | D23: =D$2*'survival functions'!D10 -> 11.024964 | E23: =E$2*'survival functions'!E10 -> 11.435799 | F23: =F$2*'survival functions'!F10 -> 11.721556 | G23: =G$2*'survival functions'!G10 -> 11.969363 | H23: =H$2*'survival functions'!H10 -> 12.211204 | I23: =I$2*'survival functions'!I10 -> 12.45578 | ... P23: =P$2*'survival functions'!P10 -> 0 | R23: =SUM(B23:P23) -> 102.96826 | S23: =R23-R22 -> 10.963258
A24: 2031 | B24: =B$2*'survival functions'!B11 -> 7.4979031 | C24: =C$2*'survival functions'!C11 -> 9.3056213 | D24: =D$2*'survival functions'!D11 -> 10.527929 | E24: =E$2*'survival functions'!E11 -> 11.245463 | F24: =F$2*'survival functions'!F11 -> 11.664515 | G24: =G$2*'survival functions'!G11 -> 11.955987 | H24: =H$2*'survival functions'!H11 -> 12.20875 | I24: =I$2*'survival functions'!I11 -> 12.455428 | ... P24: =P$2*'survival functions'!P11 -> 0 | R24: =SUM(B24:P24) -> 112.52553 | S24: =R24-R23 -> 9.5572682
A25: 2032 | B25: =B$2*'survival functions'!B12 -> 5.4217716 | C25: =C$2*'survival functions'!C12 -> 7.6478611 | D25: =D$2*'survival functions'!D12 -> 9.4917337 | E25: =E$2*'survival functions'!E12 -> 10.738487 | F25: =F$2*'survival functions'!F12 -> 11.470372 | G25: =G$2*'survival functions'!G12 -> 11.897805 | H25: =H$2*'survival functions'!H12 -> 12.195106 | I25: =I$2*'survival functions'!I12 -> 12.452925 | ... P25: =P$2*'survival functions'!P12 -> 0 | R25: =SUM(B25:P25) -> 120.19781 | S25: =R25-R24 -> 7.6722821
A26: 2033 | B26: =B$2*'survival functions'!B13 -> 3.3456401 | C26: =C$2*'survival functions'!C13 -> 5.530207 | D26: =D$2*'survival functions'!D13 -> 7.8008184 | E26: =E$2*'survival functions'!E13 -> 9.6815684 | F26: =F$2*'survival functions'!F13 -> 10.953257 | G26: =G$2*'survival functions'!G13 -> 11.69978 | H26: =H$2*'survival functions'!H13 -> 12.135761 | I26: =I$2*'survival functions'!I13 -> 12.439009 | ... P26: =P$2*'survival functions'!P13 -> 0 | R26: =SUM(B26:P26) -> 125.9474 | S26: =R26-R25 -> 5.7495963
A27: 2034 | B27: =B$2*'survival functions'!B14 -> 1.7203851 | C27: =C$2*'survival functions'!C14 -> 3.4125529 | D27: =D$2*'survival functions'!D14 -> 5.6408112 | E27: =E$2*'survival functions'!E14 -> 7.9568347 | F27: =F$2*'survival functions'!F14 -> 9.8751997 | G27: =G$2*'survival functions'!G14 -> 11.172322 | H27: =H$2*'survival functions'!H14 -> 11.933776 | I27: =I$2*'survival functions'!I14 -> 12.378476 | ... P27: =P$2*'survival functions'!P14 -> 0 | R27: =SUM(B27:P27) -> 130.18674 | S27: =R27-R26 -> 4.2393332
... A29: 2036 | B29: =B$2*'survival functions'!B16 -> 0.24669204 | C29: =C$2*'survival functions'!C16 -> 0.73891531 | D29: =D$2*'survival functions'!D16 -> 1.7898887 | E29: =E$2*'survival functions'!E16 -> 3.5504201 | F29: =F$2*'survival functions'!F16 -> 5.8686999 | G29: =G$2*'survival functions'!G16 -> 8.2782908 | H29: =H$2*'survival functions'!H16 -> 10.274158 | I29: =I$2*'survival functions'!I16 -> 11.623684 | ... P29: =P$2*'survival functions'!P16 -> 14.307821 | R29: =SUM(B29:P29) -> 136.43189 | S29: =R29-R28 -> 2.91699
A33: Stock MBC medium | B33: 2022 | C33: 2023 | D33: 2024 | E33: 2025 | F33: 2026 | G33: 2027 | H33: 2028 | I33: 2029 | J33: 2030 | K33: 2031 | L33: 2032 | M33: 2033 | N33: 2034 | O33: 2035 | P33: 2036 | R33: Stock MBC medium | S33: dS
A34: 2022 | B34: =B$3*'survival functions'!B22 -> 10.84354 | C34: =C$3*'survival functions'!C22 -> 0 | D34: =D$3*'survival functions'!D22 -> 0 | E34: =E$3*'survival functions'!E22 -> 0 | F34: =F$3*'survival functions'!F22 -> 0 | G34: =G$3*'survival functions'!G22 -> 0 | H34: =H$3*'survival functions'!H22 -> 0 | I34: =I$3*'survival functions'!I22 -> 0 | ... P34: =P$3*'survival functions'!P22 -> 0 | R34: =SUM(B34:P34) -> 10.84354 | S34: =R34 -> 10.84354
A35: 2023 | B35: =B$3*'survival functions'!B23 -> 10.8432 | C35: =C$3*'survival functions'!C23 -> 11.060411 | D35: =D$3*'survival functions'!D23 -> 0 | E35: =E$3*'survival functions'!E23 -> 0 | F35: =F$3*'survival functions'!F23 -> 0 | G35: =G$3*'survival functions'!G23 -> 0 | H35: =H$3*'survival functions'!H23 -> 0 | I35: =I$3*'survival functions'!I23 -> 0 | ... P35: =P$3*'survival functions'!P23 -> 0 | R35: =SUM(B35:P35) -> 21.903611 | S35: =R35-R34 -> 11.060071
A36: 2024 | B36: =B$3*'survival functions'!B24 -> 10.828906 | C36: =C$3*'survival functions'!C24 -> 11.060064 | D36: =D$3*'survival functions'!D24 -> 11.281619 | E36: =E$3*'survival functions'!E24 -> 0 | F36: =F$3*'survival functions'!F24 -> 0 | G36: =G$3*'survival functions'!G24 -> 0 | H36: =H$3*'survival functions'!H24 -> 0 | I36: =I$3*'survival functions'!I24 -> 0 | ... P36: =P$3*'survival functions'!P24 -> 0 | R36: =SUM(B36:P36) -> 33.170588 | S36: =R36-R35 -> 11.266978
A37: 2025 | B37: =B$3*'survival functions'!B25 -> 10.596851 | C37: =C$3*'survival functions'!C25 -> 11.045484 | D37: =D$3*'survival functions'!D25 -> 11.281265 | E37: =E$3*'survival functions'!E25 -> 11.507251 | F37: =F$3*'survival functions'!F25 -> 0 | G37: =G$3*'survival functions'!G25 -> 0 | H37: =H$3*'survival functions'!H25 -> 0 | I37: =I$3*'survival functions'!I25 -> 0 | ... P37: =P$3*'survival functions'!P25 -> 0 | R37: =SUM(B37:P37) -> 44.430851 | S37: =R37-R36 -> 11.260263
A38: 2026 | B38: =B$3*'survival functions'!B26 -> 9.1231581 | C38: =C$3*'survival functions'!C26 -> 10.808788 | D38: =D$3*'survival functions'!D26 -> 11.266393 | E38: =E$3*'survival functions'!E26 -> 11.50689 | F38: =F$3*'survival functions'!F26 -> 11.737397 | G38: =G$3*'survival functions'!G26 -> 0 | H38: =H$3*'survival functions'!H26 -> 0 | I38: =I$3*'survival functions'!I26 -> 0 | ... P38: =P$3*'survival functions'!P26 -> 0 | R38: =SUM(B38:P38) -> 54.442626 | S38: =R38-R37 -> 10.011775
A39: 2027 | B39: =B$3*'survival functions'!B27 -> 5.4217716 | C39: =C$3*'survival functions'!C27 -> 9.3056213 | D39: =D$3*'survival functions'!D27 -> 11.024964 | E39: =E$3*'survival functions'!E27 -> 11.491721 | F39: =F$3*'survival functions'!F27 -> 11.737028 | G39: =G$3*'survival functions'!G27 -> 11.972144 | H39: =H$3*'survival functions'!H27 -> 0 | I39: =I$3*'survival functions'!I27 -> 0 | ... P39: =P$3*'survival functions'!P27 -> 0 | R39: =SUM(B39:P39) -> 60.953251 | S39: =R39-R38 -> 6.5106241
A40: 2028 | B40: =B$3*'survival functions'!B28 -> 1.7203851 | C40: =C$3*'survival functions'!C28 -> 5.530207 | D40: =D$3*'survival functions'!D28 -> 9.4917337 | E40: =E$3*'survival functions'!E28 -> 11.245463 | F40: =F$3*'survival functions'!F28 -> 11.721556 | G40: =G$3*'survival functions'!G28 -> 11.971769 | H40: =H$3*'survival functions'!H28 -> 12.211587 | I40: =I$3*'survival functions'!I28 -> 0 | ... P40: =P$3*'survival functions'!P28 -> 0 | R40: =SUM(B40:P40) -> 63.892701 | S40: =R40-R39 -> 2.9394501
A41: 2029 | B41: =B$3*'survival functions'!B29 -> 0.24669204 | C41: =C$3*'survival functions'!C29 -> 1.7547928 | D41: =D$3*'survival functions'!D29 -> 5.6408112 | E41: =E$3*'survival functions'!E29 -> 9.6815684 | F41: =F$3*'survival functions'!F29 -> 11.470372 | G41: =G$3*'survival functions'!G29 -> 11.955987 | H41: =H$3*'survival functions'!H29 -> 12.211204 | I41: =I$3*'survival functions'!I29 -> 12.455819 | ... P41: =P$3*'survival functions'!P29 -> 0 | R41: =SUM(B41:P41) -> 65.417247 | S41: =R41-R40 -> 1.5245461
A42: 2030 | B42: =B$3*'survival functions'!B30 -> 0.014637678 | C42: =C$3*'survival functions'!C30 -> 0.25162588 | D42: =D$3*'survival functions'!D30 -> 1.7898887 | E42: =E$3*'survival functions'!E30 -> 5.7536274 | F42: =F$3*'survival functions'!F30 -> 9.8751997 | G42: =G$3*'survival functions'!G30 -> 11.69978 | H42: =H$3*'survival functions'!H30 -> 12.195106 | I42: =I$3*'survival functions'!I30 -> 12.455428 | ... P42: =P$3*'survival functions'!P30 -> 0 | R42: =SUM(B42:P42) -> 66.740229 | S42: =R42-R41 -> 1.3229826
A43: 2031 | B43: =B$3*'survival functions'!B31 -> 0.00034342848 | C43: =C$3*'survival functions'!C31 -> 0.014930431 | D43: =D$3*'survival functions'!D31 -> 0.2566584 | E43: =E$3*'survival functions'!E31 -> 1.8256864 | F43: =F$3*'survival functions'!F31 -> 5.8686999 | G43: =G$3*'survival functions'!G31 -> 10.072704 | H43: =H$3*'survival functions'!H31 -> 11.933776 | I43: =I$3*'survival functions'!I31 -> 12.439009 | ... P43: =P$3*'survival functions'!P31 -> 0 | R43: =SUM(B43:P43) -> 68.075377 | S43: =R43-R42 -> 1.335148
A44: 2032 | B44: =B$3*'survival functions'!B32 -> 3.1083187e-06 | C44: =C$3*'survival functions'!C32 -> 0.00035029705 | D44: =D$3*'survival functions'!D32 -> 0.01522904 | E44: =E$3*'survival functions'!E32 -> 0.26179156 | F44: =F$3*'survival functions'!F32 -> 1.8622002 | G44: =G$3*'survival functions'!G32 -> 5.9860739 | H44: =H$3*'survival functions'!H32 -> 10.274158 | I44: =I$3*'survival functions'!I32 -> 12.172451 | ... P44: =P$3*'survival functions'!P32 -> 0 | R44: =SUM(B44:P44) -> 69.436888 | S44: =R44-R43 -> 1.3615107
A45: 2033 | B45: =B$3*'survival functions'!B33 -> 1.0698106e-08 | C45: =C$3*'survival functions'!C33 -> 3.1704851e-06 | D45: =D$3*'survival functions'!D33 -> 0.00035730299 | E45: =E$3*'survival functions'!E33 -> 0.015533621 | F45: =F$3*'survival functions'!F33 -> 0.2670274 | G45: =G$3*'survival functions'!G33 -> 1.8994442 | H45: =H$3*'survival functions'!H33 -> 6.1057954 | I45: =I$3*'survival functions'!I33 -> 10.479641 | ... P45: =P$3*'survival functions'!P33 -> 0 | R45: =SUM(B45:P45) -> 70.825626 | S45: =R45-R44 -> 1.3887378
A46: 2034 | B46: =B$3*'survival functions'!B34 -> 1.3877703e-11 | C46: =C$3*'survival functions'!C34 -> 1.0912068e-08 | D46: =D$3*'survival functions'!D34 -> 3.2338948e-06 | E46: =E$3*'survival functions'!E34 -> 0.00036444905 | F46: =F$3*'survival functions'!F34 -> 0.015844293 | G46: =G$3*'survival functions'!G34 -> 0.27236794 | H46: =H$3*'survival functions'!H34 -> 1.937433 | I46: =I$3*'survival functions'!I34 -> 6.2279113 | ... P46: =P$3*'survival functions'!P34 -> 0 | R46: =SUM(B46:P46) -> 72.242138 | S46: =R46-R45 -> 1.4165125
... A48: 2036 | B48: =B$3*'survival functions'!B36 -> 1.2237897e-18 | C48: =C$3*'survival functions'!C36 -> 6.88064e-15 | D48: =D$3*'survival functions'!D36 -> 1.4438362e-11 | E48: =E$3*'survival functions'!E36 -> 1.1352915e-08 | F48: =F$3*'survival functions'!F36 -> 3.3645441e-06 | G48: =G$3*'survival functions'!G36 -> 0.00037917279 | H48: =H$3*'survival functions'!H36 -> 0.016484402 | I48: =I$3*'survival functions'!I36 -> 0.28337161 | ... P48: =P$3*'survival functions'!P36 -> 14.307821 | R48: =SUM(B48:P48) -> 75.160721 | S48: =R48-R47 -> 1.4737396
...

Sheet survival functions
A1: mean = 10 years, stdev = 0.2 * 10 | B1: 2022 | C1: 2023 | D1: 2024 | E1: 2025 | F1: 2026 | G1: 2027 | H1: 2028 | I1: 2029 | J1: 2030 | K1: 2031 | L1: 2032 | M1: 2033 | N1: 2034 | O1: 2035 | P1: 2036
A2: 2022 | B2: 0.99999971 | C2: 0 | D2: 0 | E2: 0 | F2: 0 | G2: 0 | H2: 0 | I2: 0 | J2: 0 | K2: 0 | L2: 0 | M2: 0 | N2: 0 | O2: 0 | P2: 0
A3: 2023 | B3: 0.9999966 | C3: 0.99999971 | D3: 0 | E3: 0 | F3: 0 | G3: 0 | H3: 0 | I3: 0 | J3: 0 | K3: 0 | L3: 0 | M3: 0 | N3: 0 | O3: 0 | P3: 0
A4: 2024 | B4: 0.99996833 | C4: 0.9999966 | D4: 0.99999971 | E4: 0 | F4: 0 | G4: 0 | H4: 0 | I4: 0 | J4: 0 | K4: 0 | L4: 0 | M4: 0 | N4: 0 | O4: 0 | P4: 0
A5: 2025 | B5: 0.99976737 | C5: 0.99996833 | D5: 0.9999966 | E5: 0.99999971 | F5: 0 | G5: 0 | H5: 0 | I5: 0 | J5: 0 | K5: 0 | L5: 0 | M5: 0 | N5: 0 | O5: 0 | P5: 0
A6: 2026 | B6: 0.9986501 | C6: 0.99976737 | D6: 0.99996833 | E6: 0.9999966 | F6: 0.99999971 | G6: 0 | H6: 0 | I6: 0 | J6: 0 | K6: 0 | L6: 0 | M6: 0 | N6: 0 | O6: 0 | P6: 0
A7: 2027 | B7: 0.99379033 | C7: 0.9986501 | D7: 0.99976737 | E7: 0.99996833 | F7: 0.9999966 | G7: 0.99999971 | H7: 0 | I7: 0 | J7: 0 | K7: 0 | L7: 0 | M7: 0 | N7: 0 | O7: 0 | P7: 0
A8: 2028 | B8: 0.97724987 | C8: 0.99379033 | D8: 0.9986501 | E8: 0.99976737 | F8: 0.99996833 | G8: 0.9999966 | H8: 0.99999971 | I8: 0 | J8: 0 | K8: 0 | L8: 0 | M8: 0 | N8: 0 | O8: 0 | P8: 0
A9: 2029 | B9: 0.9331928 | C9: 0.97724987 | D9: 0.99379033 | E9: 0.9986501 | F9: 0.99976737 | G9: 0.99996833 | H9: 0.9999966 | I9: 0.99999971 | J9: 0 | K9: 0 | L9: 0 | M9: 0 | N9: 0 | O9: 0 | P9: 0
A10: 2030 | B10: 0.84134475 | C10: 0.9331928 | D10: 0.97724987 | E10: 0.99379033 | F10: 0.9986501 | G10: 0.99976737 | H10: 0.99996833 | I10: 0.9999966 | J10: 0.99999971 | K10: 0 | L10: 0 | M10: 0 | N10: 0 | O10: 0 | P10: 0
A11: 2031 | B11: 0.69146246 | C11: 0.84134475 | D11: 0.9331928 | E11: 0.97724987 | F11: 0.99379033 | G11: 0.9986501 | H11: 0.99976737 | I11: 0.99996833 | J11: 0.9999966 | K11: 0.99999971 | L11: 0 | M11: 0 | N11: 0 | O11: 0 | P11: 0
A12: 2032 | B12: 0.5 | C12: 0.69146246 | D12: 0.84134475 | E12: 0.9331928 | F12: 0.97724987 | G12: 0.99379033 | H12: 0.9986501 | I12: 0.99976737 | J12: 0.99996833 | K12: 0.9999966 | L12: 0.99999971 | M12: 0 | N12: 0 | O12: 0 | P12: 0
A13: 2033 | B13: 0.30853754 | C13: 0.5 | D13: 0.69146246 | E13: 0.84134475 | F13: 0.9331928 | G13: 0.97724987 | H13: 0.99379033 | I13: 0.9986501 | J13: 0.99976737 | K13: 0.99996833 | L13: 0.9999966 | M13: 0.99999971 | N13: 0 | O13: 0 | P13: 0
... A16: 2036 | B16: 0.022750132 | C16: 0.066807201 | D16: 0.15865525 | E16: 0.30853754 | F16: 0.5 | G16: 0.69146246 | H16: 0.84134475 | I16: 0.9331928 | J16: 0.97724987 | K16: 0.99379033 | L16: 0.9986501 | M16: 0.99976737 | N16: 0.99996833 | O16: 0.9999966 | P16: 0.99999971
A21: mean = 5 years, stdev = 0.2 * 5 | B21: 2022 | C21: 2023 | D21: 2024 | E21: 2025 | F21: 2026 | G21: 2027 | H21: 2028 | I21: 2029 | J21: 2030 | K21: 2031 | L21: 2032 | M21: 2033 | N21: 2034 | O21: 2035 | P21: 2036
A22: 2022 | B22: 0.99999971 | C22: 0 | D22: 0 | E22: 0 | F22: 0 | G22: 0 | H22: 0 | I22: 0 | J22: 0 | K22: 0 | L22: 0 | M22: 0 | N22: 0 | O22: 0 | P22: 0
A23: 2023 | B23: 0.99996833 | C23: 0.99999971 | D23: 0 | E23: 0 | F23: 0 | G23: 0 | H23: 0 | I23: 0 | J23: 0 | K23: 0 | L23: 0 | M23: 0 | N23: 0 | O23: 0 | P23: 0
A24: 2024 | B24: 0.9986501 | C24: 0.99996833 | D24: 0.99999971 | E24: 0 | F24: 0 | G24: 0 | H24: 0 | I24: 0 | J24: 0 | K24: 0 | L24: 0 | M24: 0 | N24: 0 | O24: 0 | P24: 0
A25: 2025 | B25: 0.97724987 | C25: 0.9986501 | D25: 0.99996833 | E25: 0.99999971 | F25: 0 | G25: 0 | H25: 0 | I25: 0 | J25: 0 | K25: 0 | L25: 0 | M25: 0 | N25: 0 | O25: 0 | P25: 0
A26: 2026 | B26: 0.84134475 | C26: 0.97724987 | D26: 0.9986501 | E26: 0.99996833 | F26: 0.99999971 | G26: 0 | H26: 0 | I26: 0 | J26: 0 | K26: 0 | L26: 0 | M26: 0 | N26: 0 | O26: 0 | P26: 0
A27: 2027 | B27: 0.5 | C27: 0.84134475 | D27: 0.97724987 | E27: 0.9986501 | F27: 0.99996833 | G27: 0.99999971 | H27: 0 | I27: 0 | J27: 0 | K27: 0 | L27: 0 | M27: 0 | N27: 0 | O27: 0 | P27: 0
A28: 2028 | B28: 0.15865525 | C28: 0.5 | D28: 0.84134475 | E28: 0.97724987 | F28: 0.9986501 | G28: 0.99996833 | H28: 0.99999971 | I28: 0 | J28: 0 | K28: 0 | L28: 0 | M28: 0 | N28: 0 | O28: 0 | P28: 0
A29: 2029 | B29: 0.022750132 | C29: 0.15865525 | D29: 0.5 | E29: 0.84134475 | F29: 0.97724987 | G29: 0.9986501 | H29: 0.99996833 | I29: 0.99999971 | J29: 0 | K29: 0 | L29: 0 | M29: 0 | N29: 0 | O29: 0 | P29: 0
A30: 2030 | B30: 0.001349898 | C30: 0.022750132 | D30: 0.15865525 | E30: 0.5 | F30: 0.84134475 | G30: 0.97724987 | H30: 0.9986501 | I30: 0.99996833 | J30: 0.99999971 | K30: 0 | L30: 0 | M30: 0 | N30: 0 | O30: 0 | P30: 0
A31: 2031 | B31: 3.1671242e-05 | C31: 0.001349898 | D31: 0.022750132 | E31: 0.15865525 | F31: 0.5 | G31: 0.84134475 | H31: 0.97724987 | I31: 0.9986501 | J31: 0.99996833 | K31: 0.99999971 | L31: 0 | M31: 0 | N31: 0 | O31: 0 | P31: 0
A32: 2032 | B32: 2.8665157e-07 | C32: 3.1671242e-05 | D32: 0.001349898 | E32: 0.022750132 | F32: 0.15865525 | G32: 0.5 | H32: 0.84134475 | I32: 0.97724987 | J32: 0.9986501 | K32: 0.99996833 | L32: 0.99999971 | M32: 0 | N32: 0 | O32: 0 | P32: 0
A33: 2033 | B33: 9.8658765e-10 | C33: 2.8665157e-07 | D33: 3.1671242e-05 | E33: 0.001349898 | F33: 0.022750132 | G33: 0.15865525 | H33: 0.5 | I33: 0.84134475 | J33: 0.97724987 | K33: 0.9986501 | L33: 0.99996833 | M33: 0.99999971 | N33: 0 | O33: 0 | P33: 0
... A36: 2036 | B36: 1.1285884e-19 | C36: 6.2209606e-16 | D36: 1.2798125e-12 | E36: 9.8658765e-10 | F36: 2.8665157e-07 | G36: 3.1671242e-05 | H36: 0.001349898 | I36: 0.022750132 | J36: 0.15865525 | K36: 0.5 | L36: 0.84134475 | M36: 0.97724987 | N36: 0.9986501 | O36: 0.99996833 | P36: 0.99999971
A41: mean = 1 year, stdev = 0.2 * 1 | B41: 2022 | C41: 2023 | D41: 2024 | E41: 2025 | F41: 2026 | G41: 2027 | H41: 2028 | I41: 2029 | J41: 2030 | K41: 2031 | L41: 2032 | M41: 2033 | N41: 2034 | O41: 2035 | P41: 2036
A42: 2022 | B42: 0.99999971 | C42: 0 | D42: 0 | E42: 0 | F42: 0 | G42: 0 | H42: 0 | I42: 0 | J42: 0 | K42: 0 | L42: 0 | M42: 0 | N42: 0 | O42: 0 | P42: 0
A43: 2023 | B43: 0.5 | C43: 0.99999971 | D43: 0 | E43: 0 | F43: 0 | G43: 0 | H43: 0 | I43: 0 | J43: 0 | K43: 0 | L43: 0 | M43: 0 | N43: 0 | O43: 0 | P43: 0
A44: 2024 | B44: 2.8665157e-07 | C44: 0.5 | D44: 0.99999971 | E44: 0 | F44: 0 | G44: 0 | H44: 0 | I44: 0 | J44: 0 | K44: 0 | L44: 0 | M44: 0 | N44: 0 | O44: 0 | P44: 0
A45: 2025 | B45: 7.619853e-24 | C45: 2.8665157e-07 | D45: 0.5 | E45: 0.99999971 | F45: 0 | G45: 0 | H45: 0 | I45: 0 | J45: 0 | K45: 0 | L45: 0 | M45: 0 | N45: 0 | O45: 0 | P45: 0
A46: 2026 | B46: 3.6709662e-51 | C46: 7.619853e-24 | D46: 2.8665157e-07 | E46: 0.5 | F46: 0.99999971 | G46: 0 | H46: 0 | I46: 0 | J46: 0 | K46: 0 | L46: 0 | M46: 0 | N46: 0 | O46: 0 | P46: 0
A47: 2027 | B47: 2.7536241e-89 | C47: 3.6709662e-51 | D47: 7.619853e-24 | E47: 2.8665157e-07 | F47: 0.5 | G47: 0.99999971 | H47: 0 | I47: 0 | J47: 0 | K47: 0 | L47: 0 | M47: 0 | N47: 0 | O47: 0 | P47: 0
A48: 2028 | B48: 3.0566967e-138 | C48: 2.7536241e-89 | D48: 3.6709662e-51 | E48: 7.619853e-24 | F48: 2.8665157e-07 | G48: 0.5 | H48: 0.99999971 | I48: 0 | J48: 0 | K48: 0 | L48: 0 | M48: 0 | N48: 0 | O48: 0 | P48: 0
A49: 2029 | B49: 4.9067139e-198 | C49: 3.0566967e-138 | D49: 2.7536241e-89 | E49: 3.6709662e-51 | F49: 7.619853e-24 | G49: 2.8665157e-07 | H49: 0.5 | I49: 0.99999971 | J49: 0 | K49: 0 | L49: 0 | M49: 0 | N49: 0 | O49: 0 | P49: 0
A50: 2030 | B50: 1.1249107e-268 | C50: 4.9067139e-198 | D50: 3.0566967e-138 | E50: 2.7536241e-89 | F50: 3.6709662e-51 | G50: 7.619853e-24 | H50: 2.8665157e-07 | I50: 0.5 | J50: 0.99999971 | K50: 0 | L50: 0 | M50: 0 | N50: 0 | O50: 0 | P50: 0
A51: 2031 | B51: 0 | C51: 1.1249107e-268 | D51: 4.9067139e-198 | E51: 3.0566967e-138 | F51: 2.7536241e-89 | G51: 3.6709662e-51 | H51: 7.619853e-24 | I51: 2.8665157e-07 | J51: 0.5 | K51: 0.99999971 | L51: 0 | M51: 0 | N51: 0 | O51: 0 | P51: 0
A52: 2032 | B52: 0 | C52: 0 | D52: 1.1249107e-268 | E52: 4.9067139e-198 | F52: 3.0566967e-138 | G52: 2.7536241e-89 | H52: 3.6709662e-51 | I52: 7.619853e-24 | J52: 2.8665157e-07 | K52: 0.5 | L52: 0.99999971 | M52: 0 | N52: 0 | O52: 0 | P52: 0
...

Sheet Solution_material
B1: 2022 | C1: 2023 | D1: 2024 | E1: 2025 | F1: 2026 | G1: 2027 | H1: 2028 | I1: 2029 | J1: 2030 | K1: 2031 | L1: 2032 | M1: 2033 | N1: 2034 | O1: 2035 | P1: 2036
A2: ='1_1_Definition_Flows'!C2 -> F_13_20 | B2: =Tab_Data_Flows[[#This Row],[Flow_Source]] -> 129 | C2: =B2*1.02 -> 131.58 | D2: =C2*1.02 -> 134.2116 | E2: =D2*1.02 -> 136.89583 | F2: =E2*1.02 -> 139.63375 | G2: =F2*1.02 -> 142.42642 | H2: =G2*1.02 -> 145.27495 | I2: =H2*1.02 -> 148.18045 | J2: =I2*1.02 -> 151.14406 | ... P2: =O2*1.02 -> 170.21276 | R2: =SUM(B2:P2) -> 2230.8508
A3: ='1_1_Definition_Flows'!C3 -> F_20_15 | B3: =B2*'2_3_Process_TCs'!$AE$2 -> 51.6 | C3: =C2*'2_3_Process_TCs'!$AE$2 -> 52.632 | D3: =D2*'2_3_Process_TCs'!$AE$2 -> 53.68464 | E3: =E2*'2_3_Process_TCs'!$AE$2 -> 54.758333 | F3: =F2*'2_3_Process_TCs'!$AE$2 -> 55.853499 | G3: =G2*'2_3_Process_TCs'!$AE$2 -> 56.970569 | H3: =H2*'2_3_Process_TCs'!$AE$2 -> 58.109981 | I3: =I2*'2_3_Process_TCs'!$AE$2 -> 59.27218 | ... P3: =P2*'2_3_Process_TCs'!$AE$2 -> 68.085104 | R3: =SUM(B3:P3) -> 892.34031
A4: ='1_1_Definition_Flows'!C4 -> F_20_01 | B4: =B2*'2_3_Process_TCs'!$AH$2 -> 51.6 | C4: =C2*'2_3_Process_TCs'!$AH$2 -> 52.632 | D4: =D2*'2_3_Process_TCs'!$AH$2 -> 53.68464 | E4: =E2*'2_3_Process_TCs'!$AH$2 -> 54.758333 | F4: =F2*'2_3_Process_TCs'!$AH$2 -> 55.853499 | G4: =G2*'2_3_Process_TCs'!$AH$2 -> 56.970569 | H4: =H2*'2_3_Process_TCs'!$AH$2 -> 58.109981 | I4: =I2*'2_3_Process_TCs'!$AH$2 -> 59.27218 | ... P4: =P2*'2_3_Process_TCs'!$AH$2 -> 68.085104 | R4: =SUM(B4:P4) -> 892.34031
A5: ='1_1_Definition_Flows'!C5 -> F_20_16 | B5: =B2-B3-B4 -> 25.8 | C5: =C2-C3-C4 -> 26.316 | D5: =D2-D3-D4 -> 26.84232 | E5: =E2-E3-E4 -> 27.379166 | F5: =F2-F3-F4 -> 27.92675 | G5: =G2-G3-G4 -> 28.485285 | H5: =H2-H3-H4 -> 29.05499 | I5: =I2-I3-I4 -> 29.63609 | ... P5: =P2-P3-P4 -> 34.042552 | R5: =SUM(B5:P5) -> 446.17016
A6: ='1_1_Definition_Flows'!C6 -> F_04_01 | B6: ='1_2_Data_Flows'!O3 -> 39 | C6: =B6*1.02 -> 39.78 | D6: =C6*1.02 -> 40.5756 | E6: =D6*1.02 -> 41.387112 | F6: =E6*1.02 -> 42.214854 | G6: =F6*1.02 -> 43.059151 | H6: =G6*1.02 -> 43.920334 | I6: =H6*1.02 -> 44.798741 | J6: =I6*1.02 -> 45.694716 | ... P6: =O6*1.02 -> 51.459672 | R6: =SUM(B6:P6) -> 674.44326
A7: ='1_1_Definition_Flows'!C7 -> F_01_05 | B7: =(B4+B6)*'2_3_Process_TCs'!$AE$3 -> 22.9218 | C7: =(C4+C6)*'2_3_Process_TCs'!$AE$3 -> 23.380236 | D7: =(D4+D6)*'2_3_Process_TCs'!$AE$3 -> 23.847841 | E7: =(E4+E6)*'2_3_Process_TCs'!$AE$3 -> 24.324798 | F7: =(F4+F6)*'2_3_Process_TCs'!$AE$3 -> 24.811293 | G7: =(G4+G6)*'2_3_Process_TCs'!$AE$3 -> 25.307519 | H7: =(H4+H6)*'2_3_Process_TCs'!$AE$3 -> 25.81367 | I7: =(I4+I6)*'2_3_Process_TCs'!$AE$3 -> 26.329943 | ... P7: =(P4+P6)*'2_3_Process_TCs'!$AE$3 -> 30.244828 | R7: =SUM(B7:P7) -> 396.39624
A8: ='1_1_Definition_Flows'!C8 -> F_01_02 | B8: =(B4+B6)*'2_3_Process_TCs'!$AH$3 -> 67.6782 | C8: =(C4+C6)*'2_3_Process_TCs'!$AH$3 -> 69.031764 | D8: =(D4+D6)*'2_3_Process_TCs'!$AH$3 -> 70.412399 | E8: =(E4+E6)*'2_3_Process_TCs'!$AH$3 -> 71.820647 | F8: =(F4+F6)*'2_3_Process_TCs'!$AH$3 -> 73.25706 | G8: =(G4+G6)*'2_3_Process_TCs'!$AH$3 -> 74.722201 | H8: =(H4+H6)*'2_3_Process_TCs'!$AH$3 -> 76.216645 | I8: =(I4+I6)*'2_3_Process_TCs'!$AH$3 -> 77.740978 | ... P8: =(P4+P6)*'2_3_Process_TCs'!$AH$3 -> 89.299948 | R8: =SUM(B8:P8) -> 1170.3873
A9: ='1_1_Definition_Flows'!C9 -> F_02_03 | B9: =(B8+B12+B13)*'2_3_Process_TCs'!$AE$4 -> 54.217716 | C9: =(C8+C12+C13)*'2_3_Process_TCs'!$AE$4 -> 55.30207 | D9: =(D8+D12+D13)*'2_3_Process_TCs'!$AE$4 -> 56.408112 | E9: =(E8+E12+E13)*'2_3_Process_TCs'!$AE$4 -> 57.536274 | F9: =(F8+F12+F13)*'2_3_Process_TCs'!$AE$4 -> 58.686999 | G9: =(G8+G12+G13)*'2_3_Process_TCs'!$AE$4 -> 59.860739 | H9: =(H8+H12+H13)*'2_3_Process_TCs'!$AE$4 -> 61.057954 | I9: =(I8+I12+I13)*'2_3_Process_TCs'!$AE$4 -> 62.279113 | ... P9: =(P8+P12+P13)*'2_3_Process_TCs'!$AE$4 -> 71.539125 | R9: =SUM(B9:P9) -> 937.60957
A10: ='1_1_Definition_Flows'!C10 -> F_03_07 | B10: ='dynamic stock model'!B8+'dynamic stock model'!B9+'dynamic stock model'!B10 -> 1.5541594e-05 | C10: ='dynamic stock model'!C8+'dynamic stock model'!C9+'dynamic stock model'!C10 -> 16.265695 | D10: ='dynamic stock model'!D8+'dynamic stock model'!D9+'dynamic stock model'!D10 -> 32.870916 | E10: ='dynamic stock model'!E8+'dynamic stock model'!E9+'dynamic stock model'!E10 -> 33.762577 | F10: ='dynamic stock model'!F8+'dynamic stock model'!F9+'dynamic stock model'!F10 -> 35.923636 | G10: ='dynamic stock model'!G8+'dynamic stock model'!G9+'dynamic stock model'!G10 -> 40.396193 | H10: ='dynamic stock model'!H8+'dynamic stock model'!H9+'dynamic stock model'!H10 -> 45.08486 | I10: ='dynamic stock model'!I8+'dynamic stock model'!I9+'dynamic stock model'!I10 -> 47.937985 | ... P10: ='dynamic stock model'!P8+'dynamic stock model'!P9+'dynamic stock model'!P10 -> 65.894191 | R10: =SUM(B10:P10) -> 662.05256
A11: ='1_1_Definition_Flows'!C11 -> F_02_06 | B11: =(B8+B12+B13)*'2_3_Process_TCs'!$AH$4 -> 12.841038 | C11: =(C8+C12+C13)*'2_3_Process_TCs'!$AH$4 -> 13.097859 | D11: =(D8+D12+D13)*'2_3_Process_TCs'!$AH$4 -> 13.359816 | E11: =(E8+E12+E13)*'2_3_Process_TCs'!$AH$4 -> 13.627012 | F11: =(F8+F12+F13)*'2_3_Process_TCs'!$AH$4 -> 13.899552 | G11: =(G8+G12+G13)*'2_3_Process_TCs'!$AH$4 -> 14.177544 | H11: =(H8+H12+H13)*'2_3_Process_TCs'!$AH$4 -> 14.461094 | I11: =(I8+I12+I13)*'2_3_Process_TCs'!$AH$4 -> 14.750316 | ... P11: =(P8+P12+P13)*'2_3_Process_TCs'!$AH$4 -> 16.943477 | R11: =SUM(B11:P11) -> 222.06542
A12: ='1_1_Definition_Flows'!C12 -> F_11_02 | B12: ='1_2_Data_Flows'!O4 -> 1 | C12: =B12*1.02 -> 1.02 | D12: =C12*1.02 -> 1.0404 | E12: =D12*1.02 -> 1.061208 | F12: =E12*1.02 -> 1.0824322 | G12: =F12*1.02 -> 1.1040808 | H12: =G12*1.02 -> 1.1261624 | I12: =H12*1.02 -> 1.1486857 | J12: =I12*1.02 -> 1.1716594 | ... P12: =O12*1.02 -> 1.3194788 | R12: =SUM(B12:P12) -> 17.293417
A13: ='1_1_Definition_Flows'!C13 -> F_08_02 | B13: ='1_2_Data_Flows'!O5 -> 74 | C13: =B13*1.02 -> 75.48 | D13: =C13*1.02 -> 76.9896 | E13: =D13*1.02 -> 78.529392 | F13: =E13*1.02 -> 80.09998 | G13: =F13*1.02 -> 81.701979 | H13: =G13*1.02 -> 83.336019 | I13: =H13*1.02 -> 85.002739 | J13: =I13*1.02 -> 86.702794 | ... P13: =O13*1.02 -> 97.641428 | R13: =SUM(B13:P13) -> 1279.7129
A14: ='1_1_Definition_Flows'!C14 -> F_02_14 | B14: =(B8+B12+B13)*'2_3_Process_TCs'!$AK$4 -> 67.058754 | C14: =(C8+C12+C13)*'2_3_Process_TCs'!$AK$4 -> 68.399929 | D14: =(D8+D12+D13)*'2_3_Process_TCs'!$AK$4 -> 69.767928 | E14: =(E8+E12+E13)*'2_3_Process_TCs'!$AK$4 -> 71.163286 | F14: =(F8+F12+F13)*'2_3_Process_TCs'!$AK$4 -> 72.586552 | G14: =(G8+G12+G13)*'2_3_Process_TCs'!$AK$4 -> 74.038283 | H14: =(H8+H12+H13)*'2_3_Process_TCs'!$AK$4 -> 75.519049 | I14: =(I8+I12+I13)*'2_3_Process_TCs'!$AK$4 -> 77.02943 | ... P14: =(P8+P12+P13)*'2_3_Process_TCs'!$AK$4 -> 88.482602 | R14: =SUM(B14:P14) -> 1159.675
A15: ='1_1_Definition_Flows'!C15 -> F_02_12 | B15: =(B8+B12+B13)*'2_3_Process_TCs'!$AN$4 -> 8.560692 | C15: =(C8+C12+C13)*'2_3_Process_TCs'!$AN$4 -> 8.7319058 | D15: =(D8+D12+D13)*'2_3_Process_TCs'!$AN$4 -> 8.906544 | E15: =(E8+E12+E13)*'2_3_Process_TCs'!$AN$4 -> 9.0846748 | F15: =(F8+F12+F13)*'2_3_Process_TCs'!$AN$4 -> 9.2663683 | G15: =(G8+G12+G13)*'2_3_Process_TCs'!$AN$4 -> 9.4516957 | H15: =(H8+H12+H13)*'2_3_Process_TCs'!$AN$4 -> 9.6407296 | I15: =(I8+I12+I13)*'2_3_Process_TCs'!$AN$4 -> 9.8335442 | ... P15: =(P8+P12+P13)*'2_3_Process_TCs'!$AN$4 -> 11.295651 | R15: =SUM(B15:P15) -> 148.04362
A16: ='1_1_Definition_Flows'!C16 -> F_07_09 | B16: =B10*'2_3_Process_TCs'!$AE$5 -> 3.1083187e-06 | C16: =C10*'2_3_Process_TCs'!$AE$5 -> 3.2531391 | D16: =D10*'2_3_Process_TCs'!$AE$5 -> 6.5741831 | E16: =E10*'2_3_Process_TCs'!$AE$5 -> 6.7525153 | F16: =F10*'2_3_Process_TCs'!$AE$5 -> 7.1847273 | G16: =G10*'2_3_Process_TCs'!$AE$5 -> 8.0792386 | H16: =H10*'2_3_Process_TCs'!$AE$5 -> 9.0169721 | I16: =I10*'2_3_Process_TCs'!$AE$5 -> 9.5875971 | ... P16: =P10*'2_3_Process_TCs'!$AE$5 -> 13.178838 | R16: =SUM(B16:P16) -> 132.41051
A17: ='1_1_Definition_Flows'!C17 -> F_07_10 | B17: =B10*'2_3_Process_TCs'!$AH$5 -> 1.2433275e-05 | C17: =C10*'2_3_Process_TCs'!$AH$5 -> 13.012556 | D17: =D10*'2_3_Process_TCs'!$AH$5 -> 26.296732 | E17: =E10*'2_3_Process_TCs'!$AH$5 -> 27.010061 | F17: =F10*'2_3_Process_TCs'!$AH$5 -> 28.738909 | G17: =G10*'2_3_Process_TCs'!$AH$5 -> 32.316954 | H17: =H10*'2_3_Process_TCs'!$AH$5 -> 36.067888 | I17: =I10*'2_3_Process_TCs'!$AH$5 -> 38.350388 | ... P17: =P10*'2_3_Process_TCs'!$AH$5 -> 52.715353 | R17: =SUM(B17:P17) -> 529.64205
A18: ='1_1_Definition_Flows'!C18 -> F_09_17 | B18: =B16*'2_3_Process_TCs'!$AE$7 -> 9.3249561e-07 | C18: =C16*'2_3_Process_TCs'!$AE$7 -> 0.97594172 | D18: =D16*'2_3_Process_TCs'!$AE$7 -> 1.9722549 | E18: =E16*'2_3_Process_TCs'!$AE$7 -> 2.0257546 | F18: =F16*'2_3_Process_TCs'!$AE$7 -> 2.1554182 | G18: =G16*'2_3_Process_TCs'!$AE$7 -> 2.4237716 | H18: =H16*'2_3_Process_TCs'!$AE$7 -> 2.7050916 | I18: =I16*'2_3_Process_TCs'!$AE$7 -> 2.8762791 | ... P18: =P16*'2_3_Process_TCs'!$AE$7 -> 3.9536515 | R18: =SUM(B18:P18) -> 39.723154
A19: ='1_1_Definition_Flows'!C19 -> F_10_18 | B19: =B17*'2_3_Process_TCs'!$AE$8 -> 1.2433275e-06 | C19: =C17*'2_3_Process_TCs'!$AE$8 -> 1.3012556 | D19: =D17*'2_3_Process_TCs'!$AE$8 -> 2.6296732 | E19: =E17*'2_3_Process_TCs'!$AE$8 -> 2.7010061 | F19: =F17*'2_3_Process_TCs'!$AE$8 -> 2.8738909 | G19: =G17*'2_3_Process_TCs'!$AE$8 -> 3.2316954 | H19: =H17*'2_3_Process_TCs'!$AE$8 -> 3.6067888 | I19: =I17*'2_3_Process_TCs'!$AE$8 -> 3.8350388 | ... P19: =P17*'2_3_Process_TCs'!$AE$8 -> 5.2715353 | R19: =SUM(B19:P19) -> 52.964205
A20: ='1_1_Definition_Flows'!C20 -> F_10_19 | B20: =B17*'2_3_Process_TCs'!$AH$8 -> 1.1189947e-05 | C20: =C17*'2_3_Process_TCs'!$AH$8 -> 11.711301 | D20: =D17*'2_3_Process_TCs'!$AH$8 -> 23.667059 | E20: =E17*'2_3_Process_TCs'!$AH$8 -> 24.309055 | F20: =F17*'2_3_Process_TCs'!$AH$8 -> 25.865018 | G20: =G17*'2_3_Process_TCs'!$AH$8 -> 29.085259 | H20: =H17*'2_3_Process_TCs'!$AH$8 -> 32.461099 | I20: =I17*'2_3_Process_TCs'!$AH$8 -> 34.515349 | ... P20: =P17*'2_3_Process_TCs'!$AH$8 -> 47.443818 | R20: =SUM(B20:P20) -> 476.67785
A21: ='1_1_Definition_Flows'!C21 -> F_00_13 | B21: ='1_2_Data_Flows'!O6 -> 129 | C21: =B21*1.02 -> 131.58 | D21: =C21*1.02 -> 134.2116 | E21: =D21*1.02 -> 136.89583 | F21: =E21*1.02 -> 139.63375 | G21: =F21*1.02 -> 142.42642 | H21: =G21*1.02 -> 145.27495 | I21: =H21*1.02 -> 148.18045 | J21: =I21*1.02 -> 151.14406 | ... P21: =O21*1.02 -> 170.21276 | R21: =SUM(B21:P21) -> 2230.8508
A22: ='1_1_Definition_Flows'!C22 -> F_00_04 | B22: ='1_2_Data_Flows'!O7 -> 39 | C22: =B22*1.02 -> 39.78 | D22: =C22*1.02 -> 40.5756 | E22: =D22*1.02 -> 41.387112 | F22: =E22*1.02 -> 42.214854 | G22: =F22*1.02 -> 43.059151 | H22: =G22*1.02 -> 43.920334 | I22: =H22*1.02 -> 44.798741 | J22: =I22*1.02 -> 45.694716 | ... P22: =O22*1.02 -> 51.459672 | R22: =SUM(B22:P22) -> 674.44326
A23: ='1_1_Definition_Flows'!C23 -> F_00_11 | B23: ='1_2_Data_Flows'!O8 -> 1 | C23: =B23*1.02 -> 1.02 | D23: =C23*1.02 -> 1.0404 | E23: =D23*1.02 -> 1.061208 | F23: =E23*1.02 -> 1.0824322 | G23: =F23*1.02 -> 1.1040808 | H23: =G23*1.02 -> 1.1261624 | I23: =H23*1.02 -> 1.1486857 | J23: =I23*1.02 -> 1.1716594 | ... P23: =O23*1.02 -> 1.3194788 | R23: =SUM(B23:P23) -> 17.293417
A24: ='1_1_Definition_Flows'!C24 -> F_00_08 | B24: ='1_2_Data_Flows'!O9 -> 74 | C24: =B24*1.02 -> 75.48 | D24: =C24*1.02 -> 76.9896 | E24: =D24*1.02 -> 78.529392 | F24: =E24*1.02 -> 80.09998 | G24: =F24*1.02 -> 81.701979 | H24: =G24*1.02 -> 83.336019 | I24: =H24*1.02 -> 85.002739 | J24: =I24*1.02 -> 86.702794 | ... P24: =O24*1.02 -> 97.641428 | R24: =SUM(B24:P24) -> 1279.7129
A25: ='1_1_Definition_Flows'!C25 -> F_09_19 | B25: =B16*'2_3_Process_TCs'!$AH$7 -> 2.1758231e-06 | C25: =C16*'2_3_Process_TCs'!$AH$7 -> 2.2771974 | D25: =D16*'2_3_Process_TCs'!$AH$7 -> 4.6019282 | E25: =E16*'2_3_Process_TCs'!$AH$7 -> 4.7267607 | F25: =F16*'2_3_Process_TCs'!$AH$7 -> 5.0293091 | G25: =G16*'2_3_Process_TCs'!$AH$7 -> 5.655467 | H25: =H16*'2_3_Process_TCs'!$AH$7 -> 6.3118805 | I25: =I16*'2_3_Process_TCs'!$AH$7 -> 6.711318 | ... P25: =P16*'2_3_Process_TCs'!$AH$7 -> 9.2251868 | R25: =SUM(B25:P25) -> 92.687359
A26: ='1_1_Definition_Flows'!C26 -> F_17_19 | B26: =Solution_CC!B26 -> 0 | C26: =Solution_CC!C26 -> 2.8002051e-08 | D26: =Solution_CC!D26 -> 0.029306728 | E26: =Solution_CC!E26 -> 0.087605492 | F26: =Solution_CC!F26 -> 0.145668 | G26: =Solution_CC!G26 -> 0.20578887 | H26: =Solution_CC!H26 -> 0.27206776 | I26: =Solution_CC!I26 -> 0.3446994 | ... P26: =Solution_CC!P26 -> 0.92191146 | R26: =SUM(B26:P26) -> 5.737415
A31: dS_3 | B31: =B9-B10 -> 54.2177 | C31: =C9-C10 -> 39.036375 | D31: =D9-D10 -> 23.537196 | E31: =E9-E10 -> 23.773697 | F31: =F9-F10 -> 22.763363 | G31: =G9-G10 -> 19.464547 | H31: =H9-H10 -> 15.973094 | I31: =I9-I10 -> 14.341128 | ... P31: =P9-P10 -> 5.6449334 | R31: =SUM(B31:P31) -> 275.557
A32: S_3 | B32: =B31 -> 54.2177 | C32: =B32+C31 -> 93.254075 | D32: =C32+D31 -> 116.79127 | E32: =D32+E31 -> 140.56497 | F32: =E32+F31 -> 163.32833 | G32: =F32+G31 -> 182.79288 | H32: =G32+H31 -> 198.76597 | I32: =H32+I31 -> 213.1071 | J32: =I32+J31 -> 226.50704 | ... P32: =O32+P31 -> 275.557 | R32: =SUM(B32:P32) -> 2943.0193
A33: dS_5 | B33: =B7 -> 22.9218 | C33: =C7 -> 23.380236 | D33: =D7 -> 23.847841 | E33: =E7 -> 24.324798 | F33: =F7 -> 24.811293 | G33: =G7 -> 25.307519 | H33: =H7 -> 25.81367 | I33: =I7 -> 26.329943 | ... P33: =P7 -> 30.244828 | R33: =SUM(B33:P33) -> 396.39624
A34: S_5 | B34: =B33 -> 22.9218 | C34: =B34+C33 -> 46.302036 | D34: =C34+D33 -> 70.149877 | E34: =D34+E33 -> 94.474674 | F34: =E34+F33 -> 119.28597 | G34: =F34+G33 -> 144.59349 | H34: =G34+H33 -> 170.40716 | I34: =H34+I33 -> 196.7371 | J34: =I34+J33 -> 223.59364 | ... P34: =O34+P33 -> 396.39624 | R34: =SUM(B34:P34) -> 3024.8584
A35: dS_6 | B35: =B11 -> 12.841038 | C35: =C11 -> 13.097859 | D35: =D11 -> 13.359816 | E35: =E11 -> 13.627012 | F35: =F11 -> 13.899552 | G35: =G11 -> 14.177544 | H35: =H11 -> 14.461094 | I35: =I11 -> 14.750316 | ... P35: =P11 -> 16.943477 | R35: =SUM(B35:P35) -> 222.06542
A36: S_6 | B36: =B35 -> 12.841038 | C36: =B36+C35 -> 25.938897 | D36: =C36+D35 -> 39.298713 | E36: =D36+E35 -> 52.925725 | F36: =E36+F35 -> 66.825277 | G36: =F36+G35 -> 81.002821 | H36: =G36+H35 -> 95.463915 | I36: =H36+I35 -> 110.21423 | J36: =I36+J35 -> 125.25955 | ... P36: =O36+P35 -> 222.06542 | R36: =SUM(B36:P36) -> 1694.5581
A37: dS_12 | B37: =B15 -> 8.560692 | C37: =C15 -> 8.7319058 | D37: =D15 -> 8.906544 | E37: =E15 -> 9.0846748 | F37: =F15 -> 9.2663683 | G37: =G15 -> 9.4516957 | H37: =H15 -> 9.6407296 | I37: =I15 -> 9.8335442 | ... P37: =P15 -> 11.295651 | R37: =SUM(B37:P37) -> 148.04362
A38: S_12 | B38: =B37 -> 8.560692 | C38: =B38+C37 -> 17.292598 | D38: =C38+D37 -> 26.199142 | E38: =D38+E37 -> 35.283817 | F38: =E38+F37 -> 44.550185 | G38: =F38+G37 -> 54.001881 | H38: =G38+H37 -> 63.64261 | I38: =H38+I37 -> 73.476154 | J38: =I38+J37 -> 83.50637 | ... P38: =O38+P37 -> 148.04362 | R38: =SUM(B38:P38) -> 1129.7054
A39: dS_14 | B39: =B14 -> 67.058754 | C39: =C14 -> 68.399929 | D39: =D14 -> 69.767928 | E39: =E14 -> 71.163286 | F39: =F14 -> 72.586552 | G39: =G14 -> 74.038283 | H39: =H14 -> 75.519049 | I39: =I14 -> 77.02943 | ... P39: =P14 -> 88.482602 | R39: =SUM(B39:P39) -> 1159.675
A40: S_14 | B40: =B39 -> 67.058754 | C40: =C39+B40 -> 135.45868 | D40: =D39+C40 -> 205.22661 | E40: =E39+D40 -> 276.3899 | F40: =F39+E40 -> 348.97645 | G40: =G39+F40 -> 423.01473 | H40: =H39+G40 -> 498.53378 | I40: =I39+H40 -> 575.56321 | J40: =J39+I40 -> 654.13323 | ... P40: =P39+O40 -> 1159.675 | R40: =SUM(B40:P40) -> 8849.359
A41: dS_15 | B41: =B3 -> 51.6 | C41: =C3 -> 52.632 | D41: =D3 -> 53.68464 | E41: =E3 -> 54.758333 | F41: =F3 -> 55.853499 | G41: =G3 -> 56.970569 | H41: =H3 -> 58.109981 | I41: =I3 -> 59.27218 | ... P41: =P3 -> 68.085104 | R41: =SUM(B41:P41) -> 892.34031
A42: S_15 | B42: =B41 -> 51.6 | C42: =B42+C41 -> 104.232 | D42: =C42+D41 -> 157.91664 | E42: =D42+E41 -> 212.67497 | F42: =E42+F41 -> 268.52847 | G42: =F42+G41 -> 325.49904 | H42: =G42+H41 -> 383.60902 | I42: =H42+I41 -> 442.8812 | J42: =I42+J41 -> 503.33883 | ... P42: =O42+P41 -> 892.34031 | R42: =SUM(B42:P42) -> 6809.356
A43: dS_16 | B43: =B5 -> 25.8 | C43: =C5 -> 26.316 | D43: =D5 -> 26.84232 | E43: =E5 -> 27.379166 | F43: =F5 -> 27.92675 | G43: =G5 -> 28.485285 | H43: =H5 -> 29.05499 | I43: =I5 -> 29.63609 | ... P43: =P5 -> 34.042552 | R43: =SUM(B43:P43) -> 446.17016
A44: S_16 | B44: =B43 -> 25.8 | C44: =B44+C43 -> 52.116 | D44: =C44+D43 -> 78.95832 | E44: =D44+E43 -> 106.33749 | F44: =E44+F43 -> 134.26424 | G44: =F44+G43 -> 162.74952 | H44: =G44+H43 -> 191.80451 | I44: =H44+I43 -> 221.4406 | J44: =I44+J43 -> 251.66941 | ... P44: =O44+P43 -> 446.17016 | R44: =SUM(B44:P44) -> 3404.678
...

Sheet Solution_WC
B1: 2022 | C1: 2023 | D1: 2024 | E1: 2025 | F1: 2026 | G1: 2027 | H1: 2028 | I1: 2029 | J1: 2030 | K1: 2031 | L1: 2032 | M1: 2033 | N1: 2034 | O1: 2035 | P1: 2036
A2: ='1_1_Definition_Flows'!C2 -> F_13_20 | B2: {=Solution_material!B2*INDIRECT("Tab_Def_Flows[@WC]")} -> 7.74 | C2: {=Solution_material!C2*INDIRECT("Tab_Def_Flows[@WC]")} -> 7.8948 | D2: {=Solution_material!D2*INDIRECT("Tab_Def_Flows[@WC]")} -> 8.052696 | E2: {=Solution_material!E2*INDIRECT("Tab_Def_Flows[@WC]")} -> 8.2137499 | F2: {=Solution_material!F2*INDIRECT("Tab_Def_Flows[@WC]")} -> 8.3780249 | G2: {=Solution_material!G2*INDIRECT("Tab_Def_Flows[@WC]")} -> 8.5455854 | H2: {=Solution_material!H2*INDIRECT("Tab_Def_Flows[@WC]")} -> 8.7164971 | I2: {=Solution_material!I2*INDIRECT("Tab_Def_Flows[@WC]")} -> 8.8908271 | ... P2: {=Solution_material!P2*INDIRECT("Tab_Def_Flows[@WC]")} -> 10.212766 | R2: =SUM(B2:P2) -> 133.85105
A3: ='1_1_Definition_Flows'!C3 -> F_20_15 | B3: {=Solution_material!B3*INDIRECT("Tab_Def_Flows[@WC]")} -> 3.096 | C3: {=Solution_material!C3*INDIRECT("Tab_Def_Flows[@WC]")} -> 3.15792 | D3: {=Solution_material!D3*INDIRECT("Tab_Def_Flows[@WC]")} -> 3.2210784 | E3: {=Solution_material!E3*INDIRECT("Tab_Def_Flows[@WC]")} -> 3.2855 | F3: {=Solution_material!F3*INDIRECT("Tab_Def_Flows[@WC]")} -> 3.35121 | G3: {=Solution_material!G3*INDIRECT("Tab_Def_Flows[@WC]")} -> 3.4182342 | H3: {=Solution_material!H3*INDIRECT("Tab_Def_Flows[@WC]")} -> 3.4865989 | I3: {=Solution_material!I3*INDIRECT("Tab_Def_Flows[@WC]")} -> 3.5563308 | ... P3: {=Solution_material!P3*INDIRECT("Tab_Def_Flows[@WC]")} -> 4.0851063 | R3: =SUM(B3:P3) -> 53.540419
A4: ='1_1_Definition_Flows'!C4 -> F_20_01 | B4: {=Solution_material!B4*INDIRECT("Tab_Def_Flows[@WC]")} -> 3.096 | C4: {=Solution_material!C4*INDIRECT("Tab_Def_Flows[@WC]")} -> 3.15792 | D4: {=Solution_material!D4*INDIRECT("Tab_Def_Flows[@WC]")} -> 3.2210784 | E4: {=Solution_material!E4*INDIRECT("Tab_Def_Flows[@WC]")} -> 3.2855 | F4: {=Solution_material!F4*INDIRECT("Tab_Def_Flows[@WC]")} -> 3.35121 | G4: {=Solution_material!G4*INDIRECT("Tab_Def_Flows[@WC]")} -> 3.4182342 | H4: {=Solution_material!H4*INDIRECT("Tab_Def_Flows[@WC]")} -> 3.4865989 | I4: {=Solution_material!I4*INDIRECT("Tab_Def_Flows[@WC]")} -> 3.5563308 | ... P4: {=Solution_material!P4*INDIRECT("Tab_Def_Flows[@WC]")} -> 4.0851063 | R4: =SUM(B4:P4) -> 53.540419
A5: ='1_1_Definition_Flows'!C5 -> F_20_16 | B5: {=Solution_material!B5*INDIRECT("Tab_Def_Flows[@WC]")} -> 1.548 | C5: {=Solution_material!C5*INDIRECT("Tab_Def_Flows[@WC]")} -> 1.57896 | D5: {=Solution_material!D5*INDIRECT("Tab_Def_Flows[@WC]")} -> 1.6105392 | E5: {=Solution_material!E5*INDIRECT("Tab_Def_Flows[@WC]")} -> 1.64275 | F5: {=Solution_material!F5*INDIRECT("Tab_Def_Flows[@WC]")} -> 1.675605 | G5: {=Solution_material!G5*INDIRECT("Tab_Def_Flows[@WC]")} -> 1.7091171 | H5: {=Solution_material!H5*INDIRECT("Tab_Def_Flows[@WC]")} -> 1.7432994 | I5: {=Solution_material!I5*INDIRECT("Tab_Def_Flows[@WC]")} -> 1.7781654 | ... P5: {=Solution_material!P5*INDIRECT("Tab_Def_Flows[@WC]")} -> 2.0425531 | R5: =SUM(B5:P5) -> 26.770209
A6: ='1_1_Definition_Flows'!C6 -> F_04_01 | B6: {=Solution_material!B6*INDIRECT("Tab_Def_Flows[@WC]")} -> 36.66 | C6: {=Solution_material!C6*INDIRECT("Tab_Def_Flows[@WC]")} -> 37.3932 | D6: {=Solution_material!D6*INDIRECT("Tab_Def_Flows[@WC]")} -> 38.141064 | E6: {=Solution_material!E6*INDIRECT("Tab_Def_Flows[@WC]")} -> 38.903885 | F6: {=Solution_material!F6*INDIRECT("Tab_Def_Flows[@WC]")} -> 39.681963 | G6: {=Solution_material!G6*INDIRECT("Tab_Def_Flows[@WC]")} -> 40.475602 | H6: {=Solution_material!H6*INDIRECT("Tab_Def_Flows[@WC]")} -> 41.285114 | I6: {=Solution_material!I6*INDIRECT("Tab_Def_Flows[@WC]")} -> 42.110817 | ... P6: {=Solution_material!P6*INDIRECT("Tab_Def_Flows[@WC]")} -> 48.372091 | R6: =SUM(B6:P6) -> 633.97666
A7: ='1_1_Definition_Flows'!C7 -> F_01_05 | B7: {=Solution_material!B7*INDIRECT("Tab_Def_Flows[@WC]")} -> 0 | C7: {=Solution_material!C7*INDIRECT("Tab_Def_Flows[@WC]")} -> 0 | D7: {=Solution_material!D7*INDIRECT("Tab_Def_Flows[@WC]")} -> 0 | E7: {=Solution_material!E7*INDIRECT("Tab_Def_Flows[@WC]")} -> 0 | F7: {=Solution_material!F7*INDIRECT("Tab_Def_Flows[@WC]")} -> 0 | G7: {=Solution_material!G7*INDIRECT("Tab_Def_Flows[@WC]")} -> 0 | H7: {=Solution_material!H7*INDIRECT("Tab_Def_Flows[@WC]")} -> 0 | I7: {=Solution_material!I7*INDIRECT("Tab_Def_Flows[@WC]")} -> 0 | ... P7: {=Solution_material!P7*INDIRECT("Tab_Def_Flows[@WC]")} -> 0 | R7: =SUM(B7:P7) -> 0
A8: ='1_1_Definition_Flows'!C8 -> F_01_02 | B8: {=Solution_material!B8*INDIRECT("Tab_Def_Flows[@WC]")} -> 43.314048 | C8: {=Solution_material!C8*INDIRECT("Tab_Def_Flows[@WC]")} -> 44.180329 | D8: {=Solution_material!D8*INDIRECT("Tab_Def_Flows[@WC]")} -> 45.063936 | E8: {=Solution_material!E8*INDIRECT("Tab_Def_Flows[@WC]")} -> 45.965214 | F8: {=Solution_material!F8*INDIRECT("Tab_Def_Flows[@WC]")} -> 46.884519 | G8: {=Solution_material!G8*INDIRECT("Tab_Def_Flows[@WC]")} -> 47.822209 | H8: {=Solution_material!H8*INDIRECT("Tab_Def_Flows[@WC]")} -> 48.778653 | I8: {=Solution_material!I8*INDIRECT("Tab_Def_Flows[@WC]")} -> 49.754226 | ... P8: {=Solution_material!P8*INDIRECT("Tab_Def_Flows[@WC]")} -> 57.151966 | R8: =SUM(B8:P8) -> 749.04789
A9: ='1_1_Definition_Flows'!C9 -> F_02_03 | B9: {=Solution_material!B9*INDIRECT("Tab_Def_Flows[@WC]")} -> 33.072807 | C9: {=Solution_material!C9*INDIRECT("Tab_Def_Flows[@WC]")} -> 33.734263 | D9: {=Solution_material!D9*INDIRECT("Tab_Def_Flows[@WC]")} -> 34.408948 | E9: {=Solution_material!E9*INDIRECT("Tab_Def_Flows[@WC]")} -> 35.097127 | F9: {=Solution_material!F9*INDIRECT("Tab_Def_Flows[@WC]")} -> 35.79907 | G9: {=Solution_material!G9*INDIRECT("Tab_Def_Flows[@WC]")} -> 36.515051 | H9: {=Solution_material!H9*INDIRECT("Tab_Def_Flows[@WC]")} -> 37.245352 | I9: {=Solution_material!I9*INDIRECT("Tab_Def_Flows[@WC]")} -> 37.990259 | ... P9: {=Solution_material!P9*INDIRECT("Tab_Def_Flows[@WC]")} -> 43.638866 | R9: =SUM(B9:P9) -> 571.94184
A10: ='1_1_Definition_Flows'!C10 -> F_03_07 | B10: {=Solution_material!B10*INDIRECT("Tab_Def_Flows[@WC]")} -> 9.480372e-06 | C10: {=Solution_material!C10*INDIRECT("Tab_Def_Flows[@WC]")} -> 9.9220742 | D10: {=Solution_material!D10*INDIRECT("Tab_Def_Flows[@WC]")} -> 20.051259 | E10: {=Solution_material!E10*INDIRECT("Tab_Def_Flows[@WC]")} -> 20.595172 | F10: {=Solution_material!F10*INDIRECT("Tab_Def_Flows[@WC]")} -> 21.913418 | G10: {=Solution_material!G10*INDIRECT("Tab_Def_Flows[@WC]")} -> 24.641678 | H10: {=Solution_material!H10*INDIRECT("Tab_Def_Flows[@WC]")} -> 27.501765 | I10: {=Solution_material!I10*INDIRECT("Tab_Def_Flows[@WC]")} -> 29.242171 | ... P10: {=Solution_material!P10*INDIRECT("Tab_Def_Flows[@WC]")} -> 40.195457 | R10: =SUM(B10:P10) -> 403.85206
A11: ='1_1_Definition_Flows'!C11 -> F_02_06 | B11: {=Solution_material!B11*INDIRECT("Tab_Def_Flows[@WC]")} -> 8.2182643 | C11: {=Solution_material!C11*INDIRECT("Tab_Def_Flows[@WC]")} -> 8.3826296 | D11: {=Solution_material!D11*INDIRECT("Tab_Def_Flows[@WC]")} -> 8.5502822 | E11: {=Solution_material!E11*INDIRECT("Tab_Def_Flows[@WC]")} -> 8.7212878 | F11: {=Solution_material!F11*INDIRECT("Tab_Def_Flows[@WC]")} -> 8.8957136 | G11: {=Solution_material!G11*INDIRECT("Tab_Def_Flows[@WC]")} -> 9.0736279 | H11: {=Solution_material!H11*INDIRECT("Tab_Def_Flows[@WC]")} -> 9.2551004 | I11: {=Solution_material!I11*INDIRECT("Tab_Def_Flows[@WC]")} -> 9.4402024 | ... P11: {=Solution_material!P11*INDIRECT("Tab_Def_Flows[@WC]")} -> 10.843825 | R11: =SUM(B11:P11) -> 142.12187
A12: ='1_1_Definition_Flows'!C12 -> F_11_02 | B12: {=Solution_material!B12*INDIRECT("Tab_Def_Flows[@WC]")} -> 0.66 | C12: {=Solution_material!C12*INDIRECT("Tab_Def_Flows[@WC]")} -> 0.6732 | D12: {=Solution_material!D12*INDIRECT("Tab_Def_Flows[@WC]")} -> 0.686664 | E12: {=Solution_material!E12*INDIRECT("Tab_Def_Flows[@WC]")} -> 0.70039728 | F12: {=Solution_material!F12*INDIRECT("Tab_Def_Flows[@WC]")} -> 0.71440523 | G12: {=Solution_material!G12*INDIRECT("Tab_Def_Flows[@WC]")} -> 0.72869333 | H12: {=Solution_material!H12*INDIRECT("Tab_Def_Flows[@WC]")} -> 0.7432672 | I12: {=Solution_material!I12*INDIRECT("Tab_Def_Flows[@WC]")} -> 0.75813254 | ... P12: {=Solution_material!P12*INDIRECT("Tab_Def_Flows[@WC]")} -> 0.87085598 | R12: =SUM(B12:P12) -> 11.413655
A13: ='1_1_Definition_Flows'!C13 -> F_08_02 | B13: {=Solution_material!B13*INDIRECT("Tab_Def_Flows[@WC]")} -> 74 | C13: {=Solution_material!C13*INDIRECT("Tab_Def_Flows[@WC]")} -> 75.48 | D13: {=Solution_material!D13*INDIRECT("Tab_Def_Flows[@WC]")} -> 76.9896 | E13: {=Solution_material!E13*INDIRECT("Tab_Def_Flows[@WC]")} -> 78.529392 | F13: {=Solution_material!F13*INDIRECT("Tab_Def_Flows[@WC]")} -> 80.09998 | G13: {=Solution_material!G13*INDIRECT("Tab_Def_Flows[@WC]")} -> 81.701979 | H13: {=Solution_material!H13*INDIRECT("Tab_Def_Flows[@WC]")} -> 83.336019 | I13: {=Solution_material!I13*INDIRECT("Tab_Def_Flows[@WC]")} -> 85.002739 | ... P13: {=Solution_material!P13*INDIRECT("Tab_Def_Flows[@WC]")} -> 97.641428 | R13: =SUM(B13:P13) -> 1279.7129
... A26: ='1_1_Definition_Flows'!C26 -> F_17_19 | B26: {=Solution_material!B26*INDIRECT("Tab_Def_Flows[@WC]")} -> 0 | C26: {=Solution_material!C26*INDIRECT("Tab_Def_Flows[@WC]")} -> 0 | D26: {=Solution_material!D26*INDIRECT("Tab_Def_Flows[@WC]")} -> 0 | E26: {=Solution_material!E26*INDIRECT("Tab_Def_Flows[@WC]")} -> 0 | F26: {=Solution_material!F26*INDIRECT("Tab_Def_Flows[@WC]")} -> 0 | G26: {=Solution_material!G26*INDIRECT("Tab_Def_Flows[@WC]")} -> 0 | H26: {=Solution_material!H26*INDIRECT("Tab_Def_Flows[@WC]")} -> 0 | I26: {=Solution_material!I26*INDIRECT("Tab_Def_Flows[@WC]")} -> 0 | ... P26: {=Solution_material!P26*INDIRECT("Tab_Def_Flows[@WC]")} -> 0 | R26: =SUM(B26:P26) -> 0
A31: dS_3 | B31: =B9-B10 -> 33.072797 | C31: =C9-C10 -> 23.812189 | D31: =D9-D10 -> 14.35769 | E31: =E9-E10 -> 14.501955 | F31: =F9-F10 -> 13.885651 | G31: =G9-G10 -> 11.873373 | H31: =H9-H10 -> 9.7435872 | I31: =I9-I10 -> 8.748088 | ... P31: =P9-P10 -> 3.4434094 | R31: =SUM(B31:P31) -> 168.08977
A32: S_3 | B32: =B31 -> 33.072797 | C32: =B32+C31 -> 56.884986 | D32: =C32+D31 -> 71.242676 | E32: =D32+E31 -> 85.744631 | F32: =E32+F31 -> 99.630282 | G32: =F32+G31 -> 111.50366 | H32: =G32+H31 -> 121.24724 | I32: =H32+I31 -> 129.99533 | J32: =I32+J31 -> 138.16929 | ... P32: =O32+P31 -> 168.08977 | R32: =SUM(B32:P32) -> 1795.2418
A33: dS_5 | B33: =B7 -> 0 | C33: =C7 -> 0 | D33: =D7 -> 0 | E33: =E7 -> 0 | F33: =F7 -> 0 | G33: =G7 -> 0 | H33: =H7 -> 0 | I33: =I7 -> 0 | ... P33: =P7 -> 0 | R33: =SUM(B33:P33) -> 0
A34: S_5 | B34: =B33 -> 0 | C34: =B34+C33 -> 0 | D34: =C34+D33 -> 0 | E34: =D34+E33 -> 0 | F34: =E34+F33 -> 0 | G34: =F34+G33 -> 0 | H34: =G34+H33 -> 0 | I34: =H34+I33 -> 0 | J34: =I34+J33 -> 0 | ... P34: =O34+P33 -> 0 | R34: =SUM(B34:P34) -> 0
A35: dS_6 | B35: =B11 -> 8.2182643 | C35: =C11 -> 8.3826296 | D35: =D11 -> 8.5502822 | E35: =E11 -> 8.7212878 | F35: =F11 -> 8.8957136 | G35: =G11 -> 9.0736279 | H35: =H11 -> 9.2551004 | I35: =I11 -> 9.4402024 | ... P35: =P11 -> 10.843825 | R35: =SUM(B35:P35) -> 142.12187
A36: S_6 | B36: =B35 -> 8.2182643 | C36: =B36+C35 -> 16.600894 | D36: =C36+D35 -> 25.151176 | E36: =D36+E35 -> 33.872464 | F36: =E36+F35 -> 42.768178 | G36: =F36+G35 -> 51.841805 | H36: =G36+H35 -> 61.096906 | I36: =H36+I35 -> 70.537108 | J36: =I36+J35 -> 80.166115 | ... P36: =O36+P35 -> 142.12187 | R36: =SUM(B36:P36) -> 1084.5172
A37: dS_12 | B37: =B15 -> 8.560692 | C37: =C15 -> 8.7319058 | D37: =D15 -> 8.906544 | E37: =E15 -> 9.0846748 | F37: =F15 -> 9.2663683 | G37: =G15 -> 9.4516957 | H37: =H15 -> 9.6407296 | I37: =I15 -> 9.8335442 | ... P37: =P15 -> 11.295651 | R37: =SUM(B37:P37) -> 148.04362
A38: S_12 | B38: =B37 -> 8.560692 | C38: =B38+C37 -> 17.292598 | D38: =C38+D37 -> 26.199142 | E38: =D38+E37 -> 35.283817 | F38: =E38+F37 -> 44.550185 | G38: =F38+G37 -> 54.001881 | H38: =G38+H37 -> 63.64261 | I38: =H38+I37 -> 73.476154 | J38: =I38+J37 -> 83.50637 | ... P38: =O38+P37 -> 148.04362 | R38: =SUM(B38:P38) -> 1129.7054
A39: dS_14 | B39: =B14 -> 67.058754 | C39: =C14 -> 68.399929 | D39: =D14 -> 69.767928 | E39: =E14 -> 71.163286 | F39: =F14 -> 72.586552 | G39: =G14 -> 74.038283 | H39: =H14 -> 75.519049 | I39: =I14 -> 77.02943 | ... P39: =P14 -> 88.482602 | R39: =SUM(B39:P39) -> 1159.675
A40: S_14 | B40: =B39 -> 67.058754 | C40: =C39+B40 -> 135.45868 | D40: =D39+C40 -> 205.22661 | E40: =E39+D40 -> 276.3899 | F40: =F39+E40 -> 348.97645 | G40: =G39+F40 -> 423.01473 | H40: =H39+G40 -> 498.53378 | I40: =I39+H40 -> 575.56321 | J40: =J39+I40 -> 654.13323 | ... P40: =P39+O40 -> 1159.675 | R40: =SUM(B40:P40) -> 8849.359
A41: dS_15 | B41: =B3 -> 3.096 | C41: =C3 -> 3.15792 | D41: =D3 -> 3.2210784 | E41: =E3 -> 3.2855 | F41: =F3 -> 3.35121 | G41: =G3 -> 3.4182342 | H41: =H3 -> 3.4865989 | I41: =I3 -> 3.5563308 | ... P41: =P3 -> 4.0851063 | R41: =SUM(B41:P41) -> 53.540419
A42: S_15 | B42: =B41 -> 3.096 | C42: =B42+C41 -> 6.25392 | D42: =C42+D41 -> 9.4749984 | E42: =D42+E41 -> 12.760498 | F42: =E42+F41 -> 16.111708 | G42: =F42+G41 -> 19.529943 | H42: =G42+H41 -> 23.016541 | I42: =H42+I41 -> 26.572872 | J42: =I42+J41 -> 30.20033 | ... P42: =O42+P41 -> 53.540419 | R42: =SUM(B42:P42) -> 408.56136
A43: dS_16 | B43: =B5 -> 1.548 | C43: =C5 -> 1.57896 | D43: =D5 -> 1.6105392 | E43: =E5 -> 1.64275 | F43: =F5 -> 1.675605 | G43: =G5 -> 1.7091171 | H43: =H5 -> 1.7432994 | I43: =I5 -> 1.7781654 | ... P43: =P5 -> 2.0425531 | R43: =SUM(B43:P43) -> 26.770209
A44: S_16 | B44: =B43 -> 1.548 | C44: =B44+C43 -> 3.12696 | D44: =C44+D43 -> 4.7374992 | E44: =D44+E43 -> 6.3802492 | F44: =E44+F43 -> 8.0558542 | G44: =F44+G43 -> 9.7649713 | H44: =G44+H43 -> 11.508271 | I44: =H44+I43 -> 13.286436 | J44: =I44+J43 -> 15.100165 | ... P44: =O44+P43 -> 26.770209 | R44: =SUM(B44:P44) -> 204.28068
A45: dS_17 | B45: 0 | C45: =C46-B46 -> 0 | D45: =D46-C46 -> 0 | E45: =E46-D46 -> 0 | F45: =F46-E46 -> 0 | G45: =G46-F46 -> 0 | H45: =H46-G46 -> 0 | I45: =I46-H46 -> 0 | J45: =J46-I46 -> 0 | ... P45: =P46-O46 -> 0 | R45: =SUM(B45:P45) -> 0
A46: S_17 | B46: 0 | C46: 0 | D46: 0 | E46: 0 | F46: 0 | G46: 0 | H46: 0 | I46: 0 | J46: 0 | K46: 0 | L46: 0 | M46: 0 | N46: 0 | O46: 0 | P46: 0 | R46: =SUM(B46:P46) -> 0
A47: dS_18 | B47: =B19 -> 0 | C47: =C19 -> 0 | D47: =D19 -> 0 | E47: =E19 -> 0 | F47: =F19 -> 0 | G47: =G19 -> 0 | H47: =H19 -> 0 | I47: =I19 -> 0 | ... P47: =P19 -> 0 | R47: =SUM(B47:P47) -> 0
A48: S_18 | B48: =B47 -> 0 | C48: =B48+C47 -> 0 | D48: =C48+D47 -> 0 | E48: =D48+E47 -> 0 | F48: =E48+F47 -> 0 | G48: =F48+G47 -> 0 | H48: =G48+H47 -> 0 | I48: =H48+I47 -> 0 | J48: =I48+J47 -> 0 | ... P48: =O48+P47 -> 0 | R48: =SUM(B48:P48) -> 0
A49: dS_19 | B49: =B25+B26+B20 -> 0 | C49: =C25+C26+C20 -> 0 | D49: =D25+D26+D20 -> 0 | E49: =E25+E26+E20 -> 0 | F49: =F25+F26+F20 -> 0 | G49: =G25+G26+G20 -> 0 | H49: =H25+H26+H20 -> 0 | I49: =I25+I26+I20 -> 0 | ... P49: =P25+P26+P20 -> 0 | R49: =SUM(B49:P49) -> 0
A50: S_19 | B50: =B49 -> 0 | C50: =B50+C49 -> 0 | D50: =C50+D49 -> 0 | E50: =D50+E49 -> 0 | F50: =E50+F49 -> 0 | G50: =F50+G49 -> 0 | H50: =G50+H49 -> 0 | I50: =H50+I49 -> 0 | J50: =I50+J49 -> 0 | ... P50: =O50+P49 -> 0 | R50: =SUM(B50:P50) -> 0

Sheet Solution_DM
B1: 2022 | C1: 2023 | D1: 2024 | E1: 2025 | F1: 2026 | G1: 2027 | H1: 2028 | I1: 2029 | J1: 2030 | K1: 2031 | L1: 2032 | M1: 2033 | N1: 2034 | O1: 2035 | P1: 2036
