Workbook

Sheet Mass_balance_material
A1: P0 | B1: P1 | C1: P2 | D1: P3 | E1: P4 | F1: P5 | G1: P6 | H1: P7 | I1: P8 | J1: P9 | K1: P10 | L1: P11 | M1: P12 | N1: P13 | O1: P14 | P1: P15 | Q1: P16 | R1: P17 | S1: P18 | T1: P19 | U1: P20
A2: =A22-StockDict_material!B2-StockDict_material!D2-StockDict_material!F2-StockDict_material!H2-StockDict_material!J2-StockDict_material!L2-StockDict_material!N2-StockDict_material!P2-StockDict_material!R2-StockDict_material!T2 -> 2.8421713e-14 | B2: =FlowDict_material!D2+FlowDict_material!F2-FlowDict_material!H2-FlowDict_material!G2 -> 0 | C2: =FlowDict_material!H2+FlowDict_material!M2+FlowDict_material!L2-FlowDict_material!N2-FlowDict_material!I2-FlowDict_material!O2-FlowDict_material!K2 -> 0 | D2: =FlowDict_material!I2-FlowDict_material!J2-StockDict_material!B2 -> 0 | E2: =FlowDict_material!V2-FlowDict_material!F2 -> 0 | F2: =FlowDict_material!G2-StockDict_material!D2 -> 0 | G2: =FlowDict_material!K2-StockDict_material!F2 -> 0 | H2: =FlowDict_material!J2-FlowDict_material!P2-FlowDict_material!Q2 -> 0 | I2: =FlowDict_material!X2-FlowDict_material!M2 -> 0 | J2: =FlowDict_material!P2-FlowDict_material!R2-FlowDict_material!Y2 -> 0 | K2: =FlowDict_material!Q2-FlowDict_material!T2-FlowDict_material!S2 -> 5.2939559e-21 | L2: =FlowDict_material!W2-FlowDict_material!L2 -> 0 | M2: =FlowDict_material!O2-StockDict_material!H2 -> 0 | N2: =FlowDict_material!U2-FlowDict_material!B2 -> 0 | O2: =FlowDict_material!N2-StockDict_material!J2 -> 0 | P2: =FlowDict_material!C2-StockDict_material!L2 -> 0 | Q2: =FlowDict_material!E2-StockDict_material!N2 -> 0 | R2: =FlowDict_material!R2-StockDict_material!P2-FlowDict_material!Z2 -> 0 | S2: =FlowDict_material!S2-StockDict_material!R2 -> 0 | T2: =FlowDict_material!Y2+FlowDict_material!Z2+FlowDict_material!T2-StockDict_material!T2 -> 0 | U2: =FlowDict_material!B2-FlowDict_material!D2-FlowDict_material!C2-FlowDict_material!E2 -> 0
A3: =A23-StockDict_material!B3-StockDict_material!D3-StockDict_material!F3-StockDict_material!H3-StockDict_material!J3-StockDict_material!L3-StockDict_material!N3-StockDict_material!P3-StockDict_material!R3-StockDict_material!T3 -> -4.6185278e-14 | B3: =FlowDict_material!D3+FlowDict_material!F3-FlowDict_material!H3-FlowDict_material!G3 -> 0 | C3: =FlowDict_material!H3+FlowDict_material!M3+FlowDict_material!L3-FlowDict_material!N3-FlowDict_material!I3-FlowDict_material!O3-FlowDict_material!K3 -> 0 | D3: =FlowDict_material!I3-FlowDict_material!J3-StockDict_material!B3 -> 0 | E3: =FlowDict_material!V3-FlowDict_material!F3 -> 0 | F3: =FlowDict_material!G3-StockDict_material!D3 -> 0 | G3: =FlowDict_material!K3-StockDict_material!F3 -> 0 | H3: =FlowDict_material!J3-FlowDict_material!P3-FlowDict_material!Q3 -> 0 | I3: =FlowDict_material!X3-FlowDict_material!M3 -> 0 | J3: =FlowDict_material!P3-FlowDict_material!R3-FlowDict_material!Y3 -> 0 | K3: =FlowDict_material!Q3-FlowDict_material!T3-FlowDict_material!S3 -> -4.4408921e-15 | L3: =FlowDict_material!W3-FlowDict_material!L3 -> 0 | M3: =FlowDict_material!O3-StockDict_material!H3 -> 0 | N3: =FlowDict_material!U3-FlowDict_material!B3 -> 0 | O3: =FlowDict_material!N3-StockDict_material!J3 -> 0 | P3: =FlowDict_material!C3-StockDict_material!L3 -> 0 | Q3: =FlowDict_material!E3-StockDict_material!N3 -> 0 | R3: =FlowDict_material!R3-StockDict_material!P3-FlowDict_material!Z3 -> 0 | S3: =FlowDict_material!S3-StockDict_material!R3 -> 0 | T3: =FlowDict_material!Y3+FlowDict_material!Z3+FlowDict_material!T3-StockDict_material!T3 -> 0 | U3: =FlowDict_material!B3-FlowDict_material!D3-FlowDict_material!C3-FlowDict_material!E3 -> 0
A4: =A24-StockDict_material!B4-StockDict_material!D4-StockDict_material!F4-StockDict_material!H4-StockDict_material!J4-StockDict_material!L4-StockDict_material!N4-StockDict_material!P4-StockDict_material!R4-StockDict_material!T4 -> 0 | B4: =FlowDict_material!D4+FlowDict_material!F4-FlowDict_material!H4-FlowDict_material!G4 -> 0 | C4: =FlowDict_material!H4+FlowDict_material!M4+FlowDict_material!L4-FlowDict_material!N4-FlowDict_material!I4-FlowDict_material!O4-FlowDict_material!K4 -> 0 | D4: =FlowDict_material!I4-FlowDict_material!J4-StockDict_material!B4 -> 0 | E4: =FlowDict_material!V4-FlowDict_material!F4 -> 0 | F4: =FlowDict_material!G4-StockDict_material!D4 -> 0 | G4: =FlowDict_material!K4-StockDict_material!F4 -> 0 | H4: =FlowDict_material!J4-FlowDict_material!P4-FlowDict_material!Q4 -> 0 | I4: =FlowDict_material!X4-FlowDict_material!M4 -> 0 | J4: =FlowDict_material!P4-FlowDict_material!R4-FlowDict_material!Y4 -> 0 | K4: =FlowDict_material!Q4-FlowDict_material!T4-FlowDict_material!S4 -> -3.5527137e-15 | L4: =FlowDict_material!W4-FlowDict_material!L4 -> 0 | M4: =FlowDict_material!O4-StockDict_material!H4 -> 0 | N4: =FlowDict_material!U4-FlowDict_material!B4 -> 0 | O4: =FlowDict_material!N4-StockDict_material!J4 -> 0 | P4: =FlowDict_material!C4-StockDict_material!L4 -> 0 | Q4: =FlowDict_material!E4-StockDict_material!N4 -> 0 | R4: =FlowDict_material!R4-StockDict_material!P4-FlowDict_material!Z4 -> 0 | S4: =FlowDict_material!S4-StockDict_material!R4 -> 0 | T4: =FlowDict_material!Y4+FlowDict_material!Z4+FlowDict_material!T4-StockDict_material!T4 -> 0 | U4: =FlowDict_material!B4-FlowDict_material!D4-FlowDict_material!C4-FlowDict_material!E4 -> 0
A5: =A25-StockDict_material!B5-StockDict_material!D5-StockDict_material!F5-StockDict_material!H5-StockDict_material!J5-StockDict_material!L5-StockDict_material!N5-StockDict_material!P5-StockDict_material!R5-StockDict_material!T5 -> 0 | B5: =FlowDict_material!D5+FlowDict_material!F5-FlowDict_material!H5-FlowDict_material!G5 -> 0 | C5: =FlowDict_material!H5+FlowDict_material!M5+FlowDict_material!L5-FlowDict_material!N5-FlowDict_material!I5-FlowDict_material!O5-FlowDict_material!K5 -> 0 | D5: =FlowDict_material!I5-FlowDict_material!J5-StockDict_material!B5 -> 0 | E5: =FlowDict_material!V5-FlowDict_material!F5 -> 0 | F5: =FlowDict_material!G5-StockDict_material!D5 -> 0 | G5: =FlowDict_material!K5-StockDict_material!F5 -> 0 | H5: =FlowDict_material!J5-FlowDict_material!P5-FlowDict_material!Q5 -> 0 | I5: =FlowDict_material!X5-FlowDict_material!M5 -> 0 | J5: =FlowDict_material!P5-FlowDict_material!R5-FlowDict_material!Y5 -> 0 | K5: =FlowDict_material!Q5-FlowDict_material!T5-FlowDict_material!S5 -> -4.4408921e-15 | L5: =FlowDict_material!W5-FlowDict_material!L5 -> 0 | M5: =FlowDict_material!O5-StockDict_material!H5 -> 0 | N5: =FlowDict_material!U5-FlowDict_material!B5 -> 0 | O5: =FlowDict_material!N5-StockDict_material!J5 -> 0 | P5: =FlowDict_material!C5-StockDict_material!L5 -> 0 | Q5: =FlowDict_material!E5-StockDict_material!N5 -> 0 | R5: =FlowDict_material!R5-StockDict_material!P5-FlowDict_material!Z5 -> 8.8817842e-16 | S5: =FlowDict_material!S5-StockDict_material!R5 -> 0 | T5: =FlowDict_material!Y5+FlowDict_material!Z5+FlowDict_material!T5-StockDict_material!T5 -> 0 | U5: =FlowDict_material!B5-FlowDict_material!D5-FlowDict_material!C5-FlowDict_material!E5 -> 0
A6: =A26-StockDict_material!B6-StockDict_material!D6-StockDict_material!F6-StockDict_material!H6-StockDict_material!J6-StockDict_material!L6-StockDict_material!N6-StockDict_material!P6-StockDict_material!R6-StockDict_material!T6 -> 0 | B6: =FlowDict_material!D6+FlowDict_material!F6-FlowDict_material!H6-FlowDict_material!G6 -> 0 | C6: =FlowDict_material!H6+FlowDict_material!M6+FlowDict_material!L6-FlowDict_material!N6-FlowDict_material!I6-FlowDict_material!O6-FlowDict_material!K6 -> 1.7763568e-14 | D6: =FlowDict_material!I6-FlowDict_material!J6-StockDict_material!B6 -> 0 | E6: =FlowDict_material!V6-FlowDict_material!F6 -> 0 | F6: =FlowDict_material!G6-StockDict_material!D6 -> 0 | G6: =FlowDict_material!K6-StockDict_material!F6 -> 0 | H6: =FlowDict_material!J6-FlowDict_material!P6-FlowDict_material!Q6 -> 0 | I6: =FlowDict_material!X6-FlowDict_material!M6 -> 0 | J6: =FlowDict_material!P6-FlowDict_material!R6-FlowDict_material!Y6 -> 0 | K6: =FlowDict_material!Q6-FlowDict_material!T6-FlowDict_material!S6 -> 0 | L6: =FlowDict_material!W6-FlowDict_material!L6 -> 0 | M6: =FlowDict_material!O6-StockDict_material!H6 -> 0 | N6: =FlowDict_material!U6-FlowDict_material!B6 -> 0 | O6: =FlowDict_material!N6-StockDict_material!J6 -> 0 | P6: =FlowDict_material!C6-StockDict_material!L6 -> 0 | Q6: =FlowDict_material!E6-StockDict_material!N6 -> 0 | R6: =FlowDict_material!R6-StockDict_material!P6-FlowDict_material!Z6 -> 0 | S6: =FlowDict_material!S6-StockDict_material!R6 -> 0 | T6: =FlowDict_material!Y6+FlowDict_material!Z6+FlowDict_material!T6-StockDict_material!T6 -> 0 | U6: =FlowDict_material!B6-FlowDict_material!D6-FlowDict_material!C6-FlowDict_material!E6 -> 0
A7: =A27-StockDict_material!B7-StockDict_material!D7-StockDict_material!F7-StockDict_material!H7-StockDict_material!J7-StockDict_material!L7-StockDict_material!N7-StockDict_material!P7-StockDict_material!R7-StockDict_material!T7 -> 0 | B7: =FlowDict_material!D7+FlowDict_material!F7-FlowDict_material!H7-FlowDict_material!G7 -> 0 | C7: =FlowDict_material!H7+FlowDict_material!M7+FlowDict_material!L7-FlowDict_material!N7-FlowDict_material!I7-FlowDict_material!O7-FlowDict_material!K7 -> 1.4210855e-14 | D7: =FlowDict_material!I7-FlowDict_material!J7-StockDict_material!B7 -> 0 | E7: =FlowDict_material!V7-FlowDict_material!F7 -> 0 | F7: =FlowDict_material!G7-StockDict_material!D7 -> 0 | G7: =FlowDict_material!K7-StockDict_material!F7 -> 0 | H7: =FlowDict_material!J7-FlowDict_material!P7-FlowDict_material!Q7 -> 0 | I7: =FlowDict_material!X7-FlowDict_material!M7 -> 0 | J7: =FlowDict_material!P7-FlowDict_material!R7-FlowDict_material!Y7 -> 0 | K7: =FlowDict_material!Q7-FlowDict_material!T7-FlowDict_material!S7 -> 0 | L7: =FlowDict_material!W7-FlowDict_material!L7 -> 0 | M7: =FlowDict_material!O7-StockDict_material!H7 -> 0 | N7: =FlowDict_material!U7-FlowDict_material!B7 -> 0 | O7: =FlowDict_material!N7-StockDict_material!J7 -> 0 | P7: =FlowDict_material!C7-StockDict_material!L7 -> 0 | Q7: =FlowDict_material!E7-StockDict_material!N7 -> 0 | R7: =FlowDict_material!R7-StockDict_material!P7-FlowDict_material!Z7 -> 4.1633363e-16 | S7: =FlowDict_material!S7-StockDict_material!R7 -> 0 | T7: =FlowDict_material!Y7+FlowDict_material!Z7+FlowDict_material!T7-StockDict_material!T7 -> 0 | U7: =FlowDict_material!B7-FlowDict_material!D7-FlowDict_material!C7-FlowDict_material!E7 -> -4.9737992e-14
A8: =A28-StockDict_material!B8-StockDict_material!D8-StockDict_material!F8-StockDict_material!H8-StockDict_material!J8-StockDict_material!L8-StockDict_material!N8-StockDict_material!P8-StockDict_material!R8-StockDict_material!T8 -> -6.3948846e-14 | B8: =FlowDict_material!D8+FlowDict_material!F8-FlowDict_material!H8-FlowDict_material!G8 -> 0 | C8: =FlowDict_material!H8+FlowDict_material!M8+FlowDict_material!L8-FlowDict_material!N8-FlowDict_material!I8-FlowDict_material!O8-FlowDict_material!K8 -> 0 | D8: =FlowDict_material!I8-FlowDict_material!J8-StockDict_material!B8 -> 0 | E8: =FlowDict_material!V8-FlowDict_material!F8 -> 0 | F8: =FlowDict_material!G8-StockDict_material!D8 -> 0 | G8: =FlowDict_material!K8-StockDict_material!F8 -> 0 | H8: =FlowDict_material!J8-FlowDict_material!P8-FlowDict_material!Q8 -> 0 | I8: =FlowDict_material!X8-FlowDict_material!M8 -> 0 | J8: =FlowDict_material!P8-FlowDict_material!R8-FlowDict_material!Y8 -> 0 | K8: =FlowDict_material!Q8-FlowDict_material!T8-FlowDict_material!S8 -> -9.3258734e-15 | L8: =FlowDict_material!W8-FlowDict_material!L8 -> 0 | M8: =FlowDict_material!O8-StockDict_material!H8 -> 0 | N8: =FlowDict_material!U8-FlowDict_material!B8 -> 0 | O8: =FlowDict_material!N8-StockDict_material!J8 -> 0 | P8: =FlowDict_material!C8-StockDict_material!L8 -> 0 | Q8: =FlowDict_material!E8-StockDict_material!N8 -> 0 | R8: =FlowDict_material!R8-StockDict_material!P8-FlowDict_material!Z8 -> 0 | S8: =FlowDict_material!S8-StockDict_material!R8 -> 0 | T8: =FlowDict_material!Y8+FlowDict_material!Z8+FlowDict_material!T8-StockDict_material!T8 -> 0 | U8: =FlowDict_material!B8-FlowDict_material!D8-FlowDict_material!C8-FlowDict_material!E8 -> -3.1974423e-14
A9: =A29-StockDict_material!B9-StockDict_material!D9-StockDict_material!F9-StockDict_material!H9-StockDict_material!J9-StockDict_material!L9-StockDict_material!N9-StockDict_material!P9-StockDict_material!R9-StockDict_material!T9 -> -5.6843419e-14 | B9: =FlowDict_material!D9+FlowDict_material!F9-FlowDict_material!H9-FlowDict_material!G9 -> 0 | C9: =FlowDict_material!H9+FlowDict_material!M9+FlowDict_material!L9-FlowDict_material!N9-FlowDict_material!I9-FlowDict_material!O9-FlowDict_material!K9 -> 0 | D9: =FlowDict_material!I9-FlowDict_material!J9-StockDict_material!B9 -> 0 | E9: =FlowDict_material!V9-FlowDict_material!F9 -> 0 | F9: =FlowDict_material!G9-StockDict_material!D9 -> 0 | G9: =FlowDict_material!K9-StockDict_material!F9 -> 0 | H9: =FlowDict_material!J9-FlowDict_material!P9-FlowDict_material!Q9 -> 0 | I9: =FlowDict_material!X9-FlowDict_material!M9 -> 0 | J9: =FlowDict_material!P9-FlowDict_material!R9-FlowDict_material!Y9 -> 0 | K9: =FlowDict_material!Q9-FlowDict_material!T9-FlowDict_material!S9 -> 7.5495166e-15 | L9: =FlowDict_material!W9-FlowDict_material!L9 -> 0 | M9: =FlowDict_material!O9-StockDict_material!H9 -> 0 | N9: =FlowDict_material!U9-FlowDict_material!B9 -> 0 | O9: =FlowDict_material!N9-StockDict_material!J9 -> 0 | P9: =FlowDict_material!C9-StockDict_material!L9 -> 0 | Q9: =FlowDict_material!E9-StockDict_material!N9 -> 0 | R9: =FlowDict_material!R9-StockDict_material!P9-FlowDict_material!Z9 -> 0 | S9: =FlowDict_material!S9-StockDict_material!R9 -> 0 | T9: =FlowDict_material!Y9+FlowDict_material!Z9+FlowDict_material!T9-StockDict_material!T9 -> 0 | U9: =FlowDict_material!B9-FlowDict_material!D9-FlowDict_material!C9-FlowDict_material!E9 -> -4.9737992e-14
A10: =A30-StockDict_material!B10-StockDict_material!D10-StockDict_material!F10-StockDict_material!H10-StockDict_material!J10-StockDict_material!L10-StockDict_material!N10-StockDict_material!P10-StockDict_material!R10-StockDict_material!T10 -> 0 | B10: =FlowDict_material!D10+FlowDict_material!F10-FlowDict_material!H10-FlowDict_material!G10 -> 0 | C10: =FlowDict_material!H10+FlowDict_material!M10+FlowDict_material!L10-FlowDict_material!N10-FlowDict_material!I10-FlowDict_material!O10-FlowDict_material!K10 -> 0 | D10: =FlowDict_material!I10-FlowDict_material!J10-StockDict_material!B10 -> 0 | E10: =FlowDict_material!V10-FlowDict_material!F10 -> 0 | F10: =FlowDict_material!G10-StockDict_material!D10 -> 0 | G10: =FlowDict_material!K10-StockDict_material!F10 -> 0 | H10: =FlowDict_material!J10-FlowDict_material!P10-FlowDict_material!Q10 -> 0 | I10: =FlowDict_material!X10-FlowDict_material!M10 -> 0 | J10: =FlowDict_material!P10-FlowDict_material!R10-FlowDict_material!Y10 -> 0 | K10: =FlowDict_material!Q10-FlowDict_material!T10-FlowDict_material!S10 -> 0 | L10: =FlowDict_material!W10-FlowDict_material!L10 -> 0 | M10: =FlowDict_material!O10-StockDict_material!H10 -> 0 | N10: =FlowDict_material!U10-FlowDict_material!B10 -> 0 | O10: =FlowDict_material!N10-StockDict_material!J10 -> 0 | P10: =FlowDict_material!C10-StockDict_material!L10 -> 0 | Q10: =FlowDict_material!E10-StockDict_material!N10 -> 0 | R10: =FlowDict_material!R10-StockDict_material!P10-FlowDict_material!Z10 -> 0 | S10: =FlowDict_material!S10-StockDict_material!R10 -> 0 | T10: =FlowDict_material!Y10+FlowDict_material!Z10+FlowDict_material!T10-StockDict_material!T10 -> 0 | U10: =FlowDict_material!B10-FlowDict_material!D10-FlowDict_material!C10-FlowDict_material!E10 -> 0
A11: =A31-StockDict_material!B11-StockDict_material!D11-StockDict_material!F11-StockDict_material!H11-StockDict_material!J11-StockDict_material!L11-StockDict_material!N11-StockDict_material!P11-StockDict_material!R11-StockDict_material!T11 -> 0 | B11: =FlowDict_material!D11+FlowDict_material!F11-FlowDict_material!H11-FlowDict_material!G11 -> 0 | C11: =FlowDict_material!H11+FlowDict_material!M11+FlowDict_material!L11-FlowDict_material!N11-FlowDict_material!I11-FlowDict_material!O11-FlowDict_material!K11 -> 0 | D11: =FlowDict_material!I11-FlowDict_material!J11-StockDict_material!B11 -> 0 | E11: =FlowDict_material!V11-FlowDict_material!F11 -> 0 | F11: =FlowDict_material!G11-StockDict_material!D11 -> 0 | G11: =FlowDict_material!K11-StockDict_material!F11 -> 0 | H11: =FlowDict_material!J11-FlowDict_material!P11-FlowDict_material!Q11 -> 0 | I11: =FlowDict_material!X11-FlowDict_material!M11 -> 0 | J11: =FlowDict_material!P11-FlowDict_material!R11-FlowDict_material!Y11 -> 0 | K11: =FlowDict_material!Q11-FlowDict_material!T11-FlowDict_material!S11 -> 0 | L11: =FlowDict_material!W11-FlowDict_material!L11 -> 0 | M11: =FlowDict_material!O11-StockDict_material!H11 -> 0 | N11: =FlowDict_material!U11-FlowDict_material!B11 -> 0 | O11: =FlowDict_material!N11-StockDict_material!J11 -> 0 | P11: =FlowDict_material!C11-StockDict_material!L11 -> 0 | Q11: =FlowDict_material!E11-StockDict_material!N11 -> 0 | R11: =FlowDict_material!R11-StockDict_material!P11-FlowDict_material!Z11 -> -8.8817842e-16 | S11: =FlowDict_material!S11-StockDict_material!R11 -> 0 | T11: =FlowDict_material!Y11+FlowDict_material!Z11+FlowDict_material!T11-StockDict_material!T11 -> 0 | U11: =FlowDict_material!B11-FlowDict_material!D11-FlowDict_material!C11-FlowDict_material!E11 -> -4.9737992e-14
A12: =A32-StockDict_material!B12-StockDict_material!D12-StockDict_material!F12-StockDict_material!H12-StockDict_material!J12-StockDict_material!L12-StockDict_material!N12-StockDict_material!P12-StockDict_material!R12-StockDict_material!T12 -> 0 | B12: =FlowDict_material!D12+FlowDict_material!F12-FlowDict_material!H12-FlowDict_material!G12 -> 0 | C12: =FlowDict_material!H12+FlowDict_material!M12+FlowDict_material!L12-FlowDict_material!N12-FlowDict_material!I12-FlowDict_material!O12-FlowDict_material!K12 -> 1.5987212e-14 | D12: =FlowDict_material!I12-FlowDict_material!J12-StockDict_material!B12 -> 0 | E12: =FlowDict_material!V12-FlowDict_material!F12 -> 0 | F12: =FlowDict_material!G12-StockDict_material!D12 -> 0 | G12: =FlowDict_material!K12-StockDict_material!F12 -> 0 | H12: =FlowDict_material!J12-FlowDict_material!P12-FlowDict_material!Q12 -> 0 | I12: =FlowDict_material!X12-FlowDict_material!M12 -> 0 | J12: =FlowDict_material!P12-FlowDict_material!R12-FlowDict_material!Y12 -> 0 | K12: =FlowDict_material!Q12-FlowDict_material!T12-FlowDict_material!S12 -> 0 | L12: =FlowDict_material!W12-FlowDict_material!L12 -> 0 | M12: =FlowDict_material!O12-StockDict_material!H12 -> 0 | N12: =FlowDict_material!U12-FlowDict_material!B12 -> 0 | O12: =FlowDict_material!N12-StockDict_material!J12 -> 0 | P12: =FlowDict_material!C12-StockDict_material!L12 -> 0 | Q12: =FlowDict_material!E12-StockDict_material!N12 -> 0 | R12: =FlowDict_material!R12-StockDict_material!P12-FlowDict_material!Z12 -> 0 | S12: =FlowDict_material!S12-StockDict_material!R12 -> 0 | T12: =FlowDict_material!Y12+FlowDict_material!Z12+FlowDict_material!T12-StockDict_material!T12 -> 0 | U12: =FlowDict_material!B12-FlowDict_material!D12-FlowDict_material!C12-FlowDict_material!E12 -> 3.5527137e-14
A13: =A33-StockDict_material!B13-StockDict_material!D13-StockDict_material!F13-StockDict_material!H13-StockDict_material!J13-StockDict_material!L13-StockDict_material!N13-StockDict_material!P13-StockDict_material!R13-StockDict_material!T13 -> 0 | B13: =FlowDict_material!D13+FlowDict_material!F13-FlowDict_material!H13-FlowDict_material!G13 -> 0 | C13: =FlowDict_material!H13+FlowDict_material!M13+FlowDict_material!L13-FlowDict_material!N13-FlowDict_material!I13-FlowDict_material!O13-FlowDict_material!K13 -> 0 | D13: =FlowDict_material!I13-FlowDict_material!J13-StockDict_material!B13 -> 0 | E13: =FlowDict_material!V13-FlowDict_material!F13 -> 0 | F13: =FlowDict_material!G13-StockDict_material!D13 -> 0 | G13: =FlowDict_material!K13-StockDict_material!F13 -> 0 | H13: =FlowDict_material!J13-FlowDict_material!P13-FlowDict_material!Q13 -> 0 | I13: =FlowDict_material!X13-FlowDict_material!M13 -> 0 | J13: =FlowDict_material!P13-FlowDict_material!R13-FlowDict_material!Y13 -> 0 | K13: =FlowDict_material!Q13-FlowDict_material!T13-FlowDict_material!S13 -> 0 | L13: =FlowDict_material!W13-FlowDict_material!L13 -> 0 | M13: =FlowDict_material!O13-StockDict_material!H13 -> 0 | N13: =FlowDict_material!U13-FlowDict_material!B13 -> 0 | O13: =FlowDict_material!N13-StockDict_material!J13 -> 0 | P13: =FlowDict_material!C13-StockDict_material!L13 -> 0 | Q13: =FlowDict_material!E13-StockDict_material!N13 -> 0 | R13: =FlowDict_material!R13-StockDict_material!P13-FlowDict_material!Z13 -> 8.8817842e-16 | S13: =FlowDict_material!S13-StockDict_material!R13 -> 0 | T13: =FlowDict_material!Y13+FlowDict_material!Z13+FlowDict_material!T13-StockDict_material!T13 -> 0 | U13: =FlowDict_material!B13-FlowDict_material!D13-FlowDict_material!C13-FlowDict_material!E13 -> 0
... A16: =A36-StockDict_material!B16-StockDict_material!D16-StockDict_material!F16-StockDict_material!H16-StockDict_material!J16-StockDict_material!L16-StockDict_material!N16-StockDict_material!P16-StockDict_material!R16-StockDict_material!T16 -> 0 | B16: =FlowDict_material!D16+FlowDict_material!F16-FlowDict_material!H16-FlowDict_material!G16 -> 0 | C16: =FlowDict_material!H16+FlowDict_material!M16+FlowDict_material!L16-FlowDict_material!N16-FlowDict_material!I16-FlowDict_material!O16-FlowDict_material!K16 -> 0 | D16: =FlowDict_material!I16-FlowDict_material!J16-StockDict_material!B16 -> 0 | E16: =FlowDict_material!V16-FlowDict_material!F16 -> 0 | F16: =FlowDict_material!G16-StockDict_material!D16 -> 0 | G16: =FlowDict_material!K16-StockDict_material!F16 -> 0 | H16: =FlowDict_material!J16-FlowDict_material!P16-FlowDict_material!Q16 -> 0 | I16: =FlowDict_material!X16-FlowDict_material!M16 -> 0 | J16: =FlowDict_material!P16-FlowDict_material!R16-FlowDict_material!Y16 -> 0 | K16: =FlowDict_material!Q16-FlowDict_material!T16-FlowDict_material!S16 -> 0 | L16: =FlowDict_material!W16-FlowDict_material!L16 -> 0 | M16: =FlowDict_material!O16-StockDict_material!H16 -> 0 | N16: =FlowDict_material!U16-FlowDict_material!B16 -> 0 | O16: =FlowDict_material!N16-StockDict_material!J16 -> 0 | P16: =FlowDict_material!C16-StockDict_material!L16 -> 0 | Q16: =FlowDict_material!E16-StockDict_material!N16 -> 0 | R16: =FlowDict_material!R16-StockDict_material!P16-FlowDict_material!Z16 -> 0 | S16: =FlowDict_material!S16-StockDict_material!R16 -> 0 | T16: =FlowDict_material!Y16+FlowDict_material!Z16+FlowDict_material!T16-StockDict_material!T16 -> 0 | U16: =FlowDict_material!B16-FlowDict_material!D16-FlowDict_material!C16-FlowDict_material!E16 -> 0
A21: Sum outflows of P0
A22: =SUM(FlowDict_material!U2:X2) -> 243
A23: =SUM(FlowDict_material!U3:X3) -> 247.86
A24: =SUM(FlowDict_material!U4:X4) -> 252.8172
A25: =SUM(FlowDict_material!U5:X5) -> 257.87354
A26: =SUM(FlowDict_material!U6:X6) -> 263.03101
A27: =SUM(FlowDict_material!U7:X7) -> 268.29164
A28: =SUM(FlowDict_material!U8:X8) -> 273.65747
A29: =SUM(FlowDict_material!U9:X9) -> 279.13062
A30: =SUM(FlowDict_material!U10:X10) -> 284.71323
A31: =SUM(FlowDict_material!U11:X11) -> 290.40749
A32: =SUM(FlowDict_material!U12:X12) -> 296.21564
A33: =SUM(FlowDict_material!U13:X13) -> 302.13996
... A36: =SUM(FlowDict_material!U16:X16) -> 320.63334

Sheet Mass_balance_WC
A1: P0 | B1: P1 | C1: P2 | D1: P3 | E1: P4 | F1: P5 | G1: P6 | H1: P7 | I1: P8 | J1: P9 | K1: P10 | L1: P11 | M1: P12 | N1: P13 | O1: P14 | P1: P15 | Q1: P16 | R1: P17 | S1: P18 | T1: P19 | U1: P20
A2: =A22-StockDict_WC!B2-StockDict_WC!F2-StockDict_WC!D2-StockDict_WC!H2-StockDict_WC!J2-StockDict_WC!L2-StockDict_WC!N2-StockDict_WC!P2-StockDict_WC!R2-StockDict_WC!T2 -> -2.4945076 | B2: =FlowDict_WC!D2+FlowDict_WC!F2-FlowDict_WC!H2-FlowDict_WC!G2 -> -3.558048 | C2: =FlowDict_WC!H2+FlowDict_WC!M2+FlowDict_WC!L2-FlowDict_WC!N2-FlowDict_WC!I2-FlowDict_WC!O2-FlowDict_WC!K2 -> 1.0635309 | D2: =FlowDict_WC!I2-FlowDict_WC!J2-StockDict_WC!B2 -> 0 | E2: =FlowDict_WC!V2-FlowDict_WC!F2 -> 0 | F2: =FlowDict_WC!G2-StockDict_WC!D2 -> 0 | G2: =FlowDict_WC!K2-StockDict_WC!F2 -> 0 | H2: =FlowDict_WC!J2-FlowDict_WC!P2-FlowDict_WC!Q2 -> 0 | I2: =FlowDict_WC!X2-FlowDict_WC!M2 -> 0 | J2: =FlowDict_WC!P2-FlowDict_WC!R2-FlowDict_WC!Y2 -> 1.8960744e-06 | K2: =FlowDict_WC!Q2-FlowDict_WC!T2-FlowDict_WC!S2 -> 7.5842976e-06 | L2: =FlowDict_WC!W2-FlowDict_WC!L2 -> 0 | M2: =FlowDict_WC!O2-StockDict_WC!H2 -> 0 | N2: =FlowDict_WC!U2-FlowDict_WC!B2 -> 0 | O2: =FlowDict_WC!N2-StockDict_WC!J2 -> 0 | P2: =FlowDict_WC!C2-StockDict_WC!L2 -> 0 | Q2: =FlowDict_WC!E2-StockDict_WC!N2 -> 0 | R2: =FlowDict_WC!R2-StockDict_WC!P2-FlowDict_WC!Z2 -> 0 | S2: =FlowDict_WC!S2-StockDict_WC!R2 -> 0 | T2: =FlowDict_WC!Y2+FlowDict_WC!Z2+FlowDict_WC!T2-StockDict_WC!T2 -> 0 | U2: =FlowDict_WC!B2-FlowDict_WC!D2-FlowDict_WC!C2-FlowDict_WC!E2 -> 0
A3: =A23-StockDict_WC!B3-StockDict_WC!F3-StockDict_WC!D3-StockDict_WC!H3-StockDict_WC!J3-StockDict_WC!L3-StockDict_WC!N3-StockDict_WC!P3-StockDict_WC!R3-StockDict_WC!T3 -> 7.3776668 | B3: =FlowDict_WC!D3+FlowDict_WC!F3-FlowDict_WC!H3-FlowDict_WC!G3 -> -3.629209 | C3: =FlowDict_WC!H3+FlowDict_WC!M3+FlowDict_WC!L3-FlowDict_WC!N3-FlowDict_WC!I3-FlowDict_WC!O3-FlowDict_WC!K3 -> 1.0848015 | D3: =FlowDict_WC!I3-FlowDict_WC!J3-StockDict_WC!B3 -> 0 | E3: =FlowDict_WC!V3-FlowDict_WC!F3 -> 0 | F3: =FlowDict_WC!G3-StockDict_WC!D3 -> 0 | G3: =FlowDict_WC!K3-StockDict_WC!F3 -> 0 | H3: =FlowDict_WC!J3-FlowDict_WC!P3-FlowDict_WC!Q3 -> 0 | I3: =FlowDict_WC!X3-FlowDict_WC!M3 -> 0 | J3: =FlowDict_WC!P3-FlowDict_WC!R3-FlowDict_WC!Y3 -> 1.9844148 | K3: =FlowDict_WC!Q3-FlowDict_WC!T3-FlowDict_WC!S3 -> 7.9376593 | L3: =FlowDict_WC!W3-FlowDict_WC!L3 -> 0 | M3: =FlowDict_WC!O3-StockDict_WC!H3 -> 0 | N3: =FlowDict_WC!U3-FlowDict_WC!B3 -> 0 | O3: =FlowDict_WC!N3-StockDict_WC!J3 -> 0 | P3: =FlowDict_WC!C3-StockDict_WC!L3 -> 0 | Q3: =FlowDict_WC!E3-StockDict_WC!N3 -> 0 | R3: =FlowDict_WC!R3-StockDict_WC!P3-FlowDict_WC!Z3 -> 0 | S3: =FlowDict_WC!S3-StockDict_WC!R3 -> 0 | T3: =FlowDict_WC!Y3+FlowDict_WC!Z3+FlowDict_WC!T3-StockDict_WC!T3 -> 0 | U3: =FlowDict_WC!B3-FlowDict_WC!D3-FlowDict_WC!C3-FlowDict_WC!E3 -> 0
A4: =A24-StockDict_WC!B4-StockDict_WC!F4-StockDict_WC!D4-StockDict_WC!H4-StockDict_WC!J4-StockDict_WC!L4-StockDict_WC!N4-StockDict_WC!P4-StockDict_WC!R4-StockDict_WC!T4 -> 17.455963 | B4: =FlowDict_WC!D4+FlowDict_WC!F4-FlowDict_WC!H4-FlowDict_WC!G4 -> -3.7017931 | C4: =FlowDict_WC!H4+FlowDict_WC!M4+FlowDict_WC!L4-FlowDict_WC!N4-FlowDict_WC!I4-FlowDict_WC!O4-FlowDict_WC!K4 -> 1.1064976 | D4: =FlowDict_WC!I4-FlowDict_WC!J4-StockDict_WC!B4 -> 0 | E4: =FlowDict_WC!V4-FlowDict_WC!F4 -> 0 | F4: =FlowDict_WC!G4-StockDict_WC!D4 -> 0 | G4: =FlowDict_WC!K4-StockDict_WC!F4 -> 0 | H4: =FlowDict_WC!J4-FlowDict_WC!P4-FlowDict_WC!Q4 -> 0 | I4: =FlowDict_WC!X4-FlowDict_WC!M4 -> 0 | J4: =FlowDict_WC!P4-FlowDict_WC!R4-FlowDict_WC!Y4 -> 4.0102517 | K4: =FlowDict_WC!Q4-FlowDict_WC!T4-FlowDict_WC!S4 -> 16.041007 | L4: =FlowDict_WC!W4-FlowDict_WC!L4 -> 0 | M4: =FlowDict_WC!O4-StockDict_WC!H4 -> 0 | N4: =FlowDict_WC!U4-FlowDict_WC!B4 -> 0 | O4: =FlowDict_WC!N4-StockDict_WC!J4 -> 0 | P4: =FlowDict_WC!C4-StockDict_WC!L4 -> 0 | Q4: =FlowDict_WC!E4-StockDict_WC!N4 -> 0 | R4: =FlowDict_WC!R4-StockDict_WC!P4-FlowDict_WC!Z4 -> 0 | S4: =FlowDict_WC!S4-StockDict_WC!R4 -> 0 | T4: =FlowDict_WC!Y4+FlowDict_WC!Z4+FlowDict_WC!T4-StockDict_WC!T4 -> 0 | U4: =FlowDict_WC!B4-FlowDict_WC!D4-FlowDict_WC!C4-FlowDict_WC!E4 -> 0
A5: =A25-StockDict_WC!B5-StockDict_WC!F5-StockDict_WC!D5-StockDict_WC!H5-StockDict_WC!J5-StockDict_WC!L5-StockDict_WC!N5-StockDict_WC!P5-StockDict_WC!R5-StockDict_WC!T5 -> 17.94797 | B5: =FlowDict_WC!D5+FlowDict_WC!F5-FlowDict_WC!H5-FlowDict_WC!G5 -> -3.775829 | C5: =FlowDict_WC!H5+FlowDict_WC!M5+FlowDict_WC!L5-FlowDict_WC!N5-FlowDict_WC!I5-FlowDict_WC!O5-FlowDict_WC!K5 -> 1.1286275 | D5: =FlowDict_WC!I5-FlowDict_WC!J5-StockDict_WC!B5 -> 0 | E5: =FlowDict_WC!V5-FlowDict_WC!F5 -> 0 | F5: =FlowDict_WC!G5-StockDict_WC!D5 -> 0 | G5: =FlowDict_WC!K5-StockDict_WC!F5 -> 0 | H5: =FlowDict_WC!J5-FlowDict_WC!P5-FlowDict_WC!Q5 -> 0 | I5: =FlowDict_WC!X5-FlowDict_WC!M5 -> 0 | J5: =FlowDict_WC!P5-FlowDict_WC!R5-FlowDict_WC!Y5 -> 4.1190344 | K5: =FlowDict_WC!Q5-FlowDict_WC!T5-FlowDict_WC!S5 -> 16.476137 | L5: =FlowDict_WC!W5-FlowDict_WC!L5 -> 0 | M5: =FlowDict_WC!O5-StockDict_WC!H5 -> 0 | N5: =FlowDict_WC!U5-FlowDict_WC!B5 -> 0 | O5: =FlowDict_WC!N5-StockDict_WC!J5 -> 0 | P5: =FlowDict_WC!C5-StockDict_WC!L5 -> 0 | Q5: =FlowDict_WC!E5-StockDict_WC!N5 -> 0 | R5: =FlowDict_WC!R5-StockDict_WC!P5-FlowDict_WC!Z5 -> 0 | S5: =FlowDict_WC!S5-StockDict_WC!R5 -> 0 | T5: =FlowDict_WC!Y5+FlowDict_WC!Z5+FlowDict_WC!T5-StockDict_WC!T5 -> 0 | U5: =FlowDict_WC!B5-FlowDict_WC!D5-FlowDict_WC!C5-FlowDict_WC!E5 -> 0
A6: =A26-StockDict_WC!B6-StockDict_WC!F6-StockDict_WC!D6-StockDict_WC!H6-StockDict_WC!J6-StockDict_WC!L6-StockDict_WC!N6-StockDict_WC!P6-StockDict_WC!R6-StockDict_WC!T6 -> 19.213273 | B6: =FlowDict_WC!D6+FlowDict_WC!F6-FlowDict_WC!H6-FlowDict_WC!G6 -> -3.8513456 | C6: =FlowDict_WC!H6+FlowDict_WC!M6+FlowDict_WC!L6-FlowDict_WC!N6-FlowDict_WC!I6-FlowDict_WC!O6-FlowDict_WC!K6 -> 1.1512001 | D6: =FlowDict_WC!I6-FlowDict_WC!J6-StockDict_WC!B6 -> 0 | E6: =FlowDict_WC!V6-FlowDict_WC!F6 -> 0 | F6: =FlowDict_WC!G6-StockDict_WC!D6 -> 0 | G6: =FlowDict_WC!K6-StockDict_WC!F6 -> 0 | H6: =FlowDict_WC!J6-FlowDict_WC!P6-FlowDict_WC!Q6 -> 0 | I6: =FlowDict_WC!X6-FlowDict_WC!M6 -> 0 | J6: =FlowDict_WC!P6-FlowDict_WC!R6-FlowDict_WC!Y6 -> 4.3826836 | K6: =FlowDict_WC!Q6-FlowDict_WC!T6-FlowDict_WC!S6 -> 17.530735 | L6: =FlowDict_WC!W6-FlowDict_WC!L6 -> 0 | M6: =FlowDict_WC!O6-StockDict_WC!H6 -> 0 | N6: =FlowDict_WC!U6-FlowDict_WC!B6 -> 0 | O6: =FlowDict_WC!N6-StockDict_WC!J6 -> 0 | P6: =FlowDict_WC!C6-StockDict_WC!L6 -> 0 | Q6: =FlowDict_WC!E6-StockDict_WC!N6 -> 0 | R6: =FlowDict_WC!R6-StockDict_WC!P6-FlowDict_WC!Z6 -> 0 | S6: =FlowDict_WC!S6-StockDict_WC!R6 -> 0 | T6: =FlowDict_WC!Y6+FlowDict_WC!Z6+FlowDict_WC!T6-StockDict_WC!T6 -> 0 | U6: =FlowDict_WC!B6-FlowDict_WC!D6-FlowDict_WC!C6-FlowDict_WC!E6 -> 0
A7: =A27-StockDict_WC!B7-StockDict_WC!F7-StockDict_WC!D7-StockDict_WC!H7-StockDict_WC!J7-StockDict_WC!L7-StockDict_WC!N7-StockDict_WC!P7-StockDict_WC!R7-StockDict_WC!T7 -> 21.887529 | B7: =FlowDict_WC!D7+FlowDict_WC!F7-FlowDict_WC!H7-FlowDict_WC!G7 -> -3.9283725 | C7: =FlowDict_WC!H7+FlowDict_WC!M7+FlowDict_WC!L7-FlowDict_WC!N7-FlowDict_WC!I7-FlowDict_WC!O7-FlowDict_WC!K7 -> 1.1742241 | D7: =FlowDict_WC!I7-FlowDict_WC!J7-StockDict_WC!B7 -> 0 | E7: =FlowDict_WC!V7-FlowDict_WC!F7 -> 0 | F7: =FlowDict_WC!G7-StockDict_WC!D7 -> 0 | G7: =FlowDict_WC!K7-StockDict_WC!F7 -> 0 | H7: =FlowDict_WC!J7-FlowDict_WC!P7-FlowDict_WC!Q7 -> 0 | I7: =FlowDict_WC!X7-FlowDict_WC!M7 -> 0 | J7: =FlowDict_WC!P7-FlowDict_WC!R7-FlowDict_WC!Y7 -> 4.9283355 | K7: =FlowDict_WC!Q7-FlowDict_WC!T7-FlowDict_WC!S7 -> 19.713342 | L7: =FlowDict_WC!W7-FlowDict_WC!L7 -> 0 | M7: =FlowDict_WC!O7-StockDict_WC!H7 -> 0 | N7: =FlowDict_WC!U7-FlowDict_WC!B7 -> 0 | O7: =FlowDict_WC!N7-StockDict_WC!J7 -> 0 | P7: =FlowDict_WC!C7-StockDict_WC!L7 -> 0 | Q7: =FlowDict_WC!E7-StockDict_WC!N7 -> 0 | R7: =FlowDict_WC!R7-StockDict_WC!P7-FlowDict_WC!Z7 -> 0 | S7: =FlowDict_WC!S7-StockDict_WC!R7 -> 0 | T7: =FlowDict_WC!Y7+FlowDict_WC!Z7+FlowDict_WC!T7-StockDict_WC!T7 -> 0 | U7: =FlowDict_WC!B7-FlowDict_WC!D7-FlowDict_WC!C7-FlowDict_WC!E7 -> 0
A8: =A28-StockDict_WC!B8-StockDict_WC!F8-StockDict_WC!D8-StockDict_WC!H8-StockDict_WC!J8-StockDict_WC!L8-StockDict_WC!N8-StockDict_WC!P8-StockDict_WC!R8-StockDict_WC!T8 -> 24.692533 | B8: =FlowDict_WC!D8+FlowDict_WC!F8-FlowDict_WC!H8-FlowDict_WC!G8 -> -4.0069399 | C8: =FlowDict_WC!H8+FlowDict_WC!M8+FlowDict_WC!L8-FlowDict_WC!N8-FlowDict_WC!I8-FlowDict_WC!O8-FlowDict_WC!K8 -> 1.1977086 | D8: =FlowDict_WC!I8-FlowDict_WC!J8-StockDict_WC!B8 -> 0 | E8: =FlowDict_WC!V8-FlowDict_WC!F8 -> 0 | F8: =FlowDict_WC!G8-StockDict_WC!D8 -> 0 | G8: =FlowDict_WC!K8-StockDict_WC!F8 -> 0 | H8: =FlowDict_WC!J8-FlowDict_WC!P8-FlowDict_WC!Q8 -> 0 | I8: =FlowDict_WC!X8-FlowDict_WC!M8 -> 0 | J8: =FlowDict_WC!P8-FlowDict_WC!R8-FlowDict_WC!Y8 -> 5.500353 | K8: =FlowDict_WC!Q8-FlowDict_WC!T8-FlowDict_WC!S8 -> 22.001412 | L8: =FlowDict_WC!W8-FlowDict_WC!L8 -> 0 | M8: =FlowDict_WC!O8-StockDict_WC!H8 -> 0 | N8: =FlowDict_WC!U8-FlowDict_WC!B8 -> 0 | O8: =FlowDict_WC!N8-StockDict_WC!J8 -> 0 | P8: =FlowDict_WC!C8-StockDict_WC!L8 -> 0 | Q8: =FlowDict_WC!E8-StockDict_WC!N8 -> 0 | R8: =FlowDict_WC!R8-StockDict_WC!P8-FlowDict_WC!Z8 -> 0 | S8: =FlowDict_WC!S8-StockDict_WC!R8 -> 0 | T8: =FlowDict_WC!Y8+FlowDict_WC!Z8+FlowDict_WC!T8-StockDict_WC!T8 -> 0 | U8: =FlowDict_WC!B8-FlowDict_WC!D8-FlowDict_WC!C8-FlowDict_WC!E8 -> 0
A9: =A29-StockDict_WC!B9-StockDict_WC!F9-StockDict_WC!D9-StockDict_WC!H9-StockDict_WC!J9-StockDict_WC!L9-StockDict_WC!N9-StockDict_WC!P9-StockDict_WC!R9-StockDict_WC!T9 -> 26.376755 | B9: =FlowDict_WC!D9+FlowDict_WC!F9-FlowDict_WC!H9-FlowDict_WC!G9 -> -4.0870787 | C9: =FlowDict_WC!H9+FlowDict_WC!M9+FlowDict_WC!L9-FlowDict_WC!N9-FlowDict_WC!I9-FlowDict_WC!O9-FlowDict_WC!K9 -> 1.2216627 | D9: =FlowDict_WC!I9-FlowDict_WC!J9-StockDict_WC!B9 -> 0 | E9: =FlowDict_WC!V9-FlowDict_WC!F9 -> 0 | F9: =FlowDict_WC!G9-StockDict_WC!D9 -> 0 | G9: =FlowDict_WC!K9-StockDict_WC!F9 -> 0 | H9: =FlowDict_WC!J9-FlowDict_WC!P9-FlowDict_WC!Q9 -> 0 | I9: =FlowDict_WC!X9-FlowDict_WC!M9 -> 0 | J9: =FlowDict_WC!P9-FlowDict_WC!R9-FlowDict_WC!Y9 -> 5.8484342 | K9: =FlowDict_WC!Q9-FlowDict_WC!T9-FlowDict_WC!S9 -> 23.393737 | L9: =FlowDict_WC!W9-FlowDict_WC!L9 -> 0 | M9: =FlowDict_WC!O9-StockDict_WC!H9 -> 0 | N9: =FlowDict_WC!U9-FlowDict_WC!B9 -> 0 | O9: =FlowDict_WC!N9-StockDict_WC!J9 -> 0 | P9: =FlowDict_WC!C9-StockDict_WC!L9 -> 0 | Q9: =FlowDict_WC!E9-StockDict_WC!N9 -> 0 | R9: =FlowDict_WC!R9-StockDict_WC!P9-FlowDict_WC!Z9 -> 0 | S9: =FlowDict_WC!S9-StockDict_WC!R9 -> 0 | T9: =FlowDict_WC!Y9+FlowDict_WC!Z9+FlowDict_WC!T9-StockDict_WC!T9 -> 0 | U9: =FlowDict_WC!B9-FlowDict_WC!D9-FlowDict_WC!C9-FlowDict_WC!E9 -> 0
A10: =A30-StockDict_WC!B10-StockDict_WC!F10-StockDict_WC!D10-StockDict_WC!H10-StockDict_WC!J10-StockDict_WC!L10-StockDict_WC!N10-StockDict_WC!P10-StockDict_WC!R10-StockDict_WC!T10 -> 27.653378 | B10: =FlowDict_WC!D10+FlowDict_WC!F10-FlowDict_WC!H10-FlowDict_WC!G10 -> -4.1688203 | C10: =FlowDict_WC!H10+FlowDict_WC!M10+FlowDict_WC!L10-FlowDict_WC!N10-FlowDict_WC!I10-FlowDict_WC!O10-FlowDict_WC!K10 -> 1.246096 | D10: =FlowDict_WC!I10-FlowDict_WC!J10-StockDict_WC!B10 -> 0 | E10: =FlowDict_WC!V10-FlowDict_WC!F10 -> 0 | F10: =FlowDict_WC!G10-StockDict_WC!D10 -> 0 | G10: =FlowDict_WC!K10-StockDict_WC!F10 -> 0 | H10: =FlowDict_WC!J10-FlowDict_WC!P10-FlowDict_WC!Q10 -> 0 | I10: =FlowDict_WC!X10-FlowDict_WC!M10 -> 0 | J10: =FlowDict_WC!P10-FlowDict_WC!R10-FlowDict_WC!Y10 -> 6.1152204 | K10: =FlowDict_WC!Q10-FlowDict_WC!T10-FlowDict_WC!S10 -> 24.460882 | L10: =FlowDict_WC!W10-FlowDict_WC!L10 -> 0 | M10: =FlowDict_WC!O10-StockDict_WC!H10 -> 0 | N10: =FlowDict_WC!U10-FlowDict_WC!B10 -> 0 | O10: =FlowDict_WC!N10-StockDict_WC!J10 -> 0 | P10: =FlowDict_WC!C10-StockDict_WC!L10 -> 0 | Q10: =FlowDict_WC!E10-StockDict_WC!N10 -> 0 | R10: =FlowDict_WC!R10-StockDict_WC!P10-FlowDict_WC!Z10 -> 0 | S10: =FlowDict_WC!S10-StockDict_WC!R10 -> 0 | T10: =FlowDict_WC!Y10+FlowDict_WC!Z10+FlowDict_WC!T10-StockDict_WC!T10 -> 0 | U10: =FlowDict_WC!B10-FlowDict_WC!D10-FlowDict_WC!C10-FlowDict_WC!E10 -> 1.9984014e-15
A11: =A31-StockDict_WC!B11-StockDict_WC!F11-StockDict_WC!D11-StockDict_WC!H11-StockDict_WC!J11-StockDict_WC!L11-StockDict_WC!N11-StockDict_WC!P11-StockDict_WC!R11-StockDict_WC!T11 -> 29.206571 | B11: =FlowDict_WC!D11+FlowDict_WC!F11-FlowDict_WC!H11-FlowDict_WC!G11 -> -4.2521967 | C11: =FlowDict_WC!H11+FlowDict_WC!M11+FlowDict_WC!L11-FlowDict_WC!N11-FlowDict_WC!I11-FlowDict_WC!O11-FlowDict_WC!K11 -> 1.2710179 | D11: =FlowDict_WC!I11-FlowDict_WC!J11-StockDict_WC!B11 -> 7.1054274e-15 | E11: =FlowDict_WC!V11-FlowDict_WC!F11 -> 0 | F11: =FlowDict_WC!G11-StockDict_WC!D11 -> 0 | G11: =FlowDict_WC!K11-StockDict_WC!F11 -> 0 | H11: =FlowDict_WC!J11-FlowDict_WC!P11-FlowDict_WC!Q11 -> 0 | I11: =FlowDict_WC!X11-FlowDict_WC!M11 -> 0 | J11: =FlowDict_WC!P11-FlowDict_WC!R11-FlowDict_WC!Y11 -> 6.4375499 | K11: =FlowDict_WC!Q11-FlowDict_WC!T11-FlowDict_WC!S11 -> 25.750199 | L11: =FlowDict_WC!W11-FlowDict_WC!L11 -> 0 | M11: =FlowDict_WC!O11-StockDict_WC!H11 -> 0 | N11: =FlowDict_WC!U11-FlowDict_WC!B11 -> 0 | O11: =FlowDict_WC!N11-StockDict_WC!J11 -> 0 | P11: =FlowDict_WC!C11-StockDict_WC!L11 -> 0 | Q11: =FlowDict_WC!E11-StockDict_WC!N11 -> 0 | R11: =FlowDict_WC!R11-StockDict_WC!P11-FlowDict_WC!Z11 -> 0 | S11: =FlowDict_WC!S11-StockDict_WC!R11 -> 0 | T11: =FlowDict_WC!Y11+FlowDict_WC!Z11+FlowDict_WC!T11-StockDict_WC!T11 -> 0 | U11: =FlowDict_WC!B11-FlowDict_WC!D11-FlowDict_WC!C11-FlowDict_WC!E11 -> 0
A12: =A32-StockDict_WC!B12-StockDict_WC!F12-StockDict_WC!D12-StockDict_WC!H12-StockDict_WC!J12-StockDict_WC!L12-StockDict_WC!N12-StockDict_WC!P12-StockDict_WC!R12-StockDict_WC!T12 -> 31.05735 | B12: =FlowDict_WC!D12+FlowDict_WC!F12-FlowDict_WC!H12-FlowDict_WC!G12 -> -4.3372407 | C12: =FlowDict_WC!H12+FlowDict_WC!M12+FlowDict_WC!L12-FlowDict_WC!N12-FlowDict_WC!I12-FlowDict_WC!O12-FlowDict_WC!K12 -> 1.2964383 | D12: =FlowDict_WC!I12-FlowDict_WC!J12-StockDict_WC!B12 -> 7.1054274e-15 | E12: =FlowDict_WC!V12-FlowDict_WC!F12 -> 0 | F12: =FlowDict_WC!G12-StockDict_WC!D12 -> 0 | G12: =FlowDict_WC!K12-StockDict_WC!F12 -> 0 | H12: =FlowDict_WC!J12-FlowDict_WC!P12-FlowDict_WC!Q12 -> 0 | I12: =FlowDict_WC!X12-FlowDict_WC!M12 -> 0 | J12: =FlowDict_WC!P12-FlowDict_WC!R12-FlowDict_WC!Y12 -> 6.8196304 | K12: =FlowDict_WC!Q12-FlowDict_WC!T12-FlowDict_WC!S12 -> 27.278522 | L12: =FlowDict_WC!W12-FlowDict_WC!L12 -> 0 | M12: =FlowDict_WC!O12-StockDict_WC!H12 -> 0 | N12: =FlowDict_WC!U12-FlowDict_WC!B12 -> 0 | O12: =FlowDict_WC!N12-StockDict_WC!J12 -> 0 | P12: =FlowDict_WC!C12-StockDict_WC!L12 -> 0 | Q12: =FlowDict_WC!E12-StockDict_WC!N12 -> 0 | R12: =FlowDict_WC!R12-StockDict_WC!P12-FlowDict_WC!Z12 -> 0 | S12: =FlowDict_WC!S12-StockDict_WC!R12 -> 0 | T12: =FlowDict_WC!Y12+FlowDict_WC!Z12+FlowDict_WC!T12-StockDict_WC!T12 -> 0 | U12: =FlowDict_WC!B12-FlowDict_WC!D12-FlowDict_WC!C12-FlowDict_WC!E12 -> 0
A13: =A33-StockDict_WC!B13-StockDict_WC!F13-StockDict_WC!D13-StockDict_WC!H13-StockDict_WC!J13-StockDict_WC!L13-StockDict_WC!N13-StockDict_WC!P13-StockDict_WC!R13-StockDict_WC!T13 -> 32.944939 | B13: =FlowDict_WC!D13+FlowDict_WC!F13-FlowDict_WC!H13-FlowDict_WC!G13 -> -4.4239855 | C13: =FlowDict_WC!H13+FlowDict_WC!M13+FlowDict_WC!L13-FlowDict_WC!N13-FlowDict_WC!I13-FlowDict_WC!O13-FlowDict_WC!K13 -> 1.322367 | D13: =FlowDict_WC!I13-FlowDict_WC!J13-StockDict_WC!B13 -> 7.1054274e-15 | E13: =FlowDict_WC!V13-FlowDict_WC!F13 -> 0 | F13: =FlowDict_WC!G13-StockDict_WC!D13 -> 0 | G13: =FlowDict_WC!K13-StockDict_WC!F13 -> 0 | H13: =FlowDict_WC!J13-FlowDict_WC!P13-FlowDict_WC!Q13 -> 0 | I13: =FlowDict_WC!X13-FlowDict_WC!M13 -> 0 | J13: =FlowDict_WC!P13-FlowDict_WC!R13-FlowDict_WC!Y13 -> 7.2093115 | K13: =FlowDict_WC!Q13-FlowDict_WC!T13-FlowDict_WC!S13 -> 28.837246 | L13: =FlowDict_WC!W13-FlowDict_WC!L13 -> 0 | M13: =FlowDict_WC!O13-StockDict_WC!H13 -> 0 | N13: =FlowDict_WC!U13-FlowDict_WC!B13 -> 0 | O13: =FlowDict_WC!N13-StockDict_WC!J13 -> 0 | P13: =FlowDict_WC!C13-StockDict_WC!L13 -> 0 | Q13: =FlowDict_WC!E13-StockDict_WC!N13 -> 0 | R13: =FlowDict_WC!R13-StockDict_WC!P13-FlowDict_WC!Z13 -> 0 | S13: =FlowDict_WC!S13-StockDict_WC!R13 -> 0 | T13: =FlowDict_WC!Y13+FlowDict_WC!Z13+FlowDict_WC!T13-StockDict_WC!T13 -> 0 | U13: =FlowDict_WC!B13-FlowDict_WC!D13-FlowDict_WC!C13-FlowDict_WC!E13 -> 0
... A16: =A36-StockDict_WC!B16-StockDict_WC!F16-StockDict_WC!D16-StockDict_WC!H16-StockDict_WC!J16-StockDict_WC!L16-StockDict_WC!N16-StockDict_WC!P16-StockDict_WC!R16-StockDict_WC!T16 -> 36.903994 | B16: =FlowDict_WC!D16+FlowDict_WC!F16-FlowDict_WC!H16-FlowDict_WC!G16 -> -4.6947688 | C16: =FlowDict_WC!H16+FlowDict_WC!M16+FlowDict_WC!L16-FlowDict_WC!N16-FlowDict_WC!I16-FlowDict_WC!O16-FlowDict_WC!K16 -> 1.4033065 | D16: =FlowDict_WC!I16-FlowDict_WC!J16-StockDict_WC!B16 -> -7.1054274e-15 | E16: =FlowDict_WC!V16-FlowDict_WC!F16 -> 0 | F16: =FlowDict_WC!G16-StockDict_WC!D16 -> 0 | G16: =FlowDict_WC!K16-StockDict_WC!F16 -> 0 | H16: =FlowDict_WC!J16-FlowDict_WC!P16-FlowDict_WC!Q16 -> 0 | I16: =FlowDict_WC!X16-FlowDict_WC!M16 -> 0 | J16: =FlowDict_WC!P16-FlowDict_WC!R16-FlowDict_WC!Y16 -> 8.0390914 | K16: =FlowDict_WC!Q16-FlowDict_WC!T16-FlowDict_WC!S16 -> 32.156365 | L16: =FlowDict_WC!W16-FlowDict_WC!L16 -> 0 | M16: =FlowDict_WC!O16-StockDict_WC!H16 -> 0 | N16: =FlowDict_WC!U16-FlowDict_WC!B16 -> 0 | O16: =FlowDict_WC!N16-StockDict_WC!J16 -> 0 | P16: =FlowDict_WC!C16-StockDict_WC!L16 -> 0 | Q16: =FlowDict_WC!E16-StockDict_WC!N16 -> 0 | R16: =FlowDict_WC!R16-StockDict_WC!P16-FlowDict_WC!Z16 -> 0 | S16: =FlowDict_WC!S16-StockDict_WC!R16 -> 0 | T16: =FlowDict_WC!Y16+FlowDict_WC!Z16+FlowDict_WC!T16-StockDict_WC!T16 -> 0 | U16: =FlowDict_WC!B16-FlowDict_WC!D16-FlowDict_WC!C16-FlowDict_WC!E16 -> 0
A21: Sum outflows of P0
A22: =SUM(FlowDict_WC!U2:X2) -> 119.06
A23: =SUM(FlowDict_WC!U3:X3) -> 121.4412
A24: =SUM(FlowDict_WC!U4:X4) -> 123.87002
A25: =SUM(FlowDict_WC!U5:X5) -> 126.34742
A26: =SUM(FlowDict_WC!U6:X6) -> 128.87437
A27: =SUM(FlowDict_WC!U7:X7) -> 131.45186
A28: =SUM(FlowDict_WC!U8:X8) -> 134.0809
A29: =SUM(FlowDict_WC!U9:X9) -> 136.76252
A30: =SUM(FlowDict_WC!U10:X10) -> 139.49777
A31: =SUM(FlowDict_WC!U11:X11) -> 142.28772
A32: =SUM(FlowDict_WC!U12:X12) -> 145.13348
A33: =SUM(FlowDict_WC!U13:X13) -> 148.03615
... A36: =SUM(FlowDict_WC!U16:X16) -> 157.09714
B40: {=SUM(ABS(A2:A16))} -> 365.70236

Sheet Mass_balance_DM
A1: P0 | B1: P1 | C1: P2 | D1: P3 | E1: P4 | F1: P5 | G1: P6 | H1: P7 | I1: P8 | J1: P9 | K1: P10 | L1: P11 | M1: P12 | N1: P13 | O1: P14 | P1: P15 | Q1: P16 | R1: P17 | S1: P18 | T1: P19 | U1: P20
A2: =A22-StockDict_DM!B2-StockDict_DM!D2-StockDict_DM!F2-StockDict_DM!H2-StockDict_DM!J2-StockDict_DM!L2-StockDict_DM!N2-StockDict_DM!P2-StockDict_DM!R2-StockDict_DM!T2 -> 2.4945076 | B2: =FlowDict_DM!D2+FlowDict_DM!F2-FlowDict_DM!H2-FlowDict_DM!G2 -> 3.558048 | C2: =FlowDict_DM!H2+FlowDict_DM!M2+FlowDict_DM!L2-FlowDict_DM!N2-FlowDict_DM!I2-FlowDict_DM!O2-FlowDict_DM!K2 -> -1.0635309 | D2: =FlowDict_DM!I2-FlowDict_DM!J2-StockDict_DM!B2 -> 0 | E2: =FlowDict_DM!V2-FlowDict_DM!F2 -> 0 | F2: =FlowDict_DM!G2-StockDict_DM!D2 -> 0 | G2: =FlowDict_DM!K2-StockDict_DM!F2 -> 0 | H2: =FlowDict_DM!J2-FlowDict_DM!P2-FlowDict_DM!Q2 -> 0 | I2: =FlowDict_DM!X2-FlowDict_DM!M2 -> 0 | J2: =FlowDict_DM!P2-FlowDict_DM!R2-FlowDict_DM!Y2 -> -1.8960744e-06 | K2: =FlowDict_DM!Q2-FlowDict_DM!T2-FlowDict_DM!S2 -> -7.5842976e-06 | L2: =FlowDict_DM!W2-FlowDict_DM!L2 -> 0 | M2: =FlowDict_DM!O2-StockDict_DM!H2 -> 0 | N2: =FlowDict_DM!U2-FlowDict_DM!B2 -> 0 | O2: =FlowDict_DM!N2-StockDict_DM!J2 -> 0 | P2: =FlowDict_DM!C2-StockDict_DM!L2 -> 0 | Q2: =FlowDict_DM!E2-StockDict_DM!N2 -> 0 | R2: =FlowDict_DM!R2-StockDict_DM!P2-FlowDict_DM!Z2 -> 0 | S2: =FlowDict_DM!S2-StockDict_DM!R2 -> 0 | T2: =FlowDict_DM!Y2+FlowDict_DM!Z2+FlowDict_DM!T2-StockDict_DM!T2 -> 0 | U2: =FlowDict_DM!B2-FlowDict_DM!D2-FlowDict_DM!C2-FlowDict_DM!E2 -> 0
A3: =A23-StockDict_DM!B3-StockDict_DM!D3-StockDict_DM!F3-StockDict_DM!H3-StockDict_DM!J3-StockDict_DM!L3-StockDict_DM!N3-StockDict_DM!P3-StockDict_DM!R3-StockDict_DM!T3 -> -7.3776668 | B3: =FlowDict_DM!D3+FlowDict_DM!F3-FlowDict_DM!H3-FlowDict_DM!G3 -> 3.629209 | C3: =FlowDict_DM!H3+FlowDict_DM!M3+FlowDict_DM!L3-FlowDict_DM!N3-FlowDict_DM!I3-FlowDict_DM!O3-FlowDict_DM!K3 -> -1.0848015 | D3: =FlowDict_DM!I3-FlowDict_DM!J3-StockDict_DM!B3 -> 0 | E3: =FlowDict_DM!V3-FlowDict_DM!F3 -> 0 | F3: =FlowDict_DM!G3-StockDict_DM!D3 -> 0 | G3: =FlowDict_DM!K3-StockDict_DM!F3 -> 0 | H3: =FlowDict_DM!J3-FlowDict_DM!P3-FlowDict_DM!Q3 -> 0 | I3: =FlowDict_DM!X3-FlowDict_DM!M3 -> 0 | J3: =FlowDict_DM!P3-FlowDict_DM!R3-FlowDict_DM!Y3 -> -1.9844148 | K3: =FlowDict_DM!Q3-FlowDict_DM!T3-FlowDict_DM!S3 -> -7.9376593 | L3: =FlowDict_DM!W3-FlowDict_DM!L3 -> 0 | M3: =FlowDict_DM!O3-StockDict_DM!H3 -> 0 | N3: =FlowDict_DM!U3-FlowDict_DM!B3 -> 0 | O3: =FlowDict_DM!N3-StockDict_DM!J3 -> 0 | P3: =FlowDict_DM!C3-StockDict_DM!L3 -> 0 | Q3: =FlowDict_DM!E3-StockDict_DM!N3 -> 0 | R3: =FlowDict_DM!R3-StockDict_DM!P3-FlowDict_DM!Z3 -> 0 | S3: =FlowDict_DM!S3-StockDict_DM!R3 -> 0 | T3: =FlowDict_DM!Y3+FlowDict_DM!Z3+FlowDict_DM!T3-StockDict_DM!T3 -> 0 | U3: =FlowDict_DM!B3-FlowDict_DM!D3-FlowDict_DM!C3-FlowDict_DM!E3 -> 0
A4: =A24-StockDict_DM!B4-StockDict_DM!D4-StockDict_DM!F4-StockDict_DM!H4-StockDict_DM!J4-StockDict_DM!L4-StockDict_DM!N4-StockDict_DM!P4-StockDict_DM!R4-StockDict_DM!T4 -> -17.455963 | B4: =FlowDict_DM!D4+FlowDict_DM!F4-FlowDict_DM!H4-FlowDict_DM!G4 -> 3.7017931 | C4: =FlowDict_DM!H4+FlowDict_DM!M4+FlowDict_DM!L4-FlowDict_DM!N4-FlowDict_DM!I4-FlowDict_DM!O4-FlowDict_DM!K4 -> -1.1064976 | D4: =FlowDict_DM!I4-FlowDict_DM!J4-StockDict_DM!B4 -> 0 | E4: =FlowDict_DM!V4-FlowDict_DM!F4 -> 0 | F4: =FlowDict_DM!G4-StockDict_DM!D4 -> 0 | G4: =FlowDict_DM!K4-StockDict_DM!F4 -> 0 | H4: =FlowDict_DM!J4-FlowDict_DM!P4-FlowDict_DM!Q4 -> 0 | I4: =FlowDict_DM!X4-FlowDict_DM!M4 -> 0 | J4: =FlowDict_DM!P4-FlowDict_DM!R4-FlowDict_DM!Y4 -> -4.0102517 | K4: =FlowDict_DM!Q4-FlowDict_DM!T4-FlowDict_DM!S4 -> -16.041007 | L4: =FlowDict_DM!W4-FlowDict_DM!L4 -> 0 | M4: =FlowDict_DM!O4-StockDict_DM!H4 -> 0 | N4: =FlowDict_DM!U4-FlowDict_DM!B4 -> 0 | O4: =FlowDict_DM!N4-StockDict_DM!J4 -> 0 | P4: =FlowDict_DM!C4-StockDict_DM!L4 -> 0 | Q4: =FlowDict_DM!E4-StockDict_DM!N4 -> 0 | R4: =FlowDict_DM!R4-StockDict_DM!P4-FlowDict_DM!Z4 -> 0 | S4: =FlowDict_DM!S4-StockDict_DM!R4 -> 0 | T4: =FlowDict_DM!Y4+FlowDict_DM!Z4+FlowDict_DM!T4-StockDict_DM!T4 -> 0 | U4: =FlowDict_DM!B4-FlowDict_DM!D4-FlowDict_DM!C4-FlowDict_DM!E4 -> 0
A5: =A25-StockDict_DM!B5-StockDict_DM!D5-StockDict_DM!F5-StockDict_DM!H5-StockDict_DM!J5-StockDict_DM!L5-StockDict_DM!N5-StockDict_DM!P5-StockDict_DM!R5-StockDict_DM!T5 -> -17.94797 | B5: =FlowDict_DM!D5+FlowDict_DM!F5-FlowDict_DM!H5-FlowDict_DM!G5 -> 3.775829 | C5: =FlowDict_DM!H5+FlowDict_DM!M5+FlowDict_DM!L5-FlowDict_DM!N5-FlowDict_DM!I5-FlowDict_DM!O5-FlowDict_DM!K5 -> -1.1286275 | D5: =FlowDict_DM!I5-FlowDict_DM!J5-StockDict_DM!B5 -> 0 | E5: =FlowDict_DM!V5-FlowDict_DM!F5 -> 0 | F5: =FlowDict_DM!G5-StockDict_DM!D5 -> 0 | G5: =FlowDict_DM!K5-StockDict_DM!F5 -> 0 | H5: =FlowDict_DM!J5-FlowDict_DM!P5-FlowDict_DM!Q5 -> 0 | I5: =FlowDict_DM!X5-FlowDict_DM!M5 -> 0 | J5: =FlowDict_DM!P5-FlowDict_DM!R5-FlowDict_DM!Y5 -> -4.1190344 | K5: =FlowDict_DM!Q5-FlowDict_DM!T5-FlowDict_DM!S5 -> -16.476137 | L5: =FlowDict_DM!W5-FlowDict_DM!L5 -> 0 | M5: =FlowDict_DM!O5-StockDict_DM!H5 -> 0 | N5: =FlowDict_DM!U5-FlowDict_DM!B5 -> 0 | O5: =FlowDict_DM!N5-StockDict_DM!J5 -> 0 | P5: =FlowDict_DM!C5-StockDict_DM!L5 -> 0 | Q5: =FlowDict_DM!E5-StockDict_DM!N5 -> 0 | R5: =FlowDict_DM!R5-StockDict_DM!P5-FlowDict_DM!Z5 -> 8.8817842e-16 | S5: =FlowDict_DM!S5-StockDict_DM!R5 -> 0 | T5: =FlowDict_DM!Y5+FlowDict_DM!Z5+FlowDict_DM!T5-StockDict_DM!T5 -> 0 | U5: =FlowDict_DM!B5-FlowDict_DM!D5-FlowDict_DM!C5-FlowDict_DM!E5 -> 0
A6: =A26-StockDict_DM!B6-StockDict_DM!D6-StockDict_DM!F6-StockDict_DM!H6-StockDict_DM!J6-StockDict_DM!L6-StockDict_DM!N6-StockDict_DM!P6-StockDict_DM!R6-StockDict_DM!T6 -> -19.213273 | B6: =FlowDict_DM!D6+FlowDict_DM!F6-FlowDict_DM!H6-FlowDict_DM!G6 -> 3.8513456 | C6: =FlowDict_DM!H6+FlowDict_DM!M6+FlowDict_DM!L6-FlowDict_DM!N6-FlowDict_DM!I6-FlowDict_DM!O6-FlowDict_DM!K6 -> -1.1512001 | D6: =FlowDict_DM!I6-FlowDict_DM!J6-StockDict_DM!B6 -> 0 | E6: =FlowDict_DM!V6-FlowDict_DM!F6 -> 0 | F6: =FlowDict_DM!G6-StockDict_DM!D6 -> 0 | G6: =FlowDict_DM!K6-StockDict_DM!F6 -> 0 | H6: =FlowDict_DM!J6-FlowDict_DM!P6-FlowDict_DM!Q6 -> 0 | I6: =FlowDict_DM!X6-FlowDict_DM!M6 -> 0 | J6: =FlowDict_DM!P6-FlowDict_DM!R6-FlowDict_DM!Y6 -> -4.3826836 | K6: =FlowDict_DM!Q6-FlowDict_DM!T6-FlowDict_DM!S6 -> -17.530735 | L6: =FlowDict_DM!W6-FlowDict_DM!L6 -> 0 | M6: =FlowDict_DM!O6-StockDict_DM!H6 -> 0 | N6: =FlowDict_DM!U6-FlowDict_DM!B6 -> 0 | O6: =FlowDict_DM!N6-StockDict_DM!J6 -> 0 | P6: =FlowDict_DM!C6-StockDict_DM!L6 -> 0 | Q6: =FlowDict_DM!E6-StockDict_DM!N6 -> 0 | R6: =FlowDict_DM!R6-StockDict_DM!P6-FlowDict_DM!Z6 -> 0 | S6: =FlowDict_DM!S6-StockDict_DM!R6 -> 0 | T6: =FlowDict_DM!Y6+FlowDict_DM!Z6+FlowDict_DM!T6-StockDict_DM!T6 -> 0 | U6: =FlowDict_DM!B6-FlowDict_DM!D6-FlowDict_DM!C6-FlowDict_DM!E6 -> 0
A7: =A27-StockDict_DM!B7-StockDict_DM!D7-StockDict_DM!F7-StockDict_DM!H7-StockDict_DM!J7-StockDict_DM!L7-StockDict_DM!N7-StockDict_DM!P7-StockDict_DM!R7-StockDict_DM!T7 -> -21.887529 | B7: =FlowDict_DM!D7+FlowDict_DM!F7-FlowDict_DM!H7-FlowDict_DM!G7 -> 3.9283725 | C7: =FlowDict_DM!H7+FlowDict_DM!M7+FlowDict_DM!L7-FlowDict_DM!N7-FlowDict_DM!I7-FlowDict_DM!O7-FlowDict_DM!K7 -> -1.1742241 | D7: =FlowDict_DM!I7-FlowDict_DM!J7-StockDict_DM!B7 -> 0 | E7: =FlowDict_DM!V7-FlowDict_DM!F7 -> 0 | F7: =FlowDict_DM!G7-StockDict_DM!D7 -> 0 | G7: =FlowDict_DM!K7-StockDict_DM!F7 -> 0 | H7: =FlowDict_DM!J7-FlowDict_DM!P7-FlowDict_DM!Q7 -> 0 | I7: =FlowDict_DM!X7-FlowDict_DM!M7 -> 0 | J7: =FlowDict_DM!P7-FlowDict_DM!R7-FlowDict_DM!Y7 -> -4.9283355 | K7: =FlowDict_DM!Q7-FlowDict_DM!T7-FlowDict_DM!S7 -> -19.713342 | L7: =FlowDict_DM!W7-FlowDict_DM!L7 -> 0 | M7: =FlowDict_DM!O7-StockDict_DM!H7 -> 0 | N7: =FlowDict_DM!U7-FlowDict_DM!B7 -> 0 | O7: =FlowDict_DM!N7-StockDict_DM!J7 -> 0 | P7: =FlowDict_DM!C7-StockDict_DM!L7 -> 0 | Q7: =FlowDict_DM!E7-StockDict_DM!N7 -> 0 | R7: =FlowDict_DM!R7-StockDict_DM!P7-FlowDict_DM!Z7 -> 4.1633363e-16 | S7: =FlowDict_DM!S7-StockDict_DM!R7 -> 0 | T7: =FlowDict_DM!Y7+FlowDict_DM!Z7+FlowDict_DM!T7-StockDict_DM!T7 -> 0 | U7: =FlowDict_DM!B7-FlowDict_DM!D7-FlowDict_DM!C7-FlowDict_DM!E7 -> -4.6185278e-14
A8: =A28-StockDict_DM!B8-StockDict_DM!D8-StockDict_DM!F8-StockDict_DM!H8-StockDict_DM!J8-StockDict_DM!L8-StockDict_DM!N8-StockDict_DM!P8-StockDict_DM!R8-StockDict_DM!T8 -> -24.692533 | B8: =FlowDict_DM!D8+FlowDict_DM!F8-FlowDict_DM!H8-FlowDict_DM!G8 -> 4.0069399 | C8: =FlowDict_DM!H8+FlowDict_DM!M8+FlowDict_DM!L8-FlowDict_DM!N8-FlowDict_DM!I8-FlowDict_DM!O8-FlowDict_DM!K8 -> -1.1977086 | D8: =FlowDict_DM!I8-FlowDict_DM!J8-StockDict_DM!B8 -> -7.1054274e-15 | E8: =FlowDict_DM!V8-FlowDict_DM!F8 -> 0 | F8: =FlowDict_DM!G8-StockDict_DM!D8 -> 0 | G8: =FlowDict_DM!K8-StockDict_DM!F8 -> 0 | H8: =FlowDict_DM!J8-FlowDict_DM!P8-FlowDict_DM!Q8 -> 0 | I8: =FlowDict_DM!X8-FlowDict_DM!M8 -> 0 | J8: =FlowDict_DM!P8-FlowDict_DM!R8-FlowDict_DM!Y8 -> -5.500353 | K8: =FlowDict_DM!Q8-FlowDict_DM!T8-FlowDict_DM!S8 -> -22.001412 | L8: =FlowDict_DM!W8-FlowDict_DM!L8 -> 0 | M8: =FlowDict_DM!O8-StockDict_DM!H8 -> 0 | N8: =FlowDict_DM!U8-FlowDict_DM!B8 -> 0 | O8: =FlowDict_DM!N8-StockDict_DM!J8 -> 0 | P8: =FlowDict_DM!C8-StockDict_DM!L8 -> 0 | Q8: =FlowDict_DM!E8-StockDict_DM!N8 -> 0 | R8: =FlowDict_DM!R8-StockDict_DM!P8-FlowDict_DM!Z8 -> 0 | S8: =FlowDict_DM!S8-StockDict_DM!R8 -> 0 | T8: =FlowDict_DM!Y8+FlowDict_DM!Z8+FlowDict_DM!T8-StockDict_DM!T8 -> 0 | U8: =FlowDict_DM!B8-FlowDict_DM!D8-FlowDict_DM!C8-FlowDict_DM!E8 -> 5.6843419e-14
A9: =A29-StockDict_DM!B9-StockDict_DM!D9-StockDict_DM!F9-StockDict_DM!H9-StockDict_DM!J9-StockDict_DM!L9-StockDict_DM!N9-StockDict_DM!P9-StockDict_DM!R9-StockDict_DM!T9 -> -26.376755 | B9: =FlowDict_DM!D9+FlowDict_DM!F9-FlowDict_DM!H9-FlowDict_DM!G9 -> 4.0870787 | C9: =FlowDict_DM!H9+FlowDict_DM!M9+FlowDict_DM!L9-FlowDict_DM!N9-FlowDict_DM!I9-FlowDict_DM!O9-FlowDict_DM!K9 -> -1.2216627 | D9: =FlowDict_DM!I9-FlowDict_DM!J9-StockDict_DM!B9 -> 0 | E9: =FlowDict_DM!V9-FlowDict_DM!F9 -> 0 | F9: =FlowDict_DM!G9-StockDict_DM!D9 -> 0 | G9: =FlowDict_DM!K9-StockDict_DM!F9 -> 0 | H9: =FlowDict_DM!J9-FlowDict_DM!P9-FlowDict_DM!Q9 -> 0 | I9: =FlowDict_DM!X9-FlowDict_DM!M9 -> 0 | J9: =FlowDict_DM!P9-FlowDict_DM!R9-FlowDict_DM!Y9 -> -5.8484342 | K9: =FlowDict_DM!Q9-FlowDict_DM!T9-FlowDict_DM!S9 -> -23.393737 | L9: =FlowDict_DM!W9-FlowDict_DM!L9 -> 0 | M9: =FlowDict_DM!O9-StockDict_DM!H9 -> 0 | N9: =FlowDict_DM!U9-FlowDict_DM!B9 -> 0 | O9: =FlowDict_DM!N9-StockDict_DM!J9 -> 0 | P9: =FlowDict_DM!C9-StockDict_DM!L9 -> 0 | Q9: =FlowDict_DM!E9-StockDict_DM!N9 -> 0 | R9: =FlowDict_DM!R9-StockDict_DM!P9-FlowDict_DM!Z9 -> 0 | S9: =FlowDict_DM!S9-StockDict_DM!R9 -> 0 | T9: =FlowDict_DM!Y9+FlowDict_DM!Z9+FlowDict_DM!T9-StockDict_DM!T9 -> 0 | U9: =FlowDict_DM!B9-FlowDict_DM!D9-FlowDict_DM!C9-FlowDict_DM!E9 -> 0
A10: =A30-StockDict_DM!B10-StockDict_DM!D10-StockDict_DM!F10-StockDict_DM!H10-StockDict_DM!J10-StockDict_DM!L10-StockDict_DM!N10-StockDict_DM!P10-StockDict_DM!R10-StockDict_DM!T10 -> -27.653378 | B10: =FlowDict_DM!D10+FlowDict_DM!F10-FlowDict_DM!H10-FlowDict_DM!G10 -> 4.1688203 | C10: =FlowDict_DM!H10+FlowDict_DM!M10+FlowDict_DM!L10-FlowDict_DM!N10-FlowDict_DM!I10-FlowDict_DM!O10-FlowDict_DM!K10 -> -1.246096 | D10: =FlowDict_DM!I10-FlowDict_DM!J10-StockDict_DM!B10 -> 0 | E10: =FlowDict_DM!V10-FlowDict_DM!F10 -> 0 | F10: =FlowDict_DM!G10-StockDict_DM!D10 -> 0 | G10: =FlowDict_DM!K10-StockDict_DM!F10 -> 0 | H10: =FlowDict_DM!J10-FlowDict_DM!P10-FlowDict_DM!Q10 -> 0 | I10: =FlowDict_DM!X10-FlowDict_DM!M10 -> 0 | J10: =FlowDict_DM!P10-FlowDict_DM!R10-FlowDict_DM!Y10 -> -6.1152204 | K10: =FlowDict_DM!Q10-FlowDict_DM!T10-FlowDict_DM!S10 -> -24.460882 | L10: =FlowDict_DM!W10-FlowDict_DM!L10 -> 0 | M10: =FlowDict_DM!O10-StockDict_DM!H10 -> 0 | N10: =FlowDict_DM!U10-FlowDict_DM!B10 -> 0 | O10: =FlowDict_DM!N10-StockDict_DM!J10 -> 0 | P10: =FlowDict_DM!C10-StockDict_DM!L10 -> 0 | Q10: =FlowDict_DM!E10-StockDict_DM!N10 -> 0 | R10: =FlowDict_DM!R10-StockDict_DM!P10-FlowDict_DM!Z10 -> 0 | S10: =FlowDict_DM!S10-StockDict_DM!R10 -> 0 | T10: =FlowDict_DM!Y10+FlowDict_DM!Z10+FlowDict_DM!T10-StockDict_DM!T10 -> 0 | U10: =FlowDict_DM!B10-FlowDict_DM!D10-FlowDict_DM!C10-FlowDict_DM!E10 -> -3.1974423e-14
A11: =A31-StockDict_DM!B11-StockDict_DM!D11-StockDict_DM!F11-StockDict_DM!H11-StockDict_DM!J11-StockDict_DM!L11-StockDict_DM!N11-StockDict_DM!P11-StockDict_DM!R11-StockDict_DM!T11 -> -29.206571 | B11: =FlowDict_DM!D11+FlowDict_DM!F11-FlowDict_DM!H11-FlowDict_DM!G11 -> 4.2521967 | C11: =FlowDict_DM!H11+FlowDict_DM!M11+FlowDict_DM!L11-FlowDict_DM!N11-FlowDict_DM!I11-FlowDict_DM!O11-FlowDict_DM!K11 -> -1.2710179 | D11: =FlowDict_DM!I11-FlowDict_DM!J11-StockDict_DM!B11 -> 0 | E11: =FlowDict_DM!V11-FlowDict_DM!F11 -> 0 | F11: =FlowDict_DM!G11-StockDict_DM!D11 -> 0 | G11: =FlowDict_DM!K11-StockDict_DM!F11 -> 0 | H11: =FlowDict_DM!J11-FlowDict_DM!P11-FlowDict_DM!Q11 -> 0 | I11: =FlowDict_DM!X11-FlowDict_DM!M11 -> 0 | J11: =FlowDict_DM!P11-FlowDict_DM!R11-FlowDict_DM!Y11 -> -6.4375499 | K11: =FlowDict_DM!Q11-FlowDict_DM!T11-FlowDict_DM!S11 -> -25.750199 | L11: =FlowDict_DM!W11-FlowDict_DM!L11 -> 0 | M11: =FlowDict_DM!O11-StockDict_DM!H11 -> 0 | N11: =FlowDict_DM!U11-FlowDict_DM!B11 -> 0 | O11: =FlowDict_DM!N11-StockDict_DM!J11 -> 0 | P11: =FlowDict_DM!C11-StockDict_DM!L11 -> 0 | Q11: =FlowDict_DM!E11-StockDict_DM!N11 -> 0 | R11: =FlowDict_DM!R11-StockDict_DM!P11-FlowDict_DM!Z11 -> -8.8817842e-16 | S11: =FlowDict_DM!S11-StockDict_DM!R11 -> 0 | T11: =FlowDict_DM!Y11+FlowDict_DM!Z11+FlowDict_DM!T11-StockDict_DM!T11 -> 0 | U11: =FlowDict_DM!B11-FlowDict_DM!D11-FlowDict_DM!C11-FlowDict_DM!E11 -> -4.6185278e-14
A12: =A32-StockDict_DM!B12-StockDict_DM!D12-StockDict_DM!F12-StockDict_DM!H12-StockDict_DM!J12-StockDict_DM!L12-StockDict_DM!N12-StockDict_DM!P12-StockDict_DM!R12-StockDict_DM!T12 -> -31.05735 | B12: =FlowDict_DM!D12+FlowDict_DM!F12-FlowDict_DM!H12-FlowDict_DM!G12 -> 4.3372407 | C12: =FlowDict_DM!H12+FlowDict_DM!M12+FlowDict_DM!L12-FlowDict_DM!N12-FlowDict_DM!I12-FlowDict_DM!O12-FlowDict_DM!K12 -> -1.2964383 | D12: =FlowDict_DM!I12-FlowDict_DM!J12-StockDict_DM!B12 -> 7.1054274e-15 | E12: =FlowDict_DM!V12-FlowDict_DM!F12 -> 0 | F12: =FlowDict_DM!G12-StockDict_DM!D12 -> 0 | G12: =FlowDict_DM!K12-StockDict_DM!F12 -> 0 | H12: =FlowDict_DM!J12-FlowDict_DM!P12-FlowDict_DM!Q12 -> 0 | I12: =FlowDict_DM!X12-FlowDict_DM!M12 -> 0 | J12: =FlowDict_DM!P12-FlowDict_DM!R12-FlowDict_DM!Y12 -> -6.8196304 | K12: =FlowDict_DM!Q12-FlowDict_DM!T12-FlowDict_DM!S12 -> -27.278522 | L12: =FlowDict_DM!W12-FlowDict_DM!L12 -> 0 | M12: =FlowDict_DM!O12-StockDict_DM!H12 -> 0 | N12: =FlowDict_DM!U12-FlowDict_DM!B12 -> 0 | O12: =FlowDict_DM!N12-StockDict_DM!J12 -> 0 | P12: =FlowDict_DM!C12-StockDict_DM!L12 -> 0 | Q12: =FlowDict_DM!E12-StockDict_DM!N12 -> 0 | R12: =FlowDict_DM!R12-StockDict_DM!P12-FlowDict_DM!Z12 -> 0 | S12: =FlowDict_DM!S12-StockDict_DM!R12 -> 0 | T12: =FlowDict_DM!Y12+FlowDict_DM!Z12+FlowDict_DM!T12-StockDict_DM!T12 -> 0 | U12: =FlowDict_DM!B12-FlowDict_DM!D12-FlowDict_DM!C12-FlowDict_DM!E12 -> -5.3290705e-14
A13: =A33-StockDict_DM!B13-StockDict_DM!D13-StockDict_DM!F13-StockDict_DM!H13-StockDict_DM!J13-StockDict_DM!L13-StockDict_DM!N13-StockDict_DM!P13-StockDict_DM!R13-StockDict_DM!T13 -> -32.944939 | B13: =FlowDict_DM!D13+FlowDict_DM!F13-FlowDict_DM!H13-FlowDict_DM!G13 -> 4.4239855 | C13: =FlowDict_DM!H13+FlowDict_DM!M13+FlowDict_DM!L13-FlowDict_DM!N13-FlowDict_DM!I13-FlowDict_DM!O13-FlowDict_DM!K13 -> -1.322367 | D13: =FlowDict_DM!I13-FlowDict_DM!J13-StockDict_DM!B13 -> 6.6613381e-15 | E13: =FlowDict_DM!V13-FlowDict_DM!F13 -> 0 | F13: =FlowDict_DM!G13-StockDict_DM!D13 -> 0 | G13: =FlowDict_DM!K13-StockDict_DM!F13 -> 0 | H13: =FlowDict_DM!J13-FlowDict_DM!P13-FlowDict_DM!Q13 -> 0 | I13: =FlowDict_DM!X13-FlowDict_DM!M13 -> 0 | J13: =FlowDict_DM!P13-FlowDict_DM!R13-FlowDict_DM!Y13 -> -7.2093115 | K13: =FlowDict_DM!Q13-FlowDict_DM!T13-FlowDict_DM!S13 -> -28.837246 | L13: =FlowDict_DM!W13-FlowDict_DM!L13 -> 0 | M13: =FlowDict_DM!O13-StockDict_DM!H13 -> 0 | N13: =FlowDict_DM!U13-FlowDict_DM!B13 -> 0 | O13: =FlowDict_DM!N13-StockDict_DM!J13 -> 0 | P13: =FlowDict_DM!C13-StockDict_DM!L13 -> 0 | Q13: =FlowDict_DM!E13-StockDict_DM!N13 -> 0 | R13: =FlowDict_DM!R13-StockDict_DM!P13-FlowDict_DM!Z13 -> 8.8817842e-16 | S13: =FlowDict_DM!S13-StockDict_DM!R13 -> 0 | T13: =FlowDict_DM!Y13+FlowDict_DM!Z13+FlowDict_DM!T13-StockDict_DM!T13 -> 0 | U13: =FlowDict_DM!B13-FlowDict_DM!D13-FlowDict_DM!C13-FlowDict_DM!E13 -> -4.9737992e-14
... A16: =A36-StockDict_DM!B16-StockDict_DM!D16-StockDict_DM!F16-StockDict_DM!H16-StockDict_DM!J16-StockDict_DM!L16-StockDict_DM!N16-StockDict_DM!P16-StockDict_DM!R16-StockDict_DM!T16 -> -36.903994 | B16: =FlowDict_DM!D16+FlowDict_DM!F16-FlowDict_DM!H16-FlowDict_DM!G16 -> 4.6947688 | C16: =FlowDict_DM!H16+FlowDict_DM!M16+FlowDict_DM!L16-FlowDict_DM!N16-FlowDict_DM!I16-FlowDict_DM!O16-FlowDict_DM!K16 -> -1.4033065 | D16: =FlowDict_DM!I16-FlowDict_DM!J16-StockDict_DM!B16 -> 3.9968029e-15 | E16: =FlowDict_DM!V16-FlowDict_DM!F16 -> 0 | F16: =FlowDict_DM!G16-StockDict_DM!D16 -> 0 | G16: =FlowDict_DM!K16-StockDict_DM!F16 -> 0 | H16: =FlowDict_DM!J16-FlowDict_DM!P16-FlowDict_DM!Q16 -> 0 | I16: =FlowDict_DM!X16-FlowDict_DM!M16 -> 0 | J16: =FlowDict_DM!P16-FlowDict_DM!R16-FlowDict_DM!Y16 -> -8.0390914 | K16: =FlowDict_DM!Q16-FlowDict_DM!T16-FlowDict_DM!S16 -> -32.156365 | L16: =FlowDict_DM!W16-FlowDict_DM!L16 -> 0 | M16: =FlowDict_DM!O16-StockDict_DM!H16 -> 0 | N16: =FlowDict_DM!U16-FlowDict_DM!B16 -> 0 | O16: =FlowDict_DM!N16-StockDict_DM!J16 -> 0 | P16: =FlowDict_DM!C16-StockDict_DM!L16 -> 0 | Q16: =FlowDict_DM!E16-StockDict_DM!N16 -> 0 | R16: =FlowDict_DM!R16-StockDict_DM!P16-FlowDict_DM!Z16 -> 0 | S16: =FlowDict_DM!S16-StockDict_DM!R16 -> 0 | T16: =FlowDict_DM!Y16+FlowDict_DM!Z16+FlowDict_DM!T16-StockDict_DM!T16 -> 0 | U16: =FlowDict_DM!B16-FlowDict_DM!D16-FlowDict_DM!C16-FlowDict_DM!E16 -> 4.9737992e-14
A21: Sum outflows of P0
A22: =SUM(FlowDict_DM!U2:X2) -> 123.94
A23: =SUM(FlowDict_DM!U3:X3) -> 126.4188
A24: =SUM(FlowDict_DM!U4:X4) -> 128.94718
A25: =SUM(FlowDict_DM!U5:X5) -> 131.52612
A26: =SUM(FlowDict_DM!U6:X6) -> 134.15664
A27: =SUM(FlowDict_DM!U7:X7) -> 136.83977
A28: =SUM(FlowDict_DM!U8:X8) -> 139.57657
A29: =SUM(FlowDict_DM!U9:X9) -> 142.3681
A30: =SUM(FlowDict_DM!U10:X10) -> 145.21546
A31: =SUM(FlowDict_DM!U11:X11) -> 148.11977
A32: =SUM(FlowDict_DM!U12:X12) -> 151.08217
A33: =SUM(FlowDict_DM!U13:X13) -> 154.10381
... A36: =SUM(FlowDict_DM!U16:X16) -> 163.5362

Sheet Mass_balance_CC
