Workbook
Name Baumart_: [1]!Baumart[Baumart]
Name Baumart_: [2]!Baumart[Baumart]
Name Cluster_: [1]!Cluster[Cluster]
Name Cluster_: [2]!Cluster[Cluster]
Name einheit: [1]!Tabelle14[Einheit]
Name einheit: [2]!Tabelle14[Einheit]
Name Erhebungsart_: [1]!Erhebungsart[Erhebungsart]
Name Erhebungsart_: [2]!Erhebungsart[Erhebungsart]
Name Herkunft_: [1]!Herkunft[Herkunft]
Name Herkunft_: [2]!Herkunft[Herkunft]
Name Holzstrom_: [1]!Holzstrom[Holzstrom]
Name Holzstrom_: [2]!Holzstrom[Holzstrom]
Name In_Out_: [1]!Tabelleinput[In/Out]
Name In_Out_: [2]!Tabelleinput[In/Out]
Name Inhaltsverzeichnis: "MTRANS(ERSETZEN(Inhalt;1;FINDEN(""]"";Inhalt);""))"
Name Klassifizierung: [1]!Tabelle9[Klassifizierung]
Name Klassifizierung: [2]!Tabelle9[Klassifizierung]
Name Ort_: [1]!Ort[Ort]
Name Ort_: [2]!Ort[Ort]
Name Ziel_: [1]!Ziel[Ziel]
Name Ziel_: [2]!Ziel[Ziel]

Sheet Intro
B3: Der angehängte Datensatz beinhalten Informationen über Materialflüsse, Prozesse sowie Lager in der Region Brandenburg. Der Datensatz bezieht sich dabei auf verschiedene Quellen und Dokumente.
B5: Definition der Systemgrenzen:
C6: Beobachtungszeitraum: | F6: 2010 - 2020
C7: Beobachtungsgebiet: | F7: Berlin
F8: Brandenburg
F9: Berlin + Brandenburg
B11: Für die Anfertigung der Materialflussanalyse werden die folgenden Daten benötigt. Die Daten werden in seperaten Tabellenblättern dargestellt. Für jeden Datensatz werden spezifische Anforderungen definiert. Diese lassen sich einem Systemübergreifenden Fließbild zuordnen. Dieses Fließbild beinhaltet die relevanten Flüsse, Prozesse und Lager.
B14: Prozesse bilden die Grundlage für das System. Prozesse können Transferkoefizienten und Lager beinhalten. Prozesse haben einen oder mehrere Flüsse als Input sowie einen oder mehrere Flüsse als Output.
B21: Flüsse:
C23: Flüsse müssen in Mg umgerechnet werden
B32: Prozesse:
B33: Lager
B34: Transferkoeffizienten
B35: Umrechnungsfaktoren:
B36: Codelisten:

Sheet Version_02.05.

Sheet 1_Flows>>>>

Sheet 1_1_Definition_Flows
A1: Complete? | B1: ID | C1: Flow_ID | D1: Name(EN) | E1: Name(DE) | F1: Region | G1: Type_Biomass | H1: Product/By-product/waste | I1: Comment | J1: Output_Process | K1: Process_ID_O | L1: Input_Process | M1: Process_ID_I | N1: Value_Source | O1: WC? | P1: DM? | Q1: CC? | R1: WC | S1: WC_source | T1: DM | U1: DM_source | V1: CC_DM[%] | W1: CC_DM_source | X1: CC | Y1: CC_FM_source
A2: TRUE | B2: 01 | C2: ="F_"&LEFT(K2,2)&"_"&LEFT(M2,2) -> F_13_20 | D2: Rye-Plant | E2: Roggen | F2: BB | H2: Product | J2: Rye_Cultivation | K2: =_xlfn.XLOOKUP(J2,Tab_Def_Processes[Name(EN)],Tab_Def_Processes[Process_ID],,0,) -> 13_Rye_BB | L2: Rye_Harvest | M2: =_xlfn.XLOOKUP(L2,Tab_Def_Processes[Name(EN)],Tab_Def_Processes[Process_ID],,0,) -> 20_Rye_BB | N2: Data_assumption | O2: Yes | P2: Yes | Q2: Yes | R2: =1-Tab_Def_Flows[[#This Row],[DM]] -> 0.14 | S2: https://www.lfl.bayern.de/mam/cms07/iab/dateien/basisdaten22_tabelle_1a_20211210.pdf | T2: 0.86 | U2: https://www.lfl.bayern.de/mam/cms07/iab/dateien/basisdaten22_tabelle_1a_20211210.pdf | V2: 0.48 | W2: assumption | X2: =Tab_Def_Flows[[#This Row],[CC_DM'[%']]]*Tab_Def_Flows[[#This Row],[DM]] -> 0.4128
A3: TRUE | B3: 02 | C3: ="F_"&LEFT(K3,2)&"_"&LEFT(M3,2) -> F_20_15 | D3: Rye-Grain | E3: Roggen Körner | F3: BB | H3: Product | J3: Rye_Harvest | K3: =_xlfn.XLOOKUP(J3,Tab_Def_Processes[Name(EN)],Tab_Def_Processes[Process_ID],,0,) -> 20_Rye_BB | L3: Rye-Grain_Processing & Consumption | M3: =_xlfn.XLOOKUP(L3,Tab_Def_Processes[Name(EN)],Tab_Def_Processes[Process_ID],,0,) -> 15_Rye_BB | N3: Data_Literature | O3: Yes | P3: Yes | Q3: Yes | R3: =1-Tab_Def_Flows[[#This Row],[DM]] -> 0.14 | S3: https://www.lfl.bayern.de/mam/cms07/iab/dateien/basisdaten22_tabelle_1a_20211210.pdf | T3: 0.86 | U3: https://www.lfl.bayern.de/mam/cms07/iab/dateien/basisdaten22_tabelle_1a_20211210.pdf | V3: 0.48 | W3: assumption | X3: =Tab_Def_Flows[[#This Row],[CC_DM'[%']]]*Tab_Def_Flows[[#This Row],[DM]] -> 0.4128
A4: TRUE | B4: 03 | C4: ="F_"&LEFT(K4,2)&"_"&LEFT(M4,2) -> F_20_01 | D4: Rye-Straw (technical usable) | E4: Technische nutzbares Roggenstroh | F4: BB | H4: By-Product | J4: Rye_Harvest | K4: =_xlfn.XLOOKUP(J4,Tab_Def_Processes[Name(EN)],Tab_Def_Processes[Process_ID],,0,) -> 20_Rye_BB | L4: Biogas_Production | M4: =_xlfn.XLOOKUP(L4,Tab_Def_Processes[Name(EN)],Tab_Def_Processes[Process_ID],,0,) -> 01_Bio_BB | N4: Data_Literature | O4: Yes | P4: Yes | Q4: Yes | R4: =1-Tab_Def_Flows[[#This Row],[DM]] -> 0.14 | S4: https://www.lfl.bayern.de/mam/cms07/iab/dateien/basisdaten22_tabelle_1a_20211210.pdf | T4: 0.86 | U4: https://www.lfl.bayern.de/mam/cms07/iab/dateien/basisdaten22_tabelle_1a_20211210.pdf | V4: 0.48 | W4: assumption | X4: =Tab_Def_Flows[[#This Row],[CC_DM'[%']]]*Tab_Def_Flows[[#This Row],[DM]] -> 0.4128
A5: TRUE | B5: 04 | C5: ="F_"&LEFT(K5,2)&"_"&LEFT(M5,2) -> F_20_16 | D5: Rye-Straw (non-technical usable) | E5: Nicht technische nutzbares Roggenstroh | F5: BB | H5: By-Product | J5: Rye_Harvest | K5: =_xlfn.XLOOKUP(J5,Tab_Def_Processes[Name(EN)],Tab_Def_Processes[Process_ID],,0,) -> 20_Rye_BB | L5: Rye-Straw (non-mobilizable)_Degradation | M5: =_xlfn.XLOOKUP(L5,Tab_Def_Processes[Name(EN)],Tab_Def_Processes[Process_ID],,0,) -> 16_Rye_BB | N5: Data_Literature | O5: Yes | P5: Yes | Q5: Yes | R5: =1-Tab_Def_Flows[[#This Row],[DM]] -> 0.14 | S5: https://www.lfl.bayern.de/mam/cms07/iab/dateien/basisdaten22_tabelle_1a_20211210.pdf | T5: 0.86 | U5: https://www.lfl.bayern.de/mam/cms07/iab/dateien/basisdaten22_tabelle_1a_20211210.pdf | V5: 0.48 | W5: assumption | X5: =Tab_Def_Flows[[#This Row],[CC_DM'[%']]]*Tab_Def_Flows[[#This Row],[DM]] -> 0.4128
A6: TRUE | B6: 05 | C6: ="F_"&LEFT(K6,2)&"_"&LEFT(M6,2) -> F_04_01 | D6: Cow-Manure | E6: Rindergülle | F6: BB | H6: By-Product | J6: Cow-Manure_Production | K6: =_xlfn.XLOOKUP(J6,Tab_Def_Processes[Name(EN)],Tab_Def_Processes[Process_ID],,0,) -> 04_Cow_BB | L6: Biogas_Production | M6: =_xlfn.XLOOKUP(L6,Tab_Def_Processes[Name(EN)],Tab_Def_Processes[Process_ID],,0,) -> 01_Bio_BB | O6: Yes | P6: Yes | Q6: Yes | R6: =1-Tab_Def_Flows[[#This Row],[DM]] -> 0.938 | S6: Lab Data | T6: 0.062 | U6: Stramento | V6: 0.49 | W6: Stramento | X6: =Tab_Def_Flows[[#This Row],[CC_DM'[%']]]*Tab_Def_Flows[[#This Row],[DM]] -> 0.03038
A7: FALSE | B7: 06 | C7: ="F_"&LEFT(K7,2)&"_"&LEFT(M7,2) -> F_01_05 | D7: Biogas | E7: Biogas | F7: BB | H7: Product | J7: Biogas_Production | K7: =_xlfn.XLOOKUP(J7,Tab_Def_Processes[Name(EN)],Tab_Def_Processes[Process_ID],,0,) -> 01_Bio_BB | L7: Biogas_Incineration | M7: =_xlfn.XLOOKUP(L7,Tab_Def_Processes[Name(EN)],Tab_Def_Processes[Process_ID],,0,) -> 05_Bio_BB | N7: Calculation_TC | O7: Yes | P7: Yes | Q7: Yes | R7: =1-Tab_Def_Flows[[#This Row],[DM]] -> 0 | T7: 1 | U7: Stramento | V7: 0.38 | W7: Stramento | X7: =Tab_Def_Flows[[#This Row],[CC_DM'[%']]]*Tab_Def_Flows[[#This Row],[DM]] -> 0.38
A8: FALSE | B8: 07 | C8: ="F_"&LEFT(K8,2)&"_"&LEFT(M8,2) -> F_01_02 | D8: Rye-Straw-Digestate | E8: Roggenstroh Gärrest | F8: BB | H8: By-Product | J8: Biogas_Production | K8: =_xlfn.XLOOKUP(J8,Tab_Def_Processes[Name(EN)],Tab_Def_Processes[Process_ID],,0,) -> 01_Bio_BB | L8: MBC_Production | M8: =_xlfn.XLOOKUP(L8,Tab_Def_Processes[Name(EN)],Tab_Def_Processes[Process_ID],,0,) -> 02_MBC_BB | N8: Data_experiment | O8: Yes | P8: Yes | Q8: Yes | R8: =1-Tab_Def_Flows[[#This Row],[DM]] -> 0.67767062 | T8: 0.32232938 | U8: Stramento | V8: 0.382 | W8: Stramento | X8: =Tab_Def_Flows[[#This Row],[CC_DM'[%']]]*Tab_Def_Flows[[#This Row],[DM]] -> 0.12312982
A9: FALSE | B9: 08 | C9: ="F_"&LEFT(K9,2)&"_"&LEFT(M9,2) -> F_02_03 | D9: MBC-Product | E9: Mycel basierter composit | F9: BB | H9: Product | J9: MBC_Production | K9: =_xlfn.XLOOKUP(J9,Tab_Def_Processes[Name(EN)],Tab_Def_Processes[Process_ID],,0,) -> 02_MBC_BB | L9: MBC_Use-Phase | M9: =_xlfn.XLOOKUP(L9,Tab_Def_Processes[Name(EN)],Tab_Def_Processes[Process_ID],,0,) -> 03_MBC_BB | O9: Yes | P9: Yes | Q9: Yes | R9: =1-Tab_Def_Flows[[#This Row],[DM]] -> 0.6085 | T9: 0.3915 | V9: 0.398 | X9: =Tab_Def_Flows[[#This Row],[CC_DM'[%']]]*Tab_Def_Flows[[#This Row],[DM]] -> 0.155817
A10: FALSE | B10: 09 | C10: ="F_"&LEFT(K10,2)&"_"&LEFT(M10,2) -> F_03_07 | D10: MBC-EoL | E10: MBC verwendet | F10: BB | H10: Waste | J10: MBC_Use-Phase | K10: =_xlfn.XLOOKUP(J10,Tab_Def_Processes[Name(EN)],Tab_Def_Processes[Process_ID],,0,) -> 03_MBC_BB | L10: MBC-EoL_Treatment | M10: =_xlfn.XLOOKUP(L10,Tab_Def_Processes[Name(EN)],Tab_Def_Processes[Process_ID],,0,) -> 07_MBC_BB | O10: Yes | P10: Yes | Q10: Yes | R10: =R9 -> 0.6085 | T10: =T9 -> 0.3915 | V10: =V9 -> 0.398 | X10: =Tab_Def_Flows[[#This Row],[CC_DM'[%']]]*Tab_Def_Flows[[#This Row],[DM]] -> 0.155817
A11: FALSE | B11: 10 | C11: ="F_"&LEFT(K11,2)&"_"&LEFT(M11,2) -> F_02_06 | D11: MBC-Production waste | E11: MBC Produktionsabfall | F11: BB | H11: Waste | J11: MBC_Production | K11: =_xlfn.XLOOKUP(J11,Tab_Def_Processes[Name(EN)],Tab_Def_Processes[Process_ID],,0,) -> 02_MBC_BB | L11: MBC-Production Waste_Treatment | M11: =_xlfn.XLOOKUP(L11,Tab_Def_Processes[Name(EN)],Tab_Def_Processes[Process_ID],,0,) -> 06_MBC_BB | O11: Yes | P11: Yes | Q11: Yes | R11: =1-Tab_Def_Flows[[#This Row],[DM]] -> 0.58 | T11: 0.42 | V11: 0.382 | X11: =Tab_Def_Flows[[#This Row],[CC_DM'[%']]]*Tab_Def_Flows[[#This Row],[DM]] -> 0.16044
A12: FALSE | B12: 11 | C12: ="F_"&LEFT(K12,2)&"_"&LEFT(M12,2) -> F_11_02 | D12: Millet-Grain | E12: Hirsekörner | F12: BB | H12: Product | J12: Millet_Production | K12: =_xlfn.XLOOKUP(J12,Tab_Def_Processes[Name(EN)],Tab_Def_Processes[Process_ID],,0,) -> 11_Mil_BB | L12: MBC_Production | M12: =_xlfn.XLOOKUP(L12,Tab_Def_Processes[Name(EN)],Tab_Def_Processes[Process_ID],,0,) -> 02_MBC_BB | O12: Yes | P12: Yes | Q12: Yes | R12: =1-Tab_Def_Flows[[#This Row],[DM]] -> 0.08805 | T12: 0.91195 | V12: 0.462 | X12: =Tab_Def_Flows[[#This Row],[CC_DM'[%']]]*Tab_Def_Flows[[#This Row],[DM]] -> 0.4213209
A13: FALSE | B13: 12 | C13: ="F_"&LEFT(K13,2)&"_"&LEFT(M13,2) -> F_08_02 | D13: Water-Import | E13: Wasser Input MBC | F13: BB | H13: Product | J13: Water_Import | K13: =_xlfn.XLOOKUP(J13,Tab_Def_Processes[Name(EN)],Tab_Def_Processes[Process_ID],,0,) -> 08_Wat_BB | L13: MBC_Production | M13: =_xlfn.XLOOKUP(L13,Tab_Def_Processes[Name(EN)],Tab_Def_Processes[Process_ID],,0,) -> 02_MBC_BB | O13: Yes | P13: Yes | Q13: Yes | R13: =1-Tab_Def_Flows[[#This Row],[DM]] -> 1 | T13: 0 | V13: 0 | X13: =Tab_Def_Flows[[#This Row],[CC_DM'[%']]]*Tab_Def_Flows[[#This Row],[DM]] -> 0
A14: FALSE | B14: 13 | C14: ="F_"&LEFT(K14,2)&"_"&LEFT(M14,2) -> F_02_14 | D14: Water-Export | E14: Wasser Output MBC | F14: BB | H14: Waste | J14: MBC_Production | K14: =_xlfn.XLOOKUP(J14,Tab_Def_Processes[Name(EN)],Tab_Def_Processes[Process_ID],,0,) -> 02_MBC_BB | L14: Water_Export | M14: =_xlfn.XLOOKUP(L14,Tab_Def_Processes[Name(EN)],Tab_Def_Processes[Process_ID],,0,) -> 14_Wat_BB | O14: Yes | P14: Yes | Q14: Yes | R14: =1-Tab_Def_Flows[[#This Row],[DM]] -> 1 | T14: 0 | V14: 0 | X14: =Tab_Def_Flows[[#This Row],[CC_DM'[%']]]*Tab_Def_Flows[[#This Row],[DM]] -> 0
A15: FALSE | B15: 14 | C15: ="F_"&LEFT(K15,2)&"_"&LEFT(M15,2) -> F_02_12 | D15: MBC-Production-Delta | E15: Mass Delta | F15: BB | H15: Waste | J15: MBC_Production | K15: =_xlfn.XLOOKUP(J15,Tab_Def_Processes[Name(EN)],Tab_Def_Processes[Process_ID],,0,) -> 02_MBC_BB | L15: MBC-Production-Delta_Production | M15: =_xlfn.XLOOKUP(L15,Tab_Def_Processes[Name(EN)],Tab_Def_Processes[Process_ID],,0,) -> 12_MBC_BB | O15: Yes | P15: Yes | Q15: Yes | R15: =1-Tab_Def_Flows[[#This Row],[DM]] -> 0 | T15: 1 | V15: 0.36707297 | X15: =Tab_Def_Flows[[#This Row],[CC_DM'[%']]]*Tab_Def_Flows[[#This Row],[DM]] -> 0.36707297
A16: FALSE | B16: 15 | C16: ="F_"&LEFT(K16,2)&"_"&LEFT(M16,2) -> F_07_09 | D16: MBC (EoL)-Pyrolysis | E16: EoL-MBC (Pyro) | F16: BB | H16: Waste | J16: MBC-EoL_Treatment | K16: =_xlfn.XLOOKUP(J16,Tab_Def_Processes[Name(EN)],Tab_Def_Processes[Process_ID],,0,) -> 07_MBC_BB | L16: MBC-EoL_Pyrolysis | M16: =_xlfn.XLOOKUP(L16,Tab_Def_Processes[Name(EN)],Tab_Def_Processes[Process_ID],,0,) -> 09_MBC_BB | O16: Yes | P16: Yes | Q16: Yes | R16: =1-Tab_Def_Flows[[#This Row],[DM]] -> 0.6085 | T16: =T10 -> 0.3915 | V16: 0.398 | X16: =Tab_Def_Flows[[#This Row],[CC_DM'[%']]]*Tab_Def_Flows[[#This Row],[DM]] -> 0.155817
A17: FALSE | B17: 16 | C17: ="F_"&LEFT(K17,2)&"_"&LEFT(M17,2) -> F_07_10 | D17: MBC (EoL)-Incineration | E17: EoL-MBC (Inci) | F17: BB | H17: Waste | J17: MBC-EoL_Treatment | K17: =_xlfn.XLOOKUP(J17,Tab_Def_Processes[Name(EN)],Tab_Def_Processes[Process_ID],,0,) -> 07_MBC_BB | L17: MBC-EoL_Incineration | M17: =_xlfn.XLOOKUP(L17,Tab_Def_Processes[Name(EN)],Tab_Def_Processes[Process_ID],,0,) -> 10_MBC_BB | O17: Yes | P17: Yes | Q17: Yes | R17: =1-Tab_Def_Flows[[#This Row],[DM]] -> 0.6085 | T17: =T10 -> 0.3915 | V17: 0.398 | X17: =Tab_Def_Flows[[#This Row],[CC_DM'[%']]]*Tab_Def_Flows[[#This Row],[DM]] -> 0.155817
A18: FALSE | B18: 17 | C18: ="F_"&LEFT(K18,2)&"_"&LEFT(M18,2) -> F_09_17 | D18: Biochar-Pyrolysis | E18: Pyrolyse Kohle | F18: BB | H18: Product | J18: MBC-EoL_Pyrolysis | K18: =_xlfn.XLOOKUP(J18,Tab_Def_Processes[Name(EN)],Tab_Def_Processes[Process_ID],,0,) -> 09_MBC_BB | L18: Lithosphere_Stock | M18: =_xlfn.XLOOKUP(L18,Tab_Def_Processes[Name(EN)],Tab_Def_Processes[Process_ID],,0,) -> 17_Lit_BB | O18: Yes | P18: Yes | Q18: Yes | R18: =1-Tab_Def_Flows[[#This Row],[DM]] -> 0 | T18: 1 | V18: 0.95 | W18: A review of pyrolysis technologies and feedstock: A blending approach for plastic and biomass towards optimum biochar yield | X18: =Tab_Def_Flows[[#This Row],[CC_DM'[%']]]*Tab_Def_Flows[[#This Row],[DM]] -> 0.95
A19: FALSE | B19: 18 | C19: ="F_"&LEFT(K19,2)&"_"&LEFT(M19,2) -> F_10_22 | D19: Ash-Incineration | E19: Verbresnnungsasche | F19: BB | H19: Waste | J19: MBC-EoL_Incineration | K19: =_xlfn.XLOOKUP(J19,Tab_Def_Processes[Name(EN)],Tab_Def_Processes[Process_ID],,0,) -> 10_MBC_BB | L19: Environment_Stock | M19: =_xlfn.XLOOKUP(L19,Tab_Def_Processes[Name(EN)],Tab_Def_Processes[Process_ID],,0,) -> 22_Env_BB | O19: Yes | P19: Yes | Q19: Yes | R19: =1-Tab_Def_Flows[[#This Row],[DM]] -> 0 | T19: 1 | V19: 0.1 | X19: =Tab_Def_Flows[[#This Row],[CC_DM'[%']]]*Tab_Def_Flows[[#This Row],[DM]] -> 0.1
A20: FALSE | B20: 19 | C20: ="F_"&LEFT(K20,2)&"_"&LEFT(M20,2) -> F_10_19 | D20: C-from MBC (EoL)-Incineration | E20: Rauchgas | F20: BB | H20: Waste | J20: MBC-EoL_Incineration | K20: =_xlfn.XLOOKUP(J20,Tab_Def_Processes[Name(EN)],Tab_Def_Processes[Process_ID],,0,) -> 10_MBC_BB | L20: Atmosphere_Stock | M20: =_xlfn.XLOOKUP(L20,Tab_Def_Processes[Name(EN)],Tab_Def_Processes[Process_ID],,0,) -> 19_Atm_BB | N20: Calculation_TC | O20: Yes | P20: Yes | Q20: Yes | R20: =1-Tab_Def_Flows[[#This Row],[DM]] -> 0 | T20: 1 | V20: 1 | X20: =Tab_Def_Flows[[#This Row],[CC_DM'[%']]]*Tab_Def_Flows[[#This Row],[DM]] -> 1
A21: FALSE | B21: 20 | C21: ="F_"&LEFT(K21,2)&"_"&LEFT(M21,2) -> F_00_13 | D21: Environment-Rye | F21: BB | H21: Product | J21: Environment_ | K21: =_xlfn.XLOOKUP(J21,Tab_Def_Processes[Name(EN)],Tab_Def_Processes[Process_ID],,0,) -> 00_Env_BB | L21: Rye_Cultivation | M21: =_xlfn.XLOOKUP(L21,Tab_Def_Processes[Name(EN)],Tab_Def_Processes[Process_ID],,0,) -> 13_Rye_BB | O21: Yes | P21: Yes | Q21: Yes | R21: 0.23841962 | S21: https://www.lfl.bayern.de/mam/cms07/iab/dateien/basisdaten22_tabelle_1a_20211210.pdf | T21: 0.76158038 | U21: https://www.lfl.bayern.de/mam/cms07/iab/dateien/basisdaten22_tabelle_1a_20211210.pdf | V21: 0 | W21: assumption | X21: =Tab_Def_Flows[[#This Row],[CC_DM'[%']]]*Tab_Def_Flows[[#This Row],[DM]] -> 0
A22: FALSE | B22: 21 | C22: ="F_"&LEFT(K22,2)&"_"&LEFT(M22,2) -> F_00_04 | D22: Environment-Cow-Manure | F22: BB | H22: By-Product | J22: Environment_ | K22: =_xlfn.XLOOKUP(J22,Tab_Def_Processes[Name(EN)],Tab_Def_Processes[Process_ID],,0,) -> 00_Env_BB | L22: Cow-Manure_Production | M22: =_xlfn.XLOOKUP(L22,Tab_Def_Processes[Name(EN)],Tab_Def_Processes[Process_ID],,0,) -> 04_Cow_BB | O22: Yes | P22: Yes | Q22: Yes | R22: 0.96738929 | S22: Lab Data | T22: 0.032610713 | U22: Stramento | V22: 0 | W22: Stramento | X22: =Tab_Def_Flows[[#This Row],[CC_DM'[%']]]*Tab_Def_Flows[[#This Row],[DM]] -> 0
A23: FALSE | B23: 22 | C23: ="F_"&LEFT(K23,2)&"_"&LEFT(M23,2) -> F_00_11 | D23: Environment-Millet | F23: BB | H23: Product | J23: Environment_ | K23: =_xlfn.XLOOKUP(J23,Tab_Def_Processes[Name(EN)],Tab_Def_Processes[Process_ID],,0,) -> 00_Env_BB | L23: Millet_Production | M23: =_xlfn.XLOOKUP(L23,Tab_Def_Processes[Name(EN)],Tab_Def_Processes[Process_ID],,0,) -> 11_Mil_BB | O23: Yes | P23: Yes | Q23: Yes | R23: 0.15215687 | T23: 0.84784313 | V23: 0 | X23: =Tab_Def_Flows[[#This Row],[CC_DM'[%']]]*Tab_Def_Flows[[#This Row],[DM]] -> 0
A24: FALSE | B24: 23 | C24: ="F_"&LEFT(K24,2)&"_"&LEFT(M24,2) -> F_00_08 | D24: Environment-Water | F24: BB | H24: Product | J24: Environment_ | K24: =_xlfn.XLOOKUP(J24,Tab_Def_Processes[Name(EN)],Tab_Def_Processes[Process_ID],,0,) -> 00_Env_BB | L24: Water_Import | M24: =_xlfn.XLOOKUP(L24,Tab_Def_Processes[Name(EN)],Tab_Def_Processes[Process_ID],,0,) -> 08_Wat_BB | O24: Yes | P24: Yes | Q24: Yes | R24: =1-Tab_Def_Flows[[#This Row],[DM]] -> 1 | T24: 0 | V24: 0 | X24: =Tab_Def_Flows[[#This Row],[CC_DM'[%']]]*Tab_Def_Flows[[#This Row],[DM]] -> 0
A25: FALSE | B25: 24 | C25: ="F_"&LEFT(K25,2)&"_"&LEFT(M25,2) -> F_09_19 | D25: C-from MBC (EoL)-Pyrolysis | F25: BB | H25: Biomass Pyrolysis | J25: MBC-EoL_Pyrolysis | K25: =_xlfn.XLOOKUP(J25,Tab_Def_Processes[Name(EN)],Tab_Def_Processes[Process_ID],,0,) -> 09_MBC_BB | L25: Atmosphere_Stock | M25: =_xlfn.XLOOKUP(L25,Tab_Def_Processes[Name(EN)],Tab_Def_Processes[Process_ID],,0,) -> 19_Atm_BB | O25: Yes | P25: Yes | Q25: Yes | R25: =1-Tab_Def_Flows[[#This Row],[DM]] -> 0 | T25: 1 | V25: 1 | X25: =Tab_Def_Flows[[#This Row],[CC_DM'[%']]]*Tab_Def_Flows[[#This Row],[DM]] -> 1
A26: FALSE | B26: 25 | C26: ="F_"&LEFT(K26,2)&"_"&LEFT(M26,2) -> F_17_19 | D26: CO2-from Lithosphere | F26: BB | H26: Waste | J26: Lithosphere_Stock | K26: =_xlfn.XLOOKUP(J26,Tab_Def_Processes[Name(EN)],Tab_Def_Processes[Process_ID],,0,) -> 17_Lit_BB | L26: Atmosphere_Stock | M26: =_xlfn.XLOOKUP(L26,Tab_Def_Processes[Name(EN)],Tab_Def_Processes[Process_ID],,0,) -> 19_Atm_BB | O26: Yes | P26: Yes | Q26: Yes | R26: =1-Tab_Def_Flows[[#This Row],[DM]] -> 0 | T26: 1 | V26: 1 | X26: =Tab_Def_Flows[[#This Row],[CC_DM'[%']]]*Tab_Def_Flows[[#This Row],[DM]] -> 1
A27: FALSE | B27: 26 | C27: ="F_"&LEFT(K27,2)&"_"&LEFT(M27,2) -> F_09_22 | D27: Environment-from MBC (EoL)-Pyrolysis | F27: BB | J27: MBC-EoL_Pyrolysis | K27: =_xlfn.XLOOKUP(J27,Tab_Def_Processes[Name(EN)],Tab_Def_Processes[Process_ID],,0,) -> 09_MBC_BB | L27: Environment_Stock | M27: =_xlfn.XLOOKUP(L27,Tab_Def_Processes[Name(EN)],Tab_Def_Processes[Process_ID],,0,) -> 22_Env_BB | O27: Yes | P27: Yes | Q27: Yes | R27: 0.72596641 | T27: 0.27403359 | V27: 0 | X27: =Tab_Def_Flows[[#This Row],[CC_DM'[%']]]*Tab_Def_Flows[[#This Row],[DM]] -> 0
A28: TRUE | B28: 27 | C28: ="F_"&LEFT(K28,2)&"_"&LEFT(M28,2) -> F_24_24 | K28: =_xlfn.XLOOKUP(J28,Tab_Def_Processes[Name(EN)],Tab_Def_Processes[Process_ID],,0,) -> 24__ | M28: =_xlfn.XLOOKUP(L28,Tab_Def_Processes[Name(EN)],Tab_Def_Processes[Process_ID],,0,) -> 24__ | O28: Yes | P28: Yes | Q28: Yes
A29: TRUE | B29: 28 | C29: ="F_"&LEFT(K29,2)&"_"&LEFT(M29,2) -> F_01_21 | D29: Biogas-Production-Delta | J29: Biogas_Production | K29: =_xlfn.XLOOKUP(J29,Tab_Def_Processes[Name(EN)],Tab_Def_Processes[Process_ID],,0,) -> 01_Bio_BB | L29: Biogas-Production-Delta_ | M29: =_xlfn.XLOOKUP(L29,Tab_Def_Processes[Name(EN)],Tab_Def_Processes[Process_ID],,0,) -> 21_Bio_BB | O29: Yes | P29: Yes | Q29: Yes | R29: =1-Tab_Def_Flows[[#This Row],[DM]] -> 0 | T29: 1 | V29: 0.85418505 | X29: =Tab_Def_Flows[[#This Row],[CC_DM'[%']]]*Tab_Def_Flows[[#This Row],[DM]] -> 0.85418505
A30: FALSE | B30: 29 | C30: ="F_"&LEFT(K30,2)&"_"&LEFT(M30,2) -> F_19_13 | D30: CO2-to Rye_Cultivation | J30: Atmosphere_Stock | K30: =_xlfn.XLOOKUP(J30,Tab_Def_Processes[Name(EN)],Tab_Def_Processes[Process_ID],,0,) -> 19_Atm_BB | L30: Rye_Cultivation | M30: =_xlfn.XLOOKUP(L30,Tab_Def_Processes[Name(EN)],Tab_Def_Processes[Process_ID],,0,) -> 13_Rye_BB | O30: Yes | P30: Yes | Q30: Yes | R30: 0 | T30: 1 | V30: 1 | X30: =Tab_Def_Flows[[#This Row],[CC_DM'[%']]]*Tab_Def_Flows[[#This Row],[DM]] -> 1
A31: FALSE | B31: 30 | C31: ="F_"&LEFT(K31,2)&"_"&LEFT(M31,2) -> F_19_04 | D31: CO2-to Cow-Manure_Production | J31: Atmosphere_Stock | K31: =_xlfn.XLOOKUP(J31,Tab_Def_Processes[Name(EN)],Tab_Def_Processes[Process_ID],,0,) -> 19_Atm_BB | L31: Cow-Manure_Production | M31: =_xlfn.XLOOKUP(L31,Tab_Def_Processes[Name(EN)],Tab_Def_Processes[Process_ID],,0,) -> 04_Cow_BB | O31: Yes | P31: Yes | Q31: Yes | R31: 0 | T31: 1 | V31: 1 | X31: =Tab_Def_Flows[[#This Row],[CC_DM'[%']]]*Tab_Def_Flows[[#This Row],[DM]] -> 1
A32: FALSE | B32: 31 | C32: ="F_"&LEFT(K32,2)&"_"&LEFT(M32,2) -> F_19_11 | D32: CO2-to Millet_Production | J32: Atmosphere_Stock | K32: =_xlfn.XLOOKUP(J32,Tab_Def_Processes[Name(EN)],Tab_Def_Processes[Process_ID],,0,) -> 19_Atm_BB | L32: Millet_Production | M32: =_xlfn.XLOOKUP(L32,Tab_Def_Processes[Name(EN)],Tab_Def_Processes[Process_ID],,0,) -> 11_Mil_BB | O32: Yes | P32: Yes | Q32: Yes | R32: 0 | T32: 1 | V32: 1 | X32: =Tab_Def_Flows[[#This Row],[CC_DM'[%']]]*Tab_Def_Flows[[#This Row],[DM]] -> 1
A33: FALSE | B33: 32 | C33: ="F_"&LEFT(K33,2)&"_"&LEFT(M33,2) -> F_15_19 | D33: CO2-from Rye-Grain_Processing & Consumption | J33: Rye-Grain_Processing & Consumption | K33: =_xlfn.XLOOKUP(J33,Tab_Def_Processes[Name(EN)],Tab_Def_Processes[Process_ID],,0,) -> 15_Rye_BB | L33: Atmosphere_Stock | M33: =_xlfn.XLOOKUP(L33,Tab_Def_Processes[Name(EN)],Tab_Def_Processes[Process_ID],,0,) -> 19_Atm_BB | O33: Yes | P33: Yes | Q33: Yes | R33: 0 | T33: 1 | V33: 1 | X33: =Tab_Def_Flows[[#This Row],[CC_DM'[%']]]*Tab_Def_Flows[[#This Row],[DM]] -> 1
A34: FALSE | B34: 33 | C34: ="F_"&LEFT(K34,2)&"_"&LEFT(M34,2) -> F_16_19 | D34: CO2-from Rye-Straw (non-mobilizable)_Degradation | J34: Rye-Straw (non-mobilizable)_Degradation | K34: =_xlfn.XLOOKUP(J34,Tab_Def_Processes[Name(EN)],Tab_Def_Processes[Process_ID],,0,) -> 16_Rye_BB | L34: Atmosphere_Stock | M34: =_xlfn.XLOOKUP(L34,Tab_Def_Processes[Name(EN)],Tab_Def_Processes[Process_ID],,0,) -> 19_Atm_BB | O34: Yes | P34: Yes | Q34: Yes | R34: 0 | T34: 1 | V34: 1 | X34: =Tab_Def_Flows[[#This Row],[CC_DM'[%']]]*Tab_Def_Flows[[#This Row],[DM]] -> 1
A35: FALSE | B35: 34 | C35: ="F_"&LEFT(K35,2)&"_"&LEFT(M35,2) -> F_05_19 | D35: CO2-from Biogas_Incineration | J35: Biogas_Incineration | K35: =_xlfn.XLOOKUP(J35,Tab_Def_Processes[Name(EN)],Tab_Def_Processes[Process_ID],,0,) -> 05_Bio_BB | L35: Atmosphere_Stock | M35: =_xlfn.XLOOKUP(L35,Tab_Def_Processes[Name(EN)],Tab_Def_Processes[Process_ID],,0,) -> 19_Atm_BB | O35: Yes | P35: Yes | Q35: Yes | R35: =R7 -> 0 | T35: =T7 -> 1 | V35: 1 | X35: =Tab_Def_Flows[[#This Row],[CC_DM'[%']]]*Tab_Def_Flows[[#This Row],[DM]] -> 1
A36: FALSE | B36: 35 | C36: ="F_"&LEFT(K36,2)&"_"&LEFT(M36,2) -> F_15_22 | D36: Environment-from Rye-Grain_Processing & Consumption | J36: Rye-Grain_Processing & Consumption | K36: =_xlfn.XLOOKUP(J36,Tab_Def_Processes[Name(EN)],Tab_Def_Processes[Process_ID],,0,) -> 15_Rye_BB | L36: Environment_Stock | M36: =_xlfn.XLOOKUP(L36,Tab_Def_Processes[Name(EN)],Tab_Def_Processes[Process_ID],,0,) -> 22_Env_BB | O36: Yes | P36: Yes | Q36: Yes | R36: 0.23841962 | T36: 0.76158038 | V36: 0 | X36: =Tab_Def_Flows[[#This Row],[CC_DM'[%']]]*Tab_Def_Flows[[#This Row],[DM]] -> 0
A37: FALSE | B37: 36 | C37: ="F_"&LEFT(K37,2)&"_"&LEFT(M37,2) -> F_16_22 | D37: Environment-from Rye-Straw (non-mobilizable)_Degradation | J37: Rye-Straw (non-mobilizable)_Degradation | K37: =_xlfn.XLOOKUP(J37,Tab_Def_Processes[Name(EN)],Tab_Def_Processes[Process_ID],,0,) -> 16_Rye_BB | L37: Environment_Stock | M37: =_xlfn.XLOOKUP(L37,Tab_Def_Processes[Name(EN)],Tab_Def_Processes[Process_ID],,0,) -> 22_Env_BB | O37: Yes | P37: Yes | Q37: Yes | R37: 0.23841962 | T37: 0.76158038 | V37: 0 | X37: =Tab_Def_Flows[[#This Row],[CC_DM'[%']]]*Tab_Def_Flows[[#This Row],[DM]] -> 0
A38: FALSE | B38: 37 | C38: ="F_"&LEFT(K38,2)&"_"&LEFT(M38,2) -> F_12_22 | D38: Environment-from MBC-Production-Delta | J38: MBC-Production-Delta_Production | K38: =_xlfn.XLOOKUP(J38,Tab_Def_Processes[Name(EN)],Tab_Def_Processes[Process_ID],,0,) -> 12_MBC_BB | L38: Environment_Stock | M38: =_xlfn.XLOOKUP(L38,Tab_Def_Processes[Name(EN)],Tab_Def_Processes[Process_ID],,0,) -> 22_Env_BB | O38: Yes | P38: Yes | Q38: Yes | R38: 0 | T38: 1 | V38: 0 | X38: =Tab_Def_Flows[[#This Row],[CC_DM'[%']]]*Tab_Def_Flows[[#This Row],[DM]] -> 0
A39: FALSE | B39: 38 | C39: ="F_"&LEFT(K39,2)&"_"&LEFT(M39,2) -> F_12_19 | D39: CO2-from MBC-Production-Delta | J39: MBC-Production-Delta_Production | K39: =_xlfn.XLOOKUP(J39,Tab_Def_Processes[Name(EN)],Tab_Def_Processes[Process_ID],,0,) -> 12_MBC_BB | L39: Atmosphere_Stock | M39: =_xlfn.XLOOKUP(L39,Tab_Def_Processes[Name(EN)],Tab_Def_Processes[Process_ID],,0,) -> 19_Atm_BB | O39: Yes | P39: Yes | Q39: Yes | R39: 0 | T39: 1 | V39: 1 | X39: =Tab_Def_Flows[[#This Row],[CC_DM'[%']]]*Tab_Def_Flows[[#This Row],[DM]] -> 1
A40: FALSE | B40: 39 | C40: ="F_"&LEFT(K40,2)&"_"&LEFT(M40,2) -> F_06_19 | D40: CO2-from MBC-Production waste | J40: MBC-Production Waste_Treatment | K40: =_xlfn.XLOOKUP(J40,Tab_Def_Processes[Name(EN)],Tab_Def_Processes[Process_ID],,0,) -> 06_MBC_BB | L40: Atmosphere_Stock | M40: =_xlfn.XLOOKUP(L40,Tab_Def_Processes[Name(EN)],Tab_Def_Processes[Process_ID],,0,) -> 19_Atm_BB | O40: Yes | P40: Yes | Q40: Yes | R40: 0 | T40: 1 | V40: 1 | X40: =Tab_Def_Flows[[#This Row],[CC_DM'[%']]]*Tab_Def_Flows[[#This Row],[DM]] -> 1
...

Sheet 1_2_Data_Flows
A1: ID | B1: Flow_ID | C1: Name(EN) | D1: Type_Biomass | E1: Output_Process | F1: Process_ID_O | G1: Input_Process | H1: Process_ID_I | I1: TC? | J1: WC? | K1: DM? | L1: CC? | M1: Year_Flow | N1: Region_Flow | O1: Flow_Source | P1: UoM_Source | Q1: Name_Source | R1: AVV | S1: Titel_Source | T1: Year_Source | U1: Author_Source | V1: Type_Source | W1: URL | X1: CF_required? | Y1: CF | Z1: Name_CF | AA1: Flow_Py | AB1: UoM_Flow_Py | AC1: WC_[%] | AD1: WC_Flow_Py | AE1: UoM_WC_Flow_Py | AF1: DM_[%] | AG1: DM_Flow_Py2 | AH1: UoM_DM_Flow_Py | AI1: CC_[%] | AJ1: CC_Flow_Py | AK1: UoM_CC_Flow_Py
A2: =ROW()-1 -> 1 | B2: =_xlfn.XLOOKUP(C2,Tab_Def_Flows[Name(EN)],Tab_Def_Flows[Flow_ID],,0,) -> F_13_20 | C2: Rye-Plant | D2: =_xlfn.XLOOKUP(C2,Tab_Def_Flows[Name(EN)],Tab_Def_Flows[Type_Biomass],,0,) -> 0 | E2: =_xlfn.XLOOKUP(C2,Tab_Def_Flows[Name(EN)],Tab_Def_Flows[Output_Process],,0,) -> Rye_Cultivation | F2: =_xlfn.XLOOKUP(C2,Tab_Def_Flows[Name(EN)],Tab_Def_Flows[Process_ID_O],,0,) -> 13_Rye_BB | G2: =_xlfn.XLOOKUP(C2,Tab_Def_Flows[Name(EN)],Tab_Def_Flows[Input_Process],,0,) -> Rye_Harvest | H2: =_xlfn.XLOOKUP(C2,Tab_Def_Flows[Name(EN)],Tab_Def_Flows[Process_ID_I],,0,) -> 20_Rye_BB | I2: =_xlfn.XLOOKUP(C2,Tab_Def_Flows[Name(EN)],Tab_Def_Flows[Value_Source],,0,) -> Data_assumption | J2: =_xlfn.XLOOKUP(C2,Tab_Def_Flows[Name(EN)],Tab_Def_Flows[WC?],,0,) -> Yes | K2: =_xlfn.XLOOKUP(C2,Tab_Def_Flows[Name(EN)],Tab_Def_Flows[DM?],,0,) -> Yes | L2: =_xlfn.XLOOKUP(C2,Tab_Def_Flows[Name(EN)],Tab_Def_Flows[CC?],,0,) -> Yes | M2: 2022 | N2: BB | O2: 1506711.5 | P2: Mg/a | Q2: Stramento | X2: No | Y2: 365 | AA2: =IF(X2="no",O2,O2*Y2) -> 1506711.5 | AB2: Mg | AC2: =INDEX(Tab_Def_Flows[[Flow_ID]:[CC_DM_source]],MATCH(Tab_Data_Flows[[#This Row],[Name(EN)]],Tab_Def_Flows[Name(EN)],0),16) -> 0.14 | AD2: =IF(J2="Yes",AA2*Tab_Data_Flows[[#This Row],[WC_'[%']]],"N.A.") -> 210939.62 | AE2: =Tab_Data_Flows[[#This Row],[UoM_Flow_Py]] -> Mg | AF2: =INDEX(Tab_Def_Flows[[Flow_ID]:[CC_DM_source]],MATCH(Tab_Data_Flows[[#This Row],[Name(EN)]],Tab_Def_Flows[Name(EN)],0),18) -> 0.86 | AG2: =IF(K2="Yes",AF2*Tab_Data_Flows[[#This Row],[Flow_Py]],"N.A.") -> 1295771.9 | AH2: =Tab_Data_Flows[[#This Row],[UoM_Flow_Py]] -> Mg | AI2: =INDEX(Tab_Def_Flows[[Flow_ID]:[CC_DM_source]],MATCH(Tab_Data_Flows[[#This Row],[Name(EN)]],Tab_Def_Flows[Name(EN)],0),20) -> 0.48 | AJ2: =IF(L2="Yes",AI2*Tab_Data_Flows[[#This Row],[Flow_Py]]*Tab_Data_Flows[[#This Row],[DM_'[%']]],"N.A.") -> 621970.52 | AK2: =Tab_Data_Flows[[#This Row],[UoM_Flow_Py]] -> Mg | AM2: =Tab_Data_Flows[[#This Row],[CC_Flow_Py]]/27.7 -> 22453.809 | AN2: =AM2*100 -> 2245380.9
A3: =ROW()-1 -> 2 | B3: =_xlfn.XLOOKUP(C3,Tab_Def_Flows[Name(EN)],Tab_Def_Flows[Flow_ID],,0,) -> F_13_20 | C3: Rye-Plant | D3: =_xlfn.XLOOKUP(C3,Tab_Def_Flows[Name(EN)],Tab_Def_Flows[Type_Biomass],,0,) -> 0 | E3: =_xlfn.XLOOKUP(C3,Tab_Def_Flows[Name(EN)],Tab_Def_Flows[Output_Process],,0,) -> Rye_Cultivation | F3: =_xlfn.XLOOKUP(C3,Tab_Def_Flows[Name(EN)],Tab_Def_Flows[Process_ID_O],,0,) -> 13_Rye_BB | G3: =_xlfn.XLOOKUP(C3,Tab_Def_Flows[Name(EN)],Tab_Def_Flows[Input_Process],,0,) -> Rye_Harvest | H3: =_xlfn.XLOOKUP(C3,Tab_Def_Flows[Name(EN)],Tab_Def_Flows[Process_ID_I],,0,) -> 20_Rye_BB | I3: =_xlfn.XLOOKUP(C3,Tab_Def_Flows[Name(EN)],Tab_Def_Flows[Value_Source],,0,) -> Data_assumption | J3: =_xlfn.XLOOKUP(C3,Tab_Def_Flows[Name(EN)],Tab_Def_Flows[WC?],,0,) -> Yes | K3: =_xlfn.XLOOKUP(C3,Tab_Def_Flows[Name(EN)],Tab_Def_Flows[DM?],,0,) -> Yes | L3: =_xlfn.XLOOKUP(C3,Tab_Def_Flows[Name(EN)],Tab_Def_Flows[CC?],,0,) -> Yes | M3: 2023 | N3: BB | O3: =O2*1.02 -> 1536845.8 | P3: Mg/a | Q3: Stramento | X3: No | Y3: 365 | AA3: =IF(X3="no",O3,O3*Y3) -> 1536845.8 | AB3: Mg | AC3: =INDEX(Tab_Def_Flows[[Flow_ID]:[CC_DM_source]],MATCH(Tab_Data_Flows[[#This Row],[Name(EN)]],Tab_Def_Flows[Name(EN)],0),16) -> 0.14 | AD3: =IF(J3="Yes",AA3*Tab_Data_Flows[[#This Row],[WC_'[%']]],"N.A.") -> 215158.41 | AE3: =Tab_Data_Flows[[#This Row],[UoM_Flow_Py]] -> Mg | AF3: =INDEX(Tab_Def_Flows[[Flow_ID]:[CC_DM_source]],MATCH(Tab_Data_Flows[[#This Row],[Name(EN)]],Tab_Def_Flows[Name(EN)],0),18) -> 0.86 | AG3: =IF(K3="Yes",AF3*Tab_Data_Flows[[#This Row],[Flow_Py]],"N.A.") -> 1321687.4 | AH3: =Tab_Data_Flows[[#This Row],[UoM_Flow_Py]] -> Mg | AI3: =INDEX(Tab_Def_Flows[[Flow_ID]:[CC_DM_source]],MATCH(Tab_Data_Flows[[#This Row],[Name(EN)]],Tab_Def_Flows[Name(EN)],0),20) -> 0.48 | AJ3: =IF(L3="Yes",AI3*Tab_Data_Flows[[#This Row],[Flow_Py]]*Tab_Data_Flows[[#This Row],[DM_'[%']]],"N.A.") -> 634409.93 | AK3: =Tab_Data_Flows[[#This Row],[UoM_Flow_Py]] -> Mg
A4: =ROW()-1 -> 3 | B4: =_xlfn.XLOOKUP(C4,Tab_Def_Flows[Name(EN)],Tab_Def_Flows[Flow_ID],,0,) -> F_13_20 | C4: Rye-Plant | D4: =_xlfn.XLOOKUP(C4,Tab_Def_Flows[Name(EN)],Tab_Def_Flows[Type_Biomass],,0,) -> 0 | E4: =_xlfn.XLOOKUP(C4,Tab_Def_Flows[Name(EN)],Tab_Def_Flows[Output_Process],,0,) -> Rye_Cultivation | F4: =_xlfn.XLOOKUP(C4,Tab_Def_Flows[Name(EN)],Tab_Def_Flows[Process_ID_O],,0,) -> 13_Rye_BB | G4: =_xlfn.XLOOKUP(C4,Tab_Def_Flows[Name(EN)],Tab_Def_Flows[Input_Process],,0,) -> Rye_Harvest | H4: =_xlfn.XLOOKUP(C4,Tab_Def_Flows[Name(EN)],Tab_Def_Flows[Process_ID_I],,0,) -> 20_Rye_BB | I4: =_xlfn.XLOOKUP(C4,Tab_Def_Flows[Name(EN)],Tab_Def_Flows[Value_Source],,0,) -> Data_assumption | J4: =_xlfn.XLOOKUP(C4,Tab_Def_Flows[Name(EN)],Tab_Def_Flows[WC?],,0,) -> Yes | K4: =_xlfn.XLOOKUP(C4,Tab_Def_Flows[Name(EN)],Tab_Def_Flows[DM?],,0,) -> Yes | L4: =_xlfn.XLOOKUP(C4,Tab_Def_Flows[Name(EN)],Tab_Def_Flows[CC?],,0,) -> Yes | M4: 2024 | N4: BB | O4: =O3*1.02 -> 1567582.7 | P4: Mg/a | Q4: Stramento | X4: No | Y4: 365 | AA4: =IF(X4="no",O4,O4*Y4) -> 1567582.7 | AB4: Mg | AC4: =INDEX(Tab_Def_Flows[[Flow_ID]:[CC_DM_source]],MATCH(Tab_Data_Flows[[#This Row],[Name(EN)]],Tab_Def_Flows[Name(EN)],0),16) -> 0.14 | AD4: =IF(J4="Yes",AA4*Tab_Data_Flows[[#This Row],[WC_'[%']]],"N.A.") -> 219461.58 | AE4: =Tab_Data_Flows[[#This Row],[UoM_Flow_Py]] -> Mg | AF4: =INDEX(Tab_Def_Flows[[Flow_ID]:[CC_DM_source]],MATCH(Tab_Data_Flows[[#This Row],[Name(EN)]],Tab_Def_Flows[Name(EN)],0),18) -> 0.86 | AG4: =IF(K4="Yes",AF4*Tab_Data_Flows[[#This Row],[Flow_Py]],"N.A.") -> 1348121.1 | AH4: =Tab_Data_Flows[[#This Row],[UoM_Flow_Py]] -> Mg | AI4: =INDEX(Tab_Def_Flows[[Flow_ID]:[CC_DM_source]],MATCH(Tab_Data_Flows[[#This Row],[Name(EN)]],Tab_Def_Flows[Name(EN)],0),20) -> 0.48 | AJ4: =IF(L4="Yes",AI4*Tab_Data_Flows[[#This Row],[Flow_Py]]*Tab_Data_Flows[[#This Row],[DM_'[%']]],"N.A.") -> 647098.13 | AK4: =Tab_Data_Flows[[#This Row],[UoM_Flow_Py]] -> Mg
A5: =ROW()-1 -> 4 | B5: =_xlfn.XLOOKUP(C5,Tab_Def_Flows[Name(EN)],Tab_Def_Flows[Flow_ID],,0,) -> F_13_20 | C5: Rye-Plant | D5: =_xlfn.XLOOKUP(C5,Tab_Def_Flows[Name(EN)],Tab_Def_Flows[Type_Biomass],,0,) -> 0 | E5: =_xlfn.XLOOKUP(C5,Tab_Def_Flows[Name(EN)],Tab_Def_Flows[Output_Process],,0,) -> Rye_Cultivation | F5: =_xlfn.XLOOKUP(C5,Tab_Def_Flows[Name(EN)],Tab_Def_Flows[Process_ID_O],,0,) -> 13_Rye_BB | G5: =_xlfn.XLOOKUP(C5,Tab_Def_Flows[Name(EN)],Tab_Def_Flows[Input_Process],,0,) -> Rye_Harvest | H5: =_xlfn.XLOOKUP(C5,Tab_Def_Flows[Name(EN)],Tab_Def_Flows[Process_ID_I],,0,) -> 20_Rye_BB | I5: =_xlfn.XLOOKUP(C5,Tab_Def_Flows[Name(EN)],Tab_Def_Flows[Value_Source],,0,) -> Data_assumption | J5: =_xlfn.XLOOKUP(C5,Tab_Def_Flows[Name(EN)],Tab_Def_Flows[WC?],,0,) -> Yes | K5: =_xlfn.XLOOKUP(C5,Tab_Def_Flows[Name(EN)],Tab_Def_Flows[DM?],,0,) -> Yes | L5: =_xlfn.XLOOKUP(C5,Tab_Def_Flows[Name(EN)],Tab_Def_Flows[CC?],,0,) -> Yes | M5: 2025 | N5: BB | O5: =O4*1.02 -> 1598934.3 | P5: Mg/a | Q5: Stramento | X5: No | Y5: 365 | AA5: =IF(X5="no",O5,O5*Y5) -> 1598934.3 | AB5: Mg | AC5: =INDEX(Tab_Def_Flows[[Flow_ID]:[CC_DM_source]],MATCH(Tab_Data_Flows[[#This Row],[Name(EN)]],Tab_Def_Flows[Name(EN)],0),16) -> 0.14 | AD5: =IF(J5="Yes",AA5*Tab_Data_Flows[[#This Row],[WC_'[%']]],"N.A.") -> 223850.81 | AE5: =Tab_Data_Flows[[#This Row],[UoM_Flow_Py]] -> Mg | AF5: =INDEX(Tab_Def_Flows[[Flow_ID]:[CC_DM_source]],MATCH(Tab_Data_Flows[[#This Row],[Name(EN)]],Tab_Def_Flows[Name(EN)],0),18) -> 0.86 | AG5: =IF(K5="Yes",AF5*Tab_Data_Flows[[#This Row],[Flow_Py]],"N.A.") -> 1375083.5 | AH5: =Tab_Data_Flows[[#This Row],[UoM_Flow_Py]] -> Mg | AI5: =INDEX(Tab_Def_Flows[[Flow_ID]:[CC_DM_source]],MATCH(Tab_Data_Flows[[#This Row],[Name(EN)]],Tab_Def_Flows[Name(EN)],0),20) -> 0.48 | AJ5: =IF(L5="Yes",AI5*Tab_Data_Flows[[#This Row],[Flow_Py]]*Tab_Data_Flows[[#This Row],[DM_'[%']]],"N.A.") -> 660040.09 | AK5: =Tab_Data_Flows[[#This Row],[UoM_Flow_Py]] -> Mg
A6: =ROW()-1 -> 5 | B6: =_xlfn.XLOOKUP(C6,Tab_Def_Flows[Name(EN)],Tab_Def_Flows[Flow_ID],,0,) -> F_13_20 | C6: Rye-Plant | D6: =_xlfn.XLOOKUP(C6,Tab_Def_Flows[Name(EN)],Tab_Def_Flows[Type_Biomass],,0,) -> 0 | E6: =_xlfn.XLOOKUP(C6,Tab_Def_Flows[Name(EN)],Tab_Def_Flows[Output_Process],,0,) -> Rye_Cultivation | F6: =_xlfn.XLOOKUP(C6,Tab_Def_Flows[Name(EN)],Tab_Def_Flows[Process_ID_O],,0,) -> 13_Rye_BB | G6: =_xlfn.XLOOKUP(C6,Tab_Def_Flows[Name(EN)],Tab_Def_Flows[Input_Process],,0,) -> Rye_Harvest | H6: =_xlfn.XLOOKUP(C6,Tab_Def_Flows[Name(EN)],Tab_Def_Flows[Process_ID_I],,0,) -> 20_Rye_BB | I6: =_xlfn.XLOOKUP(C6,Tab_Def_Flows[Name(EN)],Tab_Def_Flows[Value_Source],,0,) -> Data_assumption | J6: =_xlfn.XLOOKUP(C6,Tab_Def_Flows[Name(EN)],Tab_Def_Flows[WC?],,0,) -> Yes | K6: =_xlfn.XLOOKUP(C6,Tab_Def_Flows[Name(EN)],Tab_Def_Flows[DM?],,0,) -> Yes | L6: =_xlfn.XLOOKUP(C6,Tab_Def_Flows[Name(EN)],Tab_Def_Flows[CC?],,0,) -> Yes | M6: 2026 | N6: BB | O6: =O5*1.02 -> 1630913 | P6: Mg/a | Q6: Stramento | X6: No | Y6: 365 | AA6: =IF(X6="no",O6,O6*Y6) -> 1630913 | AB6: Mg | AC6: =INDEX(Tab_Def_Flows[[Flow_ID]:[CC_DM_source]],MATCH(Tab_Data_Flows[[#This Row],[Name(EN)]],Tab_Def_Flows[Name(EN)],0),16) -> 0.14 | AD6: =IF(J6="Yes",AA6*Tab_Data_Flows[[#This Row],[WC_'[%']]],"N.A.") -> 228327.82 | AE6: =Tab_Data_Flows[[#This Row],[UoM_Flow_Py]] -> Mg | AF6: =INDEX(Tab_Def_Flows[[Flow_ID]:[CC_DM_source]],MATCH(Tab_Data_Flows[[#This Row],[Name(EN)]],Tab_Def_Flows[Name(EN)],0),18) -> 0.86 | AG6: =IF(K6="Yes",AF6*Tab_Data_Flows[[#This Row],[Flow_Py]],"N.A.") -> 1402585.2 | AH6: =Tab_Data_Flows[[#This Row],[UoM_Flow_Py]] -> Mg | AI6: =INDEX(Tab_Def_Flows[[Flow_ID]:[CC_DM_source]],MATCH(Tab_Data_Flows[[#This Row],[Name(EN)]],Tab_Def_Flows[Name(EN)],0),20) -> 0.48 | AJ6: =IF(L6="Yes",AI6*Tab_Data_Flows[[#This Row],[Flow_Py]]*Tab_Data_Flows[[#This Row],[DM_'[%']]],"N.A.") -> 673240.9 | AK6: =Tab_Data_Flows[[#This Row],[UoM_Flow_Py]] -> Mg
A7: =ROW()-1 -> 6 | B7: =_xlfn.XLOOKUP(C7,Tab_Def_Flows[Name(EN)],Tab_Def_Flows[Flow_ID],,0,) -> F_13_20 | C7: Rye-Plant | D7: =_xlfn.XLOOKUP(C7,Tab_Def_Flows[Name(EN)],Tab_Def_Flows[Type_Biomass],,0,) -> 0 | E7: =_xlfn.XLOOKUP(C7,Tab_Def_Flows[Name(EN)],Tab_Def_Flows[Output_Process],,0,) -> Rye_Cultivation | F7: =_xlfn.XLOOKUP(C7,Tab_Def_Flows[Name(EN)],Tab_Def_Flows[Process_ID_O],,0,) -> 13_Rye_BB | G7: =_xlfn.XLOOKUP(C7,Tab_Def_Flows[Name(EN)],Tab_Def_Flows[Input_Process],,0,) -> Rye_Harvest | H7: =_xlfn.XLOOKUP(C7,Tab_Def_Flows[Name(EN)],Tab_Def_Flows[Process_ID_I],,0,) -> 20_Rye_BB | I7: =_xlfn.XLOOKUP(C7,Tab_Def_Flows[Name(EN)],Tab_Def_Flows[Value_Source],,0,) -> Data_assumption | J7: =_xlfn.XLOOKUP(C7,Tab_Def_Flows[Name(EN)],Tab_Def_Flows[WC?],,0,) -> Yes | K7: =_xlfn.XLOOKUP(C7,Tab_Def_Flows[Name(EN)],Tab_Def_Flows[DM?],,0,) -> Yes | L7: =_xlfn.XLOOKUP(C7,Tab_Def_Flows[Name(EN)],Tab_Def_Flows[CC?],,0,) -> Yes | M7: 2027 | N7: BB | O7: =O6*1.02 -> 1663531.3 | P7: Mg/a | Q7: Stramento | X7: No | Y7: 365 | AA7: =IF(X7="no",O7,O7*Y7) -> 1663531.3 | AB7: Mg | AC7: =INDEX(Tab_Def_Flows[[Flow_ID]:[CC_DM_source]],MATCH(Tab_Data_Flows[[#This Row],[Name(EN)]],Tab_Def_Flows[Name(EN)],0),16) -> 0.14 | AD7: =IF(J7="Yes",AA7*Tab_Data_Flows[[#This Row],[WC_'[%']]],"N.A.") -> 232894.38 | AE7: =Tab_Data_Flows[[#This Row],[UoM_Flow_Py]] -> Mg | AF7: =INDEX(Tab_Def_Flows[[Flow_ID]:[CC_DM_source]],MATCH(Tab_Data_Flows[[#This Row],[Name(EN)]],Tab_Def_Flows[Name(EN)],0),18) -> 0.86 | AG7: =IF(K7="Yes",AF7*Tab_Data_Flows[[#This Row],[Flow_Py]],"N.A.") -> 1430636.9 | AH7: =Tab_Data_Flows[[#This Row],[UoM_Flow_Py]] -> Mg | AI7: =INDEX(Tab_Def_Flows[[Flow_ID]:[CC_DM_source]],MATCH(Tab_Data_Flows[[#This Row],[Name(EN)]],Tab_Def_Flows[Name(EN)],0),20) -> 0.48 | AJ7: =IF(L7="Yes",AI7*Tab_Data_Flows[[#This Row],[Flow_Py]]*Tab_Data_Flows[[#This Row],[DM_'[%']]],"N.A.") -> 686705.71 | AK7: =Tab_Data_Flows[[#This Row],[UoM_Flow_Py]] -> Mg
A8: =ROW()-1 -> 7 | B8: =_xlfn.XLOOKUP(C8,Tab_Def_Flows[Name(EN)],Tab_Def_Flows[Flow_ID],,0,) -> F_13_20 | C8: Rye-Plant | D8: =_xlfn.XLOOKUP(C8,Tab_Def_Flows[Name(EN)],Tab_Def_Flows[Type_Biomass],,0,) -> 0 | E8: =_xlfn.XLOOKUP(C8,Tab_Def_Flows[Name(EN)],Tab_Def_Flows[Output_Process],,0,) -> Rye_Cultivation | F8: =_xlfn.XLOOKUP(C8,Tab_Def_Flows[Name(EN)],Tab_Def_Flows[Process_ID_O],,0,) -> 13_Rye_BB | G8: =_xlfn.XLOOKUP(C8,Tab_Def_Flows[Name(EN)],Tab_Def_Flows[Input_Process],,0,) -> Rye_Harvest | H8: =_xlfn.XLOOKUP(C8,Tab_Def_Flows[Name(EN)],Tab_Def_Flows[Process_ID_I],,0,) -> 20_Rye_BB | I8: =_xlfn.XLOOKUP(C8,Tab_Def_Flows[Name(EN)],Tab_Def_Flows[Value_Source],,0,) -> Data_assumption | J8: =_xlfn.XLOOKUP(C8,Tab_Def_Flows[Name(EN)],Tab_Def_Flows[WC?],,0,) -> Yes | K8: =_xlfn.XLOOKUP(C8,Tab_Def_Flows[Name(EN)],Tab_Def_Flows[DM?],,0,) -> Yes | L8: =_xlfn.XLOOKUP(C8,Tab_Def_Flows[Name(EN)],Tab_Def_Flows[CC?],,0,) -> Yes | M8: 2028 | N8: BB | O8: =O7*1.02 -> 1696801.9 | P8: Mg/a | Q8: Stramento | X8: No | Y8: 365 | AA8: =IF(X8="no",O8,O8*Y8) -> 1696801.9 | AB8: Mg | AC8: =INDEX(Tab_Def_Flows[[Flow_ID]:[CC_DM_source]],MATCH(Tab_Data_Flows[[#This Row],[Name(EN)]],Tab_Def_Flows[Name(EN)],0),16) -> 0.14 | AD8: =IF(J8="Yes",AA8*Tab_Data_Flows[[#This Row],[WC_'[%']]],"N.A.") -> 237552.27 | AE8: =Tab_Data_Flows[[#This Row],[UoM_Flow_Py]] -> Mg | AF8: =INDEX(Tab_Def_Flows[[Flow_ID]:[CC_DM_source]],MATCH(Tab_Data_Flows[[#This Row],[Name(EN)]],Tab_Def_Flows[Name(EN)],0),18) -> 0.86 | AG8: =IF(K8="Yes",AF8*Tab_Data_Flows[[#This Row],[Flow_Py]],"N.A.") -> 1459249.6 | AH8: =Tab_Data_Flows[[#This Row],[UoM_Flow_Py]] -> Mg | AI8: =INDEX(Tab_Def_Flows[[Flow_ID]:[CC_DM_source]],MATCH(Tab_Data_Flows[[#This Row],[Name(EN)]],Tab_Def_Flows[Name(EN)],0),20) -> 0.48 | AJ8: =IF(L8="Yes",AI8*Tab_Data_Flows[[#This Row],[Flow_Py]]*Tab_Data_Flows[[#This Row],[DM_'[%']]],"N.A.") -> 700439.83 | AK8: =Tab_Data_Flows[[#This Row],[UoM_Flow_Py]] -> Mg
B9: =_xlfn.XLOOKUP(C9,Tab_Def_Flows[Name(EN)],Tab_Def_Flows[Flow_ID],,0,) -> F_13_20 | C9: Rye-Plant | D9: =_xlfn.XLOOKUP(C9,Tab_Def_Flows[Name(EN)],Tab_Def_Flows[Type_Biomass],,0,) -> 0 | E9: =_xlfn.XLOOKUP(C9,Tab_Def_Flows[Name(EN)],Tab_Def_Flows[Output_Process],,0,) -> Rye_Cultivation | F9: =_xlfn.XLOOKUP(C9,Tab_Def_Flows[Name(EN)],Tab_Def_Flows[Process_ID_O],,0,) -> 13_Rye_BB | G9: =_xlfn.XLOOKUP(C9,Tab_Def_Flows[Name(EN)],Tab_Def_Flows[Input_Process],,0,) -> Rye_Harvest | H9: =_xlfn.XLOOKUP(C9,Tab_Def_Flows[Name(EN)],Tab_Def_Flows[Process_ID_I],,0,) -> 20_Rye_BB | I9: =_xlfn.XLOOKUP(C9,Tab_Def_Flows[Name(EN)],Tab_Def_Flows[Value_Source],,0,) -> Data_assumption | J9: =_xlfn.XLOOKUP(C9,Tab_Def_Flows[Name(EN)],Tab_Def_Flows[WC?],,0,) -> Yes | K9: =_xlfn.XLOOKUP(C9,Tab_Def_Flows[Name(EN)],Tab_Def_Flows[DM?],,0,) -> Yes | L9: =_xlfn.XLOOKUP(C9,Tab_Def_Flows[Name(EN)],Tab_Def_Flows[CC?],,0,) -> Yes | M9: 2029 | N9: BB | O9: =O8*1.02 -> 1730737.9 | P9: Mg/a | R9: =INDEX(Tab_WC_DM_CC[[Flow_ID]:[CC_source]],MATCH(Tab_Data_Flows[[#This Row],[Name(EN)]],Tab_WC_DM_CC[Name(EN)],0),12) -> #N/A | S9: =MATCH(Tab_Data_Flows[[#This Row],[Name(EN)]],Tab_WC_DM_CC[Name(EN)],0) -> #N/A | X9: No | Z9: ='3_1_Calculation_factors (Wood)'!$A$14 -> Mittelwert | AA9: =IF(X9="no",O9,O9*Y9) -> 1730737.9 | AB9: Mg | AC9: =INDEX(Tab_Def_Flows[[Flow_ID]:[CC_DM_source]],MATCH(Tab_Data_Flows[[#This Row],[Name(EN)]],Tab_Def_Flows[Name(EN)],0),16) -> 0.14 | AD9: =IF(J9="Yes",AA9*Tab_Data_Flows[[#This Row],[WC_'[%']]],"N.A.") -> 242303.31 | AE9: =Tab_Data_Flows[[#This Row],[UoM_Flow_Py]] -> Mg | AF9: =INDEX(Tab_Def_Flows[[Flow_ID]:[CC_DM_source]],MATCH(Tab_Data_Flows[[#This Row],[Name(EN)]],Tab_Def_Flows[Name(EN)],0),18) -> 0.86 | AG9: =IF(K9="Yes",AF9*Tab_Data_Flows[[#This Row],[Flow_Py]],"N.A.") -> 1488434.6 | AH9: =Tab_Data_Flows[[#This Row],[UoM_Flow_Py]] -> Mg | AI9: =INDEX(Tab_Def_Flows[[Flow_ID]:[CC_DM_source]],MATCH(Tab_Data_Flows[[#This Row],[Name(EN)]],Tab_Def_Flows[Name(EN)],0),20) -> 0.48 | AJ9: =IF(L9="Yes",AI9*Tab_Data_Flows[[#This Row],[Flow_Py]]*Tab_Data_Flows[[#This Row],[DM_'[%']]],"N.A.") -> 714448.63 | AK9: =Tab_Data_Flows[[#This Row],[UoM_Flow_Py]] -> Mg
B10: =_xlfn.XLOOKUP(C10,Tab_Def_Flows[Name(EN)],Tab_Def_Flows[Flow_ID],,0,) -> F_13_20 | C10: Rye-Plant | D10: =_xlfn.XLOOKUP(C10,Tab_Def_Flows[Name(EN)],Tab_Def_Flows[Type_Biomass],,0,) -> 0 | E10: =_xlfn.XLOOKUP(C10,Tab_Def_Flows[Name(EN)],Tab_Def_Flows[Output_Process],,0,) -> Rye_Cultivation | F10: =_xlfn.XLOOKUP(C10,Tab_Def_Flows[Name(EN)],Tab_Def_Flows[Process_ID_O],,0,) -> 13_Rye_BB | G10: =_xlfn.XLOOKUP(C10,Tab_Def_Flows[Name(EN)],Tab_Def_Flows[Input_Process],,0,) -> Rye_Harvest | H10: =_xlfn.XLOOKUP(C10,Tab_Def_Flows[Name(EN)],Tab_Def_Flows[Process_ID_I],,0,) -> 20_Rye_BB | I10: =_xlfn.XLOOKUP(C10,Tab_Def_Flows[Name(EN)],Tab_Def_Flows[Value_Source],,0,) -> Data_assumption | J10: =_xlfn.XLOOKUP(C10,Tab_Def_Flows[Name(EN)],Tab_Def_Flows[WC?],,0,) -> Yes | K10: =_xlfn.XLOOKUP(C10,Tab_Def_Flows[Name(EN)],Tab_Def_Flows[DM?],,0,) -> Yes | L10: =_xlfn.XLOOKUP(C10,Tab_Def_Flows[Name(EN)],Tab_Def_Flows[CC?],,0,) -> Yes | M10: 2030 | N10: BB | O10: =O9*1.02 -> 1765352.7 | P10: Mg/a | R10: =INDEX(Tab_WC_DM_CC[[Flow_ID]:[CC_source]],MATCH(Tab_Data_Flows[[#This Row],[Name(EN)]],Tab_WC_DM_CC[Name(EN)],0),12) -> #N/A | S10: =MATCH(Tab_Data_Flows[[#This Row],[Name(EN)]],Tab_WC_DM_CC[Name(EN)],0) -> #N/A | X10: No | Z10: ='3_1_Calculation_factors (Wood)'!$A$14 -> Mittelwert | AA10: =IF(X10="no",O10,O10*Y10) -> 1765352.7 | AB10: Mg | AC10: =INDEX(Tab_Def_Flows[[Flow_ID]:[CC_DM_source]],MATCH(Tab_Data_Flows[[#This Row],[Name(EN)]],Tab_Def_Flows[Name(EN)],0),16) -> 0.14 | AD10: =IF(J10="Yes",AA10*Tab_Data_Flows[[#This Row],[WC_'[%']]],"N.A.") -> 247149.38 | AE10: =Tab_Data_Flows[[#This Row],[UoM_Flow_Py]] -> Mg | AF10: =INDEX(Tab_Def_Flows[[Flow_ID]:[CC_DM_source]],MATCH(Tab_Data_Flows[[#This Row],[Name(EN)]],Tab_Def_Flows[Name(EN)],0),18) -> 0.86 | AG10: =IF(K10="Yes",AF10*Tab_Data_Flows[[#This Row],[Flow_Py]],"N.A.") -> 1518203.3 | AH10: =Tab_Data_Flows[[#This Row],[UoM_Flow_Py]] -> Mg | AI10: =INDEX(Tab_Def_Flows[[Flow_ID]:[CC_DM_source]],MATCH(Tab_Data_Flows[[#This Row],[Name(EN)]],Tab_Def_Flows[Name(EN)],0),20) -> 0.48 | AJ10: =IF(L10="Yes",AI10*Tab_Data_Flows[[#This Row],[Flow_Py]]*Tab_Data_Flows[[#This Row],[DM_'[%']]],"N.A.") -> 728737.6 | AK10: =Tab_Data_Flows[[#This Row],[UoM_Flow_Py]] -> Mg
B11: =_xlfn.XLOOKUP(C11,Tab_Def_Flows[Name(EN)],Tab_Def_Flows[Flow_ID],,0,) -> F_13_20 | C11: Rye-Plant | D11: =_xlfn.XLOOKUP(C11,Tab_Def_Flows[Name(EN)],Tab_Def_Flows[Type_Biomass],,0,) -> 0 | E11: =_xlfn.XLOOKUP(C11,Tab_Def_Flows[Name(EN)],Tab_Def_Flows[Output_Process],,0,) -> Rye_Cultivation | F11: =_xlfn.XLOOKUP(C11,Tab_Def_Flows[Name(EN)],Tab_Def_Flows[Process_ID_O],,0,) -> 13_Rye_BB | G11: =_xlfn.XLOOKUP(C11,Tab_Def_Flows[Name(EN)],Tab_Def_Flows[Input_Process],,0,) -> Rye_Harvest | H11: =_xlfn.XLOOKUP(C11,Tab_Def_Flows[Name(EN)],Tab_Def_Flows[Process_ID_I],,0,) -> 20_Rye_BB | I11: =_xlfn.XLOOKUP(C11,Tab_Def_Flows[Name(EN)],Tab_Def_Flows[Value_Source],,0,) -> Data_assumption | J11: =_xlfn.XLOOKUP(C11,Tab_Def_Flows[Name(EN)],Tab_Def_Flows[WC?],,0,) -> Yes | K11: =_xlfn.XLOOKUP(C11,Tab_Def_Flows[Name(EN)],Tab_Def_Flows[DM?],,0,) -> Yes | L11: =_xlfn.XLOOKUP(C11,Tab_Def_Flows[Name(EN)],Tab_Def_Flows[CC?],,0,) -> Yes | M11: 2031 | N11: BB | O11: =O10*1.02 -> 1800659.8 | P11: Mg/a | R11: =INDEX(Tab_WC_DM_CC[[Flow_ID]:[CC_source]],MATCH(Tab_Data_Flows[[#This Row],[Name(EN)]],Tab_WC_DM_CC[Name(EN)],0),12) -> #N/A | S11: =MATCH(Tab_Data_Flows[[#This Row],[Name(EN)]],Tab_WC_DM_CC[Name(EN)],0) -> #N/A | X11: No | Z11: ='3_1_Calculation_factors (Wood)'!$A$14 -> Mittelwert | AA11: =IF(X11="no",O11,O11*Y11) -> 1800659.8 | AB11: Mg | AC11: =INDEX(Tab_Def_Flows[[Flow_ID]:[CC_DM_source]],MATCH(Tab_Data_Flows[[#This Row],[Name(EN)]],Tab_Def_Flows[Name(EN)],0),16) -> 0.14 | AD11: =IF(J11="Yes",AA11*Tab_Data_Flows[[#This Row],[WC_'[%']]],"N.A.") -> 252092.37 | AE11: =Tab_Data_Flows[[#This Row],[UoM_Flow_Py]] -> Mg | AF11: =INDEX(Tab_Def_Flows[[Flow_ID]:[CC_DM_source]],MATCH(Tab_Data_Flows[[#This Row],[Name(EN)]],Tab_Def_Flows[Name(EN)],0),18) -> 0.86 | AG11: =IF(K11="Yes",AF11*Tab_Data_Flows[[#This Row],[Flow_Py]],"N.A.") -> 1548567.4 | AH11: =Tab_Data_Flows[[#This Row],[UoM_Flow_Py]] -> Mg | AI11: =INDEX(Tab_Def_Flows[[Flow_ID]:[CC_DM_source]],MATCH(Tab_Data_Flows[[#This Row],[Name(EN)]],Tab_Def_Flows[Name(EN)],0),20) -> 0.48 | AJ11: =IF(L11="Yes",AI11*Tab_Data_Flows[[#This Row],[Flow_Py]]*Tab_Data_Flows[[#This Row],[DM_'[%']]],"N.A.") -> 743312.35 | AK11: =Tab_Data_Flows[[#This Row],[UoM_Flow_Py]] -> Mg
B12: =_xlfn.XLOOKUP(C12,Tab_Def_Flows[Name(EN)],Tab_Def_Flows[Flow_ID],,0,) -> F_13_20 | C12: Rye-Plant | D12: =_xlfn.XLOOKUP(C12,Tab_Def_Flows[Name(EN)],Tab_Def_Flows[Type_Biomass],,0,) -> 0 | E12: =_xlfn.XLOOKUP(C12,Tab_Def_Flows[Name(EN)],Tab_Def_Flows[Output_Process],,0,) -> Rye_Cultivation | F12: =_xlfn.XLOOKUP(C12,Tab_Def_Flows[Name(EN)],Tab_Def_Flows[Process_ID_O],,0,) -> 13_Rye_BB | G12: =_xlfn.XLOOKUP(C12,Tab_Def_Flows[Name(EN)],Tab_Def_Flows[Input_Process],,0,) -> Rye_Harvest | H12: =_xlfn.XLOOKUP(C12,Tab_Def_Flows[Name(EN)],Tab_Def_Flows[Process_ID_I],,0,) -> 20_Rye_BB | I12: =_xlfn.XLOOKUP(C12,Tab_Def_Flows[Name(EN)],Tab_Def_Flows[Value_Source],,0,) -> Data_assumption | J12: =_xlfn.XLOOKUP(C12,Tab_Def_Flows[Name(EN)],Tab_Def_Flows[WC?],,0,) -> Yes | K12: =_xlfn.XLOOKUP(C12,Tab_Def_Flows[Name(EN)],Tab_Def_Flows[DM?],,0,) -> Yes | L12: =_xlfn.XLOOKUP(C12,Tab_Def_Flows[Name(EN)],Tab_Def_Flows[CC?],,0,) -> Yes | M12: 2032 | N12: BB | O12: =O11*1.02 -> 1836673 | P12: Mg/a | R12: =INDEX(Tab_WC_DM_CC[[Flow_ID]:[CC_source]],MATCH(Tab_Data_Flows[[#This Row],[Name(EN)]],Tab_WC_DM_CC[Name(EN)],0),12) -> #N/A | S12: =MATCH(Tab_Data_Flows[[#This Row],[Name(EN)]],Tab_WC_DM_CC[Name(EN)],0) -> #N/A | X12: No | Z12: ='3_1_Calculation_factors (Wood)'!$A$14 -> Mittelwert | AA12: =IF(X12="no",O12,O12*Y12) -> 1836673 | AB12: Mg | AC12: =INDEX(Tab_Def_Flows[[Flow_ID]:[CC_DM_source]],MATCH(Tab_Data_Flows[[#This Row],[Name(EN)]],Tab_Def_Flows[Name(EN)],0),16) -> 0.14 | AD12: =IF(J12="Yes",AA12*Tab_Data_Flows[[#This Row],[WC_'[%']]],"N.A.") -> 257134.21 | AE12: =Tab_Data_Flows[[#This Row],[UoM_Flow_Py]] -> Mg | AF12: =INDEX(Tab_Def_Flows[[Flow_ID]:[CC_DM_source]],MATCH(Tab_Data_Flows[[#This Row],[Name(EN)]],Tab_Def_Flows[Name(EN)],0),18) -> 0.86 | AG12: =IF(K12="Yes",AF12*Tab_Data_Flows[[#This Row],[Flow_Py]],"N.A.") -> 1579538.7 | AH12: =Tab_Data_Flows[[#This Row],[UoM_Flow_Py]] -> Mg | AI12: =INDEX(Tab_Def_Flows[[Flow_ID]:[CC_DM_source]],MATCH(Tab_Data_Flows[[#This Row],[Name(EN)]],Tab_Def_Flows[Name(EN)],0),20) -> 0.48 | AJ12: =IF(L12="Yes",AI12*Tab_Data_Flows[[#This Row],[Flow_Py]]*Tab_Data_Flows[[#This Row],[DM_'[%']]],"N.A.") -> 758178.6 | AK12: =Tab_Data_Flows[[#This Row],[UoM_Flow_Py]] -> Mg
B13: =_xlfn.XLOOKUP(C13,Tab_Def_Flows[Name(EN)],Tab_Def_Flows[Flow_ID],,0,) -> F_13_20 | C13: Rye-Plant | D13: =_xlfn.XLOOKUP(C13,Tab_Def_Flows[Name(EN)],Tab_Def_Flows[Type_Biomass],,0,) -> 0 | E13: =_xlfn.XLOOKUP(C13,Tab_Def_Flows[Name(EN)],Tab_Def_Flows[Output_Process],,0,) -> Rye_Cultivation | F13: =_xlfn.XLOOKUP(C13,Tab_Def_Flows[Name(EN)],Tab_Def_Flows[Process_ID_O],,0,) -> 13_Rye_BB | G13: =_xlfn.XLOOKUP(C13,Tab_Def_Flows[Name(EN)],Tab_Def_Flows[Input_Process],,0,) -> Rye_Harvest | H13: =_xlfn.XLOOKUP(C13,Tab_Def_Flows[Name(EN)],Tab_Def_Flows[Process_ID_I],,0,) -> 20_Rye_BB | I13: =_xlfn.XLOOKUP(C13,Tab_Def_Flows[Name(EN)],Tab_Def_Flows[Value_Source],,0,) -> Data_assumption | J13: =_xlfn.XLOOKUP(C13,Tab_Def_Flows[Name(EN)],Tab_Def_Flows[WC?],,0,) -> Yes | K13: =_xlfn.XLOOKUP(C13,Tab_Def_Flows[Name(EN)],Tab_Def_Flows[DM?],,0,) -> Yes | L13: =_xlfn.XLOOKUP(C13,Tab_Def_Flows[Name(EN)],Tab_Def_Flows[CC?],,0,) -> Yes | M13: 2033 | N13: BB | O13: =O12*1.02 -> 1873406.4 | P13: Mg/a | R13: =INDEX(Tab_WC_DM_CC[[Flow_ID]:[CC_source]],MATCH(Tab_Data_Flows[[#This Row],[Name(EN)]],Tab_WC_DM_CC[Name(EN)],0),12) -> #N/A | S13: =MATCH(Tab_Data_Flows[[#This Row],[Name(EN)]],Tab_WC_DM_CC[Name(EN)],0) -> #N/A | X13: No | Z13: ='3_1_Calculation_factors (Wood)'!$A$14 -> Mittelwert | AA13: =IF(X13="no",O13,O13*Y13) -> 1873406.4 | AB13: Mg | AC13: =INDEX(Tab_Def_Flows[[Flow_ID]:[CC_DM_source]],MATCH(Tab_Data_Flows[[#This Row],[Name(EN)]],Tab_Def_Flows[Name(EN)],0),16) -> 0.14 | AD13: =IF(J13="Yes",AA13*Tab_Data_Flows[[#This Row],[WC_'[%']]],"N.A.") -> 262276.9 | AE13: =Tab_Data_Flows[[#This Row],[UoM_Flow_Py]] -> Mg | AF13: =INDEX(Tab_Def_Flows[[Flow_ID]:[CC_DM_source]],MATCH(Tab_Data_Flows[[#This Row],[Name(EN)]],Tab_Def_Flows[Name(EN)],0),18) -> 0.86 | AG13: =IF(K13="Yes",AF13*Tab_Data_Flows[[#This Row],[Flow_Py]],"N.A.") -> 1611129.5 | AH13: =Tab_Data_Flows[[#This Row],[UoM_Flow_Py]] -> Mg | AI13: =INDEX(Tab_Def_Flows[[Flow_ID]:[CC_DM_source]],MATCH(Tab_Data_Flows[[#This Row],[Name(EN)]],Tab_Def_Flows[Name(EN)],0),20) -> 0.48 | AJ13: =IF(L13="Yes",AI13*Tab_Data_Flows[[#This Row],[Flow_Py]]*Tab_Data_Flows[[#This Row],[DM_'[%']]],"N.A.") -> 773342.17 | AK13: =Tab_Data_Flows[[#This Row],[UoM_Flow_Py]] -> Mg
B14: =_xlfn.XLOOKUP(C14,Tab_Def_Flows[Name(EN)],Tab_Def_Flows[Flow_ID],,0,) -> F_13_20 | C14: Rye-Plant | D14: =_xlfn.XLOOKUP(C14,Tab_Def_Flows[Name(EN)],Tab_Def_Flows[Type_Biomass],,0,) -> 0 | E14: =_xlfn.XLOOKUP(C14,Tab_Def_Flows[Name(EN)],Tab_Def_Flows[Output_Process],,0,) -> Rye_Cultivation | F14: =_xlfn.XLOOKUP(C14,Tab_Def_Flows[Name(EN)],Tab_Def_Flows[Process_ID_O],,0,) -> 13_Rye_BB | G14: =_xlfn.XLOOKUP(C14,Tab_Def_Flows[Name(EN)],Tab_Def_Flows[Input_Process],,0,) -> Rye_Harvest | H14: =_xlfn.XLOOKUP(C14,Tab_Def_Flows[Name(EN)],Tab_Def_Flows[Process_ID_I],,0,) -> 20_Rye_BB | I14: =_xlfn.XLOOKUP(C14,Tab_Def_Flows[Name(EN)],Tab_Def_Flows[Value_Source],,0,) -> Data_assumption | J14: =_xlfn.XLOOKUP(C14,Tab_Def_Flows[Name(EN)],Tab_Def_Flows[WC?],,0,) -> Yes | K14: =_xlfn.XLOOKUP(C14,Tab_Def_Flows[Name(EN)],Tab_Def_Flows[DM?],,0,) -> Yes | L14: =_xlfn.XLOOKUP(C14,Tab_Def_Flows[Name(EN)],Tab_Def_Flows[CC?],,0,) -> Yes | M14: 2034 | N14: BB | O14: =O13*1.02 -> 1910874.5 | P14: Mg/a | R14: =INDEX(Tab_WC_DM_CC[[Flow_ID]:[CC_source]],MATCH(Tab_Data_Flows[[#This Row],[Name(EN)]],Tab_WC_DM_CC[Name(EN)],0),12) -> #N/A | S14: =MATCH(Tab_Data_Flows[[#This Row],[Name(EN)]],Tab_WC_DM_CC[Name(EN)],0) -> #N/A | X14: No | Z14: ='3_1_Calculation_factors (Wood)'!$A$14 -> Mittelwert | AA14: =IF(X14="no",O14,O14*Y14) -> 1910874.5 | AB14: Mg | AC14: =INDEX(Tab_Def_Flows[[Flow_ID]:[CC_DM_source]],MATCH(Tab_Data_Flows[[#This Row],[Name(EN)]],Tab_Def_Flows[Name(EN)],0),16) -> 0.14 | AD14: =IF(J14="Yes",AA14*Tab_Data_Flows[[#This Row],[WC_'[%']]],"N.A.") -> 267522.44 | AE14: =Tab_Data_Flows[[#This Row],[UoM_Flow_Py]] -> Mg | AF14: =INDEX(Tab_Def_Flows[[Flow_ID]:[CC_DM_source]],MATCH(Tab_Data_Flows[[#This Row],[Name(EN)]],Tab_Def_Flows[Name(EN)],0),18) -> 0.86 | AG14: =IF(K14="Yes",AF14*Tab_Data_Flows[[#This Row],[Flow_Py]],"N.A.") -> 1643352.1 | AH14: =Tab_Data_Flows[[#This Row],[UoM_Flow_Py]] -> Mg | AI14: =INDEX(Tab_Def_Flows[[Flow_ID]:[CC_DM_source]],MATCH(Tab_Data_Flows[[#This Row],[Name(EN)]],Tab_Def_Flows[Name(EN)],0),20) -> 0.48 | AJ14: =IF(L14="Yes",AI14*Tab_Data_Flows[[#This Row],[Flow_Py]]*Tab_Data_Flows[[#This Row],[DM_'[%']]],"N.A.") -> 788809.01 | AK14: =Tab_Data_Flows[[#This Row],[UoM_Flow_Py]] -> Mg
B15: =_xlfn.XLOOKUP(C15,Tab_Def_Flows[Name(EN)],Tab_Def_Flows[Flow_ID],,0,) -> F_13_20 | C15: Rye-Plant | D15: =_xlfn.XLOOKUP(C15,Tab_Def_Flows[Name(EN)],Tab_Def_Flows[Type_Biomass],,0,) -> 0 | E15: =_xlfn.XLOOKUP(C15,Tab_Def_Flows[Name(EN)],Tab_Def_Flows[Output_Process],,0,) -> Rye_Cultivation | F15: =_xlfn.XLOOKUP(C15,Tab_Def_Flows[Name(EN)],Tab_Def_Flows[Process_ID_O],,0,) -> 13_Rye_BB | G15: =_xlfn.XLOOKUP(C15,Tab_Def_Flows[Name(EN)],Tab_Def_Flows[Input_Process],,0,) -> Rye_Harvest | H15: =_xlfn.XLOOKUP(C15,Tab_Def_Flows[Name(EN)],Tab_Def_Flows[Process_ID_I],,0,) -> 20_Rye_BB | I15: =_xlfn.XLOOKUP(C15,Tab_Def_Flows[Name(EN)],Tab_Def_Flows[Value_Source],,0,) -> Data_assumption | J15: =_xlfn.XLOOKUP(C15,Tab_Def_Flows[Name(EN)],Tab_Def_Flows[WC?],,0,) -> Yes | K15: =_xlfn.XLOOKUP(C15,Tab_Def_Flows[Name(EN)],Tab_Def_Flows[DM?],,0,) -> Yes | L15: =_xlfn.XLOOKUP(C15,Tab_Def_Flows[Name(EN)],Tab_Def_Flows[CC?],,0,) -> Yes | M15: 2035 | N15: BB | O15: =O14*1.02 -> 1949092 | P15: Mg/a | R15: =INDEX(Tab_WC_DM_CC[[Flow_ID]:[CC_source]],MATCH(Tab_Data_Flows[[#This Row],[Name(EN)]],Tab_WC_DM_CC[Name(EN)],0),12) -> #N/A | S15: =MATCH(Tab_Data_Flows[[#This Row],[Name(EN)]],Tab_WC_DM_CC[Name(EN)],0) -> #N/A | X15: No | Z15: ='3_1_Calculation_factors (Wood)'!$A$14 -> Mittelwert | AA15: =IF(X15="no",O15,O15*Y15) -> 1949092 | AB15: Mg | AC15: =INDEX(Tab_Def_Flows[[Flow_ID]:[CC_DM_source]],MATCH(Tab_Data_Flows[[#This Row],[Name(EN)]],Tab_Def_Flows[Name(EN)],0),16) -> 0.14 | AD15: =IF(J15="Yes",AA15*Tab_Data_Flows[[#This Row],[WC_'[%']]],"N.A.") -> 272872.89 | AE15: =Tab_Data_Flows[[#This Row],[UoM_Flow_Py]] -> Mg | AF15: =INDEX(Tab_Def_Flows[[Flow_ID]:[CC_DM_source]],MATCH(Tab_Data_Flows[[#This Row],[Name(EN)]],Tab_Def_Flows[Name(EN)],0),18) -> 0.86 | AG15: =IF(K15="Yes",AF15*Tab_Data_Flows[[#This Row],[Flow_Py]],"N.A.") -> 1676219.2 | AH15: =Tab_Data_Flows[[#This Row],[UoM_Flow_Py]] -> Mg | AI15: =INDEX(Tab_Def_Flows[[Flow_ID]:[CC_DM_source]],MATCH(Tab_Data_Flows[[#This Row],[Name(EN)]],Tab_Def_Flows[Name(EN)],0),20) -> 0.48 | AJ15: =IF(L15="Yes",AI15*Tab_Data_Flows[[#This Row],[Flow_Py]]*Tab_Data_Flows[[#This Row],[DM_'[%']]],"N.A.") -> 804585.19 | AK15: =Tab_Data_Flows[[#This Row],[UoM_Flow_Py]] -> Mg
B16: =_xlfn.XLOOKUP(C16,Tab_Def_Flows[Name(EN)],Tab_Def_Flows[Flow_ID],,0,) -> F_13_20 | C16: Rye-Plant | D16: =_xlfn.XLOOKUP(C16,Tab_Def_Flows[Name(EN)],Tab_Def_Flows[Type_Biomass],,0,) -> 0 | E16: =_xlfn.XLOOKUP(C16,Tab_Def_Flows[Name(EN)],Tab_Def_Flows[Output_Process],,0,) -> Rye_Cultivation | F16: =_xlfn.XLOOKUP(C16,Tab_Def_Flows[Name(EN)],Tab_Def_Flows[Process_ID_O],,0,) -> 13_Rye_BB | G16: =_xlfn.XLOOKUP(C16,Tab_Def_Flows[Name(EN)],Tab_Def_Flows[Input_Process],,0,) -> Rye_Harvest | H16: =_xlfn.XLOOKUP(C16,Tab_Def_Flows[Name(EN)],Tab_Def_Flows[Process_ID_I],,0,) -> 20_Rye_BB | I16: =_xlfn.XLOOKUP(C16,Tab_Def_Flows[Name(EN)],Tab_Def_Flows[Value_Source],,0,) -> Data_assumption | J16: =_xlfn.XLOOKUP(C16,Tab_Def_Flows[Name(EN)],Tab_Def_Flows[WC?],,0,) -> Yes | K16: =_xlfn.XLOOKUP(C16,Tab_Def_Flows[Name(EN)],Tab_Def_Flows[DM?],,0,) -> Yes | L16: =_xlfn.XLOOKUP(C16,Tab_Def_Flows[Name(EN)],Tab_Def_Flows[CC?],,0,) -> Yes | M16: 2036 | N16: BB | O16: =O15*1.02 -> 1988073.9 | P16: Mg/a | R16: =INDEX(Tab_WC_DM_CC[[Flow_ID]:[CC_source]],MATCH(Tab_Data_Flows[[#This Row],[Name(EN)]],Tab_WC_DM_CC[Name(EN)],0),12) -> #N/A | S16: =MATCH(Tab_Data_Flows[[#This Row],[Name(EN)]],Tab_WC_DM_CC[Name(EN)],0) -> #N/A | X16: No | Z16: ='3_1_Calculation_factors (Wood)'!$A$14 -> Mittelwert | AA16: =IF(X16="no",O16,O16*Y16) -> 1988073.9 | AB16: Mg | AC16: =INDEX(Tab_Def_Flows[[Flow_ID]:[CC_DM_source]],MATCH(Tab_Data_Flows[[#This Row],[Name(EN)]],Tab_Def_Flows[Name(EN)],0),16) -> 0.14 | AD16: =IF(J16="Yes",AA16*Tab_Data_Flows[[#This Row],[WC_'[%']]],"N.A.") -> 278330.34 | AE16: =Tab_Data_Flows[[#This Row],[UoM_Flow_Py]] -> Mg | AF16: =INDEX(Tab_Def_Flows[[Flow_ID]:[CC_DM_source]],MATCH(Tab_Data_Flows[[#This Row],[Name(EN)]],Tab_Def_Flows[Name(EN)],0),18) -> 0.86 | AG16: =IF(K16="Yes",AF16*Tab_Data_Flows[[#This Row],[Flow_Py]],"N.A.") -> 1709743.5 | AH16: =Tab_Data_Flows[[#This Row],[UoM_Flow_Py]] -> Mg | AI16: =INDEX(Tab_Def_Flows[[Flow_ID]:[CC_DM_source]],MATCH(Tab_Data_Flows[[#This Row],[Name(EN)]],Tab_Def_Flows[Name(EN)],0),20) -> 0.48 | AJ16: =IF(L16="Yes",AI16*Tab_Data_Flows[[#This Row],[Flow_Py]]*Tab_Data_Flows[[#This Row],[DM_'[%']]],"N.A.") -> 820676.9 | AK16: =Tab_Data_Flows[[#This Row],[UoM_Flow_Py]] -> Mg
B17: =_xlfn.XLOOKUP(C17,Tab_Def_Flows[Name(EN)],Tab_Def_Flows[Flow_ID],,0,) -> F_13_20 | C17: Rye-Plant | D17: =_xlfn.XLOOKUP(C17,Tab_Def_Flows[Name(EN)],Tab_Def_Flows[Type_Biomass],,0,) -> 0 | E17: =_xlfn.XLOOKUP(C17,Tab_Def_Flows[Name(EN)],Tab_Def_Flows[Output_Process],,0,) -> Rye_Cultivation | F17: =_xlfn.XLOOKUP(C17,Tab_Def_Flows[Name(EN)],Tab_Def_Flows[Process_ID_O],,0,) -> 13_Rye_BB | G17: =_xlfn.XLOOKUP(C17,Tab_Def_Flows[Name(EN)],Tab_Def_Flows[Input_Process],,0,) -> Rye_Harvest | H17: =_xlfn.XLOOKUP(C17,Tab_Def_Flows[Name(EN)],Tab_Def_Flows[Process_ID_I],,0,) -> 20_Rye_BB | I17: =_xlfn.XLOOKUP(C17,Tab_Def_Flows[Name(EN)],Tab_Def_Flows[Value_Source],,0,) -> Data_assumption | J17: =_xlfn.XLOOKUP(C17,Tab_Def_Flows[Name(EN)],Tab_Def_Flows[WC?],,0,) -> Yes | K17: =_xlfn.XLOOKUP(C17,Tab_Def_Flows[Name(EN)],Tab_Def_Flows[DM?],,0,) -> Yes | L17: =_xlfn.XLOOKUP(C17,Tab_Def_Flows[Name(EN)],Tab_Def_Flows[CC?],,0,) -> Yes | M17: 2037 | N17: BB | O17: =O16*1.02 -> 2027835.4 | P17: Mg/a | R17: =INDEX(Tab_WC_DM_CC[[Flow_ID]:[CC_source]],MATCH(Tab_Data_Flows[[#This Row],[Name(EN)]],Tab_WC_DM_CC[Name(EN)],0),12) -> #N/A | S17: =MATCH(Tab_Data_Flows[[#This Row],[Name(EN)]],Tab_WC_DM_CC[Name(EN)],0) -> #N/A | X17: No | Z17: ='3_1_Calculation_factors (Wood)'!$A$14 -> Mittelwert | AA17: =IF(X17="no",O17,O17*Y17) -> 2027835.4 | AB17: Mg | AC17: =INDEX(Tab_Def_Flows[[Flow_ID]:[CC_DM_source]],MATCH(Tab_Data_Flows[[#This Row],[Name(EN)]],Tab_Def_Flows[Name(EN)],0),16) -> 0.14 | AD17: =IF(J17="Yes",AA17*Tab_Data_Flows[[#This Row],[WC_'[%']]],"N.A.") -> 283896.95 | AE17: =Tab_Data_Flows[[#This Row],[UoM_Flow_Py]] -> Mg | AF17: =INDEX(Tab_Def_Flows[[Flow_ID]:[CC_DM_source]],MATCH(Tab_Data_Flows[[#This Row],[Name(EN)]],Tab_Def_Flows[Name(EN)],0),18) -> 0.86 | AG17: =IF(K17="Yes",AF17*Tab_Data_Flows[[#This Row],[Flow_Py]],"N.A.") -> 1743938.4 | AH17: =Tab_Data_Flows[[#This Row],[UoM_Flow_Py]] -> Mg | AI17: =INDEX(Tab_Def_Flows[[Flow_ID]:[CC_DM_source]],MATCH(Tab_Data_Flows[[#This Row],[Name(EN)]],Tab_Def_Flows[Name(EN)],0),20) -> 0.48 | AJ17: =IF(L17="Yes",AI17*Tab_Data_Flows[[#This Row],[Flow_Py]]*Tab_Data_Flows[[#This Row],[DM_'[%']]],"N.A.") -> 837090.43 | AK17: =Tab_Data_Flows[[#This Row],[UoM_Flow_Py]] -> Mg
