Workbook
Name Baumart_: [1]!Baumart[Baumart]
Name Baumart_: [2]!Baumart[Baumart]
Name Cluster_: [1]!Cluster[Cluster]
Name Cluster_: [2]!Cluster[Cluster]
Name einheit: [1]!Tabelle14[Einheit]
Name einheit: [2]!Tabelle14[Einheit]
Name Erhebungsart_: [1]!Erhebungsart[Erhebungsart]
Name Erhebungsart_: [2]!Erhebungsart[Erhebungsart]
Name Herkunft_: [1]!Herkunft[Herkunft]
Name Herkunft_: [2]!Herkunft[Herkunft]
Name Holzstrom_: [1]!Holzstrom[Holzstrom]
Name Holzstrom_: [2]!Holzstrom[Holzstrom]
Name In_Out_: [1]!Tabelleinput[In/Out]
Name In_Out_: [2]!Tabelleinput[In/Out]
Name Inhaltsverzeichnis: "MTRANS(ERSETZEN(Inhalt;1;FINDEN(""]"";Inhalt);""))"
Name Klassifizierung: [1]!Tabelle9[Klassifizierung]
Name Klassifizierung: [2]!Tabelle9[Klassifizierung]
Name Ort_: [1]!Ort[Ort]
Name Ort_: [2]!Ort[Ort]
Name Ziel_: [1]!Ziel[Ziel]
Name Ziel_: [2]!Ziel[Ziel]

Sheet Intro
B2: Title:
B4: Der angehängte Datensatz beinhalten Informationen über Materialflüsse, Prozesse sowie Lager in der Region Brandenburg. Der Datensatz bezieht sich dabei auf verschiedene Quellen und Dokumente.
B6: Definition der Systemgrenzen:
C7: Beobachtungszeitraum: | F7: 2010 - 2020
C8: Beobachtungsgebiet: | F8: Berlin
F9: Brandenburg
F10: Berlin + Brandenburg
B12: Für die Anfertigung der Materialflussanalyse werden die folgenden Daten benötigt. Die Daten werden in seperaten Tabellenblättern dargestellt. Für jeden Datensatz werden spezifische Anforderungen definiert. Diese lassen sich einem Systemübergreifenden Fließbild zuordnen. Dieses Fließbild beinhaltet die relevanten Flüsse, Prozesse und Lager.
B15: Prozesse bilden die Grundlage für das System. Prozesse können Transferkoefizienten und Lager beinhalten. Prozesse haben einen oder mehrere Flüsse als Input sowie einen oder mehrere Flüsse als Output.
B22: Flüsse:
C24: Flüsse müssen in Mg umgerechnet werden
B33: Prozesse:
B34: Lager
B35: Transferkoeffizienten
B36: Umrechnungsfaktoren:
B37: Codelisten:

Sheet Version_CS1_28.05.

Sheet 1_Flows>>>>

Sheet 1_1_Definition_Flows
A1: Complete? | B1: ID | C1: Flow_ID | D1: Name(EN) | E1: Name(DE) | F1: Region | G1: Type_Biomass | H1: Product/By-product/waste | I1: Comment | J1: Output_Process | K1: Process_ID_O | L1: Input_Process | M1: Process_ID_I | N1: Value_Source | O1: WC? | P1: DM? | Q1: CC? | R1: WC | S1: WC_source | T1: DM | U1: DM_source | V1: CC_DM[%] | W1: CC_DM_source | X1: CC | Y1: CC_FM_source
A2: FALSE | B2: 01 | C2: ="F_"&LEFT(K2,2)&"_"&LEFT(M2,2) -> F_00_01 | D2: Biomass 1 | J2: Cultivation | K2: =_xlfn.XLOOKUP(J2,Tab_Def_Processes[Name(EN)],Tab_Def_Processes[Process_ID],,0,) -> 00_Cul_ | L2: Harvesting | M2: =_xlfn.XLOOKUP(L2,Tab_Def_Processes[Name(EN)],Tab_Def_Processes[Process_ID],,0,) -> 01_Har_ | O2: Yes | P2: Yes | Q2: Yes | R2: 0 | S2: Assumption | T2: 1 | U2: Assumption | V2: 0.5 | W2: Assumption | X2: =Tab_Def_Flows[[#This Row],[CC_DM'[%']]]*Tab_Def_Flows[[#This Row],[DM]] -> 0.5 | Y2: Caclualtion
A3: FALSE | B3: 02 | C3: ="F_"&LEFT(K3,2)&"_"&LEFT(M3,2) -> F_01_02 | D3: Biomass 2 | J3: Harvesting | K3: =_xlfn.XLOOKUP(J3,Tab_Def_Processes[Name(EN)],Tab_Def_Processes[Process_ID],,0,) -> 01_Har_ | L3: Food | M3: =_xlfn.XLOOKUP(L3,Tab_Def_Processes[Name(EN)],Tab_Def_Processes[Process_ID],,0,) -> 02_Foo_ | O3: Yes | P3: Yes | Q3: Yes | R3: 0 | S3: Assumption | T3: 1 | U3: Assumption | V3: 0.5 | W3: Assumption | X3: =Tab_Def_Flows[[#This Row],[CC_DM'[%']]]*Tab_Def_Flows[[#This Row],[DM]] -> 0.5 | Y3: Caclualtion
A4: FALSE | B4: 03 | C4: ="F_"&LEFT(K4,2)&"_"&LEFT(M4,2) -> F_01_03 | D4: Biomass 3 | J4: Harvesting | K4: =_xlfn.XLOOKUP(J4,Tab_Def_Processes[Name(EN)],Tab_Def_Processes[Process_ID],,0,) -> 01_Har_ | L4: Straw c&d | M4: =_xlfn.XLOOKUP(L4,Tab_Def_Processes[Name(EN)],Tab_Def_Processes[Process_ID],,0,) -> 03_Str_ | O4: Yes | P4: Yes | Q4: Yes | R4: 0 | S4: Assumption | T4: 1 | U4: Assumption | V4: 0.5 | W4: Assumption | X4: =Tab_Def_Flows[[#This Row],[CC_DM'[%']]]*Tab_Def_Flows[[#This Row],[DM]] -> 0.5 | Y4: Caclualtion
A5: FALSE | B5: 04 | C5: ="F_"&LEFT(K5,2)&"_"&LEFT(M5,2) -> F_03_04 | D5: Biomass 4 | J5: Straw c&d | K5: =_xlfn.XLOOKUP(J5,Tab_Def_Processes[Name(EN)],Tab_Def_Processes[Process_ID],,0,) -> 03_Str_ | L5: Incorporation | M5: =_xlfn.XLOOKUP(L5,Tab_Def_Processes[Name(EN)],Tab_Def_Processes[Process_ID],,0,) -> 04_Inc_ | O5: Yes | P5: Yes | Q5: Yes | R5: 0 | S5: Assumption | T5: 1 | U5: Assumption | V5: 0.5 | W5: Assumption | X5: =Tab_Def_Flows[[#This Row],[CC_DM'[%']]]*Tab_Def_Flows[[#This Row],[DM]] -> 0.5 | Y5: Caclualtion
A6: FALSE | B6: 05 | C6: ="F_"&LEFT(K6,2)&"_"&LEFT(M6,2) -> F_03_05 | D6: Biomass 5 | J6: Straw c&d | K6: =_xlfn.XLOOKUP(J6,Tab_Def_Processes[Name(EN)],Tab_Def_Processes[Process_ID],,0,) -> 03_Str_ | L6: Composting | M6: =_xlfn.XLOOKUP(L6,Tab_Def_Processes[Name(EN)],Tab_Def_Processes[Process_ID],,0,) -> 05_Com_ | O6: Yes | P6: Yes | Q6: Yes | R6: 0 | S6: Assumption | T6: 1 | U6: Assumption | V6: 0.5 | W6: Assumption | X6: =Tab_Def_Flows[[#This Row],[CC_DM'[%']]]*Tab_Def_Flows[[#This Row],[DM]] -> 0.5 | Y6: Caclualtion
A7: FALSE | B7: 06 | C7: ="F_"&LEFT(K7,2)&"_"&LEFT(M7,2) -> F_03_06 | D7: Biomass 6 | J7: Straw c&d | K7: =_xlfn.XLOOKUP(J7,Tab_Def_Processes[Name(EN)],Tab_Def_Processes[Process_ID],,0,) -> 03_Str_ | L7: HTC | M7: =_xlfn.XLOOKUP(L7,Tab_Def_Processes[Name(EN)],Tab_Def_Processes[Process_ID],,0,) -> 06_HTC_ | O7: Yes | P7: Yes | Q7: Yes | R7: 0 | S7: Assumption | T7: 1 | U7: Assumption | V7: 0.5 | W7: Assumption | X7: =Tab_Def_Flows[[#This Row],[CC_DM'[%']]]*Tab_Def_Flows[[#This Row],[DM]] -> 0.5 | Y7: Caclualtion
A8: FALSE | B8: 07 | C8: ="F_"&LEFT(K8,2)&"_"&LEFT(M8,2) -> F_03_07 | D8: Biomass 7 | J8: Straw c&d | K8: =_xlfn.XLOOKUP(J8,Tab_Def_Processes[Name(EN)],Tab_Def_Processes[Process_ID],,0,) -> 03_Str_ | L8: AD | M8: =_xlfn.XLOOKUP(L8,Tab_Def_Processes[Name(EN)],Tab_Def_Processes[Process_ID],,0,) -> 07_AD_ | O8: Yes | P8: Yes | Q8: Yes | R8: 0 | S8: Assumption | T8: 1 | U8: Assumption | V8: 0.5 | W8: Assumption | X8: =Tab_Def_Flows[[#This Row],[CC_DM'[%']]]*Tab_Def_Flows[[#This Row],[DM]] -> 0.5 | Y8: Caclualtion
A9: FALSE | B9: 08 | C9: ="F_"&LEFT(K9,2)&"_"&LEFT(M9,2) -> F_03_08 | D9: Biomass 8 | J9: Straw c&d | K9: =_xlfn.XLOOKUP(J9,Tab_Def_Processes[Name(EN)],Tab_Def_Processes[Process_ID],,0,) -> 03_Str_ | L9: Animal bedding | M9: =_xlfn.XLOOKUP(L9,Tab_Def_Processes[Name(EN)],Tab_Def_Processes[Process_ID],,0,) -> 08_Ani_ | O9: Yes | P9: Yes | Q9: Yes | R9: 0 | S9: Assumption | T9: 1 | U9: Assumption | V9: 0.5 | W9: Assumption | X9: =Tab_Def_Flows[[#This Row],[CC_DM'[%']]]*Tab_Def_Flows[[#This Row],[DM]] -> 0.5 | Y9: Caclualtion
A10: FALSE | B10: 09 | C10: ="F_"&LEFT(K10,2)&"_"&LEFT(M10,2) -> F_04_09 | D10: Biomass 9 | J10: Incorporation | K10: =_xlfn.XLOOKUP(J10,Tab_Def_Processes[Name(EN)],Tab_Def_Processes[Process_ID],,0,) -> 04_Inc_ | L10: Soil | M10: =_xlfn.XLOOKUP(L10,Tab_Def_Processes[Name(EN)],Tab_Def_Processes[Process_ID],,0,) -> 09_Soi_ | O10: Yes | P10: Yes | Q10: Yes | R10: 0 | S10: Assumption | T10: 1 | U10: Assumption | V10: 0.5 | W10: Assumption | X10: =Tab_Def_Flows[[#This Row],[CC_DM'[%']]]*Tab_Def_Flows[[#This Row],[DM]] -> 0.5 | Y10: Caclualtion
A11: FALSE | B11: 10 | C11: ="F_"&LEFT(K11,2)&"_"&LEFT(M11,2) -> F_05_09 | D11: Biomass 10 | J11: Composting | K11: =_xlfn.XLOOKUP(J11,Tab_Def_Processes[Name(EN)],Tab_Def_Processes[Process_ID],,0,) -> 05_Com_ | L11: Soil | M11: =_xlfn.XLOOKUP(L11,Tab_Def_Processes[Name(EN)],Tab_Def_Processes[Process_ID],,0,) -> 09_Soi_ | O11: Yes | P11: Yes | Q11: Yes | R11: 0 | S11: Assumption | T11: 1 | U11: Assumption | V11: 0.5 | W11: Assumption | X11: =Tab_Def_Flows[[#This Row],[CC_DM'[%']]]*Tab_Def_Flows[[#This Row],[DM]] -> 0.5 | Y11: Caclualtion
A12: FALSE | B12: 11 | C12: ="F_"&LEFT(K12,2)&"_"&LEFT(M12,2) -> F_05_10 | D12: Biomass 11 | J12: Composting | K12: =_xlfn.XLOOKUP(J12,Tab_Def_Processes[Name(EN)],Tab_Def_Processes[Process_ID],,0,) -> 05_Com_ | L12: Atmosphere | M12: =_xlfn.XLOOKUP(L12,Tab_Def_Processes[Name(EN)],Tab_Def_Processes[Process_ID],,0,) -> 10_Atm_ | O12: Yes | P12: Yes | Q12: Yes | R12: 0 | S12: Assumption | T12: 1 | U12: Assumption | V12: 0.5 | W12: Assumption | X12: =Tab_Def_Flows[[#This Row],[CC_DM'[%']]]*Tab_Def_Flows[[#This Row],[DM]] -> 0.5 | Y12: Caclualtion
A13: FALSE | B13: 12 | C13: ="F_"&LEFT(K13,2)&"_"&LEFT(M13,2) -> F_05_11 | D13: Biomass 12 | J13: Composting | K13: =_xlfn.XLOOKUP(J13,Tab_Def_Processes[Name(EN)],Tab_Def_Processes[Process_ID],,0,) -> 05_Com_ | L13: Surface water and aquifer | M13: =_xlfn.XLOOKUP(L13,Tab_Def_Processes[Name(EN)],Tab_Def_Processes[Process_ID],,0,) -> 11_Sur_ | O13: Yes | P13: Yes | Q13: Yes | R13: 0 | S13: Assumption | T13: 1 | U13: Assumption | V13: 0.5 | W13: Assumption | X13: =Tab_Def_Flows[[#This Row],[CC_DM'[%']]]*Tab_Def_Flows[[#This Row],[DM]] -> 0.5 | Y13: Caclualtion
... A16: FALSE | B16: 15 | C16: ="F_"&LEFT(K16,2)&"_"&LEFT(M16,2) -> F_09_10 | D16: Biomass 15 | J16: Soil | K16: =_xlfn.XLOOKUP(J16,Tab_Def_Processes[Name(EN)],Tab_Def_Processes[Process_ID],,0,) -> 09_Soi_ | L16: Atmosphere | M16: =_xlfn.XLOOKUP(L16,Tab_Def_Processes[Name(EN)],Tab_Def_Processes[Process_ID],,0,) -> 10_Atm_ | O16: Yes | P16: Yes | Q16: Yes | R16: 0 | S16: Assumption | T16: 1 | U16: Assumption | V16: 0.5 | W16: Assumption | X16: =Tab_Def_Flows[[#This Row],[CC_DM'[%']]]*Tab_Def_Flows[[#This Row],[DM]] -> 0.5 | Y16: Caclualtion
A17: FALSE | B17: 16 | C17: ="F_"&LEFT(K17,2)&"_"&LEFT(M17,2) -> F_12_12 | K17: =_xlfn.XLOOKUP(J17,Tab_Def_Processes[Name(EN)],Tab_Def_Processes[Process_ID],,0,) -> 12__ | M17: =_xlfn.XLOOKUP(L17,Tab_Def_Processes[Name(EN)],Tab_Def_Processes[Process_ID],,0,) -> 12__ | X17: =Tab_Def_Flows[[#This Row],[CC_DM'[%']]]*Tab_Def_Flows[[#This Row],[DM]] -> 0
A18: FALSE | B18: 17 | C18: ="F_"&LEFT(K18,2)&"_"&LEFT(M18,2) -> F_12_12 | K18: =_xlfn.XLOOKUP(J18,Tab_Def_Processes[Name(EN)],Tab_Def_Processes[Process_ID],,0,) -> 12__ | M18: =_xlfn.XLOOKUP(L18,Tab_Def_Processes[Name(EN)],Tab_Def_Processes[Process_ID],,0,) -> 12__ | X18: =Tab_Def_Flows[[#This Row],[CC_DM'[%']]]*Tab_Def_Flows[[#This Row],[DM]] -> 0
A19: FALSE | B19: 18 | C19: ="F_"&LEFT(K19,2)&"_"&LEFT(M19,2) -> F_12_12 | K19: =_xlfn.XLOOKUP(J19,Tab_Def_Processes[Name(EN)],Tab_Def_Processes[Process_ID],,0,) -> 12__ | M19: =_xlfn.XLOOKUP(L19,Tab_Def_Processes[Name(EN)],Tab_Def_Processes[Process_ID],,0,) -> 12__ | X19: =Tab_Def_Flows[[#This Row],[CC_DM'[%']]]*Tab_Def_Flows[[#This Row],[DM]] -> 0
A20: FALSE | B20: 19 | C20: ="F_"&LEFT(K20,2)&"_"&LEFT(M20,2) -> F_12_12 | K20: =_xlfn.XLOOKUP(J20,Tab_Def_Processes[Name(EN)],Tab_Def_Processes[Process_ID],,0,) -> 12__ | M20: =_xlfn.XLOOKUP(L20,Tab_Def_Processes[Name(EN)],Tab_Def_Processes[Process_ID],,0,) -> 12__ | X20: =Tab_Def_Flows[[#This Row],[CC_DM'[%']]]*Tab_Def_Flows[[#This Row],[DM]] -> 0
A21: FALSE | B21: 20 | C21: ="F_"&LEFT(K21,2)&"_"&LEFT(M21,2) -> F_12_12 | K21: =_xlfn.XLOOKUP(J21,Tab_Def_Processes[Name(EN)],Tab_Def_Processes[Process_ID],,0,) -> 12__ | M21: =_xlfn.XLOOKUP(L21,Tab_Def_Processes[Name(EN)],Tab_Def_Processes[Process_ID],,0,) -> 12__ | X21: =Tab_Def_Flows[[#This Row],[CC_DM'[%']]]*Tab_Def_Flows[[#This Row],[DM]] -> 0
A22: FALSE | B22: 21 | C22: ="F_"&LEFT(K22,2)&"_"&LEFT(M22,2) -> F_12_12 | K22: =_xlfn.XLOOKUP(J22,Tab_Def_Processes[Name(EN)],Tab_Def_Processes[Process_ID],,0,) -> 12__ | M22: =_xlfn.XLOOKUP(L22,Tab_Def_Processes[Name(EN)],Tab_Def_Processes[Process_ID],,0,) -> 12__ | X22: =Tab_Def_Flows[[#This Row],[CC_DM'[%']]]*Tab_Def_Flows[[#This Row],[DM]] -> 0
A23: FALSE | B23: 22 | C23: ="F_"&LEFT(K23,2)&"_"&LEFT(M23,2) -> F_12_12 | K23: =_xlfn.XLOOKUP(J23,Tab_Def_Processes[Name(EN)],Tab_Def_Processes[Process_ID],,0,) -> 12__ | M23: =_xlfn.XLOOKUP(L23,Tab_Def_Processes[Name(EN)],Tab_Def_Processes[Process_ID],,0,) -> 12__ | X23: =Tab_Def_Flows[[#This Row],[CC_DM'[%']]]*Tab_Def_Flows[[#This Row],[DM]] -> 0
A24: FALSE | B24: 23 | C24: ="F_"&LEFT(K24,2)&"_"&LEFT(M24,2) -> F_12_12 | K24: =_xlfn.XLOOKUP(J24,Tab_Def_Processes[Name(EN)],Tab_Def_Processes[Process_ID],,0,) -> 12__ | M24: =_xlfn.XLOOKUP(L24,Tab_Def_Processes[Name(EN)],Tab_Def_Processes[Process_ID],,0,) -> 12__ | X24: =Tab_Def_Flows[[#This Row],[CC_DM'[%']]]*Tab_Def_Flows[[#This Row],[DM]] -> 0
A25: FALSE | B25: 24 | C25: ="F_"&LEFT(K25,2)&"_"&LEFT(M25,2) -> F_12_12 | K25: =_xlfn.XLOOKUP(J25,Tab_Def_Processes[Name(EN)],Tab_Def_Processes[Process_ID],,0,) -> 12__ | M25: =_xlfn.XLOOKUP(L25,Tab_Def_Processes[Name(EN)],Tab_Def_Processes[Process_ID],,0,) -> 12__ | X25: =Tab_Def_Flows[[#This Row],[CC_DM'[%']]]*Tab_Def_Flows[[#This Row],[DM]] -> 0
A26: FALSE | B26: 25 | C26: ="F_"&LEFT(K26,2)&"_"&LEFT(M26,2) -> F_12_12 | K26: =_xlfn.XLOOKUP(J26,Tab_Def_Processes[Name(EN)],Tab_Def_Processes[Process_ID],,0,) -> 12__ | M26: =_xlfn.XLOOKUP(L26,Tab_Def_Processes[Name(EN)],Tab_Def_Processes[Process_ID],,0,) -> 12__ | X26: =Tab_Def_Flows[[#This Row],[CC_DM'[%']]]*Tab_Def_Flows[[#This Row],[DM]] -> 0
A27: FALSE | B27: 26 | C27: ="F_"&LEFT(K27,2)&"_"&LEFT(M27,2) -> F_12_12 | K27: =_xlfn.XLOOKUP(J27,Tab_Def_Processes[Name(EN)],Tab_Def_Processes[Process_ID],,0,) -> 12__ | M27: =_xlfn.XLOOKUP(L27,Tab_Def_Processes[Name(EN)],Tab_Def_Processes[Process_ID],,0,) -> 12__ | X27: =Tab_Def_Flows[[#This Row],[CC_DM'[%']]]*Tab_Def_Flows[[#This Row],[DM]] -> 0
A28: FALSE | B28: 27 | C28: ="F_"&LEFT(K28,2)&"_"&LEFT(M28,2) -> F_12_12 | K28: =_xlfn.XLOOKUP(J28,Tab_Def_Processes[Name(EN)],Tab_Def_Processes[Process_ID],,0,) -> 12__ | M28: =_xlfn.XLOOKUP(L28,Tab_Def_Processes[Name(EN)],Tab_Def_Processes[Process_ID],,0,) -> 12__ | X28: =Tab_Def_Flows[[#This Row],[CC_DM'[%']]]*Tab_Def_Flows[[#This Row],[DM]] -> 0
... A77: FALSE | B77: 76 | C77: ="F_"&LEFT(K77,2)&"_"&LEFT(M77,2) -> F_12_12 | K77: =_xlfn.XLOOKUP(J77,Tab_Def_Processes[Name(EN)],Tab_Def_Processes[Process_ID],,0,) -> 12__ | M77: =_xlfn.XLOOKUP(L77,Tab_Def_Processes[Name(EN)],Tab_Def_Processes[Process_ID],,0,) -> 12__ | X77: =Tab_Def_Flows[[#This Row],[CC_DM'[%']]]*Tab_Def_Flows[[#This Row],[DM]] -> 0

Sheet 1_2_Data_Flows
A1: ID | B1: Flow_ID | C1: Name(EN) | D1: Type_Biomass | E1: Output_Process | F1: Process_ID_O | G1: Input_Process | H1: Process_ID_I | I1: TC? | J1: WC? | K1: DM? | L1: CC? | M1: Year_Flow | N1: Region_Flow | O1: Flow_Source | P1: UoM_Source | Q1: Name_Source | R1: AVV | S1: Titel_Source | T1: Year_Source | U1: Author_Source | V1: Type_Source | W1: URL | X1: CF_required? | Y1: CF | Z1: Name_CF | AA1: Flow_Py | AB1: UoM_Flow_Py | AC1: WC_[%] | AD1: WC_Flow_Py | AE1: UoM_WC_Flow_Py | AF1: DM_[%] | AG1: DM_Flow_Py2 | AH1: UoM_DM_Flow_Py | AI1: CC_[%] | AJ1: CC_Flow_Py | AK1: UoM_CC_Flow_Py
A2: =ROW()-1 -> 1 | B2: =_xlfn.XLOOKUP(C2,Tab_Def_Flows[Name(EN)],Tab_Def_Flows[Flow_ID],,0,) -> F_00_01 | C2: Biomass 1 | D2: =_xlfn.XLOOKUP(C2,Tab_Def_Flows[Name(EN)],Tab_Def_Flows[Type_Biomass],,0,) -> 0 | E2: =_xlfn.XLOOKUP(C2,Tab_Def_Flows[Name(EN)],Tab_Def_Flows[Output_Process],,0,) -> Cultivation | F2: =_xlfn.XLOOKUP(C2,Tab_Def_Flows[Name(EN)],Tab_Def_Flows[Process_ID_O],,0,) -> 00_Cul_ | G2: =_xlfn.XLOOKUP(C2,Tab_Def_Flows[Name(EN)],Tab_Def_Flows[Input_Process],,0,) -> Harvesting | H2: =_xlfn.XLOOKUP(C2,Tab_Def_Flows[Name(EN)],Tab_Def_Flows[Process_ID_I],,0,) -> 01_Har_ | I2: =_xlfn.XLOOKUP(C2,Tab_Def_Flows[Name(EN)],Tab_Def_Flows[Value_Source],,0,) -> 0 | J2: =_xlfn.XLOOKUP(C2,Tab_Def_Flows[Name(EN)],Tab_Def_Flows[WC?],,0,) -> Yes | K2: =_xlfn.XLOOKUP(C2,Tab_Def_Flows[Name(EN)],Tab_Def_Flows[DM?],,0,) -> Yes | L2: =_xlfn.XLOOKUP(C2,Tab_Def_Flows[Name(EN)],Tab_Def_Flows[CC?],,0,) -> Yes | M2: 2020 | N2: BB | O2: 100 | Q2: Stramento | X2: No | AA2: =IF(X2="no",O2,O2*Y2) -> 100 | AC2: =INDEX(Tab_Def_Flows[[Flow_ID]:[CC_DM_source]],MATCH(Tab_Data_Flows[[#This Row],[Name(EN)]],Tab_Def_Flows[Name(EN)],0),16) -> 0 | AD2: =IF(J2="Yes",AA2*Tab_Data_Flows[[#This Row],[WC_'[%']]],"N.A.") -> 0 | AE2: =Tab_Data_Flows[[#This Row],[UoM_Flow_Py]] -> 0 | AF2: =INDEX(Tab_Def_Flows[[Flow_ID]:[CC_DM_source]],MATCH(Tab_Data_Flows[[#This Row],[Name(EN)]],Tab_Def_Flows[Name(EN)],0),18) -> 1 | AG2: =IF(K2="Yes",AF2*Tab_Data_Flows[[#This Row],[Flow_Py]],"N.A.") -> 100 | AH2: =Tab_Data_Flows[[#This Row],[UoM_Flow_Py]] -> 0 | AI2: =INDEX(Tab_Def_Flows[[Flow_ID]:[CC_DM_source]],MATCH(Tab_Data_Flows[[#This Row],[Name(EN)]],Tab_Def_Flows[Name(EN)],0),20) -> 0.5 | AJ2: =IF(L2="Yes",AI2*Tab_Data_Flows[[#This Row],[Flow_Py]]*Tab_Data_Flows[[#This Row],[DM_'[%']]],"N.A.") -> 50 | AK2: =Tab_Data_Flows[[#This Row],[UoM_Flow_Py]] -> 0
A3: =ROW()-1 -> 2 | B3: =_xlfn.XLOOKUP(C3,Tab_Def_Flows[Name(EN)],Tab_Def_Flows[Flow_ID],,0,) -> F_00_01 | C3: Biomass 1 | D3: =_xlfn.XLOOKUP(C3,Tab_Def_Flows[Name(EN)],Tab_Def_Flows[Type_Biomass],,0,) -> 0 | E3: =_xlfn.XLOOKUP(C3,Tab_Def_Flows[Name(EN)],Tab_Def_Flows[Output_Process],,0,) -> Cultivation | F3: =_xlfn.XLOOKUP(C3,Tab_Def_Flows[Name(EN)],Tab_Def_Flows[Process_ID_O],,0,) -> 00_Cul_ | G3: =_xlfn.XLOOKUP(C3,Tab_Def_Flows[Name(EN)],Tab_Def_Flows[Input_Process],,0,) -> Harvesting | H3: =_xlfn.XLOOKUP(C3,Tab_Def_Flows[Name(EN)],Tab_Def_Flows[Process_ID_I],,0,) -> 01_Har_ | I3: =_xlfn.XLOOKUP(C3,Tab_Def_Flows[Name(EN)],Tab_Def_Flows[Value_Source],,0,) -> 0 | J3: =_xlfn.XLOOKUP(C3,Tab_Def_Flows[Name(EN)],Tab_Def_Flows[WC?],,0,) -> Yes | K3: =_xlfn.XLOOKUP(C3,Tab_Def_Flows[Name(EN)],Tab_Def_Flows[DM?],,0,) -> Yes | L3: =_xlfn.XLOOKUP(C3,Tab_Def_Flows[Name(EN)],Tab_Def_Flows[CC?],,0,) -> Yes | M3: 2021 | N3: BB | O3: 110 | Q3: Stramento | X3: No | AA3: =IF(X3="no",O3,O3*Y3) -> 110 | AC3: =INDEX(Tab_Def_Flows[[Flow_ID]:[CC_DM_source]],MATCH(Tab_Data_Flows[[#This Row],[Name(EN)]],Tab_Def_Flows[Name(EN)],0),16) -> 0 | AD3: =IF(J3="Yes",AA3*Tab_Data_Flows[[#This Row],[WC_'[%']]],"N.A.") -> 0 | AE3: =Tab_Data_Flows[[#This Row],[UoM_Flow_Py]] -> 0 | AF3: =INDEX(Tab_Def_Flows[[Flow_ID]:[CC_DM_source]],MATCH(Tab_Data_Flows[[#This Row],[Name(EN)]],Tab_Def_Flows[Name(EN)],0),18) -> 1 | AG3: =IF(K3="Yes",AF3*Tab_Data_Flows[[#This Row],[Flow_Py]],"N.A.") -> 110 | AH3: =Tab_Data_Flows[[#This Row],[UoM_Flow_Py]] -> 0 | AI3: =INDEX(Tab_Def_Flows[[Flow_ID]:[CC_DM_source]],MATCH(Tab_Data_Flows[[#This Row],[Name(EN)]],Tab_Def_Flows[Name(EN)],0),20) -> 0.5 | AJ3: =IF(L3="Yes",AI3*Tab_Data_Flows[[#This Row],[Flow_Py]]*Tab_Data_Flows[[#This Row],[DM_'[%']]],"N.A.") -> 55 | AK3: =Tab_Data_Flows[[#This Row],[UoM_Flow_Py]] -> 0
A4: =ROW()-1 -> 3 | B4: =_xlfn.XLOOKUP(C4,Tab_Def_Flows[Name(EN)],Tab_Def_Flows[Flow_ID],,0,) -> F_00_01 | C4: Biomass 1 | D4: =_xlfn.XLOOKUP(C4,Tab_Def_Flows[Name(EN)],Tab_Def_Flows[Type_Biomass],,0,) -> 0 | E4: =_xlfn.XLOOKUP(C4,Tab_Def_Flows[Name(EN)],Tab_Def_Flows[Output_Process],,0,) -> Cultivation | F4: =_xlfn.XLOOKUP(C4,Tab_Def_Flows[Name(EN)],Tab_Def_Flows[Process_ID_O],,0,) -> 00_Cul_ | G4: =_xlfn.XLOOKUP(C4,Tab_Def_Flows[Name(EN)],Tab_Def_Flows[Input_Process],,0,) -> Harvesting | H4: =_xlfn.XLOOKUP(C4,Tab_Def_Flows[Name(EN)],Tab_Def_Flows[Process_ID_I],,0,) -> 01_Har_ | I4: =_xlfn.XLOOKUP(C4,Tab_Def_Flows[Name(EN)],Tab_Def_Flows[Value_Source],,0,) -> 0 | J4: =_xlfn.XLOOKUP(C4,Tab_Def_Flows[Name(EN)],Tab_Def_Flows[WC?],,0,) -> Yes | K4: =_xlfn.XLOOKUP(C4,Tab_Def_Flows[Name(EN)],Tab_Def_Flows[DM?],,0,) -> Yes | L4: =_xlfn.XLOOKUP(C4,Tab_Def_Flows[Name(EN)],Tab_Def_Flows[CC?],,0,) -> Yes | M4: 2022 | N4: BB | O4: 120 | Q4: Stramento | X4: No | AA4: =IF(X4="no",O4,O4*Y4) -> 120 | AC4: =INDEX(Tab_Def_Flows[[Flow_ID]:[CC_DM_source]],MATCH(Tab_Data_Flows[[#This Row],[Name(EN)]],Tab_Def_Flows[Name(EN)],0),16) -> 0 | AD4: =IF(J4="Yes",AA4*Tab_Data_Flows[[#This Row],[WC_'[%']]],"N.A.") -> 0 | AE4: =Tab_Data_Flows[[#This Row],[UoM_Flow_Py]] -> 0 | AF4: =INDEX(Tab_Def_Flows[[Flow_ID]:[CC_DM_source]],MATCH(Tab_Data_Flows[[#This Row],[Name(EN)]],Tab_Def_Flows[Name(EN)],0),18) -> 1 | AG4: =IF(K4="Yes",AF4*Tab_Data_Flows[[#This Row],[Flow_Py]],"N.A.") -> 120 | AH4: =Tab_Data_Flows[[#This Row],[UoM_Flow_Py]] -> 0 | AI4: =INDEX(Tab_Def_Flows[[Flow_ID]:[CC_DM_source]],MATCH(Tab_Data_Flows[[#This Row],[Name(EN)]],Tab_Def_Flows[Name(EN)],0),20) -> 0.5 | AJ4: =IF(L4="Yes",AI4*Tab_Data_Flows[[#This Row],[Flow_Py]]*Tab_Data_Flows[[#This Row],[DM_'[%']]],"N.A.") -> 60 | AK4: =Tab_Data_Flows[[#This Row],[UoM_Flow_Py]] -> 0
A5: =ROW()-1 -> 4 | B5: =_xlfn.XLOOKUP(C5,Tab_Def_Flows[Name(EN)],Tab_Def_Flows[Flow_ID],,0,) -> F_00_01 | C5: Biomass 1 | D5: =_xlfn.XLOOKUP(C5,Tab_Def_Flows[Name(EN)],Tab_Def_Flows[Type_Biomass],,0,) -> 0 | E5: =_xlfn.XLOOKUP(C5,Tab_Def_Flows[Name(EN)],Tab_Def_Flows[Output_Process],,0,) -> Cultivation | F5: =_xlfn.XLOOKUP(C5,Tab_Def_Flows[Name(EN)],Tab_Def_Flows[Process_ID_O],,0,) -> 00_Cul_ | G5: =_xlfn.XLOOKUP(C5,Tab_Def_Flows[Name(EN)],Tab_Def_Flows[Input_Process],,0,) -> Harvesting | H5: =_xlfn.XLOOKUP(C5,Tab_Def_Flows[Name(EN)],Tab_Def_Flows[Process_ID_I],,0,) -> 01_Har_ | I5: =_xlfn.XLOOKUP(C5,Tab_Def_Flows[Name(EN)],Tab_Def_Flows[Value_Source],,0,) -> 0 | J5: =_xlfn.XLOOKUP(C5,Tab_Def_Flows[Name(EN)],Tab_Def_Flows[WC?],,0,) -> Yes | K5: =_xlfn.XLOOKUP(C5,Tab_Def_Flows[Name(EN)],Tab_Def_Flows[DM?],,0,) -> Yes | L5: =_xlfn.XLOOKUP(C5,Tab_Def_Flows[Name(EN)],Tab_Def_Flows[CC?],,0,) -> Yes | M5: 2023 | N5: BB | O5: 130 | Q5: Stramento | X5: No | AA5: =IF(X5="no",O5,O5*Y5) -> 130 | AC5: =INDEX(Tab_Def_Flows[[Flow_ID]:[CC_DM_source]],MATCH(Tab_Data_Flows[[#This Row],[Name(EN)]],Tab_Def_Flows[Name(EN)],0),16) -> 0 | AD5: =IF(J5="Yes",AA5*Tab_Data_Flows[[#This Row],[WC_'[%']]],"N.A.") -> 0 | AE5: =Tab_Data_Flows[[#This Row],[UoM_Flow_Py]] -> 0 | AF5: =INDEX(Tab_Def_Flows[[Flow_ID]:[CC_DM_source]],MATCH(Tab_Data_Flows[[#This Row],[Name(EN)]],Tab_Def_Flows[Name(EN)],0),18) -> 1 | AG5: =IF(K5="Yes",AF5*Tab_Data_Flows[[#This Row],[Flow_Py]],"N.A.") -> 130 | AH5: =Tab_Data_Flows[[#This Row],[UoM_Flow_Py]] -> 0 | AI5: =INDEX(Tab_Def_Flows[[Flow_ID]:[CC_DM_source]],MATCH(Tab_Data_Flows[[#This Row],[Name(EN)]],Tab_Def_Flows[Name(EN)],0),20) -> 0.5 | AJ5: =IF(L5="Yes",AI5*Tab_Data_Flows[[#This Row],[Flow_Py]]*Tab_Data_Flows[[#This Row],[DM_'[%']]],"N.A.") -> 65 | AK5: =Tab_Data_Flows[[#This Row],[UoM_Flow_Py]] -> 0
A6: =ROW()-1 -> 5 | B6: =_xlfn.XLOOKUP(C6,Tab_Def_Flows[Name(EN)],Tab_Def_Flows[Flow_ID],,0,) -> F_00_01 | C6: Biomass 1 | D6: =_xlfn.XLOOKUP(C6,Tab_Def_Flows[Name(EN)],Tab_Def_Flows[Type_Biomass],,0,) -> 0 | E6: =_xlfn.XLOOKUP(C6,Tab_Def_Flows[Name(EN)],Tab_Def_Flows[Output_Process],,0,) -> Cultivation | F6: =_xlfn.XLOOKUP(C6,Tab_Def_Flows[Name(EN)],Tab_Def_Flows[Process_ID_O],,0,) -> 00_Cul_ | G6: =_xlfn.XLOOKUP(C6,Tab_Def_Flows[Name(EN)],Tab_Def_Flows[Input_Process],,0,) -> Harvesting | H6: =_xlfn.XLOOKUP(C6,Tab_Def_Flows[Name(EN)],Tab_Def_Flows[Process_ID_I],,0,) -> 01_Har_ | I6: =_xlfn.XLOOKUP(C6,Tab_Def_Flows[Name(EN)],Tab_Def_Flows[Value_Source],,0,) -> 0 | J6: =_xlfn.XLOOKUP(C6,Tab_Def_Flows[Name(EN)],Tab_Def_Flows[WC?],,0,) -> Yes | K6: =_xlfn.XLOOKUP(C6,Tab_Def_Flows[Name(EN)],Tab_Def_Flows[DM?],,0,) -> Yes | L6: =_xlfn.XLOOKUP(C6,Tab_Def_Flows[Name(EN)],Tab_Def_Flows[CC?],,0,) -> Yes | M6: 2024 | N6: BB | O6: 140 | Q6: Stramento | X6: No | AA6: =IF(X6="no",O6,O6*Y6) -> 140 | AC6: =INDEX(Tab_Def_Flows[[Flow_ID]:[CC_DM_source]],MATCH(Tab_Data_Flows[[#This Row],[Name(EN)]],Tab_Def_Flows[Name(EN)],0),16) -> 0 | AD6: =IF(J6="Yes",AA6*Tab_Data_Flows[[#This Row],[WC_'[%']]],"N.A.") -> 0 | AE6: =Tab_Data_Flows[[#This Row],[UoM_Flow_Py]] -> 0 | AF6: =INDEX(Tab_Def_Flows[[Flow_ID]:[CC_DM_source]],MATCH(Tab_Data_Flows[[#This Row],[Name(EN)]],Tab_Def_Flows[Name(EN)],0),18) -> 1 | AG6: =IF(K6="Yes",AF6*Tab_Data_Flows[[#This Row],[Flow_Py]],"N.A.") -> 140 | AH6: =Tab_Data_Flows[[#This Row],[UoM_Flow_Py]] -> 0 | AI6: =INDEX(Tab_Def_Flows[[Flow_ID]:[CC_DM_source]],MATCH(Tab_Data_Flows[[#This Row],[Name(EN)]],Tab_Def_Flows[Name(EN)],0),20) -> 0.5 | AJ6: =IF(L6="Yes",AI6*Tab_Data_Flows[[#This Row],[Flow_Py]]*Tab_Data_Flows[[#This Row],[DM_'[%']]],"N.A.") -> 70 | AK6: =Tab_Data_Flows[[#This Row],[UoM_Flow_Py]] -> 0
A7: =ROW()-1 -> 6 | B7: =_xlfn.XLOOKUP(C7,Tab_Def_Flows[Name(EN)],Tab_Def_Flows[Flow_ID],,0,) -> F_00_01 | C7: Biomass 1 | D7: =_xlfn.XLOOKUP(C7,Tab_Def_Flows[Name(EN)],Tab_Def_Flows[Type_Biomass],,0,) -> 0 | E7: =_xlfn.XLOOKUP(C7,Tab_Def_Flows[Name(EN)],Tab_Def_Flows[Output_Process],,0,) -> Cultivation | F7: =_xlfn.XLOOKUP(C7,Tab_Def_Flows[Name(EN)],Tab_Def_Flows[Process_ID_O],,0,) -> 00_Cul_ | G7: =_xlfn.XLOOKUP(C7,Tab_Def_Flows[Name(EN)],Tab_Def_Flows[Input_Process],,0,) -> Harvesting | H7: =_xlfn.XLOOKUP(C7,Tab_Def_Flows[Name(EN)],Tab_Def_Flows[Process_ID_I],,0,) -> 01_Har_ | I7: =_xlfn.XLOOKUP(C7,Tab_Def_Flows[Name(EN)],Tab_Def_Flows[Value_Source],,0,) -> 0 | J7: =_xlfn.XLOOKUP(C7,Tab_Def_Flows[Name(EN)],Tab_Def_Flows[WC?],,0,) -> Yes | K7: =_xlfn.XLOOKUP(C7,Tab_Def_Flows[Name(EN)],Tab_Def_Flows[DM?],,0,) -> Yes | L7: =_xlfn.XLOOKUP(C7,Tab_Def_Flows[Name(EN)],Tab_Def_Flows[CC?],,0,) -> Yes | M7: 2025 | N7: BB | O7: 150 | Q7: Stramento | X7: No | AA7: =IF(X7="no",O7,O7*Y7) -> 150 | AC7: =INDEX(Tab_Def_Flows[[Flow_ID]:[CC_DM_source]],MATCH(Tab_Data_Flows[[#This Row],[Name(EN)]],Tab_Def_Flows[Name(EN)],0),16) -> 0 | AD7: =IF(J7="Yes",AA7*Tab_Data_Flows[[#This Row],[WC_'[%']]],"N.A.") -> 0 | AE7: =Tab_Data_Flows[[#This Row],[UoM_Flow_Py]] -> 0 | AF7: =INDEX(Tab_Def_Flows[[Flow_ID]:[CC_DM_source]],MATCH(Tab_Data_Flows[[#This Row],[Name(EN)]],Tab_Def_Flows[Name(EN)],0),18) -> 1 | AG7: =IF(K7="Yes",AF7*Tab_Data_Flows[[#This Row],[Flow_Py]],"N.A.") -> 150 | AH7: =Tab_Data_Flows[[#This Row],[UoM_Flow_Py]] -> 0 | AI7: =INDEX(Tab_Def_Flows[[Flow_ID]:[CC_DM_source]],MATCH(Tab_Data_Flows[[#This Row],[Name(EN)]],Tab_Def_Flows[Name(EN)],0),20) -> 0.5 | AJ7: =IF(L7="Yes",AI7*Tab_Data_Flows[[#This Row],[Flow_Py]]*Tab_Data_Flows[[#This Row],[DM_'[%']]],"N.A.") -> 75 | AK7: =Tab_Data_Flows[[#This Row],[UoM_Flow_Py]] -> 0
A8: =ROW()-1 -> 7 | B8: =_xlfn.XLOOKUP(C8,Tab_Def_Flows[Name(EN)],Tab_Def_Flows[Flow_ID],,0,) -> F_00_01 | C8: Biomass 1 | D8: =_xlfn.XLOOKUP(C8,Tab_Def_Flows[Name(EN)],Tab_Def_Flows[Type_Biomass],,0,) -> 0 | E8: =_xlfn.XLOOKUP(C8,Tab_Def_Flows[Name(EN)],Tab_Def_Flows[Output_Process],,0,) -> Cultivation | F8: =_xlfn.XLOOKUP(C8,Tab_Def_Flows[Name(EN)],Tab_Def_Flows[Process_ID_O],,0,) -> 00_Cul_ | G8: =_xlfn.XLOOKUP(C8,Tab_Def_Flows[Name(EN)],Tab_Def_Flows[Input_Process],,0,) -> Harvesting | H8: =_xlfn.XLOOKUP(C8,Tab_Def_Flows[Name(EN)],Tab_Def_Flows[Process_ID_I],,0,) -> 01_Har_ | I8: =_xlfn.XLOOKUP(C8,Tab_Def_Flows[Name(EN)],Tab_Def_Flows[Value_Source],,0,) -> 0 | J8: =_xlfn.XLOOKUP(C8,Tab_Def_Flows[Name(EN)],Tab_Def_Flows[WC?],,0,) -> Yes | K8: =_xlfn.XLOOKUP(C8,Tab_Def_Flows[Name(EN)],Tab_Def_Flows[DM?],,0,) -> Yes | L8: =_xlfn.XLOOKUP(C8,Tab_Def_Flows[Name(EN)],Tab_Def_Flows[CC?],,0,) -> Yes | M8: 2026 | N8: BB | O8: 160 | Q8: Stramento | X8: No | AA8: =IF(X8="no",O8,O8*Y8) -> 160 | AC8: =INDEX(Tab_Def_Flows[[Flow_ID]:[CC_DM_source]],MATCH(Tab_Data_Flows[[#This Row],[Name(EN)]],Tab_Def_Flows[Name(EN)],0),16) -> 0 | AD8: =IF(J8="Yes",AA8*Tab_Data_Flows[[#This Row],[WC_'[%']]],"N.A.") -> 0 | AE8: =Tab_Data_Flows[[#This Row],[UoM_Flow_Py]] -> 0 | AF8: =INDEX(Tab_Def_Flows[[Flow_ID]:[CC_DM_source]],MATCH(Tab_Data_Flows[[#This Row],[Name(EN)]],Tab_Def_Flows[Name(EN)],0),18) -> 1 | AG8: =IF(K8="Yes",AF8*Tab_Data_Flows[[#This Row],[Flow_Py]],"N.A.") -> 160 | AH8: =Tab_Data_Flows[[#This Row],[UoM_Flow_Py]] -> 0 | AI8: =INDEX(Tab_Def_Flows[[Flow_ID]:[CC_DM_source]],MATCH(Tab_Data_Flows[[#This Row],[Name(EN)]],Tab_Def_Flows[Name(EN)],0),20) -> 0.5 | AJ8: =IF(L8="Yes",AI8*Tab_Data_Flows[[#This Row],[Flow_Py]]*Tab_Data_Flows[[#This Row],[DM_'[%']]],"N.A.") -> 80 | AK8: =Tab_Data_Flows[[#This Row],[UoM_Flow_Py]] -> 0
A9: =ROW()-1 -> 8 | B9: =_xlfn.XLOOKUP(C9,Tab_Def_Flows[Name(EN)],Tab_Def_Flows[Flow_ID],,0,) -> F_00_01 | C9: Biomass 1 | D9: =_xlfn.XLOOKUP(C9,Tab_Def_Flows[Name(EN)],Tab_Def_Flows[Type_Biomass],,0,) -> 0 | E9: =_xlfn.XLOOKUP(C9,Tab_Def_Flows[Name(EN)],Tab_Def_Flows[Output_Process],,0,) -> Cultivation | F9: =_xlfn.XLOOKUP(C9,Tab_Def_Flows[Name(EN)],Tab_Def_Flows[Process_ID_O],,0,) -> 00_Cul_ | G9: =_xlfn.XLOOKUP(C9,Tab_Def_Flows[Name(EN)],Tab_Def_Flows[Input_Process],,0,) -> Harvesting | H9: =_xlfn.XLOOKUP(C9,Tab_Def_Flows[Name(EN)],Tab_Def_Flows[Process_ID_I],,0,) -> 01_Har_ | I9: =_xlfn.XLOOKUP(C9,Tab_Def_Flows[Name(EN)],Tab_Def_Flows[Value_Source],,0,) -> 0 | J9: =_xlfn.XLOOKUP(C9,Tab_Def_Flows[Name(EN)],Tab_Def_Flows[WC?],,0,) -> Yes | K9: =_xlfn.XLOOKUP(C9,Tab_Def_Flows[Name(EN)],Tab_Def_Flows[DM?],,0,) -> Yes | L9: =_xlfn.XLOOKUP(C9,Tab_Def_Flows[Name(EN)],Tab_Def_Flows[CC?],,0,) -> Yes | M9: 2027 | N9: BB | O9: 170 | R9: =INDEX(Tab_WC_DM_CC[[Flow_ID]:[CC_source]],MATCH(Tab_Data_Flows[[#This Row],[Name(EN)]],Tab_WC_DM_CC[Name(EN)],0),12) -> #N/A | S9: =MATCH(Tab_Data_Flows[[#This Row],[Name(EN)]],Tab_WC_DM_CC[Name(EN)],0) -> #N/A | X9: No | AA9: =IF(X9="no",O9,O9*Y9) -> 170 | AC9: =INDEX(Tab_Def_Flows[[Flow_ID]:[CC_DM_source]],MATCH(Tab_Data_Flows[[#This Row],[Name(EN)]],Tab_Def_Flows[Name(EN)],0),16) -> 0 | AD9: =IF(J9="Yes",AA9*Tab_Data_Flows[[#This Row],[WC_'[%']]],"N.A.") -> 0 | AE9: =Tab_Data_Flows[[#This Row],[UoM_Flow_Py]] -> 0 | AF9: =INDEX(Tab_Def_Flows[[Flow_ID]:[CC_DM_source]],MATCH(Tab_Data_Flows[[#This Row],[Name(EN)]],Tab_Def_Flows[Name(EN)],0),18) -> 1 | AG9: =IF(K9="Yes",AF9*Tab_Data_Flows[[#This Row],[Flow_Py]],"N.A.") -> 170 | AH9: =Tab_Data_Flows[[#This Row],[UoM_Flow_Py]] -> 0 | AI9: =INDEX(Tab_Def_Flows[[Flow_ID]:[CC_DM_source]],MATCH(Tab_Data_Flows[[#This Row],[Name(EN)]],Tab_Def_Flows[Name(EN)],0),20) -> 0.5 | AJ9: =IF(L9="Yes",AI9*Tab_Data_Flows[[#This Row],[Flow_Py]]*Tab_Data_Flows[[#This Row],[DM_'[%']]],"N.A.") -> 85 | AK9: =Tab_Data_Flows[[#This Row],[UoM_Flow_Py]] -> 0
A10: =ROW()-1 -> 9 | B10: =_xlfn.XLOOKUP(C10,Tab_Def_Flows[Name(EN)],Tab_Def_Flows[Flow_ID],,0,) -> F_00_01 | C10: Biomass 1 | D10: =_xlfn.XLOOKUP(C10,Tab_Def_Flows[Name(EN)],Tab_Def_Flows[Type_Biomass],,0,) -> 0 | E10: =_xlfn.XLOOKUP(C10,Tab_Def_Flows[Name(EN)],Tab_Def_Flows[Output_Process],,0,) -> Cultivation | F10: =_xlfn.XLOOKUP(C10,Tab_Def_Flows[Name(EN)],Tab_Def_Flows[Process_ID_O],,0,) -> 00_Cul_ | G10: =_xlfn.XLOOKUP(C10,Tab_Def_Flows[Name(EN)],Tab_Def_Flows[Input_Process],,0,) -> Harvesting | H10: =_xlfn.XLOOKUP(C10,Tab_Def_Flows[Name(EN)],Tab_Def_Flows[Process_ID_I],,0,) -> 01_Har_ | I10: =_xlfn.XLOOKUP(C10,Tab_Def_Flows[Name(EN)],Tab_Def_Flows[Value_Source],,0,) -> 0 | J10: =_xlfn.XLOOKUP(C10,Tab_Def_Flows[Name(EN)],Tab_Def_Flows[WC?],,0,) -> Yes | K10: =_xlfn.XLOOKUP(C10,Tab_Def_Flows[Name(EN)],Tab_Def_Flows[DM?],,0,) -> Yes | L10: =_xlfn.XLOOKUP(C10,Tab_Def_Flows[Name(EN)],Tab_Def_Flows[CC?],,0,) -> Yes | M10: 2028 | N10: BB | O10: 180 | R10: =INDEX(Tab_WC_DM_CC[[Flow_ID]:[CC_source]],MATCH(Tab_Data_Flows[[#This Row],[Name(EN)]],Tab_WC_DM_CC[Name(EN)],0),12) -> #N/A | S10: =MATCH(Tab_Data_Flows[[#This Row],[Name(EN)]],Tab_WC_DM_CC[Name(EN)],0) -> #N/A | X10: No | AA10: =IF(X10="no",O10,O10*Y10) -> 180 | AC10: =INDEX(Tab_Def_Flows[[Flow_ID]:[CC_DM_source]],MATCH(Tab_Data_Flows[[#This Row],[Name(EN)]],Tab_Def_Flows[Name(EN)],0),16) -> 0 | AD10: =IF(J10="Yes",AA10*Tab_Data_Flows[[#This Row],[WC_'[%']]],"N.A.") -> 0 | AE10: =Tab_Data_Flows[[#This Row],[UoM_Flow_Py]] -> 0 | AF10: =INDEX(Tab_Def_Flows[[Flow_ID]:[CC_DM_source]],MATCH(Tab_Data_Flows[[#This Row],[Name(EN)]],Tab_Def_Flows[Name(EN)],0),18) -> 1 | AG10: =IF(K10="Yes",AF10*Tab_Data_Flows[[#This Row],[Flow_Py]],"N.A.") -> 180 | AH10: =Tab_Data_Flows[[#This Row],[UoM_Flow_Py]] -> 0 | AI10: =INDEX(Tab_Def_Flows[[Flow_ID]:[CC_DM_source]],MATCH(Tab_Data_Flows[[#This Row],[Name(EN)]],Tab_Def_Flows[Name(EN)],0),20) -> 0.5 | AJ10: =IF(L10="Yes",AI10*Tab_Data_Flows[[#This Row],[Flow_Py]]*Tab_Data_Flows[[#This Row],[DM_'[%']]],"N.A.") -> 90 | AK10: =Tab_Data_Flows[[#This Row],[UoM_Flow_Py]] -> 0
A11: =ROW()-1 -> 10 | B11: =_xlfn.XLOOKUP(C11,Tab_Def_Flows[Name(EN)],Tab_Def_Flows[Flow_ID],,0,) -> F_00_01 | C11: Biomass 1 | D11: =_xlfn.XLOOKUP(C11,Tab_Def_Flows[Name(EN)],Tab_Def_Flows[Type_Biomass],,0,) -> 0 | E11: =_xlfn.XLOOKUP(C11,Tab_Def_Flows[Name(EN)],Tab_Def_Flows[Output_Process],,0,) -> Cultivation | F11: =_xlfn.XLOOKUP(C11,Tab_Def_Flows[Name(EN)],Tab_Def_Flows[Process_ID_O],,0,) -> 00_Cul_ | G11: =_xlfn.XLOOKUP(C11,Tab_Def_Flows[Name(EN)],Tab_Def_Flows[Input_Process],,0,) -> Harvesting | H11: =_xlfn.XLOOKUP(C11,Tab_Def_Flows[Name(EN)],Tab_Def_Flows[Process_ID_I],,0,) -> 01_Har_ | I11: =_xlfn.XLOOKUP(C11,Tab_Def_Flows[Name(EN)],Tab_Def_Flows[Value_Source],,0,) -> 0 | J11: =_xlfn.XLOOKUP(C11,Tab_Def_Flows[Name(EN)],Tab_Def_Flows[WC?],,0,) -> Yes | K11: =_xlfn.XLOOKUP(C11,Tab_Def_Flows[Name(EN)],Tab_Def_Flows[DM?],,0,) -> Yes | L11: =_xlfn.XLOOKUP(C11,Tab_Def_Flows[Name(EN)],Tab_Def_Flows[CC?],,0,) -> Yes | M11: 2029 | N11: BB | O11: 190 | R11: =INDEX(Tab_WC_DM_CC[[Flow_ID]:[CC_source]],MATCH(Tab_Data_Flows[[#This Row],[Name(EN)]],Tab_WC_DM_CC[Name(EN)],0),12) -> #N/A | S11: =MATCH(Tab_Data_Flows[[#This Row],[Name(EN)]],Tab_WC_DM_CC[Name(EN)],0) -> #N/A | X11: No | AA11: =IF(X11="no",O11,O11*Y11) -> 190 | AC11: =INDEX(Tab_Def_Flows[[Flow_ID]:[CC_DM_source]],MATCH(Tab_Data_Flows[[#This Row],[Name(EN)]],Tab_Def_Flows[Name(EN)],0),16) -> 0 | AD11: =IF(J11="Yes",AA11*Tab_Data_Flows[[#This Row],[WC_'[%']]],"N.A.") -> 0 | AE11: =Tab_Data_Flows[[#This Row],[UoM_Flow_Py]] -> 0 | AF11: =INDEX(Tab_Def_Flows[[Flow_ID]:[CC_DM_source]],MATCH(Tab_Data_Flows[[#This Row],[Name(EN)]],Tab_Def_Flows[Name(EN)],0),18) -> 1 | AG11: =IF(K11="Yes",AF11*Tab_Data_Flows[[#This Row],[Flow_Py]],"N.A.") -> 190 | AH11: =Tab_Data_Flows[[#This Row],[UoM_Flow_Py]] -> 0 | AI11: =INDEX(Tab_Def_Flows[[Flow_ID]:[CC_DM_source]],MATCH(Tab_Data_Flows[[#This Row],[Name(EN)]],Tab_Def_Flows[Name(EN)],0),20) -> 0.5 | AJ11: =IF(L11="Yes",AI11*Tab_Data_Flows[[#This Row],[Flow_Py]]*Tab_Data_Flows[[#This Row],[DM_'[%']]],"N.A.") -> 95 | AK11: =Tab_Data_Flows[[#This Row],[UoM_Flow_Py]] -> 0
A12: =ROW()-1 -> 11 | B12: =_xlfn.XLOOKUP(C12,Tab_Def_Flows[Name(EN)],Tab_Def_Flows[Flow_ID],,0,) -> F_00_01 | C12: Biomass 1 | D12: =_xlfn.XLOOKUP(C12,Tab_Def_Flows[Name(EN)],Tab_Def_Flows[Type_Biomass],,0,) -> 0 | E12: =_xlfn.XLOOKUP(C12,Tab_Def_Flows[Name(EN)],Tab_Def_Flows[Output_Process],,0,) -> Cultivation | F12: =_xlfn.XLOOKUP(C12,Tab_Def_Flows[Name(EN)],Tab_Def_Flows[Process_ID_O],,0,) -> 00_Cul_ | G12: =_xlfn.XLOOKUP(C12,Tab_Def_Flows[Name(EN)],Tab_Def_Flows[Input_Process],,0,) -> Harvesting | H12: =_xlfn.XLOOKUP(C12,Tab_Def_Flows[Name(EN)],Tab_Def_Flows[Process_ID_I],,0,) -> 01_Har_ | I12: =_xlfn.XLOOKUP(C12,Tab_Def_Flows[Name(EN)],Tab_Def_Flows[Value_Source],,0,) -> 0 | J12: =_xlfn.XLOOKUP(C12,Tab_Def_Flows[Name(EN)],Tab_Def_Flows[WC?],,0,) -> Yes | K12: =_xlfn.XLOOKUP(C12,Tab_Def_Flows[Name(EN)],Tab_Def_Flows[DM?],,0,) -> Yes | L12: =_xlfn.XLOOKUP(C12,Tab_Def_Flows[Name(EN)],Tab_Def_Flows[CC?],,0,) -> Yes | M12: 2030 | N12: BB | O12: 200 | R12: =INDEX(Tab_WC_DM_CC[[Flow_ID]:[CC_source]],MATCH(Tab_Data_Flows[[#This Row],[Name(EN)]],Tab_WC_DM_CC[Name(EN)],0),12) -> #N/A | S12: =MATCH(Tab_Data_Flows[[#This Row],[Name(EN)]],Tab_WC_DM_CC[Name(EN)],0) -> #N/A | X12: No | AA12: =IF(X12="no",O12,O12*Y12) -> 200 | AC12: =INDEX(Tab_Def_Flows[[Flow_ID]:[CC_DM_source]],MATCH(Tab_Data_Flows[[#This Row],[Name(EN)]],Tab_Def_Flows[Name(EN)],0),16) -> 0 | AD12: =IF(J12="Yes",AA12*Tab_Data_Flows[[#This Row],[WC_'[%']]],"N.A.") -> 0 | AE12: =Tab_Data_Flows[[#This Row],[UoM_Flow_Py]] -> 0 | AF12: =INDEX(Tab_Def_Flows[[Flow_ID]:[CC_DM_source]],MATCH(Tab_Data_Flows[[#This Row],[Name(EN)]],Tab_Def_Flows[Name(EN)],0),18) -> 1 | AG12: =IF(K12="Yes",AF12*Tab_Data_Flows[[#This Row],[Flow_Py]],"N.A.") -> 200 | AH12: =Tab_Data_Flows[[#This Row],[UoM_Flow_Py]] -> 0 | AI12: =INDEX(Tab_Def_Flows[[Flow_ID]:[CC_DM_source]],MATCH(Tab_Data_Flows[[#This Row],[Name(EN)]],Tab_Def_Flows[Name(EN)],0),20) -> 0.5 | AJ12: =IF(L12="Yes",AI12*Tab_Data_Flows[[#This Row],[Flow_Py]]*Tab_Data_Flows[[#This Row],[DM_'[%']]],"N.A.") -> 100 | AK12: =Tab_Data_Flows[[#This Row],[UoM_Flow_Py]] -> 0
A13: =ROW()-1 -> 12 | B13: =_xlfn.XLOOKUP(C13,Tab_Def_Flows[Name(EN)],Tab_Def_Flows[Flow_ID],,0,) -> F_00_01 | C13: Biomass 1 | D13: =_xlfn.XLOOKUP(C13,Tab_Def_Flows[Name(EN)],Tab_Def_Flows[Type_Biomass],,0,) -> 0 | E13: =_xlfn.XLOOKUP(C13,Tab_Def_Flows[Name(EN)],Tab_Def_Flows[Output_Process],,0,) -> Cultivation | F13: =_xlfn.XLOOKUP(C13,Tab_Def_Flows[Name(EN)],Tab_Def_Flows[Process_ID_O],,0,) -> 00_Cul_ | G13: =_xlfn.XLOOKUP(C13,Tab_Def_Flows[Name(EN)],Tab_Def_Flows[Input_Process],,0,) -> Harvesting | H13: =_xlfn.XLOOKUP(C13,Tab_Def_Flows[Name(EN)],Tab_Def_Flows[Process_ID_I],,0,) -> 01_Har_ | I13: =_xlfn.XLOOKUP(C13,Tab_Def_Flows[Name(EN)],Tab_Def_Flows[Value_Source],,0,) -> 0 | J13: =_xlfn.XLOOKUP(C13,Tab_Def_Flows[Name(EN)],Tab_Def_Flows[WC?],,0,) -> Yes | K13: =_xlfn.XLOOKUP(C13,Tab_Def_Flows[Name(EN)],Tab_Def_Flows[DM?],,0,) -> Yes | L13: =_xlfn.XLOOKUP(C13,Tab_Def_Flows[Name(EN)],Tab_Def_Flows[CC?],,0,) -> Yes | M13: 2031 | N13: BB | O13: 10 | R13: =INDEX(Tab_WC_DM_CC[[Flow_ID]:[CC_source]],MATCH(Tab_Data_Flows[[#This Row],[Name(EN)]],Tab_WC_DM_CC[Name(EN)],0),12) -> #N/A | S13: =MATCH(Tab_Data_Flows[[#This Row],[Name(EN)]],Tab_WC_DM_CC[Name(EN)],0) -> #N/A | X13: No | AA13: =IF(X13="no",O13,O13*Y13) -> 10 | AC13: =INDEX(Tab_Def_Flows[[Flow_ID]:[CC_DM_source]],MATCH(Tab_Data_Flows[[#This Row],[Name(EN)]],Tab_Def_Flows[Name(EN)],0),16) -> 0 | AD13: =IF(J13="Yes",AA13*Tab_Data_Flows[[#This Row],[WC_'[%']]],"N.A.") -> 0 | AE13: =Tab_Data_Flows[[#This Row],[UoM_Flow_Py]] -> 0 | AF13: =INDEX(Tab_Def_Flows[[Flow_ID]:[CC_DM_source]],MATCH(Tab_Data_Flows[[#This Row],[Name(EN)]],Tab_Def_Flows[Name(EN)],0),18) -> 1 | AG13: =IF(K13="Yes",AF13*Tab_Data_Flows[[#This Row],[Flow_Py]],"N.A.") -> 10 | AH13: =Tab_Data_Flows[[#This Row],[UoM_Flow_Py]] -> 0 | AI13: =INDEX(Tab_Def_Flows[[Flow_ID]:[CC_DM_source]],MATCH(Tab_Data_Flows[[#This Row],[Name(EN)]],Tab_Def_Flows[Name(EN)],0),20) -> 0.5 | AJ13: =IF(L13="Yes",AI13*Tab_Data_Flows[[#This Row],[Flow_Py]]*Tab_Data_Flows[[#This Row],[DM_'[%']]],"N.A.") -> 5 | AK13: =Tab_Data_Flows[[#This Row],[UoM_Flow_Py]] -> 0
A14: =ROW()-1 -> 13 | B14: =_xlfn.XLOOKUP(C14,Tab_Def_Flows[Name(EN)],Tab_Def_Flows[Flow_ID],,0,) -> F_00_01 | C14: Biomass 1 | D14: =_xlfn.XLOOKUP(C14,Tab_Def_Flows[Name(EN)],Tab_Def_Flows[Type_Biomass],,0,) -> 0 | E14: =_xlfn.XLOOKUP(C14,Tab_Def_Flows[Name(EN)],Tab_Def_Flows[Output_Process],,0,) -> Cultivation | F14: =_xlfn.XLOOKUP(C14,Tab_Def_Flows[Name(EN)],Tab_Def_Flows[Process_ID_O],,0,) -> 00_Cul_ | G14: =_xlfn.XLOOKUP(C14,Tab_Def_Flows[Name(EN)],Tab_Def_Flows[Input_Process],,0,) -> Harvesting | H14: =_xlfn.XLOOKUP(C14,Tab_Def_Flows[Name(EN)],Tab_Def_Flows[Process_ID_I],,0,) -> 01_Har_ | I14: =_xlfn.XLOOKUP(C14,Tab_Def_Flows[Name(EN)],Tab_Def_Flows[Value_Source],,0,) -> 0 | J14: =_xlfn.XLOOKUP(C14,Tab_Def_Flows[Name(EN)],Tab_Def_Flows[WC?],,0,) -> Yes | K14: =_xlfn.XLOOKUP(C14,Tab_Def_Flows[Name(EN)],Tab_Def_Flows[DM?],,0,) -> Yes | L14: =_xlfn.XLOOKUP(C14,Tab_Def_Flows[Name(EN)],Tab_Def_Flows[CC?],,0,) -> Yes | M14: 2032 | N14: BB | O14: 220 | R14: =INDEX(Tab_WC_DM_CC[[Flow_ID]:[CC_source]],MATCH(Tab_Data_Flows[[#This Row],[Name(EN)]],Tab_WC_DM_CC[Name(EN)],0),12) -> #N/A | S14: =MATCH(Tab_Data_Flows[[#This Row],[Name(EN)]],Tab_WC_DM_CC[Name(EN)],0) -> #N/A | X14: No | AA14: =IF(X14="no",O14,O14*Y14) -> 220 | AC14: =INDEX(Tab_Def_Flows[[Flow_ID]:[CC_DM_source]],MATCH(Tab_Data_Flows[[#This Row],[Name(EN)]],Tab_Def_Flows[Name(EN)],0),16) -> 0 | AD14: =IF(J14="Yes",AA14*Tab_Data_Flows[[#This Row],[WC_'[%']]],"N.A.") -> 0 | AE14: =Tab_Data_Flows[[#This Row],[UoM_Flow_Py]] -> 0 | AF14: =INDEX(Tab_Def_Flows[[Flow_ID]:[CC_DM_source]],MATCH(Tab_Data_Flows[[#This Row],[Name(EN)]],Tab_Def_Flows[Name(EN)],0),18) -> 1 | AG14: =IF(K14="Yes",AF14*Tab_Data_Flows[[#This Row],[Flow_Py]],"N.A.") -> 220 | AH14: =Tab_Data_Flows[[#This Row],[UoM_Flow_Py]] -> 0 | AI14: =INDEX(Tab_Def_Flows[[Flow_ID]:[CC_DM_source]],MATCH(Tab_Data_Flows[[#This Row],[Name(EN)]],Tab_Def_Flows[Name(EN)],0),20) -> 0.5 | AJ14: =IF(L14="Yes",AI14*Tab_Data_Flows[[#This Row],[Flow_Py]]*Tab_Data_Flows[[#This Row],[DM_'[%']]],"N.A.") -> 110 | AK14: =Tab_Data_Flows[[#This Row],[UoM_Flow_Py]] -> 0
A15: =ROW()-1 -> 14 | B15: =_xlfn.XLOOKUP(C15,Tab_Def_Flows[Name(EN)],Tab_Def_Flows[Flow_ID],,0,) -> F_00_01 | C15: Biomass 1 | D15: =_xlfn.XLOOKUP(C15,Tab_Def_Flows[Name(EN)],Tab_Def_Flows[Type_Biomass],,0,) -> 0 | E15: =_xlfn.XLOOKUP(C15,Tab_Def_Flows[Name(EN)],Tab_Def_Flows[Output_Process],,0,) -> Cultivation | F15: =_xlfn.XLOOKUP(C15,Tab_Def_Flows[Name(EN)],Tab_Def_Flows[Process_ID_O],,0,) -> 00_Cul_ | G15: =_xlfn.XLOOKUP(C15,Tab_Def_Flows[Name(EN)],Tab_Def_Flows[Input_Process],,0,) -> Harvesting | H15: =_xlfn.XLOOKUP(C15,Tab_Def_Flows[Name(EN)],Tab_Def_Flows[Process_ID_I],,0,) -> 01_Har_ | I15: =_xlfn.XLOOKUP(C15,Tab_Def_Flows[Name(EN)],Tab_Def_Flows[Value_Source],,0,) -> 0 | J15: =_xlfn.XLOOKUP(C15,Tab_Def_Flows[Name(EN)],Tab_Def_Flows[WC?],,0,) -> Yes | K15: =_xlfn.XLOOKUP(C15,Tab_Def_Flows[Name(EN)],Tab_Def_Flows[DM?],,0,) -> Yes | L15: =_xlfn.XLOOKUP(C15,Tab_Def_Flows[Name(EN)],Tab_Def_Flows[CC?],,0,) -> Yes | M15: 2033 | N15: BB | O15: 230 | R15: =INDEX(Tab_WC_DM_CC[[Flow_ID]:[CC_source]],MATCH(Tab_Data_Flows[[#This Row],[Name(EN)]],Tab_WC_DM_CC[Name(EN)],0),12) -> #N/A | S15: =MATCH(Tab_Data_Flows[[#This Row],[Name(EN)]],Tab_WC_DM_CC[Name(EN)],0) -> #N/A | X15: No | AA15: =IF(X15="no",O15,O15*Y15) -> 230 | AC15: =INDEX(Tab_Def_Flows[[Flow_ID]:[CC_DM_source]],MATCH(Tab_Data_Flows[[#This Row],[Name(EN)]],Tab_Def_Flows[Name(EN)],0),16) -> 0 | AD15: =IF(J15="Yes",AA15*Tab_Data_Flows[[#This Row],[WC_'[%']]],"N.A.") -> 0 | AE15: =Tab_Data_Flows[[#This Row],[UoM_Flow_Py]] -> 0 | AF15: =INDEX(Tab_Def_Flows[[Flow_ID]:[CC_DM_source]],MATCH(Tab_Data_Flows[[#This Row],[Name(EN)]],Tab_Def_Flows[Name(EN)],0),18) -> 1 | AG15: =IF(K15="Yes",AF15*Tab_Data_Flows[[#This Row],[Flow_Py]],"N.A.") -> 230 | AH15: =Tab_Data_Flows[[#This Row],[UoM_Flow_Py]] -> 0 | AI15: =INDEX(Tab_Def_Flows[[Flow_ID]:[CC_DM_source]],MATCH(Tab_Data_Flows[[#This Row],[Name(EN)]],Tab_Def_Flows[Name(EN)],0),20) -> 0.5 | AJ15: =IF(L15="Yes",AI15*Tab_Data_Flows[[#This Row],[Flow_Py]]*Tab_Data_Flows[[#This Row],[DM_'[%']]],"N.A.") -> 115 | AK15: =Tab_Data_Flows[[#This Row],[UoM_Flow_Py]] -> 0
A16: =ROW()-1 -> 15 | B16: =_xlfn.XLOOKUP(C16,Tab_Def_Flows[Name(EN)],Tab_Def_Flows[Flow_ID],,0,) -> F_00_01 | C16: Biomass 1 | D16: =_xlfn.XLOOKUP(C16,Tab_Def_Flows[Name(EN)],Tab_Def_Flows[Type_Biomass],,0,) -> 0 | E16: =_xlfn.XLOOKUP(C16,Tab_Def_Flows[Name(EN)],Tab_Def_Flows[Output_Process],,0,) -> Cultivation | F16: =_xlfn.XLOOKUP(C16,Tab_Def_Flows[Name(EN)],Tab_Def_Flows[Process_ID_O],,0,) -> 00_Cul_ | G16: =_xlfn.XLOOKUP(C16,Tab_Def_Flows[Name(EN)],Tab_Def_Flows[Input_Process],,0,) -> Harvesting | H16: =_xlfn.XLOOKUP(C16,Tab_Def_Flows[Name(EN)],Tab_Def_Flows[Process_ID_I],,0,) -> 01_Har_ | I16: =_xlfn.XLOOKUP(C16,Tab_Def_Flows[Name(EN)],Tab_Def_Flows[Value_Source],,0,) -> 0 | J16: =_xlfn.XLOOKUP(C16,Tab_Def_Flows[Name(EN)],Tab_Def_Flows[WC?],,0,) -> Yes | K16: =_xlfn.XLOOKUP(C16,Tab_Def_Flows[Name(EN)],Tab_Def_Flows[DM?],,0,) -> Yes | L16: =_xlfn.XLOOKUP(C16,Tab_Def_Flows[Name(EN)],Tab_Def_Flows[CC?],,0,) -> Yes | M16: 2034 | N16: BB | O16: 240 | R16: =INDEX(Tab_WC_DM_CC[[Flow_ID]:[CC_source]],MATCH(Tab_Data_Flows[[#This Row],[Name(EN)]],Tab_WC_DM_CC[Name(EN)],0),12) -> #N/A | S16: =MATCH(Tab_Data_Flows[[#This Row],[Name(EN)]],Tab_WC_DM_CC[Name(EN)],0) -> #N/A | X16: No | AA16: =IF(X16="no",O16,O16*Y16) -> 240 | AC16: =INDEX(Tab_Def_Flows[[Flow_ID]:[CC_DM_source]],MATCH(Tab_Data_Flows[[#This Row],[Name(EN)]],Tab_Def_Flows[Name(EN)],0),16) -> 0 | AD16: =IF(J16="Yes",AA16*Tab_Data_Flows[[#This Row],[WC_'[%']]],"N.A.") -> 0 | AE16: =Tab_Data_Flows[[#This Row],[UoM_Flow_Py]] -> 0 | AF16: =INDEX(Tab_Def_Flows[[Flow_ID]:[CC_DM_source]],MATCH(Tab_Data_Flows[[#This Row],[Name(EN)]],Tab_Def_Flows[Name(EN)],0),18) -> 1 | AG16: =IF(K16="Yes",AF16*Tab_Data_Flows[[#This Row],[Flow_Py]],"N.A.") -> 240 | AH16: =Tab_Data_Flows[[#This Row],[UoM_Flow_Py]] -> 0 | AI16: =INDEX(Tab_Def_Flows[[Flow_ID]:[CC_DM_source]],MATCH(Tab_Data_Flows[[#This Row],[Name(EN)]],Tab_Def_Flows[Name(EN)],0),20) -> 0.5 | AJ16: =IF(L16="Yes",AI16*Tab_Data_Flows[[#This Row],[Flow_Py]]*Tab_Data_Flows[[#This Row],[DM_'[%']]],"N.A.") -> 120 | AK16: =Tab_Data_Flows[[#This Row],[UoM_Flow_Py]] -> 0
A17: =ROW()-1 -> 16 | B17: =_xlfn.XLOOKUP(C17,Tab_Def_Flows[Name(EN)],Tab_Def_Flows[Flow_ID],,0,) -> F_00_01 | C17: Biomass 1 | D17: =_xlfn.XLOOKUP(C17,Tab_Def_Flows[Name(EN)],Tab_Def_Flows[Type_Biomass],,0,) -> 0 | E17: =_xlfn.XLOOKUP(C17,Tab_Def_Flows[Name(EN)],Tab_Def_Flows[Output_Process],,0,) -> Cultivation | F17: =_xlfn.XLOOKUP(C17,Tab_Def_Flows[Name(EN)],Tab_Def_Flows[Process_ID_O],,0,) -> 00_Cul_ | G17: =_xlfn.XLOOKUP(C17,Tab_Def_Flows[Name(EN)],Tab_Def_Flows[Input_Process],,0,) -> Harvesting | H17: =_xlfn.XLOOKUP(C17,Tab_Def_Flows[Name(EN)],Tab_Def_Flows[Process_ID_I],,0,) -> 01_Har_ | I17: =_xlfn.XLOOKUP(C17,Tab_Def_Flows[Name(EN)],Tab_Def_Flows[Value_Source],,0,) -> 0 | J17: =_xlfn.XLOOKUP(C17,Tab_Def_Flows[Name(EN)],Tab_Def_Flows[WC?],,0,) -> Yes | K17: =_xlfn.XLOOKUP(C17,Tab_Def_Flows[Name(EN)],Tab_Def_Flows[DM?],,0,) -> Yes | L17: =_xlfn.XLOOKUP(C17,Tab_Def_Flows[Name(EN)],Tab_Def_Flows[CC?],,0,) -> Yes | M17: 2035 | N17: BB | O17: 250 | R17: =INDEX(Tab_WC_DM_CC[[Flow_ID]:[CC_source]],MATCH(Tab_Data_Flows[[#This Row],[Name(EN)]],Tab_WC_DM_CC[Name(EN)],0),12) -> #N/A | S17: =MATCH(Tab_Data_Flows[[#This Row],[Name(EN)]],Tab_WC_DM_CC[Name(EN)],0) -> #N/A | X17: No | AA17: =IF(X17="no",O17,O17*Y17) -> 250 | AC17: =INDEX(Tab_Def_Flows[[Flow_ID]:[CC_DM_source]],MATCH(Tab_Data_Flows[[#This Row],[Name(EN)]],Tab_Def_Flows[Name(EN)],0),16) -> 0 | AD17: =IF(J17="Yes",AA17*Tab_Data_Flows[[#This Row],[WC_'[%']]],"N.A.") -> 0 | AE17: =Tab_Data_Flows[[#This Row],[UoM_Flow_Py]] -> 0 | AF17: =INDEX(Tab_Def_Flows[[Flow_ID]:[CC_DM_source]],MATCH(Tab_Data_Flows[[#This Row],[Name(EN)]],Tab_Def_Flows[Name(EN)],0),18) -> 1 | AG17: =IF(K17="Yes",AF17*Tab_Data_Flows[[#This Row],[Flow_Py]],"N.A.") -> 250 | AH17: =Tab_Data_Flows[[#This Row],[UoM_Flow_Py]] -> 0 | AI17: =INDEX(Tab_Def_Flows[[Flow_ID]:[CC_DM_source]],MATCH(Tab_Data_Flows[[#This Row],[Name(EN)]],Tab_Def_Flows[Name(EN)],0),20) -> 0.5 | AJ17: =IF(L17="Yes",AI17*Tab_Data_Flows[[#This Row],[Flow_Py]]*Tab_Data_Flows[[#This Row],[DM_'[%']]],"N.A.") -> 125 | AK17: =Tab_Data_Flows[[#This Row],[UoM_Flow_Py]] -> 0
A18: =ROW()-1 -> 17 | B18: =_xlfn.XLOOKUP(C18,Tab_Def_Flows[Name(EN)],Tab_Def_Flows[Flow_ID],,0,) -> F_00_01 | C18: Biomass 1 | D18: =_xlfn.XLOOKUP(C18,Tab_Def_Flows[Name(EN)],Tab_Def_Flows[Type_Biomass],,0,) -> 0 | E18: =_xlfn.XLOOKUP(C18,Tab_Def_Flows[Name(EN)],Tab_Def_Flows[Output_Process],,0,) -> Cultivation | F18: =_xlfn.XLOOKUP(C18,Tab_Def_Flows[Name(EN)],Tab_Def_Flows[Process_ID_O],,0,) -> 00_Cul_ | G18: =_xlfn.XLOOKUP(C18,Tab_Def_Flows[Name(EN)],Tab_Def_Flows[Input_Process],,0,) -> Harvesting | H18: =_xlfn.XLOOKUP(C18,Tab_Def_Flows[Name(EN)],Tab_Def_Flows[Process_ID_I],,0,) -> 01_Har_ | I18: =_xlfn.XLOOKUP(C18,Tab_Def_Flows[Name(EN)],Tab_Def_Flows[Value_Source],,0,) -> 0 | J18: =_xlfn.XLOOKUP(C18,Tab_Def_Flows[Name(EN)],Tab_Def_Flows[WC?],,0,) -> Yes | K18: =_xlfn.XLOOKUP(C18,Tab_Def_Flows[Name(EN)],Tab_Def_Flows[DM?],,0,) -> Yes | L18: =_xlfn.XLOOKUP(C18,Tab_Def_Flows[Name(EN)],Tab_Def_Flows[CC?],,0,) -> Yes | M18: 2036 | N18: BB | O18: 260 | R18: =INDEX(Tab_WC_DM_CC[[Flow_ID]:[CC_source]],MATCH(Tab_Data_Flows[[#This Row],[Name(EN)]],Tab_WC_DM_CC[Name(EN)],0),12) -> #N/A | S18: =MATCH(Tab_Data_Flows[[#This Row],[Name(EN)]],Tab_WC_DM_CC[Name(EN)],0) -> #N/A | X18: No | AA18: =IF(X18="no",O18,O18*Y18) -> 260 | AC18: =INDEX(Tab_Def_Flows[[Flow_ID]:[CC_DM_source]],MATCH(Tab_Data_Flows[[#This Row],[Name(EN)]],Tab_Def_Flows[Name(EN)],0),16) -> 0 | AD18: =IF(J18="Yes",AA18*Tab_Data_Flows[[#This Row],[WC_'[%']]],"N.A.") -> 0 | AE18: =Tab_Data_Flows[[#This Row],[UoM_Flow_Py]] -> 0 | AF18: =INDEX(Tab_Def_Flows[[Flow_ID]:[CC_DM_source]],MATCH(Tab_Data_Flows[[#This Row],[Name(EN)]],Tab_Def_Flows[Name(EN)],0),18) -> 1 | AG18: =IF(K18="Yes",AF18*Tab_Data_Flows[[#This Row],[Flow_Py]],"N.A.") -> 260 | AH18: =Tab_Data_Flows[[#This Row],[UoM_Flow_Py]] -> 0 | AI18: =INDEX(Tab_Def_Flows[[Flow_ID]:[CC_DM_source]],MATCH(Tab_Data_Flows[[#This Row],[Name(EN)]],Tab_Def_Flows[Name(EN)],0),20) -> 0.5 | AJ18: =IF(L18="Yes",AI18*Tab_Data_Flows[[#This Row],[Flow_Py]]*Tab_Data_Flows[[#This Row],[DM_'[%']]],"N.A.") -> 130 | AK18: =Tab_Data_Flows[[#This Row],[UoM_Flow_Py]] -> 0
A19: =ROW()-1 -> 18 | B19: =_xlfn.XLOOKUP(C19,Tab_Def_Flows[Name(EN)],Tab_Def_Flows[Flow_ID],,0,) -> F_00_01 | C19: Biomass 1 | D19: =_xlfn.XLOOKUP(C19,Tab_Def_Flows[Name(EN)],Tab_Def_Flows[Type_Biomass],,0,) -> 0 | E19: =_xlfn.XLOOKUP(C19,Tab_Def_Flows[Name(EN)],Tab_Def_Flows[Output_Process],,0,) -> Cultivation | F19: =_xlfn.XLOOKUP(C19,Tab_Def_Flows[Name(EN)],Tab_Def_Flows[Process_ID_O],,0,) -> 00_Cul_ | G19: =_xlfn.XLOOKUP(C19,Tab_Def_Flows[Name(EN)],Tab_Def_Flows[Input_Process],,0,) -> Harvesting | H19: =_xlfn.XLOOKUP(C19,Tab_Def_Flows[Name(EN)],Tab_Def_Flows[Process_ID_I],,0,) -> 01_Har_ | I19: =_xlfn.XLOOKUP(C19,Tab_Def_Flows[Name(EN)],Tab_Def_Flows[Value_Source],,0,) -> 0 | J19: =_xlfn.XLOOKUP(C19,Tab_Def_Flows[Name(EN)],Tab_Def_Flows[WC?],,0,) -> Yes | K19: =_xlfn.XLOOKUP(C19,Tab_Def_Flows[Name(EN)],Tab_Def_Flows[DM?],,0,) -> Yes | L19: =_xlfn.XLOOKUP(C19,Tab_Def_Flows[Name(EN)],Tab_Def_Flows[CC?],,0,) -> Yes | M19: 2037 | N19: BB | O19: 270 | R19: =INDEX(Tab_WC_DM_CC[[Flow_ID]:[CC_source]],MATCH(Tab_Data_Flows[[#This Row],[Name(EN)]],Tab_WC_DM_CC[Name(EN)],0),12) -> #N/A | S19: =MATCH(Tab_Data_Flows[[#This Row],[Name(EN)]],Tab_WC_DM_CC[Name(EN)],0) -> #N/A | X19: No | AA19: =IF(X19="no",O19,O19*Y19) -> 270 | AC19: =INDEX(Tab_Def_Flows[[Flow_ID]:[CC_DM_source]],MATCH(Tab_Data_Flows[[#This Row],[Name(EN)]],Tab_Def_Flows[Name(EN)],0),16) -> 0 | AD19: =IF(J19="Yes",AA19*Tab_Data_Flows[[#This Row],[WC_'[%']]],"N.A.") -> 0 | AE19: =Tab_Data_Flows[[#This Row],[UoM_Flow_Py]] -> 0 | AF19: =INDEX(Tab_Def_Flows[[Flow_ID]:[CC_DM_source]],MATCH(Tab_Data_Flows[[#This Row],[Name(EN)]],Tab_Def_Flows[Name(EN)],0),18) -> 1 | AG19: =IF(K19="Yes",AF19*Tab_Data_Flows[[#This Row],[Flow_Py]],"N.A.") -> 270 | AH19: =Tab_Data_Flows[[#This Row],[UoM_Flow_Py]] -> 0 | AI19: =INDEX(Tab_Def_Flows[[Flow_ID]:[CC_DM_source]],MATCH(Tab_Data_Flows[[#This Row],[Name(EN)]],Tab_Def_Flows[Name(EN)],0),20) -> 0.5 | AJ19: =IF(L19="Yes",AI19*Tab_Data_Flows[[#This Row],[Flow_Py]]*Tab_Data_Flows[[#This Row],[DM_'[%']]],"N.A.") -> 135 | AK19: =Tab_Data_Flows[[#This Row],[UoM_Flow_Py]] -> 0
A20: =ROW()-1 -> 19 | B20: =_xlfn.XLOOKUP(C20,Tab_Def_Flows[Name(EN)],Tab_Def_Flows[Flow_ID],,0,) -> F_00_01 | C20: Biomass 1 | D20: =_xlfn.XLOOKUP(C20,Tab_Def_Flows[Name(EN)],Tab_Def_Flows[Type_Biomass],,0,) -> 0 | E20: =_xlfn.XLOOKUP(C20,Tab_Def_Flows[Name(EN)],Tab_Def_Flows[Output_Process],,0,) -> Cultivation | F20: =_xlfn.XLOOKUP(C20,Tab_Def_Flows[Name(EN)],Tab_Def_Flows[Process_ID_O],,0,) -> 00_Cul_ | G20: =_xlfn.XLOOKUP(C20,Tab_Def_Flows[Name(EN)],Tab_Def_Flows[Input_Process],,0,) -> Harvesting | H20: =_xlfn.XLOOKUP(C20,Tab_Def_Flows[Name(EN)],Tab_Def_Flows[Process_ID_I],,0,) -> 01_Har_ | I20: =_xlfn.XLOOKUP(C20,Tab_Def_Flows[Name(EN)],Tab_Def_Flows[Value_Source],,0,) -> 0 | J20: =_xlfn.XLOOKUP(C20,Tab_Def_Flows[Name(EN)],Tab_Def_Flows[WC?],,0,) -> Yes | K20: =_xlfn.XLOOKUP(C20,Tab_Def_Flows[Name(EN)],Tab_Def_Flows[DM?],,0,) -> Yes | L20: =_xlfn.XLOOKUP(C20,Tab_Def_Flows[Name(EN)],Tab_Def_Flows[CC?],,0,) -> Yes | M20: 2038 | N20: BB | O20: 280 | R20: =INDEX(Tab_WC_DM_CC[[Flow_ID]:[CC_source]],MATCH(Tab_Data_Flows[[#This Row],[Name(EN)]],Tab_WC_DM_CC[Name(EN)],0),12) -> #N/A | S20: =MATCH(Tab_Data_Flows[[#This Row],[Name(EN)]],Tab_WC_DM_CC[Name(EN)],0) -> #N/A | X20: No | AA20: =IF(X20="no",O20,O20*Y20) -> 280 | AC20: =INDEX(Tab_Def_Flows[[Flow_ID]:[CC_DM_source]],MATCH(Tab_Data_Flows[[#This Row],[Name(EN)]],Tab_Def_Flows[Name(EN)],0),16) -> 0 | AD20: =IF(J20="Yes",AA20*Tab_Data_Flows[[#This Row],[WC_'[%']]],"N.A.") -> 0 | AE20: =Tab_Data_Flows[[#This Row],[UoM_Flow_Py]] -> 0 | AF20: =INDEX(Tab_Def_Flows[[Flow_ID]:[CC_DM_source]],MATCH(Tab_Data_Flows[[#This Row],[Name(EN)]],Tab_Def_Flows[Name(EN)],0),18) -> 1 | AG20: =IF(K20="Yes",AF20*Tab_Data_Flows[[#This Row],[Flow_Py]],"N.A.") -> 280 | AH20: =Tab_Data_Flows[[#This Row],[UoM_Flow_Py]] -> 0 | AI20: =INDEX(Tab_Def_Flows[[Flow_ID]:[CC_DM_source]],MATCH(Tab_Data_Flows[[#This Row],[Name(EN)]],Tab_Def_Flows[Name(EN)],0),20) -> 0.5 | AJ20: =IF(L20="Yes",AI20*Tab_Data_Flows[[#This Row],[Flow_Py]]*Tab_Data_Flows[[#This Row],[DM_'[%']]],"N.A.") -> 140 | AK20: =Tab_Data_Flows[[#This Row],[UoM_Flow_Py]] -> 0
... A22: =ROW()-1 -> 21 | B22: =_xlfn.XLOOKUP(C22,Tab_Def_Flows[Name(EN)],Tab_Def_Flows[Flow_ID],,0,) -> F_00_01 | C22: Biomass 1 | D22: =_xlfn.XLOOKUP(C22,Tab_Def_Flows[Name(EN)],Tab_Def_Flows[Type_Biomass],,0,) -> 0 | E22: =_xlfn.XLOOKUP(C22,Tab_Def_Flows[Name(EN)],Tab_Def_Flows[Output_Process],,0,) -> Cultivation | F22: =_xlfn.XLOOKUP(C22,Tab_Def_Flows[Name(EN)],Tab_Def_Flows[Process_ID_O],,0,) -> 00_Cul_ | G22: =_xlfn.XLOOKUP(C22,Tab_Def_Flows[Name(EN)],Tab_Def_Flows[Input_Process],,0,) -> Harvesting | H22: =_xlfn.XLOOKUP(C22,Tab_Def_Flows[Name(EN)],Tab_Def_Flows[Process_ID_I],,0,) -> 01_Har_ | I22: =_xlfn.XLOOKUP(C22,Tab_Def_Flows[Name(EN)],Tab_Def_Flows[Value_Source],,0,) -> 0 | J22: =_xlfn.XLOOKUP(C22,Tab_Def_Flows[Name(EN)],Tab_Def_Flows[WC?],,0,) -> Yes | K22: =_xlfn.XLOOKUP(C22,Tab_Def_Flows[Name(EN)],Tab_Def_Flows[DM?],,0,) -> Yes | L22: =_xlfn.XLOOKUP(C22,Tab_Def_Flows[Name(EN)],Tab_Def_Flows[CC?],,0,) -> Yes | M22: 2040 | N22: BB | O22: 300 | R22: =INDEX(Tab_WC_DM_CC[[Flow_ID]:[CC_source]],MATCH(Tab_Data_Flows[[#This Row],[Name(EN)]],Tab_WC_DM_CC[Name(EN)],0),12) -> #N/A | S22: =MATCH(Tab_Data_Flows[[#This Row],[Name(EN)]],Tab_WC_DM_CC[Name(EN)],0) -> #N/A | X22: No | AA22: =IF(X22="no",O22,O22*Y22) -> 300 | AC22: =INDEX(Tab_Def_Flows[[Flow_ID]:[CC_DM_source]],MATCH(Tab_Data_Flows[[#This Row],[Name(EN)]],Tab_Def_Flows[Name(EN)],0),16) -> 0 | AD22: =IF(J22="Yes",AA22*Tab_Data_Flows[[#This Row],[WC_'[%']]],"N.A.") -> 0 | AE22: =Tab_Data_Flows[[#This Row],[UoM_Flow_Py]] -> 0 | AF22: =INDEX(Tab_Def_Flows[[Flow_ID]:[CC_DM_source]],MATCH(Tab_Data_Flows[[#This Row],[Name(EN)]],Tab_Def_Flows[Name(EN)],0),18) -> 1 | AG22: =IF(K22="Yes",AF22*Tab_Data_Flows[[#This Row],[Flow_Py]],"N.A.") -> 300 | AH22: =Tab_Data_Flows[[#This Row],[UoM_Flow_Py]] -> 0 | AI22: =INDEX(Tab_Def_Flows[[Flow_ID]:[CC_DM_source]],MATCH(Tab_Data_Flows[[#This Row],[Name(EN)]],Tab_Def_Flows[Name(EN)],0),20) -> 0.5 | AJ22: =IF(L22="Yes",AI22*Tab_Data_Flows[[#This Row],[Flow_Py]]*Tab_Data_Flows[[#This Row],[DM_'[%']]],"N.A.") -> 150 | AK22: =Tab_Data_Flows[[#This Row],[UoM_Flow_Py]] -> 0
A23: =ROW()-1 -> 22 | B23: =_xlfn.XLOOKUP(C23,Tab_Def_Flows[Name(EN)],Tab_Def_Flows[Flow_ID],,0,) -> F_12_12 | D23: =_xlfn.XLOOKUP(C23,Tab_Def_Flows[Name(EN)],Tab_Def_Flows[Type_Biomass],,0,) -> 0 | E23: =_xlfn.XLOOKUP(C23,Tab_Def_Flows[Name(EN)],Tab_Def_Flows[Output_Process],,0,) -> 0 | F23: =_xlfn.XLOOKUP(C23,Tab_Def_Flows[Name(EN)],Tab_Def_Flows[Process_ID_O],,0,) -> 12__ | G23: =_xlfn.XLOOKUP(C23,Tab_Def_Flows[Name(EN)],Tab_Def_Flows[Input_Process],,0,) -> 0 | H23: =_xlfn.XLOOKUP(C23,Tab_Def_Flows[Name(EN)],Tab_Def_Flows[Process_ID_I],,0,) -> 12__ | I23: =_xlfn.XLOOKUP(C23,Tab_Def_Flows[Name(EN)],Tab_Def_Flows[Value_Source],,0,) -> 0 | J23: =_xlfn.XLOOKUP(C23,Tab_Def_Flows[Name(EN)],Tab_Def_Flows[WC?],,0,) -> 0 | K23: =_xlfn.XLOOKUP(C23,Tab_Def_Flows[Name(EN)],Tab_Def_Flows[DM?],,0,) -> 0 | L23: =_xlfn.XLOOKUP(C23,Tab_Def_Flows[Name(EN)],Tab_Def_Flows[CC?],,0,) -> 0 | N23: BB | R23: =INDEX(Tab_WC_DM_CC[[Flow_ID]:[CC_source]],MATCH(Tab_Data_Flows[[#This Row],[Name(EN)]],Tab_WC_DM_CC[Name(EN)],0),12) -> #N/A | S23: =MATCH(Tab_Data_Flows[[#This Row],[Name(EN)]],Tab_WC_DM_CC[Name(EN)],0) -> #N/A | X23: No | AA23: =IF(X23="no",O23,O23*Y23) -> 0 | AC23: =INDEX(Tab_Def_Flows[[Flow_ID]:[CC_DM_source]],MATCH(Tab_Data_Flows[[#This Row],[Name(EN)]],Tab_Def_Flows[Name(EN)],0),16) -> #N/A | AD23: =IF(J23="Yes",AA23*Tab_Data_Flows[[#This Row],[WC_'[%']]],"N.A.") -> N.A. | AE23: =Tab_Data_Flows[[#This Row],[UoM_Flow_Py]] -> 0 | AF23: =INDEX(Tab_Def_Flows[[Flow_ID]:[CC_DM_source]],MATCH(Tab_Data_Flows[[#This Row],[Name(EN)]],Tab_Def_Flows[Name(EN)],0),18) -> #N/A | AG23: =IF(K23="Yes",AF23*Tab_Data_Flows[[#This Row],[Flow_Py]],"N.A.") -> N.A. | AH23: =Tab_Data_Flows[[#This Row],[UoM_Flow_Py]] -> 0 | AI23: =INDEX(Tab_Def_Flows[[Flow_ID]:[CC_DM_source]],MATCH(Tab_Data_Flows[[#This Row],[Name(EN)]],Tab_Def_Flows[Name(EN)],0),20) -> #N/A | AJ23: =IF(L23="Yes",AI23*Tab_Data_Flows[[#This Row],[Flow_Py]]*Tab_Data_Flows[[#This Row],[DM_'[%']]],"N.A.") -> N.A. | AK23: =Tab_Data_Flows[[#This Row],[UoM_Flow_Py]] -> 0
A24: =ROW()-1 -> 23 | B24: =_xlfn.XLOOKUP(C24,Tab_Def_Flows[Name(EN)],Tab_Def_Flows[Flow_ID],,0,) -> F_12_12 | D24: =_xlfn.XLOOKUP(C24,Tab_Def_Flows[Name(EN)],Tab_Def_Flows[Type_Biomass],,0,) -> 0 | E24: =_xlfn.XLOOKUP(C24,Tab_Def_Flows[Name(EN)],Tab_Def_Flows[Output_Process],,0,) -> 0 | F24: =_xlfn.XLOOKUP(C24,Tab_Def_Flows[Name(EN)],Tab_Def_Flows[Process_ID_O],,0,) -> 12__ | G24: =_xlfn.XLOOKUP(C24,Tab_Def_Flows[Name(EN)],Tab_Def_Flows[Input_Process],,0,) -> 0 | H24: =_xlfn.XLOOKUP(C24,Tab_Def_Flows[Name(EN)],Tab_Def_Flows[Process_ID_I],,0,) -> 12__ | I24: =_xlfn.XLOOKUP(C24,Tab_Def_Flows[Name(EN)],Tab_Def_Flows[Value_Source],,0,) -> 0 | J24: =_xlfn.XLOOKUP(C24,Tab_Def_Flows[Name(EN)],Tab_Def_Flows[WC?],,0,) -> 0 | K24: =_xlfn.XLOOKUP(C24,Tab_Def_Flows[Name(EN)],Tab_Def_Flows[DM?],,0,) -> 0 | L24: =_xlfn.XLOOKUP(C24,Tab_Def_Flows[Name(EN)],Tab_Def_Flows[CC?],,0,) -> 0 | N24: BB | R24: =INDEX(Tab_WC_DM_CC[[Flow_ID]:[CC_source]],MATCH(Tab_Data_Flows[[#This Row],[Name(EN)]],Tab_WC_DM_CC[Name(EN)],0),12) -> #N/A | S24: =MATCH(Tab_Data_Flows[[#This Row],[Name(EN)]],Tab_WC_DM_CC[Name(EN)],0) -> #N/A | X24: No | AA24: =IF(X24="no",O24,O24*Y24) -> 0 | AC24: =INDEX(Tab_Def_Flows[[Flow_ID]:[CC_DM_source]],MATCH(Tab_Data_Flows[[#This Row],[Name(EN)]],Tab_Def_Flows[Name(EN)],0),16) -> #N/A | AD24: =IF(J24="Yes",AA24*Tab_Data_Flows[[#This Row],[WC_'[%']]],"N.A.") -> N.A. | AE24: =Tab_Data_Flows[[#This Row],[UoM_Flow_Py]] -> 0 | AF24: =INDEX(Tab_Def_Flows[[Flow_ID]:[CC_DM_source]],MATCH(Tab_Data_Flows[[#This Row],[Name(EN)]],Tab_Def_Flows[Name(EN)],0),18) -> #N/A | AG24: =IF(K24="Yes",AF24*Tab_Data_Flows[[#This Row],[Flow_Py]],"N.A.") -> N.A. | AH24: =Tab_Data_Flows[[#This Row],[UoM_Flow_Py]] -> 0 | AI24: =INDEX(Tab_Def_Flows[[Flow_ID]:[CC_DM_source]],MATCH(Tab_Data_Flows[[#This Row],[Name(EN)]],Tab_Def_Flows[Name(EN)],0),20) -> #N/A | AJ24: =IF(L24="Yes",AI24*Tab_Data_Flows[[#This Row],[Flow_Py]]*Tab_Data_Flows[[#This Row],[DM_'[%']]],"N.A.") -> N.A. | AK24: =Tab_Data_Flows[[#This Row],[UoM_Flow_Py]] -> 0
