Workbook
Name Baumart_: '3_1_Calculation_factors (Wood)'!#REF!
Name Baumart_: #REF!
Name Cluster_: '3_1_Calculation_factors (Wood)'!#REF!
Name Cluster_: #REF!
Name einheit: '3_1_Calculation_factors (Wood)'!#REF!
Name einheit: #REF!
Name Erhebungsart_: '3_1_Calculation_factors (Wood)'!#REF!
Name Erhebungsart_: #REF!
Name Herkunft_: '3_1_Calculation_factors (Wood)'!#REF!
Name Herkunft_: #REF!
Name Holzstrom_: '3_1_Calculation_factors (Wood)'!#REF!
Name Holzstrom_: #REF!
Name In_Out_: '3_1_Calculation_factors (Wood)'!#REF!
Name In_Out_: #REF!
Name Inhaltsverzeichnis: "MTRANS(ERSETZEN(Inhalt;1;FINDEN(""]"";Inhalt);""))"
Name Klassifizierung: '3_1_Calculation_factors (Wood)'!#REF!
Name Klassifizierung: #REF!
Name Ort_: '3_1_Calculation_factors (Wood)'!#REF!
Name Ort_: #REF!
Name Tab_Process_TCs_dyn: Tab_Process_TCs2527[]
Name Tab_Process_TCs_dyn: #REF!
Name Ziel_: '3_1_Calculation_factors (Wood)'!#REF!
Name Ziel_: #REF!

Sheet Intro
B2: Title:
B4: Der angehängte Datensatz beinhalten Informationen über Materialflüsse, Prozesse sowie Lager in der Region Brandenburg. Der Datensatz bezieht sich dabei auf verschiedene Quellen und Dokumente.
B6: Definition der Systemgrenzen: | T6: {=_xlfn.SEQUENCE(I7-H7+1,1,H7,1)} -> 2025
C7: Beobachtungszeitraum: | F7: 2010 - 2020 | H7: 2025 | I7: 2050 | T7: 2026
C8: Beobachtungsgebiet: | F8: Berlin | T8: 2027
F9: Brandenburg | T9: 2028
T10: 2029
T11: 2030
B12: Für die Anfertigung der Materialflussanalyse werden die folgenden Daten benötigt. Die Daten werden in seperaten Tabellenblättern dargestellt. Für jeden Datensatz werden spezifische Anforderungen definiert. Diese lassen sich einem Systemübergreifenden Fließbild zuordnen. Dieses Fließbild beinhaltet die relevanten Flüsse, Prozesse und Lager. | T12: 2031
T13: 2032
T14: 2033
B15: Prozesse bilden die Grundlage für das System. Prozesse können Transferkoefizienten und Lager beinhalten. Prozesse haben einen oder mehrere Flüsse als Input sowie einen oder mehrere Flüsse als Output. | T15: 2034
T16: 2035
T17: 2036
T18: 2037
T19: 2038
T20: 2039
T21: 2040
B22: Flüsse: | T22: 2041
T23: 2042
C24: Flüsse müssen in Mg umgerechnet werden | T24: 2043
T25: 2044
T26: 2045
T27: 2046
T28: 2047
T29: 2048
T30: 2049
T31: 2050
B33: Prozesse:
B34: Lager
B35: Transferkoeffizienten
B36: Umrechnungsfaktoren:
B37: Codelisten:
B40: Autoren: | C40: Johannes Roland Scholz
C41: Lukas Hoppe

Sheet 1_1_Definition_Flows
A1: Complete? | B1: ID | C1: Flow_ID | D1: Name(EN) | E1: Region | F1: Type_Biomass | G1: Comment | H1: Output_Process | I1: Process_ID_O | J1: Input_Process | K1: Process_ID_I | L1: Value_Source | M1: WC? | N1: DM? | O1: CC? | P1: WC | Q1: WC_source | R1: DM | S1: DM_source | T1: CC_DM[%] | U1: CC_DM_source | V1: CC | W1: CC_FM_source
A2: TRUE | B2: 0 | C2: ="F_"&LEFT(I2,2)&"_"&LEFT(K2,2) -> F_00_01 | D2: Wood | H2: Biosphere | I2: =_xlfn.XLOOKUP(H2,Tab_Def_Processes[Name(EN)],Tab_Def_Processes[Process_ID],,0,) -> 00_Bio_ | J2: Raw Material Extraction | K2: =_xlfn.XLOOKUP(J2,Tab_Def_Processes[Name(EN)],Tab_Def_Processes[Process_ID],,0,) -> 01_Raw_ | M2: Yes | N2: Yes | O2: Yes | P2: 0 | Q2: Assumption | R2: 1 | S2: Assumption | T2: 0.5 | U2: Assumption | V2: =Tab_Def_Flows[[#This Row],[CC_DM'[%']]]*Tab_Def_Flows[[#This Row],[DM]] -> 0.5 | W2: Caclualtion
A3: TRUE | B3: 1 | C3: ="F_"&LEFT(I3,2)&"_"&LEFT(K3,2) -> F_01_02 | D3: Logs | H3: Raw Material Extraction | I3: =_xlfn.XLOOKUP(H3,Tab_Def_Processes[Name(EN)],Tab_Def_Processes[Process_ID],,0,) -> 01_Raw_ | J3: Processing | K3: =_xlfn.XLOOKUP(J3,Tab_Def_Processes[Name(EN)],Tab_Def_Processes[Process_ID],,0,) -> 02_Pro_ | M3: Yes | N3: Yes | O3: Yes | P3: 0 | Q3: Assumption | R3: 1 | S3: Assumption | T3: 0.5 | U3: Assumption | V3: =Tab_Def_Flows[[#This Row],[CC_DM'[%']]]*Tab_Def_Flows[[#This Row],[DM]] -> 0.5 | W3: Caclualtion
A4: TRUE | B4: 2 | C4: ="F_"&LEFT(I4,2)&"_"&LEFT(K4,2) -> F_01_00 | D4: Forestry Resiudes | H4: Raw Material Extraction | I4: =_xlfn.XLOOKUP(H4,Tab_Def_Processes[Name(EN)],Tab_Def_Processes[Process_ID],,0,) -> 01_Raw_ | J4: Biosphere | K4: =_xlfn.XLOOKUP(J4,Tab_Def_Processes[Name(EN)],Tab_Def_Processes[Process_ID],,0,) -> 00_Bio_ | M4: Yes | N4: Yes | O4: Yes | P4: 0 | Q4: Assumption | R4: 1 | S4: Assumption | T4: 0.5 | U4: Assumption | V4: 0.5 | W4: Caclualtion
A5: TRUE | B5: 3 | C5: ="F_"&LEFT(I5,2)&"_"&LEFT(K5,2) -> F_02_03 | D5: Timber Truss | H5: Processing | I5: =_xlfn.XLOOKUP(H5,Tab_Def_Processes[Name(EN)],Tab_Def_Processes[Process_ID],,0,) -> 02_Pro_ | J5: Use | K5: =_xlfn.XLOOKUP(J5,Tab_Def_Processes[Name(EN)],Tab_Def_Processes[Process_ID],,0,) -> 03_Use_ | M5: Yes | N5: Yes | O5: Yes | P5: 0 | Q5: Assumption | R5: 1 | S5: Assumption | T5: 0.5 | U5: Assumption | V5: =Tab_Def_Flows[[#This Row],[CC_DM'[%']]]*Tab_Def_Flows[[#This Row],[DM]] -> 0.5 | W5: Caclualtion
A6: TRUE | B6: 4 | C6: ="F_"&LEFT(I6,2)&"_"&LEFT(K6,2) -> F_03_04 | D6: Wood Beam for Reuse | H6: Use | I6: =_xlfn.XLOOKUP(H6,Tab_Def_Processes[Name(EN)],Tab_Def_Processes[Process_ID],,0,) -> 03_Use_ | J6: Refurbishment | K6: =_xlfn.XLOOKUP(J6,Tab_Def_Processes[Name(EN)],Tab_Def_Processes[Process_ID],,0,) -> 04_Ref_ | M6: Yes | N6: Yes | O6: Yes | P6: 0 | Q6: Assumption | R6: 1 | S6: Assumption | T6: 0.5 | U6: Assumption | V6: =Tab_Def_Flows[[#This Row],[CC_DM'[%']]]*Tab_Def_Flows[[#This Row],[DM]] -> 0.5 | W6: Caclualtion
A7: TRUE | B7: 5 | C7: ="F_"&LEFT(I7,2)&"_"&LEFT(K7,2) -> F_04_03 | D7: Refurbished wood | H7: Refurbishment | I7: =_xlfn.XLOOKUP(H7,Tab_Def_Processes[Name(EN)],Tab_Def_Processes[Process_ID],,0,) -> 04_Ref_ | J7: Use | K7: =_xlfn.XLOOKUP(J7,Tab_Def_Processes[Name(EN)],Tab_Def_Processes[Process_ID],,0,) -> 03_Use_ | M7: Yes | N7: Yes | O7: Yes | P7: 0 | Q7: Assumption | R7: 1 | S7: Assumption | T7: 0.5 | U7: Assumption | V7: =Tab_Def_Flows[[#This Row],[CC_DM'[%']]]*Tab_Def_Flows[[#This Row],[DM]] -> 0.5 | W7: Caclualtion
A8: TRUE | B8: 6 | C8: ="F_"&LEFT(I8,2)&"_"&LEFT(K8,2) -> F_03_05 | D8: Waste Wood | H8: Use | I8: =_xlfn.XLOOKUP(H8,Tab_Def_Processes[Name(EN)],Tab_Def_Processes[Process_ID],,0,) -> 03_Use_ | J8: Degredation | K8: =_xlfn.XLOOKUP(J8,Tab_Def_Processes[Name(EN)],Tab_Def_Processes[Process_ID],,0,) -> 05_Deg_ | M8: Yes | N8: Yes | O8: Yes | P8: 0 | Q8: Assumption | R8: 1 | S8: Assumption | T8: 0.5 | U8: Assumption | V8: =Tab_Def_Flows[[#This Row],[CC_DM'[%']]]*Tab_Def_Flows[[#This Row],[DM]] -> 0.5 | W8: Caclualtion
A9: TRUE | B9: 7 | C9: ="F_"&LEFT(I9,2)&"_"&LEFT(K9,2) -> F_03_06 | D9: Inc_Timber Truss | H9: Use | I9: =_xlfn.XLOOKUP(H9,Tab_Def_Processes[Name(EN)],Tab_Def_Processes[Process_ID],,0,) -> 03_Use_ | J9: Incineration | K9: =_xlfn.XLOOKUP(J9,Tab_Def_Processes[Name(EN)],Tab_Def_Processes[Process_ID],,0,) -> 06_Inc_ | M9: Yes | N9: Yes | O9: Yes | P9: 0 | Q9: Assumption | R9: 1 | S9: Assumption | T9: 0.5 | U9: Assumption | V9: =Tab_Def_Flows[[#This Row],[CC_DM'[%']]]*Tab_Def_Flows[[#This Row],[DM]] -> 0.5 | W9: Caclualtion
A10: TRUE | B10: 8 | C10: ="F_"&LEFT(I10,2)&"_"&LEFT(K10,2) -> F_05_07 | D10: Deg_Atm_Carbon | H10: Degredation | I10: =_xlfn.XLOOKUP(H10,Tab_Def_Processes[Name(EN)],Tab_Def_Processes[Process_ID],,0,) -> 05_Deg_ | J10: Atmosphere | K10: =_xlfn.XLOOKUP(J10,Tab_Def_Processes[Name(EN)],Tab_Def_Processes[Process_ID],,0,) -> 07_Atm_ | M10: Yes | N10: Yes | O10: Yes | P10: 0 | Q10: Assumption | R10: 1 | S10: Assumption | T10: 0.5 | U10: Assumption | V10: =Tab_Def_Flows[[#This Row],[CC_DM'[%']]]*Tab_Def_Flows[[#This Row],[DM]] -> 0.5 | W10: Caclualtion
A11: TRUE | B11: 9 | C11: ="F_"&LEFT(I11,2)&"_"&LEFT(K11,2) -> F_05_00 | D11: Deg_Bio | H11: Degredation | I11: =_xlfn.XLOOKUP(H11,Tab_Def_Processes[Name(EN)],Tab_Def_Processes[Process_ID],,0,) -> 05_Deg_ | J11: Biosphere | K11: =_xlfn.XLOOKUP(J11,Tab_Def_Processes[Name(EN)],Tab_Def_Processes[Process_ID],,0,) -> 00_Bio_ | M11: Yes | N11: Yes | O11: Yes | P11: 0 | Q11: Assumption | R11: 1 | S11: Assumption | T11: 0.5 | U11: Assumption | V11: =Tab_Def_Flows[[#This Row],[CC_DM'[%']]]*Tab_Def_Flows[[#This Row],[DM]] -> 0.5 | W11: Caclualtion
A12: TRUE | B12: 10 | C12: ="F_"&LEFT(I12,2)&"_"&LEFT(K12,2) -> F_06_07 | D12: Inc_Carbon_Atm | H12: Incineration | I12: =_xlfn.XLOOKUP(H12,Tab_Def_Processes[Name(EN)],Tab_Def_Processes[Process_ID],,0,) -> 06_Inc_ | J12: Atmosphere | K12: =_xlfn.XLOOKUP(J12,Tab_Def_Processes[Name(EN)],Tab_Def_Processes[Process_ID],,0,) -> 07_Atm_ | M12: Yes | N12: Yes | O12: Yes | P12: 0 | Q12: Assumption | R12: 1 | S12: Assumption | T12: 0.5 | U12: Assumption | V12: =Tab_Def_Flows[[#This Row],[CC_DM'[%']]]*Tab_Def_Flows[[#This Row],[DM]] -> 0.5 | W12: Caclualtion
A13: TRUE | B13: 11 | C13: ="F_"&LEFT(I13,2)&"_"&LEFT(K13,2) -> F_06_08 | D13: Inc_Ash_Ant | H13: Incineration | I13: =_xlfn.XLOOKUP(H13,Tab_Def_Processes[Name(EN)],Tab_Def_Processes[Process_ID],,0,) -> 06_Inc_ | J13: Anthroposphere | K13: =_xlfn.XLOOKUP(J13,Tab_Def_Processes[Name(EN)],Tab_Def_Processes[Process_ID],,0,) -> 08_Ant_ | M13: Yes | N13: Yes | O13: Yes | P13: 0 | Q13: Assumption | R13: 1 | S13: Assumption | T13: 0.5 | U13: Assumption | V13: =Tab_Def_Flows[[#This Row],[CC_DM'[%']]]*Tab_Def_Flows[[#This Row],[DM]] -> 0.5 | W13: Caclualtion
A14: TRUE | B14: 12 | C14: ="F_"&LEFT(I14,2)&"_"&LEFT(K14,2) -> F_02_08 | D14: Proc_Wood Cuttings | H14: Processing | I14: =_xlfn.XLOOKUP(H14,Tab_Def_Processes[Name(EN)],Tab_Def_Processes[Process_ID],,0,) -> 02_Pro_ | J14: Anthroposphere | K14: =_xlfn.XLOOKUP(J14,Tab_Def_Processes[Name(EN)],Tab_Def_Processes[Process_ID],,0,) -> 08_Ant_ | M14: Yes | N14: Yes | O14: Yes | P14: 0 | Q14: Assumption | R14: 1 | S14: Assumption | T14: 0.5 | U14: Assumption | V14: =Tab_Def_Flows[[#This Row],[CC_DM'[%']]]*Tab_Def_Flows[[#This Row],[DM]] -> 0.5 | W14: Caclualtion
A15: TRUE | B15: 13 | C15: ="F_"&LEFT(I15,2)&"_"&LEFT(K15,2) -> F_04_08 | D15: SecMaterial | H15: Refurbishment | I15: =_xlfn.XLOOKUP(H15,Tab_Def_Processes[Name(EN)],Tab_Def_Processes[Process_ID],,0,) -> 04_Ref_ | J15: Anthroposphere | K15: =_xlfn.XLOOKUP(J15,Tab_Def_Processes[Name(EN)],Tab_Def_Processes[Process_ID],,0,) -> 08_Ant_ | M15: Yes | N15: Yes | O15: Yes | P15: 0 | Q15: Assumption | R15: 1 | S15: Assumption | T15: 0.5 | U15: Assumption | V15: =Tab_Def_Flows[[#This Row],[CC_DM'[%']]]*Tab_Def_Flows[[#This Row],[DM]] -> 0.5 | W15: Caclualtion
A16: TRUE | B16: 14 | C16: ="F_"&LEFT(I16,2)&"_"&LEFT(K16,2) -> F_07_00 | D16: Atm_Bio | H16: Atmosphere | I16: =_xlfn.XLOOKUP(H16,Tab_Def_Processes[Name(EN)],Tab_Def_Processes[Process_ID],,0,) -> 07_Atm_ | J16: Biosphere | K16: =_xlfn.XLOOKUP(J16,Tab_Def_Processes[Name(EN)],Tab_Def_Processes[Process_ID],,0,) -> 00_Bio_ | M16: Yes | N16: Yes | O16: Yes | P16: 0 | Q16: Assumption | R16: 1 | S16: Assumption | T16: 0.5 | U16: Assumption | V16: =Tab_Def_Flows[[#This Row],[CC_DM'[%']]]*Tab_Def_Flows[[#This Row],[DM]] -> 0.5 | W16: Caclualtion

Sheet 2_1_Definition_Processes
A1: Complete? | B1: ID | C1: Process_ID | D1: Name(EN) | E1: Region | F1: Carbon_Stock | G1: Life_Phase | H1: Description | I1: Process_Type | J1: TC? | K1: Dyn_TC? | L1: Stock? | M1: Input_Flow_I_1 | N1: Flow_ID_I_1 | O1: Input_Flow_I_2 | P1: Flow_ID_I_2 | Q1: Input_Flow_I_3 | R1: Flow_ID_I_3 | S1: Input_Flow_I_4 | T1: Flow_ID_I_4 | U1: Input_Flow_I_5 | V1: Flow_ID_I_5 | W1: Output_Flow_O_1 | X1: Flow_ID_O_1 | Y1: Output_Flow_O_2 | Z1: Flow_ID_O_2 | AA1: Output_Flow_O_3 | AB1: Flow_ID_O_3
A2: TRUE | B2: 00 | C2: =LEFT(B2,2)&"_"&LEFT(D2,3)&"_"&LEFT(E2,3) -> 00_Bio_ | D2: Biosphere | I2: Process | J2: Yes | K2: Yes | L2: Yes | M2: N.A. | N2: =_xlfn.XLOOKUP(M2,Tab_Def_Flows[Name(EN)],Tab_Def_Flows[Flow_ID],,0,) -> #N/A | O2: N.A. | P2: =_xlfn.XLOOKUP(O2,Tab_Def_Flows[Name(EN)],Tab_Def_Flows[Flow_ID],,0,) -> #N/A | Q2: N.A. | R2: =_xlfn.XLOOKUP(Q2,Tab_Def_Flows[Name(EN)],Tab_Def_Flows[Flow_ID],,0,) -> #N/A | S2: N.A. | T2: =_xlfn.XLOOKUP(S2,Tab_Def_Flows[Name(EN)],Tab_Def_Flows[Flow_ID],,0,) -> #N/A | U2: N.A. | V2: =_xlfn.XLOOKUP(U2,Tab_Def_Flows[Name(EN)],Tab_Def_Flows[Flow_ID],,0,) -> #N/A | W2: Wood | X2: =_xlfn.XLOOKUP(W2,Tab_Def_Flows[Name(EN)],Tab_Def_Flows[Flow_ID],,0,) -> F_00_01 | Z2: =_xlfn.XLOOKUP(Y2,Tab_Def_Flows[Name(EN)],Tab_Def_Flows[Flow_ID],,0,) -> #N/A | AB2: =_xlfn.XLOOKUP(AA2,Tab_Def_Flows[Name(EN)],Tab_Def_Flows[Flow_ID],,0,) -> #N/A
A3: TRUE | B3: 01 | C3: =LEFT(B3,2)&"_"&LEFT(D3,3)&"_"&LEFT(E3,3) -> 01_Raw_ | D3: Raw Material Extraction | I3: Process | J3: Yes | K3: Yes | L3: No | M3: N.A. | N3: =_xlfn.XLOOKUP(M3,Tab_Def_Flows[Name(EN)],Tab_Def_Flows[Flow_ID],,0,) -> #N/A | O3: N.A. | P3: =_xlfn.XLOOKUP(O3,Tab_Def_Flows[Name(EN)],Tab_Def_Flows[Flow_ID],,0,) -> #N/A | Q3: N.A. | R3: =_xlfn.XLOOKUP(Q3,Tab_Def_Flows[Name(EN)],Tab_Def_Flows[Flow_ID],,0,) -> #N/A | S3: N.A. | T3: =_xlfn.XLOOKUP(S3,Tab_Def_Flows[Name(EN)],Tab_Def_Flows[Flow_ID],,0,) -> #N/A | U3: N.A. | V3: =_xlfn.XLOOKUP(U3,Tab_Def_Flows[Name(EN)],Tab_Def_Flows[Flow_ID],,0,) -> #N/A | W3: Logs | X3: =_xlfn.XLOOKUP(W3,Tab_Def_Flows[Name(EN)],Tab_Def_Flows[Flow_ID],,0,) -> F_01_02 | Y3: Forestry Resiudes | Z3: =_xlfn.XLOOKUP(Y3,Tab_Def_Flows[Name(EN)],Tab_Def_Flows[Flow_ID],,0,) -> F_01_00 | AB3: =_xlfn.XLOOKUP(AA3,Tab_Def_Flows[Name(EN)],Tab_Def_Flows[Flow_ID],,0,) -> #N/A
A4: TRUE | B4: 02 | C4: =LEFT(B4,2)&"_"&LEFT(D4,3)&"_"&LEFT(E4,3) -> 02_Pro_ | D4: Processing | I4: Process | J4: Yes | K4: Yes | L4: Yes | M4: N.A. | N4: =_xlfn.XLOOKUP(M4,Tab_Def_Flows[Name(EN)],Tab_Def_Flows[Flow_ID],,0,) -> #N/A | O4: N.A. | P4: =_xlfn.XLOOKUP(O4,Tab_Def_Flows[Name(EN)],Tab_Def_Flows[Flow_ID],,0,) -> #N/A | Q4: N.A. | R4: =_xlfn.XLOOKUP(Q4,Tab_Def_Flows[Name(EN)],Tab_Def_Flows[Flow_ID],,0,) -> #N/A | S4: N.A. | T4: =_xlfn.XLOOKUP(S4,Tab_Def_Flows[Name(EN)],Tab_Def_Flows[Flow_ID],,0,) -> #N/A | U4: N.A. | V4: =_xlfn.XLOOKUP(U4,Tab_Def_Flows[Name(EN)],Tab_Def_Flows[Flow_ID],,0,) -> #N/A | W4: Timber Truss | X4: =_xlfn.XLOOKUP(W4,Tab_Def_Flows[Name(EN)],Tab_Def_Flows[Flow_ID],,0,) -> F_02_03 | Y4: Proc_Wood Cuttings | Z4: =_xlfn.XLOOKUP(Y4,Tab_Def_Flows[Name(EN)],Tab_Def_Flows[Flow_ID],,0,) -> F_02_08 | AB4: =_xlfn.XLOOKUP(AA4,Tab_Def_Flows[Name(EN)],Tab_Def_Flows[Flow_ID],,0,) -> #N/A
A5: TRUE | B5: 03 | C5: =LEFT(B5,2)&"_"&LEFT(D5,3)&"_"&LEFT(E5,3) -> 03_Use_ | D5: Use | I5: Process | J5: Yes | K5: Yes | L5: Yes | M5: N.A. | N5: =_xlfn.XLOOKUP(M5,Tab_Def_Flows[Name(EN)],Tab_Def_Flows[Flow_ID],,0,) -> #N/A | O5: N.A. | P5: =_xlfn.XLOOKUP(O5,Tab_Def_Flows[Name(EN)],Tab_Def_Flows[Flow_ID],,0,) -> #N/A | Q5: N.A. | R5: =_xlfn.XLOOKUP(Q5,Tab_Def_Flows[Name(EN)],Tab_Def_Flows[Flow_ID],,0,) -> #N/A | S5: N.A. | T5: =_xlfn.XLOOKUP(S5,Tab_Def_Flows[Name(EN)],Tab_Def_Flows[Flow_ID],,0,) -> #N/A | U5: N.A. | V5: =_xlfn.XLOOKUP(U5,Tab_Def_Flows[Name(EN)],Tab_Def_Flows[Flow_ID],,0,) -> #N/A | W5: Inc_Timber Truss | X5: =_xlfn.XLOOKUP(W5,Tab_Def_Flows[Name(EN)],Tab_Def_Flows[Flow_ID],,0,) -> F_03_06 | Y5: Wood Beam for Reuse | Z5: =_xlfn.XLOOKUP(Y5,Tab_Def_Flows[Name(EN)],Tab_Def_Flows[Flow_ID],,0,) -> F_03_04 | AA5: Waste Wood | AB5: =_xlfn.XLOOKUP(AA5,Tab_Def_Flows[Name(EN)],Tab_Def_Flows[Flow_ID],,0,) -> F_03_05
A6: TRUE | B6: 04 | C6: =LEFT(B6,2)&"_"&LEFT(D6,3)&"_"&LEFT(E6,3) -> 04_Ref_ | D6: Refurbishment | I6: Process | J6: Yes | K6: No | L6: No | M6: N.A. | N6: =_xlfn.XLOOKUP(M6,Tab_Def_Flows[Name(EN)],Tab_Def_Flows[Flow_ID],,0,) -> #N/A | O6: N.A. | P6: =_xlfn.XLOOKUP(O6,Tab_Def_Flows[Name(EN)],Tab_Def_Flows[Flow_ID],,0,) -> #N/A | Q6: N.A. | R6: =_xlfn.XLOOKUP(Q6,Tab_Def_Flows[Name(EN)],Tab_Def_Flows[Flow_ID],,0,) -> #N/A | S6: N.A. | T6: =_xlfn.XLOOKUP(S6,Tab_Def_Flows[Name(EN)],Tab_Def_Flows[Flow_ID],,0,) -> #N/A | U6: N.A. | V6: =_xlfn.XLOOKUP(U6,Tab_Def_Flows[Name(EN)],Tab_Def_Flows[Flow_ID],,0,) -> #N/A | W6: Refurbished wood | X6: =_xlfn.XLOOKUP(W6,Tab_Def_Flows[Name(EN)],Tab_Def_Flows[Flow_ID],,0,) -> F_04_03 | Y6: SecMaterial | Z6: =_xlfn.XLOOKUP(Y6,Tab_Def_Flows[Name(EN)],Tab_Def_Flows[Flow_ID],,0,) -> F_04_08 | AB6: =_xlfn.XLOOKUP(AA6,Tab_Def_Flows[Name(EN)],Tab_Def_Flows[Flow_ID],,0,) -> #N/A
A7: TRUE | B7: 05 | C7: =LEFT(B7,2)&"_"&LEFT(D7,3)&"_"&LEFT(E7,3) -> 05_Deg_ | D7: Degredation | I7: Process | J7: Yes | K7: No | L7: No | M7: N.A. | N7: =_xlfn.XLOOKUP(M7,Tab_Def_Flows[Name(EN)],Tab_Def_Flows[Flow_ID],,0,) -> #N/A | O7: N.A. | P7: =_xlfn.XLOOKUP(O7,Tab_Def_Flows[Name(EN)],Tab_Def_Flows[Flow_ID],,0,) -> #N/A | Q7: N.A. | R7: =_xlfn.XLOOKUP(Q7,Tab_Def_Flows[Name(EN)],Tab_Def_Flows[Flow_ID],,0,) -> #N/A | S7: N.A. | T7: =_xlfn.XLOOKUP(S7,Tab_Def_Flows[Name(EN)],Tab_Def_Flows[Flow_ID],,0,) -> #N/A | U7: N.A. | V7: =_xlfn.XLOOKUP(U7,Tab_Def_Flows[Name(EN)],Tab_Def_Flows[Flow_ID],,0,) -> #N/A | W7: Deg_Atm_Carbon | X7: =_xlfn.XLOOKUP(W7,Tab_Def_Flows[Name(EN)],Tab_Def_Flows[Flow_ID],,0,) -> F_05_07 | Y7: Deg_Bio | Z7: =_xlfn.XLOOKUP(Y7,Tab_Def_Flows[Name(EN)],Tab_Def_Flows[Flow_ID],,0,) -> F_05_00 | AB7: =_xlfn.XLOOKUP(AA7,Tab_Def_Flows[Name(EN)],Tab_Def_Flows[Flow_ID],,0,) -> #N/A
A8: TRUE | B8: 06 | C8: =LEFT(B8,2)&"_"&LEFT(D8,3)&"_"&LEFT(E8,3) -> 06_Inc_ | D8: Incineration | I8: Process | J8: Yes | K8: No | L8: No | M8: N.A. | N8: =_xlfn.XLOOKUP(M8,Tab_Def_Flows[Name(EN)],Tab_Def_Flows[Flow_ID],,0,) -> #N/A | O8: N.A. | P8: =_xlfn.XLOOKUP(O8,Tab_Def_Flows[Name(EN)],Tab_Def_Flows[Flow_ID],,0,) -> #N/A | Q8: N.A. | R8: =_xlfn.XLOOKUP(Q8,Tab_Def_Flows[Name(EN)],Tab_Def_Flows[Flow_ID],,0,) -> #N/A | S8: N.A. | T8: =_xlfn.XLOOKUP(S8,Tab_Def_Flows[Name(EN)],Tab_Def_Flows[Flow_ID],,0,) -> #N/A | U8: N.A. | V8: =_xlfn.XLOOKUP(U8,Tab_Def_Flows[Name(EN)],Tab_Def_Flows[Flow_ID],,0,) -> #N/A | W8: Inc_Ash_Ant | X8: =_xlfn.XLOOKUP(W8,Tab_Def_Flows[Name(EN)],Tab_Def_Flows[Flow_ID],,0,) -> F_06_08 | Y8: Inc_Carbon_Atm | Z8: =_xlfn.XLOOKUP(Y8,Tab_Def_Flows[Name(EN)],Tab_Def_Flows[Flow_ID],,0,) -> F_06_07 | AB8: =_xlfn.XLOOKUP(AA8,Tab_Def_Flows[Name(EN)],Tab_Def_Flows[Flow_ID],,0,) -> #N/A
A9: TRUE | B9: 07 | C9: =LEFT(B9,2)&"_"&LEFT(D9,3)&"_"&LEFT(E9,3) -> 07_Atm_ | D9: Atmosphere | I9: Process | J9: No | K9: No | L9: Yes | M9: N.A. | N9: =_xlfn.XLOOKUP(M9,Tab_Def_Flows[Name(EN)],Tab_Def_Flows[Flow_ID],,0,) -> #N/A | O9: N.A. | P9: =_xlfn.XLOOKUP(O9,Tab_Def_Flows[Name(EN)],Tab_Def_Flows[Flow_ID],,0,) -> #N/A | Q9: N.A. | R9: =_xlfn.XLOOKUP(Q9,Tab_Def_Flows[Name(EN)],Tab_Def_Flows[Flow_ID],,0,) -> #N/A | S9: N.A. | T9: =_xlfn.XLOOKUP(S9,Tab_Def_Flows[Name(EN)],Tab_Def_Flows[Flow_ID],,0,) -> #N/A | U9: N.A. | V9: =_xlfn.XLOOKUP(U9,Tab_Def_Flows[Name(EN)],Tab_Def_Flows[Flow_ID],,0,) -> #N/A | W9: Atm_Bio | X9: =_xlfn.XLOOKUP(W9,Tab_Def_Flows[Name(EN)],Tab_Def_Flows[Flow_ID],,0,) -> F_07_00 | Z9: =_xlfn.XLOOKUP(Y9,Tab_Def_Flows[Name(EN)],Tab_Def_Flows[Flow_ID],,0,) -> #N/A | AB9: =_xlfn.XLOOKUP(AA9,Tab_Def_Flows[Name(EN)],Tab_Def_Flows[Flow_ID],,0,) -> #N/A
A10: TRUE | B10: 08 | C10: =LEFT(B10,2)&"_"&LEFT(D10,3)&"_"&LEFT(E10,3) -> 08_Ant_ | D10: Anthroposphere | I10: Process | J10: No | K10: No | L10: Yes | M10: N.A. | N10: =_xlfn.XLOOKUP(M10,Tab_Def_Flows[Name(EN)],Tab_Def_Flows[Flow_ID],,0,) -> #N/A | O10: N.A. | P10: =_xlfn.XLOOKUP(O10,Tab_Def_Flows[Name(EN)],Tab_Def_Flows[Flow_ID],,0,) -> #N/A | Q10: N.A. | R10: =_xlfn.XLOOKUP(Q10,Tab_Def_Flows[Name(EN)],Tab_Def_Flows[Flow_ID],,0,) -> #N/A | S10: N.A. | T10: =_xlfn.XLOOKUP(S10,Tab_Def_Flows[Name(EN)],Tab_Def_Flows[Flow_ID],,0,) -> #N/A | U10: N.A. | V10: =_xlfn.XLOOKUP(U10,Tab_Def_Flows[Name(EN)],Tab_Def_Flows[Flow_ID],,0,) -> #N/A | X10: =_xlfn.XLOOKUP(W10,Tab_Def_Flows[Name(EN)],Tab_Def_Flows[Flow_ID],,0,) -> #N/A | Z10: =_xlfn.XLOOKUP(Y10,Tab_Def_Flows[Name(EN)],Tab_Def_Flows[Flow_ID],,0,) -> #N/A | AB10: =_xlfn.XLOOKUP(AA10,Tab_Def_Flows[Name(EN)],Tab_Def_Flows[Flow_ID],,0,) -> #N/A

Sheet 1_2_Data_Flows
A1: ID | B1: Flow_ID | C1: Name(EN) | D1: Type_Biomass | E1: Output_Process | F1: Process_ID_O | G1: Input_Process | H1: Process_ID_I | I1: TC? | J1: WC? | K1: DM? | L1: CC? | M1: Year_Flow | N1: Region_Flow | O1: Flow_Source | P1: UoM_Source | Q1: Name_Source | R1: AVV | S1: Titel_Source | T1: Year_Source | U1: Author_Source | V1: Type_Source | W1: URL | X1: CF_required? | Y1: CF | Z1: Name_CF | AA1: Flow_Py | AB1: UoM_Flow_Py | AC1: WC_[%] | AD1: WC_Flow_Py | AE1: UoM_WC_Flow_Py | AF1: DM_[%] | AG1: DM_Flow_Py2 | AH1: UoM_DM_Flow_Py | AI1: CC_[%] | AJ1: CC_Flow_Py | AK1: UoM_CC_Flow_Py
A2: =ROW()-1 -> 1 | B2: =_xlfn.XLOOKUP(C2,Tab_Def_Flows[Name(EN)],Tab_Def_Flows[Flow_ID],,0,) -> F_00_01 | C2: Wood | D2: =_xlfn.XLOOKUP(C2,Tab_Def_Flows[Name(EN)],Tab_Def_Flows[Type_Biomass],,0,) -> 0 | E2: =_xlfn.XLOOKUP(C2,Tab_Def_Flows[Name(EN)],Tab_Def_Flows[Output_Process],,0,) -> Biosphere | F2: =_xlfn.XLOOKUP(C2,Tab_Def_Flows[Name(EN)],Tab_Def_Flows[Process_ID_O],,0,) -> 00_Bio_ | G2: =_xlfn.XLOOKUP(C2,Tab_Def_Flows[Name(EN)],Tab_Def_Flows[Input_Process],,0,) -> Raw Material Extraction | H2: =_xlfn.XLOOKUP(C2,Tab_Def_Flows[Name(EN)],Tab_Def_Flows[Process_ID_I],,0,) -> 01_Raw_ | I2: =_xlfn.XLOOKUP(C2,Tab_Def_Flows[Name(EN)],Tab_Def_Flows[Value_Source],,0,) -> 0 | J2: =_xlfn.XLOOKUP(C2,Tab_Def_Flows[Name(EN)],Tab_Def_Flows[WC?],,0,) -> Yes | K2: =_xlfn.XLOOKUP(C2,Tab_Def_Flows[Name(EN)],Tab_Def_Flows[DM?],,0,) -> Yes | L2: =_xlfn.XLOOKUP(C2,Tab_Def_Flows[Name(EN)],Tab_Def_Flows[CC?],,0,) -> Yes | M2: 1920 | N2: BB | O2: 1857.6 | P2: Mg | Q2: Stramento | X2: No | AA2: =IF(X2="no",O2,O2*Y2) -> 1857.6 | AB2: Mg | AC2: =INDEX(Tab_Def_Flows[[Flow_ID]:[CC_DM_source]],MATCH(Tab_Data_Flows[[#This Row],[Name(EN)]],Tab_Def_Flows[Name(EN)],0),14) -> 0 | AD2: =IF(J2="Yes",AA2*Tab_Data_Flows[[#This Row],[WC_'[%']]],"N.A.") -> 0 | AE2: =Tab_Data_Flows[[#This Row],[UoM_Flow_Py]] -> Mg | AF2: =INDEX(Tab_Def_Flows[[Flow_ID]:[CC_DM_source]],MATCH(Tab_Data_Flows[[#This Row],[Name(EN)]],Tab_Def_Flows[Name(EN)],0),16) -> 1 | AG2: =IF(K2="Yes",AF2*Tab_Data_Flows[[#This Row],[Flow_Py]],"N.A.") -> 1857.6 | AH2: =Tab_Data_Flows[[#This Row],[UoM_Flow_Py]] -> Mg | AI2: =INDEX(Tab_Def_Flows[[Flow_ID]:[CC_DM_source]],MATCH(Tab_Data_Flows[[#This Row],[Name(EN)]],Tab_Def_Flows[Name(EN)],0),18) -> 0.5 | AJ2: =IF(L2="Yes",AI2*Tab_Data_Flows[[#This Row],[Flow_Py]]*Tab_Data_Flows[[#This Row],[DM_'[%']]],"N.A.") -> 928.8 | AK2: =Tab_Data_Flows[[#This Row],[UoM_Flow_Py]] -> Mg
A3: =ROW()-1 -> 2 | B3: =_xlfn.XLOOKUP(C3,Tab_Def_Flows[Name(EN)],Tab_Def_Flows[Flow_ID],,0,) -> F_00_01 | C3: Wood | D3: =_xlfn.XLOOKUP(C3,Tab_Def_Flows[Name(EN)],Tab_Def_Flows[Type_Biomass],,0,) -> 0 | E3: =_xlfn.XLOOKUP(C3,Tab_Def_Flows[Name(EN)],Tab_Def_Flows[Output_Process],,0,) -> Biosphere | F3: =_xlfn.XLOOKUP(C3,Tab_Def_Flows[Name(EN)],Tab_Def_Flows[Process_ID_O],,0,) -> 00_Bio_ | G3: =_xlfn.XLOOKUP(C3,Tab_Def_Flows[Name(EN)],Tab_Def_Flows[Input_Process],,0,) -> Raw Material Extraction | H3: =_xlfn.XLOOKUP(C3,Tab_Def_Flows[Name(EN)],Tab_Def_Flows[Process_ID_I],,0,) -> 01_Raw_ | I3: =_xlfn.XLOOKUP(C3,Tab_Def_Flows[Name(EN)],Tab_Def_Flows[Value_Source],,0,) -> 0 | J3: =_xlfn.XLOOKUP(C3,Tab_Def_Flows[Name(EN)],Tab_Def_Flows[WC?],,0,) -> Yes | K3: =_xlfn.XLOOKUP(C3,Tab_Def_Flows[Name(EN)],Tab_Def_Flows[DM?],,0,) -> Yes | L3: =_xlfn.XLOOKUP(C3,Tab_Def_Flows[Name(EN)],Tab_Def_Flows[CC?],,0,) -> Yes | M3: 1921 | O3: 173.6 | P3: Mg | Q3: Stramento | X3: No | AA3: =IF(X3="no",O3,O3*Y3) -> 173.6 | AB3: Mg | AC3: =INDEX(Tab_Def_Flows[[Flow_ID]:[CC_DM_source]],MATCH(Tab_Data_Flows[[#This Row],[Name(EN)]],Tab_Def_Flows[Name(EN)],0),14) -> 0 | AD3: =IF(J3="Yes",AA3*Tab_Data_Flows[[#This Row],[WC_'[%']]],"N.A.") -> 0 | AE3: =Tab_Data_Flows[[#This Row],[UoM_Flow_Py]] -> Mg | AF3: =INDEX(Tab_Def_Flows[[Flow_ID]:[CC_DM_source]],MATCH(Tab_Data_Flows[[#This Row],[Name(EN)]],Tab_Def_Flows[Name(EN)],0),16) -> 1 | AG3: =IF(K3="Yes",AF3*Tab_Data_Flows[[#This Row],[Flow_Py]],"N.A.") -> 173.6 | AH3: =Tab_Data_Flows[[#This Row],[UoM_Flow_Py]] -> Mg | AI3: =INDEX(Tab_Def_Flows[[Flow_ID]:[CC_DM_source]],MATCH(Tab_Data_Flows[[#This Row],[Name(EN)]],Tab_Def_Flows[Name(EN)],0),18) -> 0.5 | AJ3: =IF(L3="Yes",AI3*Tab_Data_Flows[[#This Row],[Flow_Py]]*Tab_Data_Flows[[#This Row],[DM_'[%']]],"N.A.") -> 86.8 | AK3: =Tab_Data_Flows[[#This Row],[UoM_Flow_Py]] -> Mg
A4: =ROW()-1 -> 3 | B4: =_xlfn.XLOOKUP(C4,Tab_Def_Flows[Name(EN)],Tab_Def_Flows[Flow_ID],,0,) -> F_00_01 | C4: Wood | D4: =_xlfn.XLOOKUP(C4,Tab_Def_Flows[Name(EN)],Tab_Def_Flows[Type_Biomass],,0,) -> 0 | E4: =_xlfn.XLOOKUP(C4,Tab_Def_Flows[Name(EN)],Tab_Def_Flows[Output_Process],,0,) -> Biosphere | F4: =_xlfn.XLOOKUP(C4,Tab_Def_Flows[Name(EN)],Tab_Def_Flows[Process_ID_O],,0,) -> 00_Bio_ | G4: =_xlfn.XLOOKUP(C4,Tab_Def_Flows[Name(EN)],Tab_Def_Flows[Input_Process],,0,) -> Raw Material Extraction | H4: =_xlfn.XLOOKUP(C4,Tab_Def_Flows[Name(EN)],Tab_Def_Flows[Process_ID_I],,0,) -> 01_Raw_ | I4: =_xlfn.XLOOKUP(C4,Tab_Def_Flows[Name(EN)],Tab_Def_Flows[Value_Source],,0,) -> 0 | J4: =_xlfn.XLOOKUP(C4,Tab_Def_Flows[Name(EN)],Tab_Def_Flows[WC?],,0,) -> Yes | K4: =_xlfn.XLOOKUP(C4,Tab_Def_Flows[Name(EN)],Tab_Def_Flows[DM?],,0,) -> Yes | L4: =_xlfn.XLOOKUP(C4,Tab_Def_Flows[Name(EN)],Tab_Def_Flows[CC?],,0,) -> Yes | M4: 1922 | O4: 186.4 | P4: Mg | Q4: Stramento | X4: No | AA4: =IF(X4="no",O4,O4*Y4) -> 186.4 | AB4: Mg | AC4: =INDEX(Tab_Def_Flows[[Flow_ID]:[CC_DM_source]],MATCH(Tab_Data_Flows[[#This Row],[Name(EN)]],Tab_Def_Flows[Name(EN)],0),14) -> 0 | AD4: =IF(J4="Yes",AA4*Tab_Data_Flows[[#This Row],[WC_'[%']]],"N.A.") -> 0 | AE4: =Tab_Data_Flows[[#This Row],[UoM_Flow_Py]] -> Mg | AF4: =INDEX(Tab_Def_Flows[[Flow_ID]:[CC_DM_source]],MATCH(Tab_Data_Flows[[#This Row],[Name(EN)]],Tab_Def_Flows[Name(EN)],0),16) -> 1 | AG4: =IF(K4="Yes",AF4*Tab_Data_Flows[[#This Row],[Flow_Py]],"N.A.") -> 186.4 | AH4: =Tab_Data_Flows[[#This Row],[UoM_Flow_Py]] -> Mg | AI4: =INDEX(Tab_Def_Flows[[Flow_ID]:[CC_DM_source]],MATCH(Tab_Data_Flows[[#This Row],[Name(EN)]],Tab_Def_Flows[Name(EN)],0),18) -> 0.5 | AJ4: =IF(L4="Yes",AI4*Tab_Data_Flows[[#This Row],[Flow_Py]]*Tab_Data_Flows[[#This Row],[DM_'[%']]],"N.A.") -> 93.2 | AK4: =Tab_Data_Flows[[#This Row],[UoM_Flow_Py]] -> Mg
A5: =ROW()-1 -> 4 | B5: =_xlfn.XLOOKUP(C5,Tab_Def_Flows[Name(EN)],Tab_Def_Flows[Flow_ID],,0,) -> F_00_01 | C5: Wood | D5: =_xlfn.XLOOKUP(C5,Tab_Def_Flows[Name(EN)],Tab_Def_Flows[Type_Biomass],,0,) -> 0 | E5: =_xlfn.XLOOKUP(C5,Tab_Def_Flows[Name(EN)],Tab_Def_Flows[Output_Process],,0,) -> Biosphere | F5: =_xlfn.XLOOKUP(C5,Tab_Def_Flows[Name(EN)],Tab_Def_Flows[Process_ID_O],,0,) -> 00_Bio_ | G5: =_xlfn.XLOOKUP(C5,Tab_Def_Flows[Name(EN)],Tab_Def_Flows[Input_Process],,0,) -> Raw Material Extraction | H5: =_xlfn.XLOOKUP(C5,Tab_Def_Flows[Name(EN)],Tab_Def_Flows[Process_ID_I],,0,) -> 01_Raw_ | I5: =_xlfn.XLOOKUP(C5,Tab_Def_Flows[Name(EN)],Tab_Def_Flows[Value_Source],,0,) -> 0 | J5: =_xlfn.XLOOKUP(C5,Tab_Def_Flows[Name(EN)],Tab_Def_Flows[WC?],,0,) -> Yes | K5: =_xlfn.XLOOKUP(C5,Tab_Def_Flows[Name(EN)],Tab_Def_Flows[DM?],,0,) -> Yes | L5: =_xlfn.XLOOKUP(C5,Tab_Def_Flows[Name(EN)],Tab_Def_Flows[CC?],,0,) -> Yes | M5: 1923 | O5: 173.6 | P5: Mg | Q5: Stramento | X5: No | AA5: =IF(X5="no",O5,O5*Y5) -> 173.6 | AB5: Mg | AC5: =INDEX(Tab_Def_Flows[[Flow_ID]:[CC_DM_source]],MATCH(Tab_Data_Flows[[#This Row],[Name(EN)]],Tab_Def_Flows[Name(EN)],0),14) -> 0 | AD5: =IF(J5="Yes",AA5*Tab_Data_Flows[[#This Row],[WC_'[%']]],"N.A.") -> 0 | AE5: =Tab_Data_Flows[[#This Row],[UoM_Flow_Py]] -> Mg | AF5: =INDEX(Tab_Def_Flows[[Flow_ID]:[CC_DM_source]],MATCH(Tab_Data_Flows[[#This Row],[Name(EN)]],Tab_Def_Flows[Name(EN)],0),16) -> 1 | AG5: =IF(K5="Yes",AF5*Tab_Data_Flows[[#This Row],[Flow_Py]],"N.A.") -> 173.6 | AH5: =Tab_Data_Flows[[#This Row],[UoM_Flow_Py]] -> Mg | AI5: =INDEX(Tab_Def_Flows[[Flow_ID]:[CC_DM_source]],MATCH(Tab_Data_Flows[[#This Row],[Name(EN)]],Tab_Def_Flows[Name(EN)],0),18) -> 0.5 | AJ5: =IF(L5="Yes",AI5*Tab_Data_Flows[[#This Row],[Flow_Py]]*Tab_Data_Flows[[#This Row],[DM_'[%']]],"N.A.") -> 86.8 | AK5: =Tab_Data_Flows[[#This Row],[UoM_Flow_Py]] -> Mg
A6: =ROW()-1 -> 5 | B6: =_xlfn.XLOOKUP(C6,Tab_Def_Flows[Name(EN)],Tab_Def_Flows[Flow_ID],,0,) -> F_00_01 | C6: Wood | D6: =_xlfn.XLOOKUP(C6,Tab_Def_Flows[Name(EN)],Tab_Def_Flows[Type_Biomass],,0,) -> 0 | E6: =_xlfn.XLOOKUP(C6,Tab_Def_Flows[Name(EN)],Tab_Def_Flows[Output_Process],,0,) -> Biosphere | F6: =_xlfn.XLOOKUP(C6,Tab_Def_Flows[Name(EN)],Tab_Def_Flows[Process_ID_O],,0,) -> 00_Bio_ | G6: =_xlfn.XLOOKUP(C6,Tab_Def_Flows[Name(EN)],Tab_Def_Flows[Input_Process],,0,) -> Raw Material Extraction | H6: =_xlfn.XLOOKUP(C6,Tab_Def_Flows[Name(EN)],Tab_Def_Flows[Process_ID_I],,0,) -> 01_Raw_ | I6: =_xlfn.XLOOKUP(C6,Tab_Def_Flows[Name(EN)],Tab_Def_Flows[Value_Source],,0,) -> 0 | J6: =_xlfn.XLOOKUP(C6,Tab_Def_Flows[Name(EN)],Tab_Def_Flows[WC?],,0,) -> Yes | K6: =_xlfn.XLOOKUP(C6,Tab_Def_Flows[Name(EN)],Tab_Def_Flows[DM?],,0,) -> Yes | L6: =_xlfn.XLOOKUP(C6,Tab_Def_Flows[Name(EN)],Tab_Def_Flows[CC?],,0,) -> Yes | M6: 1924 | O6: 115.8 | P6: Mg | Q6: Stramento | X6: No | AA6: =IF(X6="no",O6,O6*Y6) -> 115.8 | AB6: Mg | AC6: =INDEX(Tab_Def_Flows[[Flow_ID]:[CC_DM_source]],MATCH(Tab_Data_Flows[[#This Row],[Name(EN)]],Tab_Def_Flows[Name(EN)],0),14) -> 0 | AD6: =IF(J6="Yes",AA6*Tab_Data_Flows[[#This Row],[WC_'[%']]],"N.A.") -> 0 | AE6: =Tab_Data_Flows[[#This Row],[UoM_Flow_Py]] -> Mg | AF6: =INDEX(Tab_Def_Flows[[Flow_ID]:[CC_DM_source]],MATCH(Tab_Data_Flows[[#This Row],[Name(EN)]],Tab_Def_Flows[Name(EN)],0),16) -> 1 | AG6: =IF(K6="Yes",AF6*Tab_Data_Flows[[#This Row],[Flow_Py]],"N.A.") -> 115.8 | AH6: =Tab_Data_Flows[[#This Row],[UoM_Flow_Py]] -> Mg | AI6: =INDEX(Tab_Def_Flows[[Flow_ID]:[CC_DM_source]],MATCH(Tab_Data_Flows[[#This Row],[Name(EN)]],Tab_Def_Flows[Name(EN)],0),18) -> 0.5 | AJ6: =IF(L6="Yes",AI6*Tab_Data_Flows[[#This Row],[Flow_Py]]*Tab_Data_Flows[[#This Row],[DM_'[%']]],"N.A.") -> 57.9 | AK6: =Tab_Data_Flows[[#This Row],[UoM_Flow_Py]] -> Mg
A7: =ROW()-1 -> 6 | B7: =_xlfn.XLOOKUP(C7,Tab_Def_Flows[Name(EN)],Tab_Def_Flows[Flow_ID],,0,) -> F_00_01 | C7: Wood | D7: =_xlfn.XLOOKUP(C7,Tab_Def_Flows[Name(EN)],Tab_Def_Flows[Type_Biomass],,0,) -> 0 | E7: =_xlfn.XLOOKUP(C7,Tab_Def_Flows[Name(EN)],Tab_Def_Flows[Output_Process],,0,) -> Biosphere | F7: =_xlfn.XLOOKUP(C7,Tab_Def_Flows[Name(EN)],Tab_Def_Flows[Process_ID_O],,0,) -> 00_Bio_ | G7: =_xlfn.XLOOKUP(C7,Tab_Def_Flows[Name(EN)],Tab_Def_Flows[Input_Process],,0,) -> Raw Material Extraction | H7: =_xlfn.XLOOKUP(C7,Tab_Def_Flows[Name(EN)],Tab_Def_Flows[Process_ID_I],,0,) -> 01_Raw_ | I7: =_xlfn.XLOOKUP(C7,Tab_Def_Flows[Name(EN)],Tab_Def_Flows[Value_Source],,0,) -> 0 | J7: =_xlfn.XLOOKUP(C7,Tab_Def_Flows[Name(EN)],Tab_Def_Flows[WC?],,0,) -> Yes | K7: =_xlfn.XLOOKUP(C7,Tab_Def_Flows[Name(EN)],Tab_Def_Flows[DM?],,0,) -> Yes | L7: =_xlfn.XLOOKUP(C7,Tab_Def_Flows[Name(EN)],Tab_Def_Flows[CC?],,0,) -> Yes | M7: 1925 | O7: 147.8 | P7: Mg | R7: =INDEX(Tab_WC_DM_CC[[Flow_ID]:[CC_source]],MATCH(Tab_Data_Flows[[#This Row],[Name(EN)]],Tab_WC_DM_CC[Name(EN)],0),12) -> #N/A | S7: =MATCH(Tab_Data_Flows[[#This Row],[Name(EN)]],Tab_WC_DM_CC[Name(EN)],0) -> #N/A | X7: No | AA7: =IF(X7="no",O7,O7*Y7) -> 147.8 | AB7: Mg | AC7: =INDEX(Tab_Def_Flows[[Flow_ID]:[CC_DM_source]],MATCH(Tab_Data_Flows[[#This Row],[Name(EN)]],Tab_Def_Flows[Name(EN)],0),14) -> 0 | AD7: =IF(J7="Yes",AA7*Tab_Data_Flows[[#This Row],[WC_'[%']]],"N.A.") -> 0 | AE7: =Tab_Data_Flows[[#This Row],[UoM_Flow_Py]] -> Mg | AF7: =INDEX(Tab_Def_Flows[[Flow_ID]:[CC_DM_source]],MATCH(Tab_Data_Flows[[#This Row],[Name(EN)]],Tab_Def_Flows[Name(EN)],0),16) -> 1 | AG7: =IF(K7="Yes",AF7*Tab_Data_Flows[[#This Row],[Flow_Py]],"N.A.") -> 147.8 | AH7: =Tab_Data_Flows[[#This Row],[UoM_Flow_Py]] -> Mg | AI7: =INDEX(Tab_Def_Flows[[Flow_ID]:[CC_DM_source]],MATCH(Tab_Data_Flows[[#This Row],[Name(EN)]],Tab_Def_Flows[Name(EN)],0),18) -> 0.5 | AJ7: =IF(L7="Yes",AI7*Tab_Data_Flows[[#This Row],[Flow_Py]]*Tab_Data_Flows[[#This Row],[DM_'[%']]],"N.A.") -> 73.9 | AK7: =Tab_Data_Flows[[#This Row],[UoM_Flow_Py]] -> Mg
A8: =ROW()-1 -> 7 | B8: =_xlfn.XLOOKUP(C8,Tab_Def_Flows[Name(EN)],Tab_Def_Flows[Flow_ID],,0,) -> F_00_01 | C8: Wood | D8: =_xlfn.XLOOKUP(C8,Tab_Def_Flows[Name(EN)],Tab_Def_Flows[Type_Biomass],,0,) -> 0 | E8: =_xlfn.XLOOKUP(C8,Tab_Def_Flows[Name(EN)],Tab_Def_Flows[Output_Process],,0,) -> Biosphere | F8: =_xlfn.XLOOKUP(C8,Tab_Def_Flows[Name(EN)],Tab_Def_Flows[Process_ID_O],,0,) -> 00_Bio_ | G8: =_xlfn.XLOOKUP(C8,Tab_Def_Flows[Name(EN)],Tab_Def_Flows[Input_Process],,0,) -> Raw Material Extraction | H8: =_xlfn.XLOOKUP(C8,Tab_Def_Flows[Name(EN)],Tab_Def_Flows[Process_ID_I],,0,) -> 01_Raw_ | I8: =_xlfn.XLOOKUP(C8,Tab_Def_Flows[Name(EN)],Tab_Def_Flows[Value_Source],,0,) -> 0 | J8: =_xlfn.XLOOKUP(C8,Tab_Def_Flows[Name(EN)],Tab_Def_Flows[WC?],,0,) -> Yes | K8: =_xlfn.XLOOKUP(C8,Tab_Def_Flows[Name(EN)],Tab_Def_Flows[DM?],,0,) -> Yes | L8: =_xlfn.XLOOKUP(C8,Tab_Def_Flows[Name(EN)],Tab_Def_Flows[CC?],,0,) -> Yes | M8: 1926 | O8: 103 | P8: Mg | R8: =INDEX(Tab_WC_DM_CC[[Flow_ID]:[CC_source]],MATCH(Tab_Data_Flows[[#This Row],[Name(EN)]],Tab_WC_DM_CC[Name(EN)],0),12) -> #N/A | S8: =MATCH(Tab_Data_Flows[[#This Row],[Name(EN)]],Tab_WC_DM_CC[Name(EN)],0) -> #N/A | X8: No | AA8: =IF(X8="no",O8,O8*Y8) -> 103 | AB8: Mg | AC8: =INDEX(Tab_Def_Flows[[Flow_ID]:[CC_DM_source]],MATCH(Tab_Data_Flows[[#This Row],[Name(EN)]],Tab_Def_Flows[Name(EN)],0),14) -> 0 | AD8: =IF(J8="Yes",AA8*Tab_Data_Flows[[#This Row],[WC_'[%']]],"N.A.") -> 0 | AE8: =Tab_Data_Flows[[#This Row],[UoM_Flow_Py]] -> Mg | AF8: =INDEX(Tab_Def_Flows[[Flow_ID]:[CC_DM_source]],MATCH(Tab_Data_Flows[[#This Row],[Name(EN)]],Tab_Def_Flows[Name(EN)],0),16) -> 1 | AG8: =IF(K8="Yes",AF8*Tab_Data_Flows[[#This Row],[Flow_Py]],"N.A.") -> 103 | AH8: =Tab_Data_Flows[[#This Row],[UoM_Flow_Py]] -> Mg | AI8: =INDEX(Tab_Def_Flows[[Flow_ID]:[CC_DM_source]],MATCH(Tab_Data_Flows[[#This Row],[Name(EN)]],Tab_Def_Flows[Name(EN)],0),18) -> 0.5 | AJ8: =IF(L8="Yes",AI8*Tab_Data_Flows[[#This Row],[Flow_Py]]*Tab_Data_Flows[[#This Row],[DM_'[%']]],"N.A.") -> 51.5 | AK8: =Tab_Data_Flows[[#This Row],[UoM_Flow_Py]] -> Mg
A9: =ROW()-1 -> 8 | B9: =_xlfn.XLOOKUP(C9,Tab_Def_Flows[Name(EN)],Tab_Def_Flows[Flow_ID],,0,) -> F_00_01 | C9: Wood | D9: =_xlfn.XLOOKUP(C9,Tab_Def_Flows[Name(EN)],Tab_Def_Flows[Type_Biomass],,0,) -> 0 | E9: =_xlfn.XLOOKUP(C9,Tab_Def_Flows[Name(EN)],Tab_Def_Flows[Output_Process],,0,) -> Biosphere | F9: =_xlfn.XLOOKUP(C9,Tab_Def_Flows[Name(EN)],Tab_Def_Flows[Process_ID_O],,0,) -> 00_Bio_ | G9: =_xlfn.XLOOKUP(C9,Tab_Def_Flows[Name(EN)],Tab_Def_Flows[Input_Process],,0,) -> Raw Material Extraction | H9: =_xlfn.XLOOKUP(C9,Tab_Def_Flows[Name(EN)],Tab_Def_Flows[Process_ID_I],,0,) -> 01_Raw_ | I9: =_xlfn.XLOOKUP(C9,Tab_Def_Flows[Name(EN)],Tab_Def_Flows[Value_Source],,0,) -> 0 | J9: =_xlfn.XLOOKUP(C9,Tab_Def_Flows[Name(EN)],Tab_Def_Flows[WC?],,0,) -> Yes | K9: =_xlfn.XLOOKUP(C9,Tab_Def_Flows[Name(EN)],Tab_Def_Flows[DM?],,0,) -> Yes | L9: =_xlfn.XLOOKUP(C9,Tab_Def_Flows[Name(EN)],Tab_Def_Flows[CC?],,0,) -> Yes | M9: 1927 | O9: 109.2 | P9: Mg | R9: =INDEX(Tab_WC_DM_CC[[Flow_ID]:[CC_source]],MATCH(Tab_Data_Flows[[#This Row],[Name(EN)]],Tab_WC_DM_CC[Name(EN)],0),12) -> #N/A | S9: =MATCH(Tab_Data_Flows[[#This Row],[Name(EN)]],Tab_WC_DM_CC[Name(EN)],0) -> #N/A | X9: No | AA9: =IF(X9="no",O9,O9*Y9) -> 109.2 | AB9: Mg | AC9: =INDEX(Tab_Def_Flows[[Flow_ID]:[CC_DM_source]],MATCH(Tab_Data_Flows[[#This Row],[Name(EN)]],Tab_Def_Flows[Name(EN)],0),14) -> 0 | AD9: =IF(J9="Yes",AA9*Tab_Data_Flows[[#This Row],[WC_'[%']]],"N.A.") -> 0 | AE9: =Tab_Data_Flows[[#This Row],[UoM_Flow_Py]] -> Mg | AF9: =INDEX(Tab_Def_Flows[[Flow_ID]:[CC_DM_source]],MATCH(Tab_Data_Flows[[#This Row],[Name(EN)]],Tab_Def_Flows[Name(EN)],0),16) -> 1 | AG9: =IF(K9="Yes",AF9*Tab_Data_Flows[[#This Row],[Flow_Py]],"N.A.") -> 109.2 | AH9: =Tab_Data_Flows[[#This Row],[UoM_Flow_Py]] -> Mg | AI9: =INDEX(Tab_Def_Flows[[Flow_ID]:[CC_DM_source]],MATCH(Tab_Data_Flows[[#This Row],[Name(EN)]],Tab_Def_Flows[Name(EN)],0),18) -> 0.5 | AJ9: =IF(L9="Yes",AI9*Tab_Data_Flows[[#This Row],[Flow_Py]]*Tab_Data_Flows[[#This Row],[DM_'[%']]],"N.A.") -> 54.6 | AK9: =Tab_Data_Flows[[#This Row],[UoM_Flow_Py]] -> Mg
A10: =ROW()-1 -> 9 | B10: =_xlfn.XLOOKUP(C10,Tab_Def_Flows[Name(EN)],Tab_Def_Flows[Flow_ID],,0,) -> F_00_01 | C10: Wood | D10: =_xlfn.XLOOKUP(C10,Tab_Def_Flows[Name(EN)],Tab_Def_Flows[Type_Biomass],,0,) -> 0 | E10: =_xlfn.XLOOKUP(C10,Tab_Def_Flows[Name(EN)],Tab_Def_Flows[Output_Process],,0,) -> Biosphere | F10: =_xlfn.XLOOKUP(C10,Tab_Def_Flows[Name(EN)],Tab_Def_Flows[Process_ID_O],,0,) -> 00_Bio_ | G10: =_xlfn.XLOOKUP(C10,Tab_Def_Flows[Name(EN)],Tab_Def_Flows[Input_Process],,0,) -> Raw Material Extraction | H10: =_xlfn.XLOOKUP(C10,Tab_Def_Flows[Name(EN)],Tab_Def_Flows[Process_ID_I],,0,) -> 01_Raw_ | I10: =_xlfn.XLOOKUP(C10,Tab_Def_Flows[Name(EN)],Tab_Def_Flows[Value_Source],,0,) -> 0 | J10: =_xlfn.XLOOKUP(C10,Tab_Def_Flows[Name(EN)],Tab_Def_Flows[WC?],,0,) -> Yes | K10: =_xlfn.XLOOKUP(C10,Tab_Def_Flows[Name(EN)],Tab_Def_Flows[DM?],,0,) -> Yes | L10: =_xlfn.XLOOKUP(C10,Tab_Def_Flows[Name(EN)],Tab_Def_Flows[CC?],,0,) -> Yes | M10: 1928 | O10: 77.2 | P10: Mg | R10: =INDEX(Tab_WC_DM_CC[[Flow_ID]:[CC_source]],MATCH(Tab_Data_Flows[[#This Row],[Name(EN)]],Tab_WC_DM_CC[Name(EN)],0),12) -> #N/A | S10: =MATCH(Tab_Data_Flows[[#This Row],[Name(EN)]],Tab_WC_DM_CC[Name(EN)],0) -> #N/A | X10: No | AA10: =IF(X10="no",O10,O10*Y10) -> 77.2 | AB10: Mg | AC10: =INDEX(Tab_Def_Flows[[Flow_ID]:[CC_DM_source]],MATCH(Tab_Data_Flows[[#This Row],[Name(EN)]],Tab_Def_Flows[Name(EN)],0),14) -> 0 | AD10: =IF(J10="Yes",AA10*Tab_Data_Flows[[#This Row],[WC_'[%']]],"N.A.") -> 0 | AE10: =Tab_Data_Flows[[#This Row],[UoM_Flow_Py]] -> Mg | AF10: =INDEX(Tab_Def_Flows[[Flow_ID]:[CC_DM_source]],MATCH(Tab_Data_Flows[[#This Row],[Name(EN)]],Tab_Def_Flows[Name(EN)],0),16) -> 1 | AG10: =IF(K10="Yes",AF10*Tab_Data_Flows[[#This Row],[Flow_Py]],"N.A.") -> 77.2 | AH10: =Tab_Data_Flows[[#This Row],[UoM_Flow_Py]] -> Mg | AI10: =INDEX(Tab_Def_Flows[[Flow_ID]:[CC_DM_source]],MATCH(Tab_Data_Flows[[#This Row],[Name(EN)]],Tab_Def_Flows[Name(EN)],0),18) -> 0.5 | AJ10: =IF(L10="Yes",AI10*Tab_Data_Flows[[#This Row],[Flow_Py]]*Tab_Data_Flows[[#This Row],[DM_'[%']]],"N.A.") -> 38.6 | AK10: =Tab_Data_Flows[[#This Row],[UoM_Flow_Py]] -> Mg
A11: =ROW()-1 -> 10 | B11: =_xlfn.XLOOKUP(C11,Tab_Def_Flows[Name(EN)],Tab_Def_Flows[Flow_ID],,0,) -> F_00_01 | C11: Wood | D11: =_xlfn.XLOOKUP(C11,Tab_Def_Flows[Name(EN)],Tab_Def_Flows[Type_Biomass],,0,) -> 0 | E11: =_xlfn.XLOOKUP(C11,Tab_Def_Flows[Name(EN)],Tab_Def_Flows[Output_Process],,0,) -> Biosphere | F11: =_xlfn.XLOOKUP(C11,Tab_Def_Flows[Name(EN)],Tab_Def_Flows[Process_ID_O],,0,) -> 00_Bio_ | G11: =_xlfn.XLOOKUP(C11,Tab_Def_Flows[Name(EN)],Tab_Def_Flows[Input_Process],,0,) -> Raw Material Extraction | H11: =_xlfn.XLOOKUP(C11,Tab_Def_Flows[Name(EN)],Tab_Def_Flows[Process_ID_I],,0,) -> 01_Raw_ | I11: =_xlfn.XLOOKUP(C11,Tab_Def_Flows[Name(EN)],Tab_Def_Flows[Value_Source],,0,) -> 0 | J11: =_xlfn.XLOOKUP(C11,Tab_Def_Flows[Name(EN)],Tab_Def_Flows[WC?],,0,) -> Yes | K11: =_xlfn.XLOOKUP(C11,Tab_Def_Flows[Name(EN)],Tab_Def_Flows[DM?],,0,) -> Yes | L11: =_xlfn.XLOOKUP(C11,Tab_Def_Flows[Name(EN)],Tab_Def_Flows[CC?],,0,) -> Yes | M11: 1929 | O11: 83.6 | P11: Mg | R11: =INDEX(Tab_WC_DM_CC[[Flow_ID]:[CC_source]],MATCH(Tab_Data_Flows[[#This Row],[Name(EN)]],Tab_WC_DM_CC[Name(EN)],0),12) -> #N/A | S11: =MATCH(Tab_Data_Flows[[#This Row],[Name(EN)]],Tab_WC_DM_CC[Name(EN)],0) -> #N/A | X11: No | AA11: =IF(X11="no",O11,O11*Y11) -> 83.6 | AB11: Mg | AC11: =INDEX(Tab_Def_Flows[[Flow_ID]:[CC_DM_source]],MATCH(Tab_Data_Flows[[#This Row],[Name(EN)]],Tab_Def_Flows[Name(EN)],0),14) -> 0 | AD11: =IF(J11="Yes",AA11*Tab_Data_Flows[[#This Row],[WC_'[%']]],"N.A.") -> 0 | AE11: =Tab_Data_Flows[[#This Row],[UoM_Flow_Py]] -> Mg | AF11: =INDEX(Tab_Def_Flows[[Flow_ID]:[CC_DM_source]],MATCH(Tab_Data_Flows[[#This Row],[Name(EN)]],Tab_Def_Flows[Name(EN)],0),16) -> 1 | AG11: =IF(K11="Yes",AF11*Tab_Data_Flows[[#This Row],[Flow_Py]],"N.A.") -> 83.6 | AH11: =Tab_Data_Flows[[#This Row],[UoM_Flow_Py]] -> Mg | AI11: =INDEX(Tab_Def_Flows[[Flow_ID]:[CC_DM_source]],MATCH(Tab_Data_Flows[[#This Row],[Name(EN)]],Tab_Def_Flows[Name(EN)],0),18) -> 0.5 | AJ11: =IF(L11="Yes",AI11*Tab_Data_Flows[[#This Row],[Flow_Py]]*Tab_Data_Flows[[#This Row],[DM_'[%']]],"N.A.") -> 41.8 | AK11: =Tab_Data_Flows[[#This Row],[UoM_Flow_Py]] -> Mg
A12: =ROW()-1 -> 11 | B12: =_xlfn.XLOOKUP(C12,Tab_Def_Flows[Name(EN)],Tab_Def_Flows[Flow_ID],,0,) -> F_00_01 | C12: Wood | D12: =_xlfn.XLOOKUP(C12,Tab_Def_Flows[Name(EN)],Tab_Def_Flows[Type_Biomass],,0,) -> 0 | E12: =_xlfn.XLOOKUP(C12,Tab_Def_Flows[Name(EN)],Tab_Def_Flows[Output_Process],,0,) -> Biosphere | F12: =_xlfn.XLOOKUP(C12,Tab_Def_Flows[Name(EN)],Tab_Def_Flows[Process_ID_O],,0,) -> 00_Bio_ | G12: =_xlfn.XLOOKUP(C12,Tab_Def_Flows[Name(EN)],Tab_Def_Flows[Input_Process],,0,) -> Raw Material Extraction | H12: =_xlfn.XLOOKUP(C12,Tab_Def_Flows[Name(EN)],Tab_Def_Flows[Process_ID_I],,0,) -> 01_Raw_ | I12: =_xlfn.XLOOKUP(C12,Tab_Def_Flows[Name(EN)],Tab_Def_Flows[Value_Source],,0,) -> 0 | J12: =_xlfn.XLOOKUP(C12,Tab_Def_Flows[Name(EN)],Tab_Def_Flows[WC?],,0,) -> Yes | K12: =_xlfn.XLOOKUP(C12,Tab_Def_Flows[Name(EN)],Tab_Def_Flows[DM?],,0,) -> Yes | L12: =_xlfn.XLOOKUP(C12,Tab_Def_Flows[Name(EN)],Tab_Def_Flows[CC?],,0,) -> Yes | M12: 1930 | O12: 64.4 | P12: Mg | R12: =INDEX(Tab_WC_DM_CC[[Flow_ID]:[CC_source]],MATCH(Tab_Data_Flows[[#This Row],[Name(EN)]],Tab_WC_DM_CC[Name(EN)],0),12) -> #N/A | S12: =MATCH(Tab_Data_Flows[[#This Row],[Name(EN)]],Tab_WC_DM_CC[Name(EN)],0) -> #N/A | X12: No | AA12: =IF(X12="no",O12,O12*Y12) -> 64.4 | AB12: Mg | AC12: =INDEX(Tab_Def_Flows[[Flow_ID]:[CC_DM_source]],MATCH(Tab_Data_Flows[[#This Row],[Name(EN)]],Tab_Def_Flows[Name(EN)],0),14) -> 0 | AD12: =IF(J12="Yes",AA12*Tab_Data_Flows[[#This Row],[WC_'[%']]],"N.A.") -> 0 | AE12: =Tab_Data_Flows[[#This Row],[UoM_Flow_Py]] -> Mg | AF12: =INDEX(Tab_Def_Flows[[Flow_ID]:[CC_DM_source]],MATCH(Tab_Data_Flows[[#This Row],[Name(EN)]],Tab_Def_Flows[Name(EN)],0),16) -> 1 | AG12: =IF(K12="Yes",AF12*Tab_Data_Flows[[#This Row],[Flow_Py]],"N.A.") -> 64.4 | AH12: =Tab_Data_Flows[[#This Row],[UoM_Flow_Py]] -> Mg | AI12: =INDEX(Tab_Def_Flows[[Flow_ID]:[CC_DM_source]],MATCH(Tab_Data_Flows[[#This Row],[Name(EN)]],Tab_Def_Flows[Name(EN)],0),18) -> 0.5 | AJ12: =IF(L12="Yes",AI12*Tab_Data_Flows[[#This Row],[Flow_Py]]*Tab_Data_Flows[[#This Row],[DM_'[%']]],"N.A.") -> 32.2 | AK12: =Tab_Data_Flows[[#This Row],[UoM_Flow_Py]] -> Mg
A13: =ROW()-1 -> 12 | B13: =_xlfn.XLOOKUP(C13,Tab_Def_Flows[Name(EN)],Tab_Def_Flows[Flow_ID],,0,) -> F_00_01 | C13: Wood | D13: =_xlfn.XLOOKUP(C13,Tab_Def_Flows[Name(EN)],Tab_Def_Flows[Type_Biomass],,0,) -> 0 | E13: =_xlfn.XLOOKUP(C13,Tab_Def_Flows[Name(EN)],Tab_Def_Flows[Output_Process],,0,) -> Biosphere | F13: =_xlfn.XLOOKUP(C13,Tab_Def_Flows[Name(EN)],Tab_Def_Flows[Process_ID_O],,0,) -> 00_Bio_ | G13: =_xlfn.XLOOKUP(C13,Tab_Def_Flows[Name(EN)],Tab_Def_Flows[Input_Process],,0,) -> Raw Material Extraction | H13: =_xlfn.XLOOKUP(C13,Tab_Def_Flows[Name(EN)],Tab_Def_Flows[Process_ID_I],,0,) -> 01_Raw_ | I13: =_xlfn.XLOOKUP(C13,Tab_Def_Flows[Name(EN)],Tab_Def_Flows[Value_Source],,0,) -> 0 | J13: =_xlfn.XLOOKUP(C13,Tab_Def_Flows[Name(EN)],Tab_Def_Flows[WC?],,0,) -> Yes | K13: =_xlfn.XLOOKUP(C13,Tab_Def_Flows[Name(EN)],Tab_Def_Flows[DM?],,0,) -> Yes | L13: =_xlfn.XLOOKUP(C13,Tab_Def_Flows[Name(EN)],Tab_Def_Flows[CC?],,0,) -> Yes | M13: 1931 | O13: 83.6 | P13: Mg | R13: =INDEX(Tab_WC_DM_CC[[Flow_ID]:[CC_source]],MATCH(Tab_Data_Flows[[#This Row],[Name(EN)]],Tab_WC_DM_CC[Name(EN)],0),12) -> #N/A | S13: =MATCH(Tab_Data_Flows[[#This Row],[Name(EN)]],Tab_WC_DM_CC[Name(EN)],0) -> #N/A | X13: No | AA13: =IF(X13="no",O13,O13*Y13) -> 83.6 | AB13: Mg | AC13: =INDEX(Tab_Def_Flows[[Flow_ID]:[CC_DM_source]],MATCH(Tab_Data_Flows[[#This Row],[Name(EN)]],Tab_Def_Flows[Name(EN)],0),14) -> 0 | AD13: =IF(J13="Yes",AA13*Tab_Data_Flows[[#This Row],[WC_'[%']]],"N.A.") -> 0 | AE13: =Tab_Data_Flows[[#This Row],[UoM_Flow_Py]] -> Mg | AF13: =INDEX(Tab_Def_Flows[[Flow_ID]:[CC_DM_source]],MATCH(Tab_Data_Flows[[#This Row],[Name(EN)]],Tab_Def_Flows[Name(EN)],0),16) -> 1 | AG13: =IF(K13="Yes",AF13*Tab_Data_Flows[[#This Row],[Flow_Py]],"N.A.") -> 83.6 | AH13: =Tab_Data_Flows[[#This Row],[UoM_Flow_Py]] -> Mg | AI13: =INDEX(Tab_Def_Flows[[Flow_ID]:[CC_DM_source]],MATCH(Tab_Data_Flows[[#This Row],[Name(EN)]],Tab_Def_Flows[Name(EN)],0),18) -> 0.5 | AJ13: =IF(L13="Yes",AI13*Tab_Data_Flows[[#This Row],[Flow_Py]]*Tab_Data_Flows[[#This Row],[DM_'[%']]],"N.A.") -> 41.8 | AK13: =Tab_Data_Flows[[#This Row],[UoM_Flow_Py]] -> Mg
A14: =ROW()-1 -> 13 | B14: =_xlfn.XLOOKUP(C14,Tab_Def_Flows[Name(EN)],Tab_Def_Flows[Flow_ID],,0,) -> F_00_01 | C14: Wood | D14: =_xlfn.XLOOKUP(C14,Tab_Def_Flows[Name(EN)],Tab_Def_Flows[Type_Biomass],,0,) -> 0 | E14: =_xlfn.XLOOKUP(C14,Tab_Def_Flows[Name(EN)],Tab_Def_Flows[Output_Process],,0,) -> Biosphere | F14: =_xlfn.XLOOKUP(C14,Tab_Def_Flows[Name(EN)],Tab_Def_Flows[Process_ID_O],,0,) -> 00_Bio_ | G14: =_xlfn.XLOOKUP(C14,Tab_Def_Flows[Name(EN)],Tab_Def_Flows[Input_Process],,0,) -> Raw Material Extraction | H14: =_xlfn.XLOOKUP(C14,Tab_Def_Flows[Name(EN)],Tab_Def_Flows[Process_ID_I],,0,) -> 01_Raw_ | I14: =_xlfn.XLOOKUP(C14,Tab_Def_Flows[Name(EN)],Tab_Def_Flows[Value_Source],,0,) -> 0 | J14: =_xlfn.XLOOKUP(C14,Tab_Def_Flows[Name(EN)],Tab_Def_Flows[WC?],,0,) -> Yes | K14: =_xlfn.XLOOKUP(C14,Tab_Def_Flows[Name(EN)],Tab_Def_Flows[DM?],,0,) -> Yes | L14: =_xlfn.XLOOKUP(C14,Tab_Def_Flows[Name(EN)],Tab_Def_Flows[CC?],,0,) -> Yes | M14: 1932 | O14: 70.8 | P14: Mg | R14: =INDEX(Tab_WC_DM_CC[[Flow_ID]:[CC_source]],MATCH(Tab_Data_Flows[[#This Row],[Name(EN)]],Tab_WC_DM_CC[Name(EN)],0),12) -> #N/A | S14: =MATCH(Tab_Data_Flows[[#This Row],[Name(EN)]],Tab_WC_DM_CC[Name(EN)],0) -> #N/A | X14: No | AA14: =IF(X14="no",O14,O14*Y14) -> 70.8 | AB14: Mg | AC14: =INDEX(Tab_Def_Flows[[Flow_ID]:[CC_DM_source]],MATCH(Tab_Data_Flows[[#This Row],[Name(EN)]],Tab_Def_Flows[Name(EN)],0),14) -> 0 | AD14: =IF(J14="Yes",AA14*Tab_Data_Flows[[#This Row],[WC_'[%']]],"N.A.") -> 0 | AE14: =Tab_Data_Flows[[#This Row],[UoM_Flow_Py]] -> Mg | AF14: =INDEX(Tab_Def_Flows[[Flow_ID]:[CC_DM_source]],MATCH(Tab_Data_Flows[[#This Row],[Name(EN)]],Tab_Def_Flows[Name(EN)],0),16) -> 1 | AG14: =IF(K14="Yes",AF14*Tab_Data_Flows[[#This Row],[Flow_Py]],"N.A.") -> 70.8 | AH14: =Tab_Data_Flows[[#This Row],[UoM_Flow_Py]] -> Mg | AI14: =INDEX(Tab_Def_Flows[[Flow_ID]:[CC_DM_source]],MATCH(Tab_Data_Flows[[#This Row],[Name(EN)]],Tab_Def_Flows[Name(EN)],0),18) -> 0.5 | AJ14: =IF(L14="Yes",AI14*Tab_Data_Flows[[#This Row],[Flow_Py]]*Tab_Data_Flows[[#This Row],[DM_'[%']]],"N.A.") -> 35.4 | AK14: =Tab_Data_Flows[[#This Row],[UoM_Flow_Py]] -> Mg
A15: =ROW()-1 -> 14 | B15: =_xlfn.XLOOKUP(C15,Tab_Def_Flows[Name(EN)],Tab_Def_Flows[Flow_ID],,0,) -> F_00_01 | C15: Wood | D15: =_xlfn.XLOOKUP(C15,Tab_Def_Flows[Name(EN)],Tab_Def_Flows[Type_Biomass],,0,) -> 0 | E15: =_xlfn.XLOOKUP(C15,Tab_Def_Flows[Name(EN)],Tab_Def_Flows[Output_Process],,0,) -> Biosphere | F15: =_xlfn.XLOOKUP(C15,Tab_Def_Flows[Name(EN)],Tab_Def_Flows[Process_ID_O],,0,) -> 00_Bio_ | G15: =_xlfn.XLOOKUP(C15,Tab_Def_Flows[Name(EN)],Tab_Def_Flows[Input_Process],,0,) -> Raw Material Extraction | H15: =_xlfn.XLOOKUP(C15,Tab_Def_Flows[Name(EN)],Tab_Def_Flows[Process_ID_I],,0,) -> 01_Raw_ | I15: =_xlfn.XLOOKUP(C15,Tab_Def_Flows[Name(EN)],Tab_Def_Flows[Value_Source],,0,) -> 0 | J15: =_xlfn.XLOOKUP(C15,Tab_Def_Flows[Name(EN)],Tab_Def_Flows[WC?],,0,) -> Yes | K15: =_xlfn.XLOOKUP(C15,Tab_Def_Flows[Name(EN)],Tab_Def_Flows[DM?],,0,) -> Yes | L15: =_xlfn.XLOOKUP(C15,Tab_Def_Flows[Name(EN)],Tab_Def_Flows[CC?],,0,) -> Yes | M15: 1933 | O15: 51.4 | P15: Mg | R15: =INDEX(Tab_WC_DM_CC[[Flow_ID]:[CC_source]],MATCH(Tab_Data_Flows[[#This Row],[Name(EN)]],Tab_WC_DM_CC[Name(EN)],0),12) -> #N/A | S15: =MATCH(Tab_Data_Flows[[#This Row],[Name(EN)]],Tab_WC_DM_CC[Name(EN)],0) -> #N/A | X15: No | AA15: =IF(X15="no",O15,O15*Y15) -> 51.4 | AB15: Mg | AC15: =INDEX(Tab_Def_Flows[[Flow_ID]:[CC_DM_source]],MATCH(Tab_Data_Flows[[#This Row],[Name(EN)]],Tab_Def_Flows[Name(EN)],0),14) -> 0 | AD15: =IF(J15="Yes",AA15*Tab_Data_Flows[[#This Row],[WC_'[%']]],"N.A.") -> 0 | AE15: =Tab_Data_Flows[[#This Row],[UoM_Flow_Py]] -> Mg | AF15: =INDEX(Tab_Def_Flows[[Flow_ID]:[CC_DM_source]],MATCH(Tab_Data_Flows[[#This Row],[Name(EN)]],Tab_Def_Flows[Name(EN)],0),16) -> 1 | AG15: =IF(K15="Yes",AF15*Tab_Data_Flows[[#This Row],[Flow_Py]],"N.A.") -> 51.4 | AH15: =Tab_Data_Flows[[#This Row],[UoM_Flow_Py]] -> Mg | AI15: =INDEX(Tab_Def_Flows[[Flow_ID]:[CC_DM_source]],MATCH(Tab_Data_Flows[[#This Row],[Name(EN)]],Tab_Def_Flows[Name(EN)],0),18) -> 0.5 | AJ15: =IF(L15="Yes",AI15*Tab_Data_Flows[[#This Row],[Flow_Py]]*Tab_Data_Flows[[#This Row],[DM_'[%']]],"N.A.") -> 25.7 | AK15: =Tab_Data_Flows[[#This Row],[UoM_Flow_Py]] -> Mg
A16: =ROW()-1 -> 15 | B16: =_xlfn.XLOOKUP(C16,Tab_Def_Flows[Name(EN)],Tab_Def_Flows[Flow_ID],,0,) -> F_00_01 | C16: Wood | D16: =_xlfn.XLOOKUP(C16,Tab_Def_Flows[Name(EN)],Tab_Def_Flows[Type_Biomass],,0,) -> 0 | E16: =_xlfn.XLOOKUP(C16,Tab_Def_Flows[Name(EN)],Tab_Def_Flows[Output_Process],,0,) -> Biosphere | F16: =_xlfn.XLOOKUP(C16,Tab_Def_Flows[Name(EN)],Tab_Def_Flows[Process_ID_O],,0,) -> 00_Bio_ | G16: =_xlfn.XLOOKUP(C16,Tab_Def_Flows[Name(EN)],Tab_Def_Flows[Input_Process],,0,) -> Raw Material Extraction | H16: =_xlfn.XLOOKUP(C16,Tab_Def_Flows[Name(EN)],Tab_Def_Flows[Process_ID_I],,0,) -> 01_Raw_ | I16: =_xlfn.XLOOKUP(C16,Tab_Def_Flows[Name(EN)],Tab_Def_Flows[Value_Source],,0,) -> 0 | J16: =_xlfn.XLOOKUP(C16,Tab_Def_Flows[Name(EN)],Tab_Def_Flows[WC?],,0,) -> Yes | K16: =_xlfn.XLOOKUP(C16,Tab_Def_Flows[Name(EN)],Tab_Def_Flows[DM?],,0,) -> Yes | L16: =_xlfn.XLOOKUP(C16,Tab_Def_Flows[Name(EN)],Tab_Def_Flows[CC?],,0,) -> Yes | M16: 1934 | O16: 32.2 | P16: Mg | R16: =INDEX(Tab_WC_DM_CC[[Flow_ID]:[CC_source]],MATCH(Tab_Data_Flows[[#This Row],[Name(EN)]],Tab_WC_DM_CC[Name(EN)],0),12) -> #N/A | S16: =MATCH(Tab_Data_Flows[[#This Row],[Name(EN)]],Tab_WC_DM_CC[Name(EN)],0) -> #N/A | X16: No | AA16: =IF(X16="no",O16,O16*Y16) -> 32.2 | AB16: Mg | AC16: =INDEX(Tab_Def_Flows[[Flow_ID]:[CC_DM_source]],MATCH(Tab_Data_Flows[[#This Row],[Name(EN)]],Tab_Def_Flows[Name(EN)],0),14) -> 0 | AD16: =IF(J16="Yes",AA16*Tab_Data_Flows[[#This Row],[WC_'[%']]],"N.A.") -> 0 | AE16: =Tab_Data_Flows[[#This Row],[UoM_Flow_Py]] -> Mg | AF16: =INDEX(Tab_Def_Flows[[Flow_ID]:[CC_DM_source]],MATCH(Tab_Data_Flows[[#This Row],[Name(EN)]],Tab_Def_Flows[Name(EN)],0),16) -> 1 | AG16: =IF(K16="Yes",AF16*Tab_Data_Flows[[#This Row],[Flow_Py]],"N.A.") -> 32.2 | AH16: =Tab_Data_Flows[[#This Row],[UoM_Flow_Py]] -> Mg | AI16: =INDEX(Tab_Def_Flows[[Flow_ID]:[CC_DM_source]],MATCH(Tab_Data_Flows[[#This Row],[Name(EN)]],Tab_Def_Flows[Name(EN)],0),18) -> 0.5 | AJ16: =IF(L16="Yes",AI16*Tab_Data_Flows[[#This Row],[Flow_Py]]*Tab_Data_Flows[[#This Row],[DM_'[%']]],"N.A.") -> 16.1 | AK16: =Tab_Data_Flows[[#This Row],[UoM_Flow_Py]] -> Mg
A17: =ROW()-1 -> 16 | B17: =_xlfn.XLOOKUP(C17,Tab_Def_Flows[Name(EN)],Tab_Def_Flows[Flow_ID],,0,) -> F_00_01 | C17: Wood | D17: =_xlfn.XLOOKUP(C17,Tab_Def_Flows[Name(EN)],Tab_Def_Flows[Type_Biomass],,0,) -> 0 | E17: =_xlfn.XLOOKUP(C17,Tab_Def_Flows[Name(EN)],Tab_Def_Flows[Output_Process],,0,) -> Biosphere | F17: =_xlfn.XLOOKUP(C17,Tab_Def_Flows[Name(EN)],Tab_Def_Flows[Process_ID_O],,0,) -> 00_Bio_ | G17: =_xlfn.XLOOKUP(C17,Tab_Def_Flows[Name(EN)],Tab_Def_Flows[Input_Process],,0,) -> Raw Material Extraction | H17: =_xlfn.XLOOKUP(C17,Tab_Def_Flows[Name(EN)],Tab_Def_Flows[Process_ID_I],,0,) -> 01_Raw_ | I17: =_xlfn.XLOOKUP(C17,Tab_Def_Flows[Name(EN)],Tab_Def_Flows[Value_Source],,0,) -> 0 | J17: =_xlfn.XLOOKUP(C17,Tab_Def_Flows[Name(EN)],Tab_Def_Flows[WC?],,0,) -> Yes | K17: =_xlfn.XLOOKUP(C17,Tab_Def_Flows[Name(EN)],Tab_Def_Flows[DM?],,0,) -> Yes | L17: =_xlfn.XLOOKUP(C17,Tab_Def_Flows[Name(EN)],Tab_Def_Flows[CC?],,0,) -> Yes | M17: 1935 | O17: 70.8 | P17: Mg | R17: =INDEX(Tab_WC_DM_CC[[Flow_ID]:[CC_source]],MATCH(Tab_Data_Flows[[#This Row],[Name(EN)]],Tab_WC_DM_CC[Name(EN)],0),12) -> #N/A | S17: =MATCH(Tab_Data_Flows[[#This Row],[Name(EN)]],Tab_WC_DM_CC[Name(EN)],0) -> #N/A | X17: No | AA17: =IF(X17="no",O17,O17*Y17) -> 70.8 | AB17: Mg | AC17: =INDEX(Tab_Def_Flows[[Flow_ID]:[CC_DM_source]],MATCH(Tab_Data_Flows[[#This Row],[Name(EN)]],Tab_Def_Flows[Name(EN)],0),14) -> 0 | AD17: =IF(J17="Yes",AA17*Tab_Data_Flows[[#This Row],[WC_'[%']]],"N.A.") -> 0 | AE17: =Tab_Data_Flows[[#This Row],[UoM_Flow_Py]] -> Mg | AF17: =INDEX(Tab_Def_Flows[[Flow_ID]:[CC_DM_source]],MATCH(Tab_Data_Flows[[#This Row],[Name(EN)]],Tab_Def_Flows[Name(EN)],0),16) -> 1 | AG17: =IF(K17="Yes",AF17*Tab_Data_Flows[[#This Row],[Flow_Py]],"N.A.") -> 70.8 | AH17: =Tab_Data_Flows[[#This Row],[UoM_Flow_Py]] -> Mg | AI17: =INDEX(Tab_Def_Flows[[Flow_ID]:[CC_DM_source]],MATCH(Tab_Data_Flows[[#This Row],[Name(EN)]],Tab_Def_Flows[Name(EN)],0),18) -> 0.5 | AJ17: =IF(L17="Yes",AI17*Tab_Data_Flows[[#This Row],[Flow_Py]]*Tab_Data_Flows[[#This Row],[DM_'[%']]],"N.A.") -> 35.4 | AK17: =Tab_Data_Flows[[#This Row],[UoM_Flow_Py]] -> Mg
A18: =ROW()-1 -> 17 | B18: =_xlfn.XLOOKUP(C18,Tab_Def_Flows[Name(EN)],Tab_Def_Flows[Flow_ID],,0,) -> F_00_01 | C18: Wood | D18: =_xlfn.XLOOKUP(C18,Tab_Def_Flows[Name(EN)],Tab_Def_Flows[Type_Biomass],,0,) -> 0 | E18: =_xlfn.XLOOKUP(C18,Tab_Def_Flows[Name(EN)],Tab_Def_Flows[Output_Process],,0,) -> Biosphere | F18: =_xlfn.XLOOKUP(C18,Tab_Def_Flows[Name(EN)],Tab_Def_Flows[Process_ID_O],,0,) -> 00_Bio_ | G18: =_xlfn.XLOOKUP(C18,Tab_Def_Flows[Name(EN)],Tab_Def_Flows[Input_Process],,0,) -> Raw Material Extraction | H18: =_xlfn.XLOOKUP(C18,Tab_Def_Flows[Name(EN)],Tab_Def_Flows[Process_ID_I],,0,) -> 01_Raw_ | I18: =_xlfn.XLOOKUP(C18,Tab_Def_Flows[Name(EN)],Tab_Def_Flows[Value_Source],,0,) -> 0 | J18: =_xlfn.XLOOKUP(C18,Tab_Def_Flows[Name(EN)],Tab_Def_Flows[WC?],,0,) -> Yes | K18: =_xlfn.XLOOKUP(C18,Tab_Def_Flows[Name(EN)],Tab_Def_Flows[DM?],,0,) -> Yes | L18: =_xlfn.XLOOKUP(C18,Tab_Def_Flows[Name(EN)],Tab_Def_Flows[CC?],,0,) -> Yes | M18: 1936 | O18: 25.8 | P18: Mg | R18: =INDEX(Tab_WC_DM_CC[[Flow_ID]:[CC_source]],MATCH(Tab_Data_Flows[[#This Row],[Name(EN)]],Tab_WC_DM_CC[Name(EN)],0),12) -> #N/A | S18: =MATCH(Tab_Data_Flows[[#This Row],[Name(EN)]],Tab_WC_DM_CC[Name(EN)],0) -> #N/A | X18: No | AA18: =IF(X18="no",O18,O18*Y18) -> 25.8 | AB18: Mg | AC18: =INDEX(Tab_Def_Flows[[Flow_ID]:[CC_DM_source]],MATCH(Tab_Data_Flows[[#This Row],[Name(EN)]],Tab_Def_Flows[Name(EN)],0),14) -> 0 | AD18: =IF(J18="Yes",AA18*Tab_Data_Flows[[#This Row],[WC_'[%']]],"N.A.") -> 0 | AE18: =Tab_Data_Flows[[#This Row],[UoM_Flow_Py]] -> Mg | AF18: =INDEX(Tab_Def_Flows[[Flow_ID]:[CC_DM_source]],MATCH(Tab_Data_Flows[[#This Row],[Name(EN)]],Tab_Def_Flows[Name(EN)],0),16) -> 1 | AG18: =IF(K18="Yes",AF18*Tab_Data_Flows[[#This Row],[Flow_Py]],"N.A.") -> 25.8 | AH18: =Tab_Data_Flows[[#This Row],[UoM_Flow_Py]] -> Mg | AI18: =INDEX(Tab_Def_Flows[[Flow_ID]:[CC_DM_source]],MATCH(Tab_Data_Flows[[#This Row],[Name(EN)]],Tab_Def_Flows[Name(EN)],0),18) -> 0.5 | AJ18: =IF(L18="Yes",AI18*Tab_Data_Flows[[#This Row],[Flow_Py]]*Tab_Data_Flows[[#This Row],[DM_'[%']]],"N.A.") -> 12.9 | AK18: =Tab_Data_Flows[[#This Row],[UoM_Flow_Py]] -> Mg
... A28: =ROW()-1 -> 27 | B28: =_xlfn.XLOOKUP(C28,Tab_Def_Flows[Name(EN)],Tab_Def_Flows[Flow_ID],,0,) -> F_00_01 | C28: Wood | D28: =_xlfn.XLOOKUP(C28,Tab_Def_Flows[Name(EN)],Tab_Def_Flows[Type_Biomass],,0,) -> 0 | E28: =_xlfn.XLOOKUP(C28,Tab_Def_Flows[Name(EN)],Tab_Def_Flows[Output_Process],,0,) -> Biosphere | F28: =_xlfn.XLOOKUP(C28,Tab_Def_Flows[Name(EN)],Tab_Def_Flows[Process_ID_O],,0,) -> 00_Bio_ | G28: =_xlfn.XLOOKUP(C28,Tab_Def_Flows[Name(EN)],Tab_Def_Flows[Input_Process],,0,) -> Raw Material Extraction | H28: =_xlfn.XLOOKUP(C28,Tab_Def_Flows[Name(EN)],Tab_Def_Flows[Process_ID_I],,0,) -> 01_Raw_ | I28: =_xlfn.XLOOKUP(C28,Tab_Def_Flows[Name(EN)],Tab_Def_Flows[Value_Source],,0,) -> 0 | J28: =_xlfn.XLOOKUP(C28,Tab_Def_Flows[Name(EN)],Tab_Def_Flows[WC?],,0,) -> Yes | K28: =_xlfn.XLOOKUP(C28,Tab_Def_Flows[Name(EN)],Tab_Def_Flows[DM?],,0,) -> Yes | L28: =_xlfn.XLOOKUP(C28,Tab_Def_Flows[Name(EN)],Tab_Def_Flows[CC?],,0,) -> Yes | M28: 1946 | O28: 90 | P28: Mg | R28: =INDEX(Tab_WC_DM_CC[[Flow_ID]:[CC_source]],MATCH(Tab_Data_Flows[[#This Row],[Name(EN)]],Tab_WC_DM_CC[Name(EN)],0),12) -> #N/A | S28: =MATCH(Tab_Data_Flows[[#This Row],[Name(EN)]],Tab_WC_DM_CC[Name(EN)],0) -> #N/A | X28: No | AA28: =IF(X28="no",O28,O28*Y28) -> 90 | AB28: Mg | AC28: =INDEX(Tab_Def_Flows[[Flow_ID]:[CC_DM_source]],MATCH(Tab_Data_Flows[[#This Row],[Name(EN)]],Tab_Def_Flows[Name(EN)],0),14) -> 0 | AD28: =IF(J28="Yes",AA28*Tab_Data_Flows[[#This Row],[WC_'[%']]],"N.A.") -> 0 | AE28: =Tab_Data_Flows[[#This Row],[UoM_Flow_Py]] -> Mg | AF28: =INDEX(Tab_Def_Flows[[Flow_ID]:[CC_DM_source]],MATCH(Tab_Data_Flows[[#This Row],[Name(EN)]],Tab_Def_Flows[Name(EN)],0),16) -> 1 | AG28: =IF(K28="Yes",AF28*Tab_Data_Flows[[#This Row],[Flow_Py]],"N.A.") -> 90 | AH28: =Tab_Data_Flows[[#This Row],[UoM_Flow_Py]] -> Mg | AI28: =INDEX(Tab_Def_Flows[[Flow_ID]:[CC_DM_source]],MATCH(Tab_Data_Flows[[#This Row],[Name(EN)]],Tab_Def_Flows[Name(EN)],0),18) -> 0.5 | AJ28: =IF(L28="Yes",AI28*Tab_Data_Flows[[#This Row],[Flow_Py]]*Tab_Data_Flows[[#This Row],[DM_'[%']]],"N.A.") -> 45 | AK28: =Tab_Data_Flows[[#This Row],[UoM_Flow_Py]] -> Mg
A29: =ROW()-1 -> 28 | B29: =_xlfn.XLOOKUP(C29,Tab_Def_Flows[Name(EN)],Tab_Def_Flows[Flow_ID],,0,) -> F_00_01 | C29: Wood | D29: =_xlfn.XLOOKUP(C29,Tab_Def_Flows[Name(EN)],Tab_Def_Flows[Type_Biomass],,0,) -> 0 | E29: =_xlfn.XLOOKUP(C29,Tab_Def_Flows[Name(EN)],Tab_Def_Flows[Output_Process],,0,) -> Biosphere | F29: =_xlfn.XLOOKUP(C29,Tab_Def_Flows[Name(EN)],Tab_Def_Flows[Process_ID_O],,0,) -> 00_Bio_ | G29: =_xlfn.XLOOKUP(C29,Tab_Def_Flows[Name(EN)],Tab_Def_Flows[Input_Process],,0,) -> Raw Material Extraction | H29: =_xlfn.XLOOKUP(C29,Tab_Def_Flows[Name(EN)],Tab_Def_Flows[Process_ID_I],,0,) -> 01_Raw_ | I29: =_xlfn.XLOOKUP(C29,Tab_Def_Flows[Name(EN)],Tab_Def_Flows[Value_Source],,0,) -> 0 | J29: =_xlfn.XLOOKUP(C29,Tab_Def_Flows[Name(EN)],Tab_Def_Flows[WC?],,0,) -> Yes | K29: =_xlfn.XLOOKUP(C29,Tab_Def_Flows[Name(EN)],Tab_Def_Flows[DM?],,0,) -> Yes | L29: =_xlfn.XLOOKUP(C29,Tab_Def_Flows[Name(EN)],Tab_Def_Flows[CC?],,0,) -> Yes | M29: 1947 | O29: 109.2 | P29: Mg | X29: No | AA29: =IF(X29="no",O29,O29*Y29) -> 109.2 | AB29: Mg | AC29: =INDEX(Tab_Def_Flows[[Flow_ID]:[CC_DM_source]],MATCH(Tab_Data_Flows[[#This Row],[Name(EN)]],Tab_Def_Flows[Name(EN)],0),14) -> 0 | AD29: =IF(J29="Yes",AA29*Tab_Data_Flows[[#This Row],[WC_'[%']]],"N.A.") -> 0 | AE29: =Tab_Data_Flows[[#This Row],[UoM_Flow_Py]] -> Mg | AF29: =INDEX(Tab_Def_Flows[[Flow_ID]:[CC_DM_source]],MATCH(Tab_Data_Flows[[#This Row],[Name(EN)]],Tab_Def_Flows[Name(EN)],0),16) -> 1 | AG29: =IF(K29="Yes",AF29*Tab_Data_Flows[[#This Row],[Flow_Py]],"N.A.") -> 109.2 | AH29: =Tab_Data_Flows[[#This Row],[UoM_Flow_Py]] -> Mg | AI29: =INDEX(Tab_Def_Flows[[Flow_ID]:[CC_DM_source]],MATCH(Tab_Data_Flows[[#This Row],[Name(EN)]],Tab_Def_Flows[Name(EN)],0),18) -> 0.5 | AJ29: =IF(L29="Yes",AI29*Tab_Data_Flows[[#This Row],[Flow_Py]]*Tab_Data_Flows[[#This Row],[DM_'[%']]],"N.A.") -> 54.6 | AK29: =Tab_Data_Flows[[#This Row],[UoM_Flow_Py]] -> Mg
