Workbook
Name Baumart_: [1]!Baumart[Baumart]
Name Baumart_: [2]!Baumart[Baumart]
Name Cluster_: [1]!Cluster[Cluster]
Name Cluster_: [2]!Cluster[Cluster]
Name einheit: [1]!Tabelle14[Einheit]
Name einheit: [2]!Tabelle14[Einheit]
Name Erhebungsart_: [1]!Erhebungsart[Erhebungsart]
Name Erhebungsart_: [2]!Erhebungsart[Erhebungsart]
Name Herkunft_: [1]!Herkunft[Herkunft]
Name Herkunft_: [2]!Herkunft[Herkunft]
Name Holzstrom_: [1]!Holzstrom[Holzstrom]
Name Holzstrom_: [2]!Holzstrom[Holzstrom]
Name In_Out_: [1]!Tabelleinput[In/Out]
Name In_Out_: [2]!Tabelleinput[In/Out]
Name Inhaltsverzeichnis: "MTRANS(ERSETZEN(Inhalt;1;FINDEN(""]"";Inhalt);""))"
Name Klassifizierung: [1]!Tabelle9[Klassifizierung]
Name Klassifizierung: [2]!Tabelle9[Klassifizierung]
Name Ort_: [1]!Ort[Ort]
Name Ort_: [2]!Ort[Ort]
Name Ziel_: [1]!Ziel[Ziel]
Name Ziel_: [2]!Ziel[Ziel]

Sheet Intro
B3: Der angehängte Datensatz beinhalten Informationen über Materialflüsse, Prozesse sowie Lager in der Region Brandenburg. Der Datensatz bezieht sich dabei auf verschiedene Quellen und Dokumente.
B5: Definition der Systemgrenzen:
C6: Beobachtungszeitraum: | F6: 2010 - 2020
C7: Beobachtungsgebiet: | F7: Berlin
F8: Brandenburg
F9: Berlin + Brandenburg
B11: Für die Anfertigung der Materialflussanalyse werden die folgenden Daten benötigt. Die Daten werden in seperaten Tabellenblättern dargestellt. Für jeden Datensatz werden spezifische Anforderungen definiert. Diese lassen sich einem Systemübergreifenden Fließbild zuordnen. Dieses Fließbild beinhaltet die relevanten Flüsse, Prozesse und Lager.
B14: Prozesse bilden die Grundlage für das System. Prozesse können Transferkoefizienten und Lager beinhalten. Prozesse haben einen oder mehrere Flüsse als Input sowie einen oder mehrere Flüsse als Output.
B21: Flüsse:
C23: Flüsse müssen in Mg umgerechnet werden
B32: Prozesse:
B33: Lager
B34: Transferkoeffizienten
B35: Umrechnungsfaktoren:
B36: Codelisten:

Sheet Version_20.02.

Sheet 1_Flows>>>>

Sheet 1_1_Definition_Flows
A1: Complete? | B1: ID | C1: Flow_ID | D1: Name(EN) | E1: Name(DE) | F1: Region | G1: Type_Biomass | H1: Product/By-product/waste | I1: Comment | J1: Output_Process | K1: Process_ID_O | L1: Input_Process | M1: Process_ID_I | N1: Value_Source | O1: WC? | P1: DM? | Q1: CC? | R1: WC | S1: WC_source | T1: DM | U1: DM_source | V1: CC_DM[%] | W1: CC_DM_source | X1: CC | Y1: CC_FM_source
A2: TRUE | B2: =ROW()-1 -> 1 | C2: ="F_"&LEFT(K2,2)&"_"&LEFT(M2,2) -> F_13_20 | D2: Rye plant | E2: Roggen | F2: BB | H2: Product | J2: Rye cultivation | K2: =_xlfn.XLOOKUP(J2,Tab_Def_Processes[Name(EN)],Tab_Def_Processes[Process_ID],,0,) -> 13_Rye_BB | L2: Rye cultivation and harvest | M2: =_xlfn.XLOOKUP(L2,Tab_Def_Processes[Name(EN)],Tab_Def_Processes[Process_ID],,0,) -> 20_Rye_BB | N2: Data_assumption | O2: Yes | P2: Yes | Q2: Yes | R2: 0.06 | T2: 0.94 | U2: assumption | V2: 0.49 | W2: assumption | X2: =Tab_Def_Flows[[#This Row],[CC_DM'[%']]]*Tab_Def_Flows[[#This Row],[DM]] -> 0.4606
A3: TRUE | B3: =ROW()-1 -> 2 | C3: ="F_"&LEFT(K3,2)&"_"&LEFT(M3,2) -> F_20_15 | D3: Rye grain | E3: Roggen Körner | F3: BB | H3: Product | J3: Rye cultivation and harvest | K3: =_xlfn.XLOOKUP(J3,Tab_Def_Processes[Name(EN)],Tab_Def_Processes[Process_ID],,0,) -> 20_Rye_BB | L3: Rye processing and consumption | M3: =_xlfn.XLOOKUP(L3,Tab_Def_Processes[Name(EN)],Tab_Def_Processes[Process_ID],,0,) -> 15_Rye_BB | N3: Data_Literature | O3: Yes | P3: Yes | Q3: Yes | R3: 0.06 | T3: 0.94 | U3: assumption | V3: 0.49 | W3: assumption | X3: =Tab_Def_Flows[[#This Row],[CC_DM'[%']]]*Tab_Def_Flows[[#This Row],[DM]] -> 0.4606
A4: TRUE | B4: =ROW()-1 -> 3 | C4: ="F_"&LEFT(K4,2)&"_"&LEFT(M4,2) -> F_20_01 | D4: Technical usable rye straw | E4: Technische nutzbares Roggenstroh | F4: BB | H4: By-Product | J4: Rye cultivation and harvest | K4: =_xlfn.XLOOKUP(J4,Tab_Def_Processes[Name(EN)],Tab_Def_Processes[Process_ID],,0,) -> 20_Rye_BB | L4: Biogas production | M4: =_xlfn.XLOOKUP(L4,Tab_Def_Processes[Name(EN)],Tab_Def_Processes[Process_ID],,0,) -> 01_Bio_BB | N4: Data_Literature | O4: Yes | P4: Yes | Q4: Yes | R4: 0.06 | T4: 0.94 | U4: assumption | V4: 0.49 | W4: assumption | X4: =Tab_Def_Flows[[#This Row],[CC_DM'[%']]]*Tab_Def_Flows[[#This Row],[DM]] -> 0.4606
A5: TRUE | B5: =ROW()-1 -> 4 | C5: ="F_"&LEFT(K5,2)&"_"&LEFT(M5,2) -> F_20_16 | D5: Non technical usable Rye straw | E5: Nicht technische nutzbares Roggenstroh | F5: BB | H5: By-Product | J5: Rye cultivation and harvest | K5: =_xlfn.XLOOKUP(J5,Tab_Def_Processes[Name(EN)],Tab_Def_Processes[Process_ID],,0,) -> 20_Rye_BB | L5: Not mobilizable Rye Straw | M5: =_xlfn.XLOOKUP(L5,Tab_Def_Processes[Name(EN)],Tab_Def_Processes[Process_ID],,0,) -> 16_Not_BB | N5: Data_Literature | O5: Yes | P5: Yes | Q5: Yes | R5: 0.06 | T5: 0.94 | U5: assumption | V5: 0.49 | W5: assumption | X5: =Tab_Def_Flows[[#This Row],[CC_DM'[%']]]*Tab_Def_Flows[[#This Row],[DM]] -> 0.4606
A6: TRUE | B6: =ROW()-1 -> 5 | C6: ="F_"&LEFT(K6,2)&"_"&LEFT(M6,2) -> F_04_01 | D6: Cow Manure | E6: Rindergülle | F6: BB | H6: By-Product | J6: Life stock farming | K6: =_xlfn.XLOOKUP(J6,Tab_Def_Processes[Name(EN)],Tab_Def_Processes[Process_ID],,0,) -> 04_Lif_BB | L6: Biogas production | M6: =_xlfn.XLOOKUP(L6,Tab_Def_Processes[Name(EN)],Tab_Def_Processes[Process_ID],,0,) -> 01_Bio_BB | O6: Yes | P6: Yes | Q6: Yes | R6: 0.94 | T6: 0.06 | U6: Stramento | V6: 0.49 | W6: Stramento | X6: =Tab_Def_Flows[[#This Row],[CC_DM'[%']]]*Tab_Def_Flows[[#This Row],[DM]] -> 0.0294
A7: FALSE | B7: =ROW()-1 -> 6 | C7: ="F_"&LEFT(K7,2)&"_"&LEFT(M7,2) -> F_01_05 | D7: Biogas | E7: Biogas | F7: BB | H7: Product | J7: Biogas production | K7: =_xlfn.XLOOKUP(J7,Tab_Def_Processes[Name(EN)],Tab_Def_Processes[Process_ID],,0,) -> 01_Bio_BB | L7: Biogas Incineration | M7: =_xlfn.XLOOKUP(L7,Tab_Def_Processes[Name(EN)],Tab_Def_Processes[Process_ID],,0,) -> 05_Bio_BB | N7: Calculation_TC | O7: Yes | P7: Yes | Q7: Yes | R7: 0 | T7: 1 | U7: Stramento | V7: 0.27 | W7: Stramento | X7: =Tab_Def_Flows[[#This Row],[CC_DM'[%']]]*Tab_Def_Flows[[#This Row],[DM]] -> 0.27
A8: FALSE | B8: =ROW()-1 -> 7 | C8: ="F_"&LEFT(K8,2)&"_"&LEFT(M8,2) -> F_01_02 | D8: Rye straw digestate | E8: Roggenstroh Gärrest | F8: BB | H8: By-Product | J8: Biogas production | K8: =_xlfn.XLOOKUP(J8,Tab_Def_Processes[Name(EN)],Tab_Def_Processes[Process_ID],,0,) -> 01_Bio_BB | L8: MBC production | M8: =_xlfn.XLOOKUP(L8,Tab_Def_Processes[Name(EN)],Tab_Def_Processes[Process_ID],,0,) -> 02_MBC_BB | N8: Data_experiment | O8: Yes | P8: Yes | Q8: Yes | R8: 0.64 | T8: 0.36 | U8: Stramento | V8: 0.38 | W8: Stramento | X8: =Tab_Def_Flows[[#This Row],[CC_DM'[%']]]*Tab_Def_Flows[[#This Row],[DM]] -> 0.1368
A9: FALSE | B9: =ROW()-1 -> 8 | C9: ="F_"&LEFT(K9,2)&"_"&LEFT(M9,2) -> F_02_03 | D9: MBC (new) | E9: Mycel basierter composit | F9: BB | H9: Product | J9: MBC production | K9: =_xlfn.XLOOKUP(J9,Tab_Def_Processes[Name(EN)],Tab_Def_Processes[Process_ID],,0,) -> 02_MBC_BB | L9: MBC Use phase | M9: =_xlfn.XLOOKUP(L9,Tab_Def_Processes[Name(EN)],Tab_Def_Processes[Process_ID],,0,) -> 03_MBC_BB | O9: Yes | P9: Yes | Q9: Yes | R9: 0.61 | T9: 0.39 | V9: 0.4 | X9: =Tab_Def_Flows[[#This Row],[CC_DM'[%']]]*Tab_Def_Flows[[#This Row],[DM]] -> 0.156
A10: FALSE | B10: =ROW()-1 -> 9 | C10: ="F_"&LEFT(K10,2)&"_"&LEFT(M10,2) -> F_03_07 | D10: MBC (used) | E10: MBC verwendet | F10: BB | H10: Waste | J10: MBC Use phase | K10: =_xlfn.XLOOKUP(J10,Tab_Def_Processes[Name(EN)],Tab_Def_Processes[Process_ID],,0,) -> 03_MBC_BB | L10: EoL-Treatment (MBC) | M10: =_xlfn.XLOOKUP(L10,Tab_Def_Processes[Name(EN)],Tab_Def_Processes[Process_ID],,0,) -> 07_EoL_BB | O10: Yes | P10: Yes | Q10: Yes | R10: 0.61 | T10: 0.39 | V10: 0.4 | X10: =Tab_Def_Flows[[#This Row],[CC_DM'[%']]]*Tab_Def_Flows[[#This Row],[DM]] -> 0.156
A11: FALSE | B11: =ROW()-1 -> 10 | C11: ="F_"&LEFT(K11,2)&"_"&LEFT(M11,2) -> F_02_06 | D11: MBC production waste | E11: MBC Produktionsabfall | F11: BB | H11: Waste | J11: MBC production | K11: =_xlfn.XLOOKUP(J11,Tab_Def_Processes[Name(EN)],Tab_Def_Processes[Process_ID],,0,) -> 02_MBC_BB | L11: EoL-Treatment | M11: =_xlfn.XLOOKUP(L11,Tab_Def_Processes[Name(EN)],Tab_Def_Processes[Process_ID],,0,) -> 06_EoL_BB | O11: Yes | P11: Yes | Q11: Yes | R11: 0.64 | T11: 0.36 | V11: 0.38 | X11: =Tab_Def_Flows[[#This Row],[CC_DM'[%']]]*Tab_Def_Flows[[#This Row],[DM]] -> 0.1368
A12: FALSE | B12: =ROW()-1 -> 11 | C12: ="F_"&LEFT(K12,2)&"_"&LEFT(M12,2) -> F_11_02 | D12: Millet grain | E12: Hirsekörner | F12: BB | H12: Product | J12: Millet production | K12: =_xlfn.XLOOKUP(J12,Tab_Def_Processes[Name(EN)],Tab_Def_Processes[Process_ID],,0,) -> 11_Mil_BB | L12: MBC production | M12: =_xlfn.XLOOKUP(L12,Tab_Def_Processes[Name(EN)],Tab_Def_Processes[Process_ID],,0,) -> 02_MBC_BB | O12: Yes | P12: Yes | Q12: Yes | R12: 0.66 | T12: 0.34 | V12: 0.47 | X12: =Tab_Def_Flows[[#This Row],[CC_DM'[%']]]*Tab_Def_Flows[[#This Row],[DM]] -> 0.1598
A13: FALSE | B13: =ROW()-1 -> 12 | C13: ="F_"&LEFT(K13,2)&"_"&LEFT(M13,2) -> F_08_02 | D13: Water Input MBC Production | E13: Wasser Input MBC | F13: BB | H13: Product | J13: Water System (Import) | K13: =_xlfn.XLOOKUP(J13,Tab_Def_Processes[Name(EN)],Tab_Def_Processes[Process_ID],,0,) -> 08_Wat_BB | L13: MBC production | M13: =_xlfn.XLOOKUP(L13,Tab_Def_Processes[Name(EN)],Tab_Def_Processes[Process_ID],,0,) -> 02_MBC_BB | O13: Yes | P13: Yes | Q13: Yes | R13: 1 | T13: 0 | V13: 0 | X13: =Tab_Def_Flows[[#This Row],[CC_DM'[%']]]*Tab_Def_Flows[[#This Row],[DM]] -> 0
A14: FALSE | B14: =ROW()-1 -> 13 | C14: ="F_"&LEFT(K14,2)&"_"&LEFT(M14,2) -> F_02_14 | D14: Water Output MBC Production | E14: Wasser Output MBC | F14: BB | H14: Waste | J14: MBC production | K14: =_xlfn.XLOOKUP(J14,Tab_Def_Processes[Name(EN)],Tab_Def_Processes[Process_ID],,0,) -> 02_MBC_BB | L14: Water System (Export) | M14: =_xlfn.XLOOKUP(L14,Tab_Def_Processes[Name(EN)],Tab_Def_Processes[Process_ID],,0,) -> 14_Wat_BB | O14: Yes | P14: Yes | Q14: Yes | R14: 1 | T14: 0 | V14: 0 | X14: =Tab_Def_Flows[[#This Row],[CC_DM'[%']]]*Tab_Def_Flows[[#This Row],[DM]] -> 0
A15: FALSE | B15: =ROW()-1 -> 14 | C15: ="F_"&LEFT(K15,2)&"_"&LEFT(M15,2) -> F_02_12 | D15: Mass Delta MBC production | E15: Mass Delta | F15: BB | H15: Waste | J15: MBC production | K15: =_xlfn.XLOOKUP(J15,Tab_Def_Processes[Name(EN)],Tab_Def_Processes[Process_ID],,0,) -> 02_MBC_BB | L15: Delta (MBC) | M15: =_xlfn.XLOOKUP(L15,Tab_Def_Processes[Name(EN)],Tab_Def_Processes[Process_ID],,0,) -> 12_Del_BB | O15: Yes | P15: Yes | Q15: Yes | R15: 1 | T15: 0 | V15: 0 | X15: =Tab_Def_Flows[[#This Row],[CC_DM'[%']]]*Tab_Def_Flows[[#This Row],[DM]] -> 0
A16: FALSE | B16: =ROW()-1 -> 15 | C16: ="F_"&LEFT(K16,2)&"_"&LEFT(M16,2) -> F_07_09 | D16: EoL-MBC (Pyro) | E16: EoL-MBC (Pyro) | F16: BB | H16: Waste | J16: EoL-Treatment (MBC) | K16: =_xlfn.XLOOKUP(J16,Tab_Def_Processes[Name(EN)],Tab_Def_Processes[Process_ID],,0,) -> 07_EoL_BB | L16: Biomass Pyrolysis | M16: =_xlfn.XLOOKUP(L16,Tab_Def_Processes[Name(EN)],Tab_Def_Processes[Process_ID],,0,) -> 09_Bio_BB | O16: Yes | P16: Yes | Q16: Yes | R16: 0.61 | T16: 0.39 | V16: 0.4 | X16: =Tab_Def_Flows[[#This Row],[CC_DM'[%']]]*Tab_Def_Flows[[#This Row],[DM]] -> 0.156
A17: FALSE | B17: =ROW()-1 -> 16 | C17: ="F_"&LEFT(K17,2)&"_"&LEFT(M17,2) -> F_07_10 | D17: EoL-MBC (Inci) | E17: EoL-MBC (Inci) | F17: BB | H17: Waste | J17: EoL-Treatment (MBC) | K17: =_xlfn.XLOOKUP(J17,Tab_Def_Processes[Name(EN)],Tab_Def_Processes[Process_ID],,0,) -> 07_EoL_BB | L17: Biomass Incineration | M17: =_xlfn.XLOOKUP(L17,Tab_Def_Processes[Name(EN)],Tab_Def_Processes[Process_ID],,0,) -> 10_Bio_BB | O17: Yes | P17: Yes | Q17: Yes | R17: 0.61 | T17: 0.39 | V17: 0.4 | X17: =Tab_Def_Flows[[#This Row],[CC_DM'[%']]]*Tab_Def_Flows[[#This Row],[DM]] -> 0.156
A18: FALSE | B18: =ROW()-1 -> 17 | C18: ="F_"&LEFT(K18,2)&"_"&LEFT(M18,2) -> F_09_17 | D18: Pyrolisis Char | E18: Pyrolyse Kohle | F18: BB | H18: Product | J18: Biomass Pyrolysis | K18: =_xlfn.XLOOKUP(J18,Tab_Def_Processes[Name(EN)],Tab_Def_Processes[Process_ID],,0,) -> 09_Bio_BB | L18: Lithosphere | M18: =_xlfn.XLOOKUP(L18,Tab_Def_Processes[Name(EN)],Tab_Def_Processes[Process_ID],,0,) -> 17_Lit_BB | O18: Yes | P18: Yes | Q18: Yes | R18: 0 | T18: 1 | V18: 0.95 | W18: A review of pyrolysis technologies and feedstock: A blending approach for plastic and biomass towards optimum biochar yield | X18: =Tab_Def_Flows[[#This Row],[CC_DM'[%']]]*Tab_Def_Flows[[#This Row],[DM]] -> 0.95
A19: FALSE | B19: =ROW()-1 -> 18 | C19: ="F_"&LEFT(K19,2)&"_"&LEFT(M19,2) -> F_10_18 | D19: Ash | E19: Verbresnnungsasche | F19: BB | H19: Waste | J19: Biomass Incineration | K19: =_xlfn.XLOOKUP(J19,Tab_Def_Processes[Name(EN)],Tab_Def_Processes[Process_ID],,0,) -> 10_Bio_BB | L19: Ash Treatment | M19: =_xlfn.XLOOKUP(L19,Tab_Def_Processes[Name(EN)],Tab_Def_Processes[Process_ID],,0,) -> 18_Ash_BB | O19: Yes | P19: Yes | Q19: Yes | R19: 0 | T19: 1 | V19: 0.4 | X19: =Tab_Def_Flows[[#This Row],[CC_DM'[%']]]*Tab_Def_Flows[[#This Row],[DM]] -> 0.4
A20: FALSE | B20: =ROW()-1 -> 19 | C20: ="F_"&LEFT(K20,2)&"_"&LEFT(M20,2) -> F_10_19 | D20: Flue Gas | E20: Rauchgas | F20: BB | H20: Waste | J20: Biomass Incineration | K20: =_xlfn.XLOOKUP(J20,Tab_Def_Processes[Name(EN)],Tab_Def_Processes[Process_ID],,0,) -> 10_Bio_BB | L20: Atmosphere | M20: =_xlfn.XLOOKUP(L20,Tab_Def_Processes[Name(EN)],Tab_Def_Processes[Process_ID],,0,) -> 19_Atm_BB | N20: Calculation_TC | O20: Yes | P20: Yes | Q20: Yes | R20: 0 | T20: 1 | V20: 0.95 | W20: A review of pyrolysis technologies and feedstock: A blending approach for plastic and biomass towards optimum biochar yield | X20: =Tab_Def_Flows[[#This Row],[CC_DM'[%']]]*Tab_Def_Flows[[#This Row],[DM]] -> 0.95
A21: FALSE | B21: =ROW()-1 -> 20 | C21: ="F_"&LEFT(K21,2)&"_"&LEFT(M21,2) -> F_00_13 | D21: Rye Environment | F21: BB | H21: Product | J21: Environment | K21: =_xlfn.XLOOKUP(J21,Tab_Def_Processes[Name(EN)],Tab_Def_Processes[Process_ID],,0,) -> 00_Env_BB | L21: Rye cultivation | M21: =_xlfn.XLOOKUP(L21,Tab_Def_Processes[Name(EN)],Tab_Def_Processes[Process_ID],,0,) -> 13_Rye_BB | O21: Yes | P21: Yes | Q21: Yes | R21: 0.06 | T21: 0.94 | U21: assumption | V21: 0.49 | W21: assumption | X21: =Tab_Def_Flows[[#This Row],[CC_DM'[%']]]*Tab_Def_Flows[[#This Row],[DM]] -> 0.4606
A22: FALSE | B22: =ROW()-1 -> 21 | C22: ="F_"&LEFT(K22,2)&"_"&LEFT(M22,2) -> F_00_04 | D22: Cow Manure Environment | F22: BB | H22: By-Product | J22: Environment | K22: =_xlfn.XLOOKUP(J22,Tab_Def_Processes[Name(EN)],Tab_Def_Processes[Process_ID],,0,) -> 00_Env_BB | L22: Life stock farming | M22: =_xlfn.XLOOKUP(L22,Tab_Def_Processes[Name(EN)],Tab_Def_Processes[Process_ID],,0,) -> 04_Lif_BB | O22: Yes | P22: Yes | Q22: Yes | R22: 0.94 | T22: 0.06 | U22: Stramento | V22: 0.49 | W22: Stramento | X22: =Tab_Def_Flows[[#This Row],[CC_DM'[%']]]*Tab_Def_Flows[[#This Row],[DM]] -> 0.0294
A23: FALSE | B23: =ROW()-1 -> 22 | C23: ="F_"&LEFT(K23,2)&"_"&LEFT(M23,2) -> F_00_11 | D23: Millet grain Environment | F23: BB | H23: Product | J23: Environment | K23: =_xlfn.XLOOKUP(J23,Tab_Def_Processes[Name(EN)],Tab_Def_Processes[Process_ID],,0,) -> 00_Env_BB | L23: Millet production | M23: =_xlfn.XLOOKUP(L23,Tab_Def_Processes[Name(EN)],Tab_Def_Processes[Process_ID],,0,) -> 11_Mil_BB | O23: Yes | P23: Yes | Q23: Yes | R23: 0.66 | T23: 0.34 | V23: 0.47 | X23: =Tab_Def_Flows[[#This Row],[CC_DM'[%']]]*Tab_Def_Flows[[#This Row],[DM]] -> 0.1598
A24: FALSE | B24: =ROW()-1 -> 23 | C24: ="F_"&LEFT(K24,2)&"_"&LEFT(M24,2) -> F_00_08 | D24: Water Environment | F24: BB | H24: Product | J24: Environment | K24: =_xlfn.XLOOKUP(J24,Tab_Def_Processes[Name(EN)],Tab_Def_Processes[Process_ID],,0,) -> 00_Env_BB | L24: Water System (Import) | M24: =_xlfn.XLOOKUP(L24,Tab_Def_Processes[Name(EN)],Tab_Def_Processes[Process_ID],,0,) -> 08_Wat_BB | O24: Yes | P24: Yes | Q24: Yes | R24: 1 | T24: 0 | V24: 0 | X24: =Tab_Def_Flows[[#This Row],[CC_DM'[%']]]*Tab_Def_Flows[[#This Row],[DM]] -> 0
A25: FALSE | B25: =ROW()-1 -> 24 | C25: ="F_"&LEFT(K25,2)&"_"&LEFT(M25,2) -> F_09_19 | D25: Flue Gas from Biomass Pyrolysis | F25: BB | H25: Biomass Pyrolysis | J25: Biomass Pyrolysis | K25: =_xlfn.XLOOKUP(J25,Tab_Def_Processes[Name(EN)],Tab_Def_Processes[Process_ID],,0,) -> 09_Bio_BB | L25: Atmosphere | M25: =_xlfn.XLOOKUP(L25,Tab_Def_Processes[Name(EN)],Tab_Def_Processes[Process_ID],,0,) -> 19_Atm_BB | O25: Yes | P25: Yes | Q25: Yes | R25: 0 | T25: 1 | V25: 0.95 | W25: A review of pyrolysis technologies and feedstock: A blending approach for plastic and biomass towards optimum biochar yield | X25: =Tab_Def_Flows[[#This Row],[CC_DM'[%']]]*Tab_Def_Flows[[#This Row],[DM]] -> 0.95
A26: FALSE | B26: =ROW()-1 -> 25 | C26: ="F_"&LEFT(K26,2)&"_"&LEFT(M26,2) -> F_17_19 | D26: CO2 Sequestration | F26: BB | H26: Waste | J26: Lithosphere | K26: =_xlfn.XLOOKUP(J26,Tab_Def_Processes[Name(EN)],Tab_Def_Processes[Process_ID],,0,) -> 17_Lit_BB | L26: Atmosphere | M26: =_xlfn.XLOOKUP(L26,Tab_Def_Processes[Name(EN)],Tab_Def_Processes[Process_ID],,0,) -> 19_Atm_BB | O26: Yes | P26: Yes | Q26: Yes | R26: 0 | T26: 0 | V26: 0 | X26: =12.011/(12.011+2*15.999) -> 0.27292145
A27: FALSE | B27: =ROW()-1 -> 26 | C27: ="F_"&LEFT(K27,2)&"_"&LEFT(M27,2) -> F_21_21 | K27: =_xlfn.XLOOKUP(J27,Tab_Def_Processes[Name(EN)],Tab_Def_Processes[Process_ID],,0,) -> 21__ | M27: =_xlfn.XLOOKUP(L27,Tab_Def_Processes[Name(EN)],Tab_Def_Processes[Process_ID],,0,) -> 21__
A28: FALSE | B28: =ROW()-1 -> 27 | C28: ="F_"&LEFT(K28,2)&"_"&LEFT(M28,2) -> F_21_21 | K28: =_xlfn.XLOOKUP(J28,Tab_Def_Processes[Name(EN)],Tab_Def_Processes[Process_ID],,0,) -> 21__ | M28: =_xlfn.XLOOKUP(L28,Tab_Def_Processes[Name(EN)],Tab_Def_Processes[Process_ID],,0,) -> 21__
A29: FALSE | B29: =ROW()-1 -> 28 | C29: ="F_"&LEFT(K29,2)&"_"&LEFT(M29,2) -> F_21_21 | K29: =_xlfn.XLOOKUP(J29,Tab_Def_Processes[Name(EN)],Tab_Def_Processes[Process_ID],,0,) -> 21__ | M29: =_xlfn.XLOOKUP(L29,Tab_Def_Processes[Name(EN)],Tab_Def_Processes[Process_ID],,0,) -> 21__
A30: FALSE | B30: =ROW()-1 -> 29 | C30: ="F_"&LEFT(K30,2)&"_"&LEFT(M30,2) -> F_21_21 | K30: =_xlfn.XLOOKUP(J30,Tab_Def_Processes[Name(EN)],Tab_Def_Processes[Process_ID],,0,) -> 21__ | M30: =_xlfn.XLOOKUP(L30,Tab_Def_Processes[Name(EN)],Tab_Def_Processes[Process_ID],,0,) -> 21__
A31: FALSE | B31: =ROW()-1 -> 30 | C31: ="F_"&LEFT(K31,2)&"_"&LEFT(M31,2) -> F_21_21 | K31: =_xlfn.XLOOKUP(J31,Tab_Def_Processes[Name(EN)],Tab_Def_Processes[Process_ID],,0,) -> 21__ | M31: =_xlfn.XLOOKUP(L31,Tab_Def_Processes[Name(EN)],Tab_Def_Processes[Process_ID],,0,) -> 21__
A32: FALSE | B32: =ROW()-1 -> 31 | C32: ="F_"&LEFT(K32,2)&"_"&LEFT(M32,2) -> F_21_21 | K32: =_xlfn.XLOOKUP(J32,Tab_Def_Processes[Name(EN)],Tab_Def_Processes[Process_ID],,0,) -> 21__ | M32: =_xlfn.XLOOKUP(L32,Tab_Def_Processes[Name(EN)],Tab_Def_Processes[Process_ID],,0,) -> 21__
A33: FALSE | B33: =ROW()-1 -> 32 | C33: ="F_"&LEFT(K33,2)&"_"&LEFT(M33,2) -> F_21_21 | K33: =_xlfn.XLOOKUP(J33,Tab_Def_Processes[Name(EN)],Tab_Def_Processes[Process_ID],,0,) -> 21__ | M33: =_xlfn.XLOOKUP(L33,Tab_Def_Processes[Name(EN)],Tab_Def_Processes[Process_ID],,0,) -> 21__
A34: FALSE | B34: =ROW()-1 -> 33 | C34: ="F_"&LEFT(K34,2)&"_"&LEFT(M34,2) -> F_21_21 | K34: =_xlfn.XLOOKUP(J34,Tab_Def_Processes[Name(EN)],Tab_Def_Processes[Process_ID],,0,) -> 21__ | M34: =_xlfn.XLOOKUP(L34,Tab_Def_Processes[Name(EN)],Tab_Def_Processes[Process_ID],,0,) -> 21__
A35: FALSE | B35: =ROW()-1 -> 34 | C35: ="F_"&LEFT(K35,2)&"_"&LEFT(M35,2) -> F_21_21 | K35: =_xlfn.XLOOKUP(J35,Tab_Def_Processes[Name(EN)],Tab_Def_Processes[Process_ID],,0,) -> 21__ | M35: =_xlfn.XLOOKUP(L35,Tab_Def_Processes[Name(EN)],Tab_Def_Processes[Process_ID],,0,) -> 21__
A36: FALSE | B36: =ROW()-1 -> 35 | C36: ="F_"&LEFT(K36,2)&"_"&LEFT(M36,2) -> F_21_21 | K36: =_xlfn.XLOOKUP(J36,Tab_Def_Processes[Name(EN)],Tab_Def_Processes[Process_ID],,0,) -> 21__ | M36: =_xlfn.XLOOKUP(L36,Tab_Def_Processes[Name(EN)],Tab_Def_Processes[Process_ID],,0,) -> 21__
A37: FALSE | B37: =ROW()-1 -> 36 | C37: ="F_"&LEFT(K37,2)&"_"&LEFT(M37,2) -> F_21_21 | K37: =_xlfn.XLOOKUP(J37,Tab_Def_Processes[Name(EN)],Tab_Def_Processes[Process_ID],,0,) -> 21__ | M37: =_xlfn.XLOOKUP(L37,Tab_Def_Processes[Name(EN)],Tab_Def_Processes[Process_ID],,0,) -> 21__
A38: FALSE | B38: =ROW()-1 -> 37 | C38: ="F_"&LEFT(K38,2)&"_"&LEFT(M38,2) -> F_21_21 | K38: =_xlfn.XLOOKUP(J38,Tab_Def_Processes[Name(EN)],Tab_Def_Processes[Process_ID],,0,) -> 21__ | M38: =_xlfn.XLOOKUP(L38,Tab_Def_Processes[Name(EN)],Tab_Def_Processes[Process_ID],,0,) -> 21__
... A62: FALSE | B62: =ROW()-1 -> 61 | C62: ="F_"&LEFT(K62,2)&"_"&LEFT(M62,2) -> F_21_21 | K62: =_xlfn.XLOOKUP(J62,Tab_Def_Processes[Name(EN)],Tab_Def_Processes[Process_ID],,0,) -> 21__ | M62: =_xlfn.XLOOKUP(L62,Tab_Def_Processes[Name(EN)],Tab_Def_Processes[Process_ID],,0,) -> 21__
A63: FALSE | B63: =ROW()-1 -> 62 | C63: ="F_"&LEFT(K63,2)&"_"&LEFT(M63,2) -> F_21_21 | K63: =_xlfn.XLOOKUP(J63,Tab_Def_Processes[Name(EN)],Tab_Def_Processes[Process_ID],,0,) -> 21__ | M63: =_xlfn.XLOOKUP(L63,Tab_Def_Processes[Name(EN)],Tab_Def_Processes[Process_ID],,0,) -> 21__ | O63: Yes
...

Sheet 1_2_Data_Flows
A1: ID | B1: Flow_ID | C1: Name(EN) | D1: Type_Biomass | E1: Output_Process | F1: Process_ID_O | G1: Input_Process | H1: Process_ID_I | I1: TC? | J1: WC? | K1: DM? | L1: CC? | M1: Year_Flow | N1: Region_Flow | O1: Flow_Source | P1: UoM_Source | Q1: Name_Source | R1: AVV | S1: Titel_Source | T1: Year_Source | U1: Author_Source | V1: Type_Source | W1: URL | X1: CF_required? | Y1: CF | Z1: Name_CF | AA1: Flow_Py | AB1: UoM_Flow_Py | AC1: WC_[%] | AD1: WC_Flow_Py | AE1: UoM_WC_Flow_Py | AF1: DM_[%] | AG1: DM_Flow_Py2 | AH1: UoM_DM_Flow_Py | AI1: CC_[%] | AJ1: CC_Flow_Py | AK1: UoM_CC_Flow_Py
A2: =ROW()-1 -> 1 | B2: =_xlfn.XLOOKUP(C2,Tab_Def_Flows[Name(EN)],Tab_Def_Flows[Flow_ID],,0,) -> F_13_20 | C2: Rye plant | D2: =_xlfn.XLOOKUP(C2,Tab_Def_Flows[Name(EN)],Tab_Def_Flows[Type_Biomass],,0,) -> 0 | E2: =_xlfn.XLOOKUP(C2,Tab_Def_Flows[Name(EN)],Tab_Def_Flows[Output_Process],,0,) -> Rye cultivation | F2: =_xlfn.XLOOKUP(C2,Tab_Def_Flows[Name(EN)],Tab_Def_Flows[Process_ID_O],,0,) -> 13_Rye_BB | G2: =_xlfn.XLOOKUP(C2,Tab_Def_Flows[Name(EN)],Tab_Def_Flows[Input_Process],,0,) -> Rye cultivation and harvest | H2: =_xlfn.XLOOKUP(C2,Tab_Def_Flows[Name(EN)],Tab_Def_Flows[Process_ID_I],,0,) -> 20_Rye_BB | I2: =_xlfn.XLOOKUP(C2,Tab_Def_Flows[Name(EN)],Tab_Def_Flows[Value_Source],,0,) -> Data_assumption | J2: =_xlfn.XLOOKUP(C2,Tab_Def_Flows[Name(EN)],Tab_Def_Flows[WC?],,0,) -> Yes | K2: =_xlfn.XLOOKUP(C2,Tab_Def_Flows[Name(EN)],Tab_Def_Flows[DM?],,0,) -> Yes | L2: =_xlfn.XLOOKUP(C2,Tab_Def_Flows[Name(EN)],Tab_Def_Flows[CC?],,0,) -> Yes | M2: 2022 | N2: BB | O2: 129 | P2: Mg/a | Q2: Stramento | X2: No | Y2: 365 | AA2: =IF(X2="no",O2,O2*Y2) -> 129 | AB2: Mg | AC2: =INDEX(Tab_Def_Flows[[Flow_ID]:[CC_DM_source]],MATCH(Tab_Data_Flows[[#This Row],[Name(EN)]],Tab_Def_Flows[Name(EN)],0),16) -> 0.06 | AD2: =IF(J2="Yes",AA2*Tab_Data_Flows[[#This Row],[WC_'[%']]],"N.A.") -> 7.74 | AE2: =Tab_Data_Flows[[#This Row],[UoM_Flow_Py]] -> Mg | AF2: =INDEX(Tab_Def_Flows[[Flow_ID]:[CC_DM_source]],MATCH(Tab_Data_Flows[[#This Row],[Name(EN)]],Tab_Def_Flows[Name(EN)],0),18) -> 0.94 | AG2: =IF(K2="Yes",AF2*Tab_Data_Flows[[#This Row],[Flow_Py]],"N.A.") -> 121.26 | AH2: =Tab_Data_Flows[[#This Row],[UoM_Flow_Py]] -> Mg | AI2: =INDEX(Tab_Def_Flows[[Flow_ID]:[CC_DM_source]],MATCH(Tab_Data_Flows[[#This Row],[Name(EN)]],Tab_Def_Flows[Name(EN)],0),20) -> 0.49 | AJ2: =IF(L2="Yes",AI2*Tab_Data_Flows[[#This Row],[Flow_Py]],"N.A.") -> 63.21 | AK2: =Tab_Data_Flows[[#This Row],[UoM_Flow_Py]] -> Mg
A3: =ROW()-1 -> 2 | B3: =_xlfn.XLOOKUP(C3,Tab_Def_Flows[Name(EN)],Tab_Def_Flows[Flow_ID],,0,) -> F_13_20 | C3: Rye plant | D3: =_xlfn.XLOOKUP(C3,Tab_Def_Flows[Name(EN)],Tab_Def_Flows[Type_Biomass],,0,) -> 0 | E3: =_xlfn.XLOOKUP(C3,Tab_Def_Flows[Name(EN)],Tab_Def_Flows[Output_Process],,0,) -> Rye cultivation | F3: =_xlfn.XLOOKUP(C3,Tab_Def_Flows[Name(EN)],Tab_Def_Flows[Process_ID_O],,0,) -> 13_Rye_BB | G3: =_xlfn.XLOOKUP(C3,Tab_Def_Flows[Name(EN)],Tab_Def_Flows[Input_Process],,0,) -> Rye cultivation and harvest | H3: =_xlfn.XLOOKUP(C3,Tab_Def_Flows[Name(EN)],Tab_Def_Flows[Process_ID_I],,0,) -> 20_Rye_BB | I3: =_xlfn.XLOOKUP(C3,Tab_Def_Flows[Name(EN)],Tab_Def_Flows[Value_Source],,0,) -> Data_assumption | J3: =_xlfn.XLOOKUP(C3,Tab_Def_Flows[Name(EN)],Tab_Def_Flows[WC?],,0,) -> Yes | K3: =_xlfn.XLOOKUP(C3,Tab_Def_Flows[Name(EN)],Tab_Def_Flows[DM?],,0,) -> Yes | L3: =_xlfn.XLOOKUP(C3,Tab_Def_Flows[Name(EN)],Tab_Def_Flows[CC?],,0,) -> Yes | M3: 2023 | N3: BB | O3: =O2*1.02 -> 131.58 | P3: Mg/a | Q3: Stramento | X3: No | Y3: 365 | AA3: =IF(X3="no",O3,O3*Y3) -> 131.58 | AB3: Mg | AC3: =INDEX(Tab_Def_Flows[[Flow_ID]:[CC_DM_source]],MATCH(Tab_Data_Flows[[#This Row],[Name(EN)]],Tab_Def_Flows[Name(EN)],0),16) -> 0.06 | AD3: =IF(J3="Yes",AA3*Tab_Data_Flows[[#This Row],[WC_'[%']]],"N.A.") -> 7.8948 | AE3: =Tab_Data_Flows[[#This Row],[UoM_Flow_Py]] -> Mg | AF3: =INDEX(Tab_Def_Flows[[Flow_ID]:[CC_DM_source]],MATCH(Tab_Data_Flows[[#This Row],[Name(EN)]],Tab_Def_Flows[Name(EN)],0),18) -> 0.94 | AG3: =IF(K3="Yes",AF3*Tab_Data_Flows[[#This Row],[Flow_Py]],"N.A.") -> 123.6852 | AH3: =Tab_Data_Flows[[#This Row],[UoM_Flow_Py]] -> Mg | AI3: =INDEX(Tab_Def_Flows[[Flow_ID]:[CC_DM_source]],MATCH(Tab_Data_Flows[[#This Row],[Name(EN)]],Tab_Def_Flows[Name(EN)],0),20) -> 0.49 | AJ3: =IF(L3="Yes",AI3*Tab_Data_Flows[[#This Row],[Flow_Py]],"N.A.") -> 64.4742 | AK3: =Tab_Data_Flows[[#This Row],[UoM_Flow_Py]] -> Mg
A4: =ROW()-1 -> 3 | B4: =_xlfn.XLOOKUP(C4,Tab_Def_Flows[Name(EN)],Tab_Def_Flows[Flow_ID],,0,) -> F_13_20 | C4: Rye plant | D4: =_xlfn.XLOOKUP(C4,Tab_Def_Flows[Name(EN)],Tab_Def_Flows[Type_Biomass],,0,) -> 0 | E4: =_xlfn.XLOOKUP(C4,Tab_Def_Flows[Name(EN)],Tab_Def_Flows[Output_Process],,0,) -> Rye cultivation | F4: =_xlfn.XLOOKUP(C4,Tab_Def_Flows[Name(EN)],Tab_Def_Flows[Process_ID_O],,0,) -> 13_Rye_BB | G4: =_xlfn.XLOOKUP(C4,Tab_Def_Flows[Name(EN)],Tab_Def_Flows[Input_Process],,0,) -> Rye cultivation and harvest | H4: =_xlfn.XLOOKUP(C4,Tab_Def_Flows[Name(EN)],Tab_Def_Flows[Process_ID_I],,0,) -> 20_Rye_BB | I4: =_xlfn.XLOOKUP(C4,Tab_Def_Flows[Name(EN)],Tab_Def_Flows[Value_Source],,0,) -> Data_assumption | J4: =_xlfn.XLOOKUP(C4,Tab_Def_Flows[Name(EN)],Tab_Def_Flows[WC?],,0,) -> Yes | K4: =_xlfn.XLOOKUP(C4,Tab_Def_Flows[Name(EN)],Tab_Def_Flows[DM?],,0,) -> Yes | L4: =_xlfn.XLOOKUP(C4,Tab_Def_Flows[Name(EN)],Tab_Def_Flows[CC?],,0,) -> Yes | M4: 2024 | N4: BB | O4: =O3*1.02 -> 134.2116 | P4: Mg/a | Q4: Stramento | X4: No | Y4: 365 | AA4: =IF(X4="no",O4,O4*Y4) -> 134.2116 | AB4: Mg | AC4: =INDEX(Tab_Def_Flows[[Flow_ID]:[CC_DM_source]],MATCH(Tab_Data_Flows[[#This Row],[Name(EN)]],Tab_Def_Flows[Name(EN)],0),16) -> 0.06 | AD4: =IF(J4="Yes",AA4*Tab_Data_Flows[[#This Row],[WC_'[%']]],"N.A.") -> 8.052696 | AE4: =Tab_Data_Flows[[#This Row],[UoM_Flow_Py]] -> Mg | AF4: =INDEX(Tab_Def_Flows[[Flow_ID]:[CC_DM_source]],MATCH(Tab_Data_Flows[[#This Row],[Name(EN)]],Tab_Def_Flows[Name(EN)],0),18) -> 0.94 | AG4: =IF(K4="Yes",AF4*Tab_Data_Flows[[#This Row],[Flow_Py]],"N.A.") -> 126.1589 | AH4: =Tab_Data_Flows[[#This Row],[UoM_Flow_Py]] -> Mg | AI4: =INDEX(Tab_Def_Flows[[Flow_ID]:[CC_DM_source]],MATCH(Tab_Data_Flows[[#This Row],[Name(EN)]],Tab_Def_Flows[Name(EN)],0),20) -> 0.49 | AJ4: =IF(L4="Yes",AI4*Tab_Data_Flows[[#This Row],[Flow_Py]],"N.A.") -> 65.763684 | AK4: =Tab_Data_Flows[[#This Row],[UoM_Flow_Py]] -> Mg
A5: =ROW()-1 -> 4 | B5: =_xlfn.XLOOKUP(C5,Tab_Def_Flows[Name(EN)],Tab_Def_Flows[Flow_ID],,0,) -> F_13_20 | C5: Rye plant | D5: =_xlfn.XLOOKUP(C5,Tab_Def_Flows[Name(EN)],Tab_Def_Flows[Type_Biomass],,0,) -> 0 | E5: =_xlfn.XLOOKUP(C5,Tab_Def_Flows[Name(EN)],Tab_Def_Flows[Output_Process],,0,) -> Rye cultivation | F5: =_xlfn.XLOOKUP(C5,Tab_Def_Flows[Name(EN)],Tab_Def_Flows[Process_ID_O],,0,) -> 13_Rye_BB | G5: =_xlfn.XLOOKUP(C5,Tab_Def_Flows[Name(EN)],Tab_Def_Flows[Input_Process],,0,) -> Rye cultivation and harvest | H5: =_xlfn.XLOOKUP(C5,Tab_Def_Flows[Name(EN)],Tab_Def_Flows[Process_ID_I],,0,) -> 20_Rye_BB | I5: =_xlfn.XLOOKUP(C5,Tab_Def_Flows[Name(EN)],Tab_Def_Flows[Value_Source],,0,) -> Data_assumption | J5: =_xlfn.XLOOKUP(C5,Tab_Def_Flows[Name(EN)],Tab_Def_Flows[WC?],,0,) -> Yes | K5: =_xlfn.XLOOKUP(C5,Tab_Def_Flows[Name(EN)],Tab_Def_Flows[DM?],,0,) -> Yes | L5: =_xlfn.XLOOKUP(C5,Tab_Def_Flows[Name(EN)],Tab_Def_Flows[CC?],,0,) -> Yes | M5: 2025 | N5: BB | O5: =O4*1.02 -> 136.89583 | P5: Mg/a | Q5: Stramento | X5: No | Y5: 365 | AA5: =IF(X5="no",O5,O5*Y5) -> 136.89583 | AB5: Mg | AC5: =INDEX(Tab_Def_Flows[[Flow_ID]:[CC_DM_source]],MATCH(Tab_Data_Flows[[#This Row],[Name(EN)]],Tab_Def_Flows[Name(EN)],0),16) -> 0.06 | AD5: =IF(J5="Yes",AA5*Tab_Data_Flows[[#This Row],[WC_'[%']]],"N.A.") -> 8.2137499 | AE5: =Tab_Data_Flows[[#This Row],[UoM_Flow_Py]] -> Mg | AF5: =INDEX(Tab_Def_Flows[[Flow_ID]:[CC_DM_source]],MATCH(Tab_Data_Flows[[#This Row],[Name(EN)]],Tab_Def_Flows[Name(EN)],0),18) -> 0.94 | AG5: =IF(K5="Yes",AF5*Tab_Data_Flows[[#This Row],[Flow_Py]],"N.A.") -> 128.68208 | AH5: =Tab_Data_Flows[[#This Row],[UoM_Flow_Py]] -> Mg | AI5: =INDEX(Tab_Def_Flows[[Flow_ID]:[CC_DM_source]],MATCH(Tab_Data_Flows[[#This Row],[Name(EN)]],Tab_Def_Flows[Name(EN)],0),20) -> 0.49 | AJ5: =IF(L5="Yes",AI5*Tab_Data_Flows[[#This Row],[Flow_Py]],"N.A.") -> 67.078958 | AK5: =Tab_Data_Flows[[#This Row],[UoM_Flow_Py]] -> Mg
A6: =ROW()-1 -> 5 | B6: =_xlfn.XLOOKUP(C6,Tab_Def_Flows[Name(EN)],Tab_Def_Flows[Flow_ID],,0,) -> F_13_20 | C6: Rye plant | D6: =_xlfn.XLOOKUP(C6,Tab_Def_Flows[Name(EN)],Tab_Def_Flows[Type_Biomass],,0,) -> 0 | E6: =_xlfn.XLOOKUP(C6,Tab_Def_Flows[Name(EN)],Tab_Def_Flows[Output_Process],,0,) -> Rye cultivation | F6: =_xlfn.XLOOKUP(C6,Tab_Def_Flows[Name(EN)],Tab_Def_Flows[Process_ID_O],,0,) -> 13_Rye_BB | G6: =_xlfn.XLOOKUP(C6,Tab_Def_Flows[Name(EN)],Tab_Def_Flows[Input_Process],,0,) -> Rye cultivation and harvest | H6: =_xlfn.XLOOKUP(C6,Tab_Def_Flows[Name(EN)],Tab_Def_Flows[Process_ID_I],,0,) -> 20_Rye_BB | I6: =_xlfn.XLOOKUP(C6,Tab_Def_Flows[Name(EN)],Tab_Def_Flows[Value_Source],,0,) -> Data_assumption | J6: =_xlfn.XLOOKUP(C6,Tab_Def_Flows[Name(EN)],Tab_Def_Flows[WC?],,0,) -> Yes | K6: =_xlfn.XLOOKUP(C6,Tab_Def_Flows[Name(EN)],Tab_Def_Flows[DM?],,0,) -> Yes | L6: =_xlfn.XLOOKUP(C6,Tab_Def_Flows[Name(EN)],Tab_Def_Flows[CC?],,0,) -> Yes | M6: 2026 | N6: BB | O6: =O5*1.02 -> 139.63375 | P6: Mg/a | Q6: Stramento | X6: No | Y6: 365 | AA6: =IF(X6="no",O6,O6*Y6) -> 139.63375 | AB6: Mg | AC6: =INDEX(Tab_Def_Flows[[Flow_ID]:[CC_DM_source]],MATCH(Tab_Data_Flows[[#This Row],[Name(EN)]],Tab_Def_Flows[Name(EN)],0),16) -> 0.06 | AD6: =IF(J6="Yes",AA6*Tab_Data_Flows[[#This Row],[WC_'[%']]],"N.A.") -> 8.3780249 | AE6: =Tab_Data_Flows[[#This Row],[UoM_Flow_Py]] -> Mg | AF6: =INDEX(Tab_Def_Flows[[Flow_ID]:[CC_DM_source]],MATCH(Tab_Data_Flows[[#This Row],[Name(EN)]],Tab_Def_Flows[Name(EN)],0),18) -> 0.94 | AG6: =IF(K6="Yes",AF6*Tab_Data_Flows[[#This Row],[Flow_Py]],"N.A.") -> 131.25572 | AH6: =Tab_Data_Flows[[#This Row],[UoM_Flow_Py]] -> Mg | AI6: =INDEX(Tab_Def_Flows[[Flow_ID]:[CC_DM_source]],MATCH(Tab_Data_Flows[[#This Row],[Name(EN)]],Tab_Def_Flows[Name(EN)],0),20) -> 0.49 | AJ6: =IF(L6="Yes",AI6*Tab_Data_Flows[[#This Row],[Flow_Py]],"N.A.") -> 68.420537 | AK6: =Tab_Data_Flows[[#This Row],[UoM_Flow_Py]] -> Mg
A7: =ROW()-1 -> 6 | B7: =_xlfn.XLOOKUP(C7,Tab_Def_Flows[Name(EN)],Tab_Def_Flows[Flow_ID],,0,) -> F_13_20 | C7: Rye plant | D7: =_xlfn.XLOOKUP(C7,Tab_Def_Flows[Name(EN)],Tab_Def_Flows[Type_Biomass],,0,) -> 0 | E7: =_xlfn.XLOOKUP(C7,Tab_Def_Flows[Name(EN)],Tab_Def_Flows[Output_Process],,0,) -> Rye cultivation | F7: =_xlfn.XLOOKUP(C7,Tab_Def_Flows[Name(EN)],Tab_Def_Flows[Process_ID_O],,0,) -> 13_Rye_BB | G7: =_xlfn.XLOOKUP(C7,Tab_Def_Flows[Name(EN)],Tab_Def_Flows[Input_Process],,0,) -> Rye cultivation and harvest | H7: =_xlfn.XLOOKUP(C7,Tab_Def_Flows[Name(EN)],Tab_Def_Flows[Process_ID_I],,0,) -> 20_Rye_BB | I7: =_xlfn.XLOOKUP(C7,Tab_Def_Flows[Name(EN)],Tab_Def_Flows[Value_Source],,0,) -> Data_assumption | J7: =_xlfn.XLOOKUP(C7,Tab_Def_Flows[Name(EN)],Tab_Def_Flows[WC?],,0,) -> Yes | K7: =_xlfn.XLOOKUP(C7,Tab_Def_Flows[Name(EN)],Tab_Def_Flows[DM?],,0,) -> Yes | L7: =_xlfn.XLOOKUP(C7,Tab_Def_Flows[Name(EN)],Tab_Def_Flows[CC?],,0,) -> Yes | M7: 2027 | N7: BB | O7: =O6*1.02 -> 142.42642 | P7: Mg/a | Q7: Stramento | X7: No | Y7: 365 | AA7: =IF(X7="no",O7,O7*Y7) -> 142.42642 | AB7: Mg | AC7: =INDEX(Tab_Def_Flows[[Flow_ID]:[CC_DM_source]],MATCH(Tab_Data_Flows[[#This Row],[Name(EN)]],Tab_Def_Flows[Name(EN)],0),16) -> 0.06 | AD7: =IF(J7="Yes",AA7*Tab_Data_Flows[[#This Row],[WC_'[%']]],"N.A.") -> 8.5455854 | AE7: =Tab_Data_Flows[[#This Row],[UoM_Flow_Py]] -> Mg | AF7: =INDEX(Tab_Def_Flows[[Flow_ID]:[CC_DM_source]],MATCH(Tab_Data_Flows[[#This Row],[Name(EN)]],Tab_Def_Flows[Name(EN)],0),18) -> 0.94 | AG7: =IF(K7="Yes",AF7*Tab_Data_Flows[[#This Row],[Flow_Py]],"N.A.") -> 133.88084 | AH7: =Tab_Data_Flows[[#This Row],[UoM_Flow_Py]] -> Mg | AI7: =INDEX(Tab_Def_Flows[[Flow_ID]:[CC_DM_source]],MATCH(Tab_Data_Flows[[#This Row],[Name(EN)]],Tab_Def_Flows[Name(EN)],0),20) -> 0.49 | AJ7: =IF(L7="Yes",AI7*Tab_Data_Flows[[#This Row],[Flow_Py]],"N.A.") -> 69.788948 | AK7: =Tab_Data_Flows[[#This Row],[UoM_Flow_Py]] -> Mg
A8: =ROW()-1 -> 7 | B8: =_xlfn.XLOOKUP(C8,Tab_Def_Flows[Name(EN)],Tab_Def_Flows[Flow_ID],,0,) -> F_13_20 | C8: Rye plant | D8: =_xlfn.XLOOKUP(C8,Tab_Def_Flows[Name(EN)],Tab_Def_Flows[Type_Biomass],,0,) -> 0 | E8: =_xlfn.XLOOKUP(C8,Tab_Def_Flows[Name(EN)],Tab_Def_Flows[Output_Process],,0,) -> Rye cultivation | F8: =_xlfn.XLOOKUP(C8,Tab_Def_Flows[Name(EN)],Tab_Def_Flows[Process_ID_O],,0,) -> 13_Rye_BB | G8: =_xlfn.XLOOKUP(C8,Tab_Def_Flows[Name(EN)],Tab_Def_Flows[Input_Process],,0,) -> Rye cultivation and harvest | H8: =_xlfn.XLOOKUP(C8,Tab_Def_Flows[Name(EN)],Tab_Def_Flows[Process_ID_I],,0,) -> 20_Rye_BB | I8: =_xlfn.XLOOKUP(C8,Tab_Def_Flows[Name(EN)],Tab_Def_Flows[Value_Source],,0,) -> Data_assumption | J8: =_xlfn.XLOOKUP(C8,Tab_Def_Flows[Name(EN)],Tab_Def_Flows[WC?],,0,) -> Yes | K8: =_xlfn.XLOOKUP(C8,Tab_Def_Flows[Name(EN)],Tab_Def_Flows[DM?],,0,) -> Yes | L8: =_xlfn.XLOOKUP(C8,Tab_Def_Flows[Name(EN)],Tab_Def_Flows[CC?],,0,) -> Yes | M8: 2028 | N8: BB | O8: =O7*1.02 -> 145.27495 | P8: Mg/a | Q8: Stramento | X8: No | Y8: 365 | AA8: =IF(X8="no",O8,O8*Y8) -> 145.27495 | AB8: Mg | AC8: =INDEX(Tab_Def_Flows[[Flow_ID]:[CC_DM_source]],MATCH(Tab_Data_Flows[[#This Row],[Name(EN)]],Tab_Def_Flows[Name(EN)],0),16) -> 0.06 | AD8: =IF(J8="Yes",AA8*Tab_Data_Flows[[#This Row],[WC_'[%']]],"N.A.") -> 8.7164971 | AE8: =Tab_Data_Flows[[#This Row],[UoM_Flow_Py]] -> Mg | AF8: =INDEX(Tab_Def_Flows[[Flow_ID]:[CC_DM_source]],MATCH(Tab_Data_Flows[[#This Row],[Name(EN)]],Tab_Def_Flows[Name(EN)],0),18) -> 0.94 | AG8: =IF(K8="Yes",AF8*Tab_Data_Flows[[#This Row],[Flow_Py]],"N.A.") -> 136.55845 | AH8: =Tab_Data_Flows[[#This Row],[UoM_Flow_Py]] -> Mg | AI8: =INDEX(Tab_Def_Flows[[Flow_ID]:[CC_DM_source]],MATCH(Tab_Data_Flows[[#This Row],[Name(EN)]],Tab_Def_Flows[Name(EN)],0),20) -> 0.49 | AJ8: =IF(L8="Yes",AI8*Tab_Data_Flows[[#This Row],[Flow_Py]],"N.A.") -> 71.184727 | AK8: =Tab_Data_Flows[[#This Row],[UoM_Flow_Py]] -> Mg
A9: =ROW()-1 -> 8 | B9: =_xlfn.XLOOKUP(C9,Tab_Def_Flows[Name(EN)],Tab_Def_Flows[Flow_ID],,0,) -> F_13_20 | C9: Rye plant | D9: =_xlfn.XLOOKUP(C9,Tab_Def_Flows[Name(EN)],Tab_Def_Flows[Type_Biomass],,0,) -> 0 | E9: =_xlfn.XLOOKUP(C9,Tab_Def_Flows[Name(EN)],Tab_Def_Flows[Output_Process],,0,) -> Rye cultivation | F9: =_xlfn.XLOOKUP(C9,Tab_Def_Flows[Name(EN)],Tab_Def_Flows[Process_ID_O],,0,) -> 13_Rye_BB | G9: =_xlfn.XLOOKUP(C9,Tab_Def_Flows[Name(EN)],Tab_Def_Flows[Input_Process],,0,) -> Rye cultivation and harvest | H9: =_xlfn.XLOOKUP(C9,Tab_Def_Flows[Name(EN)],Tab_Def_Flows[Process_ID_I],,0,) -> 20_Rye_BB | I9: =_xlfn.XLOOKUP(C9,Tab_Def_Flows[Name(EN)],Tab_Def_Flows[Value_Source],,0,) -> Data_assumption | J9: =_xlfn.XLOOKUP(C9,Tab_Def_Flows[Name(EN)],Tab_Def_Flows[WC?],,0,) -> Yes | K9: =_xlfn.XLOOKUP(C9,Tab_Def_Flows[Name(EN)],Tab_Def_Flows[DM?],,0,) -> Yes | L9: =_xlfn.XLOOKUP(C9,Tab_Def_Flows[Name(EN)],Tab_Def_Flows[CC?],,0,) -> Yes | M9: 2029 | N9: BB | O9: =O8*1.02 -> 148.18045 | P9: Mg/a | Q9: Stramento | X9: No | Y9: 366 | AA9: =IF(X9="no",O9,O9*Y9) -> 148.18045 | AB9: Mg | AC9: =INDEX(Tab_Def_Flows[[Flow_ID]:[CC_DM_source]],MATCH(Tab_Data_Flows[[#This Row],[Name(EN)]],Tab_Def_Flows[Name(EN)],0),16) -> 0.06 | AD9: =IF(J9="Yes",AA9*Tab_Data_Flows[[#This Row],[WC_'[%']]],"N.A.") -> 8.8908271 | AE9: =Tab_Data_Flows[[#This Row],[UoM_Flow_Py]] -> Mg | AF9: =INDEX(Tab_Def_Flows[[Flow_ID]:[CC_DM_source]],MATCH(Tab_Data_Flows[[#This Row],[Name(EN)]],Tab_Def_Flows[Name(EN)],0),18) -> 0.94 | AG9: =IF(K9="Yes",AF9*Tab_Data_Flows[[#This Row],[Flow_Py]],"N.A.") -> 139.28962 | AH9: =Tab_Data_Flows[[#This Row],[UoM_Flow_Py]] -> Mg | AI9: =INDEX(Tab_Def_Flows[[Flow_ID]:[CC_DM_source]],MATCH(Tab_Data_Flows[[#This Row],[Name(EN)]],Tab_Def_Flows[Name(EN)],0),20) -> 0.49 | AJ9: =IF(L9="Yes",AI9*Tab_Data_Flows[[#This Row],[Flow_Py]],"N.A.") -> 72.608421 | AK9: =Tab_Data_Flows[[#This Row],[UoM_Flow_Py]] -> Mg
A10: =ROW()-1 -> 9 | B10: =_xlfn.XLOOKUP(C10,Tab_Def_Flows[Name(EN)],Tab_Def_Flows[Flow_ID],,0,) -> F_13_20 | C10: Rye plant | D10: =_xlfn.XLOOKUP(C10,Tab_Def_Flows[Name(EN)],Tab_Def_Flows[Type_Biomass],,0,) -> 0 | E10: =_xlfn.XLOOKUP(C10,Tab_Def_Flows[Name(EN)],Tab_Def_Flows[Output_Process],,0,) -> Rye cultivation | F10: =_xlfn.XLOOKUP(C10,Tab_Def_Flows[Name(EN)],Tab_Def_Flows[Process_ID_O],,0,) -> 13_Rye_BB | G10: =_xlfn.XLOOKUP(C10,Tab_Def_Flows[Name(EN)],Tab_Def_Flows[Input_Process],,0,) -> Rye cultivation and harvest | H10: =_xlfn.XLOOKUP(C10,Tab_Def_Flows[Name(EN)],Tab_Def_Flows[Process_ID_I],,0,) -> 20_Rye_BB | I10: =_xlfn.XLOOKUP(C10,Tab_Def_Flows[Name(EN)],Tab_Def_Flows[Value_Source],,0,) -> Data_assumption | J10: =_xlfn.XLOOKUP(C10,Tab_Def_Flows[Name(EN)],Tab_Def_Flows[WC?],,0,) -> Yes | K10: =_xlfn.XLOOKUP(C10,Tab_Def_Flows[Name(EN)],Tab_Def_Flows[DM?],,0,) -> Yes | L10: =_xlfn.XLOOKUP(C10,Tab_Def_Flows[Name(EN)],Tab_Def_Flows[CC?],,0,) -> Yes | M10: 2030 | N10: BB | O10: =O9*1.02 -> 151.14406 | P10: Mg/a | Q10: Stramento | X10: No | Y10: 367 | AA10: =IF(X10="no",O10,O10*Y10) -> 151.14406 | AB10: Mg | AC10: =INDEX(Tab_Def_Flows[[Flow_ID]:[CC_DM_source]],MATCH(Tab_Data_Flows[[#This Row],[Name(EN)]],Tab_Def_Flows[Name(EN)],0),16) -> 0.06 | AD10: =IF(J10="Yes",AA10*Tab_Data_Flows[[#This Row],[WC_'[%']]],"N.A.") -> 9.0686436 | AE10: =Tab_Data_Flows[[#This Row],[UoM_Flow_Py]] -> Mg | AF10: =INDEX(Tab_Def_Flows[[Flow_ID]:[CC_DM_source]],MATCH(Tab_Data_Flows[[#This Row],[Name(EN)]],Tab_Def_Flows[Name(EN)],0),18) -> 0.94 | AG10: =IF(K10="Yes",AF10*Tab_Data_Flows[[#This Row],[Flow_Py]],"N.A.") -> 142.07542 | AH10: =Tab_Data_Flows[[#This Row],[UoM_Flow_Py]] -> Mg | AI10: =INDEX(Tab_Def_Flows[[Flow_ID]:[CC_DM_source]],MATCH(Tab_Data_Flows[[#This Row],[Name(EN)]],Tab_Def_Flows[Name(EN)],0),20) -> 0.49 | AJ10: =IF(L10="Yes",AI10*Tab_Data_Flows[[#This Row],[Flow_Py]],"N.A.") -> 74.060589 | AK10: =Tab_Data_Flows[[#This Row],[UoM_Flow_Py]] -> Mg
A11: =ROW()-1 -> 10 | B11: =_xlfn.XLOOKUP(C11,Tab_Def_Flows[Name(EN)],Tab_Def_Flows[Flow_ID],,0,) -> F_13_20 | C11: Rye plant | D11: =_xlfn.XLOOKUP(C11,Tab_Def_Flows[Name(EN)],Tab_Def_Flows[Type_Biomass],,0,) -> 0 | E11: =_xlfn.XLOOKUP(C11,Tab_Def_Flows[Name(EN)],Tab_Def_Flows[Output_Process],,0,) -> Rye cultivation | F11: =_xlfn.XLOOKUP(C11,Tab_Def_Flows[Name(EN)],Tab_Def_Flows[Process_ID_O],,0,) -> 13_Rye_BB | G11: =_xlfn.XLOOKUP(C11,Tab_Def_Flows[Name(EN)],Tab_Def_Flows[Input_Process],,0,) -> Rye cultivation and harvest | H11: =_xlfn.XLOOKUP(C11,Tab_Def_Flows[Name(EN)],Tab_Def_Flows[Process_ID_I],,0,) -> 20_Rye_BB | I11: =_xlfn.XLOOKUP(C11,Tab_Def_Flows[Name(EN)],Tab_Def_Flows[Value_Source],,0,) -> Data_assumption | J11: =_xlfn.XLOOKUP(C11,Tab_Def_Flows[Name(EN)],Tab_Def_Flows[WC?],,0,) -> Yes | K11: =_xlfn.XLOOKUP(C11,Tab_Def_Flows[Name(EN)],Tab_Def_Flows[DM?],,0,) -> Yes | L11: =_xlfn.XLOOKUP(C11,Tab_Def_Flows[Name(EN)],Tab_Def_Flows[CC?],,0,) -> Yes | M11: 2031 | N11: BB | O11: =O10*1.02 -> 154.16694 | P11: Mg/a | Q11: Stramento | X11: No | Y11: 368 | AA11: =IF(X11="no",O11,O11*Y11) -> 154.16694 | AB11: Mg | AC11: =INDEX(Tab_Def_Flows[[Flow_ID]:[CC_DM_source]],MATCH(Tab_Data_Flows[[#This Row],[Name(EN)]],Tab_Def_Flows[Name(EN)],0),16) -> 0.06 | AD11: =IF(J11="Yes",AA11*Tab_Data_Flows[[#This Row],[WC_'[%']]],"N.A.") -> 9.2500165 | AE11: =Tab_Data_Flows[[#This Row],[UoM_Flow_Py]] -> Mg | AF11: =INDEX(Tab_Def_Flows[[Flow_ID]:[CC_DM_source]],MATCH(Tab_Data_Flows[[#This Row],[Name(EN)]],Tab_Def_Flows[Name(EN)],0),18) -> 0.94 | AG11: =IF(K11="Yes",AF11*Tab_Data_Flows[[#This Row],[Flow_Py]],"N.A.") -> 144.91692 | AH11: =Tab_Data_Flows[[#This Row],[UoM_Flow_Py]] -> Mg | AI11: =INDEX(Tab_Def_Flows[[Flow_ID]:[CC_DM_source]],MATCH(Tab_Data_Flows[[#This Row],[Name(EN)]],Tab_Def_Flows[Name(EN)],0),20) -> 0.49 | AJ11: =IF(L11="Yes",AI11*Tab_Data_Flows[[#This Row],[Flow_Py]],"N.A.") -> 75.541801 | AK11: =Tab_Data_Flows[[#This Row],[UoM_Flow_Py]] -> Mg
A12: =ROW()-1 -> 11 | B12: =_xlfn.XLOOKUP(C12,Tab_Def_Flows[Name(EN)],Tab_Def_Flows[Flow_ID],,0,) -> F_13_20 | C12: Rye plant | D12: =_xlfn.XLOOKUP(C12,Tab_Def_Flows[Name(EN)],Tab_Def_Flows[Type_Biomass],,0,) -> 0 | E12: =_xlfn.XLOOKUP(C12,Tab_Def_Flows[Name(EN)],Tab_Def_Flows[Output_Process],,0,) -> Rye cultivation | F12: =_xlfn.XLOOKUP(C12,Tab_Def_Flows[Name(EN)],Tab_Def_Flows[Process_ID_O],,0,) -> 13_Rye_BB | G12: =_xlfn.XLOOKUP(C12,Tab_Def_Flows[Name(EN)],Tab_Def_Flows[Input_Process],,0,) -> Rye cultivation and harvest | H12: =_xlfn.XLOOKUP(C12,Tab_Def_Flows[Name(EN)],Tab_Def_Flows[Process_ID_I],,0,) -> 20_Rye_BB | I12: =_xlfn.XLOOKUP(C12,Tab_Def_Flows[Name(EN)],Tab_Def_Flows[Value_Source],,0,) -> Data_assumption | J12: =_xlfn.XLOOKUP(C12,Tab_Def_Flows[Name(EN)],Tab_Def_Flows[WC?],,0,) -> Yes | K12: =_xlfn.XLOOKUP(C12,Tab_Def_Flows[Name(EN)],Tab_Def_Flows[DM?],,0,) -> Yes | L12: =_xlfn.XLOOKUP(C12,Tab_Def_Flows[Name(EN)],Tab_Def_Flows[CC?],,0,) -> Yes | M12: 2032 | N12: BB | O12: =O11*1.02 -> 157.25028 | P12: Mg/a | Q12: Stramento | X12: No | Y12: 369 | AA12: =IF(X12="no",O12,O12*Y12) -> 157.25028 | AB12: Mg | AC12: =INDEX(Tab_Def_Flows[[Flow_ID]:[CC_DM_source]],MATCH(Tab_Data_Flows[[#This Row],[Name(EN)]],Tab_Def_Flows[Name(EN)],0),16) -> 0.06 | AD12: =IF(J12="Yes",AA12*Tab_Data_Flows[[#This Row],[WC_'[%']]],"N.A.") -> 9.4350168 | AE12: =Tab_Data_Flows[[#This Row],[UoM_Flow_Py]] -> Mg | AF12: =INDEX(Tab_Def_Flows[[Flow_ID]:[CC_DM_source]],MATCH(Tab_Data_Flows[[#This Row],[Name(EN)]],Tab_Def_Flows[Name(EN)],0),18) -> 0.94 | AG12: =IF(K12="Yes",AF12*Tab_Data_Flows[[#This Row],[Flow_Py]],"N.A.") -> 147.81526 | AH12: =Tab_Data_Flows[[#This Row],[UoM_Flow_Py]] -> Mg | AI12: =INDEX(Tab_Def_Flows[[Flow_ID]:[CC_DM_source]],MATCH(Tab_Data_Flows[[#This Row],[Name(EN)]],Tab_Def_Flows[Name(EN)],0),20) -> 0.49 | AJ12: =IF(L12="Yes",AI12*Tab_Data_Flows[[#This Row],[Flow_Py]],"N.A.") -> 77.052637 | AK12: =Tab_Data_Flows[[#This Row],[UoM_Flow_Py]] -> Mg
A13: =ROW()-1 -> 12 | B13: =_xlfn.XLOOKUP(C13,Tab_Def_Flows[Name(EN)],Tab_Def_Flows[Flow_ID],,0,) -> F_13_20 | C13: Rye plant | D13: =_xlfn.XLOOKUP(C13,Tab_Def_Flows[Name(EN)],Tab_Def_Flows[Type_Biomass],,0,) -> 0 | E13: =_xlfn.XLOOKUP(C13,Tab_Def_Flows[Name(EN)],Tab_Def_Flows[Output_Process],,0,) -> Rye cultivation | F13: =_xlfn.XLOOKUP(C13,Tab_Def_Flows[Name(EN)],Tab_Def_Flows[Process_ID_O],,0,) -> 13_Rye_BB | G13: =_xlfn.XLOOKUP(C13,Tab_Def_Flows[Name(EN)],Tab_Def_Flows[Input_Process],,0,) -> Rye cultivation and harvest | H13: =_xlfn.XLOOKUP(C13,Tab_Def_Flows[Name(EN)],Tab_Def_Flows[Process_ID_I],,0,) -> 20_Rye_BB | I13: =_xlfn.XLOOKUP(C13,Tab_Def_Flows[Name(EN)],Tab_Def_Flows[Value_Source],,0,) -> Data_assumption | J13: =_xlfn.XLOOKUP(C13,Tab_Def_Flows[Name(EN)],Tab_Def_Flows[WC?],,0,) -> Yes | K13: =_xlfn.XLOOKUP(C13,Tab_Def_Flows[Name(EN)],Tab_Def_Flows[DM?],,0,) -> Yes | L13: =_xlfn.XLOOKUP(C13,Tab_Def_Flows[Name(EN)],Tab_Def_Flows[CC?],,0,) -> Yes | M13: 2033 | N13: BB | O13: =O12*1.02 -> 160.39529 | P13: Mg/a | Q13: Stramento | X13: No | Y13: 370 | AA13: =IF(X13="no",O13,O13*Y13) -> 160.39529 | AB13: Mg | AC13: =INDEX(Tab_Def_Flows[[Flow_ID]:[CC_DM_source]],MATCH(Tab_Data_Flows[[#This Row],[Name(EN)]],Tab_Def_Flows[Name(EN)],0),16) -> 0.06 | AD13: =IF(J13="Yes",AA13*Tab_Data_Flows[[#This Row],[WC_'[%']]],"N.A.") -> 9.6237171 | AE13: =Tab_Data_Flows[[#This Row],[UoM_Flow_Py]] -> Mg | AF13: =INDEX(Tab_Def_Flows[[Flow_ID]:[CC_DM_source]],MATCH(Tab_Data_Flows[[#This Row],[Name(EN)]],Tab_Def_Flows[Name(EN)],0),18) -> 0.94 | AG13: =IF(K13="Yes",AF13*Tab_Data_Flows[[#This Row],[Flow_Py]],"N.A.") -> 150.77157 | AH13: =Tab_Data_Flows[[#This Row],[UoM_Flow_Py]] -> Mg | AI13: =INDEX(Tab_Def_Flows[[Flow_ID]:[CC_DM_source]],MATCH(Tab_Data_Flows[[#This Row],[Name(EN)]],Tab_Def_Flows[Name(EN)],0),20) -> 0.49 | AJ13: =IF(L13="Yes",AI13*Tab_Data_Flows[[#This Row],[Flow_Py]],"N.A.") -> 78.59369 | AK13: =Tab_Data_Flows[[#This Row],[UoM_Flow_Py]] -> Mg
A14: =ROW()-1 -> 13 | B14: =_xlfn.XLOOKUP(C14,Tab_Def_Flows[Name(EN)],Tab_Def_Flows[Flow_ID],,0,) -> F_13_20 | C14: Rye plant | D14: =_xlfn.XLOOKUP(C14,Tab_Def_Flows[Name(EN)],Tab_Def_Flows[Type_Biomass],,0,) -> 0 | E14: =_xlfn.XLOOKUP(C14,Tab_Def_Flows[Name(EN)],Tab_Def_Flows[Output_Process],,0,) -> Rye cultivation | F14: =_xlfn.XLOOKUP(C14,Tab_Def_Flows[Name(EN)],Tab_Def_Flows[Process_ID_O],,0,) -> 13_Rye_BB | G14: =_xlfn.XLOOKUP(C14,Tab_Def_Flows[Name(EN)],Tab_Def_Flows[Input_Process],,0,) -> Rye cultivation and harvest | H14: =_xlfn.XLOOKUP(C14,Tab_Def_Flows[Name(EN)],Tab_Def_Flows[Process_ID_I],,0,) -> 20_Rye_BB | I14: =_xlfn.XLOOKUP(C14,Tab_Def_Flows[Name(EN)],Tab_Def_Flows[Value_Source],,0,) -> Data_assumption | J14: =_xlfn.XLOOKUP(C14,Tab_Def_Flows[Name(EN)],Tab_Def_Flows[WC?],,0,) -> Yes | K14: =_xlfn.XLOOKUP(C14,Tab_Def_Flows[Name(EN)],Tab_Def_Flows[DM?],,0,) -> Yes | L14: =_xlfn.XLOOKUP(C14,Tab_Def_Flows[Name(EN)],Tab_Def_Flows[CC?],,0,) -> Yes | M14: 2034 | N14: BB | O14: =O13*1.02 -> 163.60319 | P14: Mg/a | Q14: Stramento | X14: No | Y14: 371 | AA14: =IF(X14="no",O14,O14*Y14) -> 163.60319 | AB14: Mg | AC14: =INDEX(Tab_Def_Flows[[Flow_ID]:[CC_DM_source]],MATCH(Tab_Data_Flows[[#This Row],[Name(EN)]],Tab_Def_Flows[Name(EN)],0),16) -> 0.06 | AD14: =IF(J14="Yes",AA14*Tab_Data_Flows[[#This Row],[WC_'[%']]],"N.A.") -> 9.8161915 | AE14: =Tab_Data_Flows[[#This Row],[UoM_Flow_Py]] -> Mg | AF14: =INDEX(Tab_Def_Flows[[Flow_ID]:[CC_DM_source]],MATCH(Tab_Data_Flows[[#This Row],[Name(EN)]],Tab_Def_Flows[Name(EN)],0),18) -> 0.94 | AG14: =IF(K14="Yes",AF14*Tab_Data_Flows[[#This Row],[Flow_Py]],"N.A.") -> 153.787 | AH14: =Tab_Data_Flows[[#This Row],[UoM_Flow_Py]] -> Mg | AI14: =INDEX(Tab_Def_Flows[[Flow_ID]:[CC_DM_source]],MATCH(Tab_Data_Flows[[#This Row],[Name(EN)]],Tab_Def_Flows[Name(EN)],0),20) -> 0.49 | AJ14: =IF(L14="Yes",AI14*Tab_Data_Flows[[#This Row],[Flow_Py]],"N.A.") -> 80.165564 | AK14: =Tab_Data_Flows[[#This Row],[UoM_Flow_Py]] -> Mg
... A16: =ROW()-1 -> 15 | B16: =_xlfn.XLOOKUP(C16,Tab_Def_Flows[Name(EN)],Tab_Def_Flows[Flow_ID],,0,) -> F_13_20 | C16: Rye plant | D16: =_xlfn.XLOOKUP(C16,Tab_Def_Flows[Name(EN)],Tab_Def_Flows[Type_Biomass],,0,) -> 0 | E16: =_xlfn.XLOOKUP(C16,Tab_Def_Flows[Name(EN)],Tab_Def_Flows[Output_Process],,0,) -> Rye cultivation | F16: =_xlfn.XLOOKUP(C16,Tab_Def_Flows[Name(EN)],Tab_Def_Flows[Process_ID_O],,0,) -> 13_Rye_BB | G16: =_xlfn.XLOOKUP(C16,Tab_Def_Flows[Name(EN)],Tab_Def_Flows[Input_Process],,0,) -> Rye cultivation and harvest | H16: =_xlfn.XLOOKUP(C16,Tab_Def_Flows[Name(EN)],Tab_Def_Flows[Process_ID_I],,0,) -> 20_Rye_BB | I16: =_xlfn.XLOOKUP(C16,Tab_Def_Flows[Name(EN)],Tab_Def_Flows[Value_Source],,0,) -> Data_assumption | J16: =_xlfn.XLOOKUP(C16,Tab_Def_Flows[Name(EN)],Tab_Def_Flows[WC?],,0,) -> Yes | K16: =_xlfn.XLOOKUP(C16,Tab_Def_Flows[Name(EN)],Tab_Def_Flows[DM?],,0,) -> Yes | L16: =_xlfn.XLOOKUP(C16,Tab_Def_Flows[Name(EN)],Tab_Def_Flows[CC?],,0,) -> Yes | M16: 2036 | N16: BB | O16: =O15*1.02 -> 170.21276 | P16: Mg/a | Q16: Stramento | X16: No | Y16: 371 | AA16: =IF(X16="no",O16,O16*Y16) -> 170.21276 | AB16: Mg | AC16: =INDEX(Tab_Def_Flows[[Flow_ID]:[CC_DM_source]],MATCH(Tab_Data_Flows[[#This Row],[Name(EN)]],Tab_Def_Flows[Name(EN)],0),16) -> 0.06 | AD16: =IF(J16="Yes",AA16*Tab_Data_Flows[[#This Row],[WC_'[%']]],"N.A.") -> 10.212766 | AE16: =Tab_Data_Flows[[#This Row],[UoM_Flow_Py]] -> Mg | AF16: =INDEX(Tab_Def_Flows[[Flow_ID]:[CC_DM_source]],MATCH(Tab_Data_Flows[[#This Row],[Name(EN)]],Tab_Def_Flows[Name(EN)],0),18) -> 0.94 | AG16: =IF(K16="Yes",AF16*Tab_Data_Flows[[#This Row],[Flow_Py]],"N.A.") -> 159.99999 | AH16: =Tab_Data_Flows[[#This Row],[UoM_Flow_Py]] -> Mg | AI16: =INDEX(Tab_Def_Flows[[Flow_ID]:[CC_DM_source]],MATCH(Tab_Data_Flows[[#This Row],[Name(EN)]],Tab_Def_Flows[Name(EN)],0),20) -> 0.49 | AJ16: =IF(L16="Yes",AI16*Tab_Data_Flows[[#This Row],[Flow_Py]],"N.A.") -> 83.404253 | AK16: =Tab_Data_Flows[[#This Row],[UoM_Flow_Py]] -> Mg
A17: =ROW()-1 -> 16 | B17: =_xlfn.XLOOKUP(C17,Tab_Def_Flows[Name(EN)],Tab_Def_Flows[Flow_ID],,0,) -> F_04_01 | C17: Cow Manure | D17: =_xlfn.XLOOKUP(C17,Tab_Def_Flows[Name(EN)],Tab_Def_Flows[Type_Biomass],,0,) -> 0 | E17: =_xlfn.XLOOKUP(C17,Tab_Def_Flows[Name(EN)],Tab_Def_Flows[Output_Process],,0,) -> Life stock farming | F17: =_xlfn.XLOOKUP(C17,Tab_Def_Flows[Name(EN)],Tab_Def_Flows[Process_ID_O],,0,) -> 04_Lif_BB | G17: =_xlfn.XLOOKUP(C17,Tab_Def_Flows[Name(EN)],Tab_Def_Flows[Input_Process],,0,) -> Biogas production | H17: =_xlfn.XLOOKUP(C17,Tab_Def_Flows[Name(EN)],Tab_Def_Flows[Process_ID_I],,0,) -> 01_Bio_BB | I17: =_xlfn.XLOOKUP(C17,Tab_Def_Flows[Name(EN)],Tab_Def_Flows[Value_Source],,0,) -> 0 | J17: =_xlfn.XLOOKUP(C17,Tab_Def_Flows[Name(EN)],Tab_Def_Flows[WC?],,0,) -> Yes | K17: =_xlfn.XLOOKUP(C17,Tab_Def_Flows[Name(EN)],Tab_Def_Flows[DM?],,0,) -> Yes | L17: =_xlfn.XLOOKUP(C17,Tab_Def_Flows[Name(EN)],Tab_Def_Flows[CC?],,0,) -> Yes | M17: 2022 | N17: BB | O17: 39 | P17: Mg/a | X17: No | AA17: =IF(X17="no",O17,O17*Y17) -> 39 | AB17: Mg | AC17: =INDEX(Tab_Def_Flows[[Flow_ID]:[CC_DM_source]],MATCH(Tab_Data_Flows[[#This Row],[Name(EN)]],Tab_Def_Flows[Name(EN)],0),16) -> 0.94 | AD17: =IF(J17="Yes",AA17*Tab_Data_Flows[[#This Row],[WC_'[%']]],"N.A.") -> 36.66 | AE17: =Tab_Data_Flows[[#This Row],[UoM_Flow_Py]] -> Mg | AF17: =INDEX(Tab_Def_Flows[[Flow_ID]:[CC_DM_source]],MATCH(Tab_Data_Flows[[#This Row],[Name(EN)]],Tab_Def_Flows[Name(EN)],0),18) -> 0.06 | AG17: =IF(K17="Yes",AF17*Tab_Data_Flows[[#This Row],[Flow_Py]],"N.A.") -> 2.34 | AH17: =Tab_Data_Flows[[#This Row],[UoM_Flow_Py]] -> Mg | AI17: =INDEX(Tab_Def_Flows[[Flow_ID]:[CC_DM_source]],MATCH(Tab_Data_Flows[[#This Row],[Name(EN)]],Tab_Def_Flows[Name(EN)],0),20) -> 0.49 | AJ17: =IF(L17="Yes",AI17*Tab_Data_Flows[[#This Row],[Flow_Py]],"N.A.") -> 19.11 | AK17: =Tab_Data_Flows[[#This Row],[UoM_Flow_Py]] -> Mg
A18: =ROW()-1 -> 17 | B18: =_xlfn.XLOOKUP(C18,Tab_Def_Flows[Name(EN)],Tab_Def_Flows[Flow_ID],,0,) -> F_04_01 | C18: Cow Manure | D18: =_xlfn.XLOOKUP(C18,Tab_Def_Flows[Name(EN)],Tab_Def_Flows[Type_Biomass],,0,) -> 0 | E18: =_xlfn.XLOOKUP(C18,Tab_Def_Flows[Name(EN)],Tab_Def_Flows[Output_Process],,0,) -> Life stock farming | F18: =_xlfn.XLOOKUP(C18,Tab_Def_Flows[Name(EN)],Tab_Def_Flows[Process_ID_O],,0,) -> 04_Lif_BB | G18: =_xlfn.XLOOKUP(C18,Tab_Def_Flows[Name(EN)],Tab_Def_Flows[Input_Process],,0,) -> Biogas production | H18: =_xlfn.XLOOKUP(C18,Tab_Def_Flows[Name(EN)],Tab_Def_Flows[Process_ID_I],,0,) -> 01_Bio_BB | I18: =_xlfn.XLOOKUP(C18,Tab_Def_Flows[Name(EN)],Tab_Def_Flows[Value_Source],,0,) -> 0 | J18: =_xlfn.XLOOKUP(C18,Tab_Def_Flows[Name(EN)],Tab_Def_Flows[WC?],,0,) -> Yes | K18: =_xlfn.XLOOKUP(C18,Tab_Def_Flows[Name(EN)],Tab_Def_Flows[DM?],,0,) -> Yes | L18: =_xlfn.XLOOKUP(C18,Tab_Def_Flows[Name(EN)],Tab_Def_Flows[CC?],,0,) -> Yes | M18: 2023 | N18: BB | O18: =O17*1.02 -> 39.78 | P18: Mg/a | X18: No | AA18: =IF(X18="no",O18,O18*Y18) -> 39.78 | AB18: Mg | AC18: =INDEX(Tab_Def_Flows[[Flow_ID]:[CC_DM_source]],MATCH(Tab_Data_Flows[[#This Row],[Name(EN)]],Tab_Def_Flows[Name(EN)],0),16) -> 0.94 | AD18: =IF(J18="Yes",AA18*Tab_Data_Flows[[#This Row],[WC_'[%']]],"N.A.") -> 37.3932 | AE18: =Tab_Data_Flows[[#This Row],[UoM_Flow_Py]] -> Mg | AF18: =INDEX(Tab_Def_Flows[[Flow_ID]:[CC_DM_source]],MATCH(Tab_Data_Flows[[#This Row],[Name(EN)]],Tab_Def_Flows[Name(EN)],0),18) -> 0.06 | AG18: =IF(K18="Yes",AF18*Tab_Data_Flows[[#This Row],[Flow_Py]],"N.A.") -> 2.3868 | AH18: =Tab_Data_Flows[[#This Row],[UoM_Flow_Py]] -> Mg | AI18: =INDEX(Tab_Def_Flows[[Flow_ID]:[CC_DM_source]],MATCH(Tab_Data_Flows[[#This Row],[Name(EN)]],Tab_Def_Flows[Name(EN)],0),20) -> 0.49 | AJ18: =IF(L18="Yes",AI18*Tab_Data_Flows[[#This Row],[Flow_Py]],"N.A.") -> 19.4922 | AK18: =Tab_Data_Flows[[#This Row],[UoM_Flow_Py]] -> Mg
A19: =ROW()-1 -> 18 | B19: =_xlfn.XLOOKUP(C19,Tab_Def_Flows[Name(EN)],Tab_Def_Flows[Flow_ID],,0,) -> F_04_01 | C19: Cow Manure | D19: =_xlfn.XLOOKUP(C19,Tab_Def_Flows[Name(EN)],Tab_Def_Flows[Type_Biomass],,0,) -> 0 | E19: =_xlfn.XLOOKUP(C19,Tab_Def_Flows[Name(EN)],Tab_Def_Flows[Output_Process],,0,) -> Life stock farming | F19: =_xlfn.XLOOKUP(C19,Tab_Def_Flows[Name(EN)],Tab_Def_Flows[Process_ID_O],,0,) -> 04_Lif_BB | G19: =_xlfn.XLOOKUP(C19,Tab_Def_Flows[Name(EN)],Tab_Def_Flows[Input_Process],,0,) -> Biogas production | H19: =_xlfn.XLOOKUP(C19,Tab_Def_Flows[Name(EN)],Tab_Def_Flows[Process_ID_I],,0,) -> 01_Bio_BB | I19: =_xlfn.XLOOKUP(C19,Tab_Def_Flows[Name(EN)],Tab_Def_Flows[Value_Source],,0,) -> 0 | J19: =_xlfn.XLOOKUP(C19,Tab_Def_Flows[Name(EN)],Tab_Def_Flows[WC?],,0,) -> Yes | K19: =_xlfn.XLOOKUP(C19,Tab_Def_Flows[Name(EN)],Tab_Def_Flows[DM?],,0,) -> Yes | L19: =_xlfn.XLOOKUP(C19,Tab_Def_Flows[Name(EN)],Tab_Def_Flows[CC?],,0,) -> Yes | M19: 2024 | N19: BB | O19: =O18*1.02 -> 40.5756 | P19: Mg/a | X19: No | AA19: =IF(X19="no",O19,O19*Y19) -> 40.5756 | AB19: Mg | AC19: =INDEX(Tab_Def_Flows[[Flow_ID]:[CC_DM_source]],MATCH(Tab_Data_Flows[[#This Row],[Name(EN)]],Tab_Def_Flows[Name(EN)],0),16) -> 0.94 | AD19: =IF(J19="Yes",AA19*Tab_Data_Flows[[#This Row],[WC_'[%']]],"N.A.") -> 38.141064 | AE19: =Tab_Data_Flows[[#This Row],[UoM_Flow_Py]] -> Mg | AF19: =INDEX(Tab_Def_Flows[[Flow_ID]:[CC_DM_source]],MATCH(Tab_Data_Flows[[#This Row],[Name(EN)]],Tab_Def_Flows[Name(EN)],0),18) -> 0.06 | AG19: =IF(K19="Yes",AF19*Tab_Data_Flows[[#This Row],[Flow_Py]],"N.A.") -> 2.434536 | AH19: =Tab_Data_Flows[[#This Row],[UoM_Flow_Py]] -> Mg | AI19: =INDEX(Tab_Def_Flows[[Flow_ID]:[CC_DM_source]],MATCH(Tab_Data_Flows[[#This Row],[Name(EN)]],Tab_Def_Flows[Name(EN)],0),20) -> 0.49 | AJ19: =IF(L19="Yes",AI19*Tab_Data_Flows[[#This Row],[Flow_Py]],"N.A.") -> 19.882044 | AK19: =Tab_Data_Flows[[#This Row],[UoM_Flow_Py]] -> Mg
A20: =ROW()-1 -> 19 | B20: =_xlfn.XLOOKUP(C20,Tab_Def_Flows[Name(EN)],Tab_Def_Flows[Flow_ID],,0,) -> F_04_01 | C20: Cow Manure | D20: =_xlfn.XLOOKUP(C20,Tab_Def_Flows[Name(EN)],Tab_Def_Flows[Type_Biomass],,0,) -> 0 | E20: =_xlfn.XLOOKUP(C20,Tab_Def_Flows[Name(EN)],Tab_Def_Flows[Output_Process],,0,) -> Life stock farming | F20: =_xlfn.XLOOKUP(C20,Tab_Def_Flows[Name(EN)],Tab_Def_Flows[Process_ID_O],,0,) -> 04_Lif_BB | G20: =_xlfn.XLOOKUP(C20,Tab_Def_Flows[Name(EN)],Tab_Def_Flows[Input_Process],,0,) -> Biogas production | H20: =_xlfn.XLOOKUP(C20,Tab_Def_Flows[Name(EN)],Tab_Def_Flows[Process_ID_I],,0,) -> 01_Bio_BB | I20: =_xlfn.XLOOKUP(C20,Tab_Def_Flows[Name(EN)],Tab_Def_Flows[Value_Source],,0,) -> 0 | J20: =_xlfn.XLOOKUP(C20,Tab_Def_Flows[Name(EN)],Tab_Def_Flows[WC?],,0,) -> Yes | K20: =_xlfn.XLOOKUP(C20,Tab_Def_Flows[Name(EN)],Tab_Def_Flows[DM?],,0,) -> Yes | L20: =_xlfn.XLOOKUP(C20,Tab_Def_Flows[Name(EN)],Tab_Def_Flows[CC?],,0,) -> Yes | M20: 2025 | N20: BB | O20: =O19*1.02 -> 41.387112 | P20: Mg/a | X20: No | AA20: =IF(X20="no",O20,O20*Y20) -> 41.387112 | AB20: Mg | AC20: =INDEX(Tab_Def_Flows[[Flow_ID]:[CC_DM_source]],MATCH(Tab_Data_Flows[[#This Row],[Name(EN)]],Tab_Def_Flows[Name(EN)],0),16) -> 0.94 | AD20: =IF(J20="Yes",AA20*Tab_Data_Flows[[#This Row],[WC_'[%']]],"N.A.") -> 38.903885 | AE20: =Tab_Data_Flows[[#This Row],[UoM_Flow_Py]] -> Mg | AF20: =INDEX(Tab_Def_Flows[[Flow_ID]:[CC_DM_source]],MATCH(Tab_Data_Flows[[#This Row],[Name(EN)]],Tab_Def_Flows[Name(EN)],0),18) -> 0.06 | AG20: =IF(K20="Yes",AF20*Tab_Data_Flows[[#This Row],[Flow_Py]],"N.A.") -> 2.4832267 | AH20: =Tab_Data_Flows[[#This Row],[UoM_Flow_Py]] -> Mg | AI20: =INDEX(Tab_Def_Flows[[Flow_ID]:[CC_DM_source]],MATCH(Tab_Data_Flows[[#This Row],[Name(EN)]],Tab_Def_Flows[Name(EN)],0),20) -> 0.49 | AJ20: =IF(L20="Yes",AI20*Tab_Data_Flows[[#This Row],[Flow_Py]],"N.A.") -> 20.279685 | AK20: =Tab_Data_Flows[[#This Row],[UoM_Flow_Py]] -> Mg
A21: =ROW()-1 -> 20 | B21: =_xlfn.XLOOKUP(C21,Tab_Def_Flows[Name(EN)],Tab_Def_Flows[Flow_ID],,0,) -> F_04_01 | C21: Cow Manure | D21: =_xlfn.XLOOKUP(C21,Tab_Def_Flows[Name(EN)],Tab_Def_Flows[Type_Biomass],,0,) -> 0 | E21: =_xlfn.XLOOKUP(C21,Tab_Def_Flows[Name(EN)],Tab_Def_Flows[Output_Process],,0,) -> Life stock farming | F21: =_xlfn.XLOOKUP(C21,Tab_Def_Flows[Name(EN)],Tab_Def_Flows[Process_ID_O],,0,) -> 04_Lif_BB | G21: =_xlfn.XLOOKUP(C21,Tab_Def_Flows[Name(EN)],Tab_Def_Flows[Input_Process],,0,) -> Biogas production | H21: =_xlfn.XLOOKUP(C21,Tab_Def_Flows[Name(EN)],Tab_Def_Flows[Process_ID_I],,0,) -> 01_Bio_BB | I21: =_xlfn.XLOOKUP(C21,Tab_Def_Flows[Name(EN)],Tab_Def_Flows[Value_Source],,0,) -> 0 | J21: =_xlfn.XLOOKUP(C21,Tab_Def_Flows[Name(EN)],Tab_Def_Flows[WC?],,0,) -> Yes | K21: =_xlfn.XLOOKUP(C21,Tab_Def_Flows[Name(EN)],Tab_Def_Flows[DM?],,0,) -> Yes | L21: =_xlfn.XLOOKUP(C21,Tab_Def_Flows[Name(EN)],Tab_Def_Flows[CC?],,0,) -> Yes | M21: 2026 | N21: BB | O21: =O20*1.02 -> 42.214854 | P21: Mg/a | X21: No | AA21: =IF(X21="no",O21,O21*Y21) -> 42.214854 | AB21: Mg | AC21: =INDEX(Tab_Def_Flows[[Flow_ID]:[CC_DM_source]],MATCH(Tab_Data_Flows[[#This Row],[Name(EN)]],Tab_Def_Flows[Name(EN)],0),16) -> 0.94 | AD21: =IF(J21="Yes",AA21*Tab_Data_Flows[[#This Row],[WC_'[%']]],"N.A.") -> 39.681963 | AE21: =Tab_Data_Flows[[#This Row],[UoM_Flow_Py]] -> Mg | AF21: =INDEX(Tab_Def_Flows[[Flow_ID]:[CC_DM_source]],MATCH(Tab_Data_Flows[[#This Row],[Name(EN)]],Tab_Def_Flows[Name(EN)],0),18) -> 0.06 | AG21: =IF(K21="Yes",AF21*Tab_Data_Flows[[#This Row],[Flow_Py]],"N.A.") -> 2.5328913 | AH21: =Tab_Data_Flows[[#This Row],[UoM_Flow_Py]] -> Mg | AI21: =INDEX(Tab_Def_Flows[[Flow_ID]:[CC_DM_source]],MATCH(Tab_Data_Flows[[#This Row],[Name(EN)]],Tab_Def_Flows[Name(EN)],0),20) -> 0.49 | AJ21: =IF(L21="Yes",AI21*Tab_Data_Flows[[#This Row],[Flow_Py]],"N.A.") -> 20.685279 | AK21: =Tab_Data_Flows[[#This Row],[UoM_Flow_Py]] -> Mg
