Workbook

Sheet 0_Configuration
A1: Category_Settings | B1: Setting_Name | C1: Value | D1: ODYM_ID | E1: Description | F1: Category | G1: Status
A2: ODYM Dimension: Time (t) | B2: Time | C2: TRUE | D2: FALSE | E2: ODYM Dimension time (t) is always automaticly activated. The time settings of the system are defined within the model configuration
B3: Time steps: | C3: Time in steps of 1 year | E3: Default time step of 1 year
B4: Start_Year | C4: 2025 | E4: Start year of the calculation
B5: End_Year | C5: 2050 | E5: End year of the calculation
A6: ODYM Dimension: Region (r ) | B6: Enable ODYM Dimension_Region | C6: FALSE | D6: FALSE | E6: ODYM Dimension Region (r ) is always activated. Additional Regions can be used to located processes. Regions are definend in _
B7: Region ID 1 | C7: Case_Study_Region | E7: Defined region of the Case_Study. Always activated.
B8: Region ID 2
B9: Region ID 3
A10: ODYM Dimension: Process (p) | B10: Enable ODYM Dimension_Process | C10: FALSE | D10: FALSE | E10: ODYM Dimension "Process (p) is always automaticly activated. The Processes of the system are defined within the sheet 2_1_Definition_Processes
B11: Process Type 1 | C11: Biomass Production | D11: 1
B12: Process Type 2 | C12: Biomass Processing | D12: 2
B13: Process Type 3 | C13: Use-Phase | D13: 3
B14: Process Type 4 | C14: EoL-Phase | D14: 4
B15: Process Type 5 | D15: 5
B16: Process Type 6 | D16: 6
A17: ODYM Dimension: Good (g) | B17: Enable ODYM Dimension_Goods | C17: FALSE | D17: FALSE | E17: ODYM Dimension "Good (g) is always automaticly activated. The goods of the system are defined within sheet 1_1_Definition_Flows
B18: Good Type 1 | C18: Raw Material | D18: 1
B19: Good Type 2 | C19: Processed Product | D19: 2
B20: Good Type 3 | C20: Product | D20: 3
B21: Good Type 4 | C21: Waste | D21: 4
B22: Good Type 5 | D22: 5
B23: Good Type 6 | D23: 6
A24: ODYM Dimension: Material (m) | B24: Enable ODYM Dimension_Materials | C24: FALSE | D24: FALSE | E24: ODYM Dimension "Material (m) is always automaticly activated. The Materials of the system are limited to the typical composition of biomass, which consists out of Watercontent (WC) and Dry Mass (DM).
B25: Material ID 1 | C25: WC | E25: Watercontent (WC)
B26: Material ID 2 | C26: DM | E26: Dry Mass (DM)
B27: Material ID 3
B28: Material ID 4
A29: ODYM Dimension: Elements (e ) | B29: Enable elements? | C29: TRUE | D29: FALSE | E29: ODYM Dimension "Element (e) is . The elements of the system are currently limited to carbon (C) and remaining DM. The list of elements can be extended for typical elements.
B30: Element ID 1 | C30: C | E30: Elemental Carbon
B31: Element ID 2 | C31: Remaining DM | E31: Remaining DM (DryMass - tracked elements)
B32: Element ID 3
B33: Element ID 4
B34: Element ID 5
B35: Unit_of_Measurement | C35: Mg
B36: Input_File | C36: data/01_input/250902_CS1_Wheat_Straw.xlsx | E36: Path to Excel input file | F36: Core | G36: Required
B37: Output_File | C37: data/02_output/results.xlsx | E37: Path for results output | F37: Core | G37: Required
A38: CALCULATION SETTINGS | B38: Run_DSM_Calculation | C38: TRUE | D38: FALSE | E38: Enable Dynamic Stock Model calculation | F38: Calculation | G38: Required
B39: Run_FOMP_Calculation | C39: TRUE | D39: FALSE | E39: Enable First-Order Material Process calculation | F39: Calculation | G39: Required
B40: RUN_MONTE_CARLO | C40: FALSE | D40: FALSE | E40: Enable Monte Carlo uncertainty analysis | F40: Calculation | G40: Optional
...

Sheet 1_1_Definition_Flows
A1: Complete? | B1: ID | C1: Flow_ID | D1: Flow_Name | E1: ODYM_Good_Type | F1: Flow_Output_Process | G1: Flow_Output_Process_ID | H1: Flow_Input_Process | I1: Input_Process_ID | J1: WC? | K1: DM? | L1: ODYM Dimension: material (e) | M1: CC? | N1: Flow_WC_ID | O1: Flow_WC[%] | P1: WC_source | Q1: Flow_DM_ID | R1: Flow_DM[%] | S1: DM_source | T1: Flow_CC_ID | U1: Flow_CC_DM[%] | V1: CC_DM_source | W1: Flow_CC_FM[%] | X1: CC_FM_source | Y1: ODYM_time_(t) | Z1: ODYM_Time_ID | AA1: ODYM_Region_(r) | AB1: ODYM_Region_ID | AC1: ODYM_process_(p) | AD1: ODYM_Process_ID | AE1: ODYM_Good_(g)2 | AF1: ODYM_Good_ID | AG1: ODYM_material_(m) | AH1: ODYM_Material_ID | AI1: ODYM_element_(e) | AJ1: ODYM_Element_ID | AK1: ODYM_Indices | AL1: Column2
A2: FALSE | B2: =ROW()-1 | C2: ="F_"&LEFT(G2,2)&"_"&LEFT(I2,2) | D2: Atmosphere_Input_Cultivation_C | E2: Raw Material | F2: Atmosphere | G2: =_xlfn.XLOOKUP(F2,Tab_Def_Processes[Process_Name],Tab_Def_Processes[Process_ID],,0,) | H2: Rye_Cultivation | I2: =_xlfn.XLOOKUP(H2,Tab_Def_Processes[Process_Name],Tab_Def_Processes[Process_ID],,0,) | J2: Yes | K2: Yes | M2: Yes | N2: =Tab_Def_Flows[[#This Row],[Flow_ID]]&"_WC" | O2: 0 | Q2: =Tab_Def_Flows[[#This Row],[Flow_ID]]&"_DM" | R2: 1 | T2: =Tab_Def_Flows[[#This Row],[Flow_ID]]&"_CC" | U2: 1 | W2: =Tab_Def_Flows[[#This Row],[Flow_CC_DM'[%']]]*Tab_Def_Flows[[#This Row],[Flow_DM'[%']]] | Y2: ='0_Configuration'!$C$2 | AA2: ='0_Configuration'!$C$6 | AC2: ='0_Configuration'!$C$10 | AE2: ='0_Configuration'!$C$17 | AF2: =_xlfn.XLOOKUP(Tab_Def_Flows[[#This Row],[ODYM_Good_Type]],Tab_Configuration[Value],Tab_Configuration[ODYM_ID],,0,) | AG2: ='0_Configuration'!$C$24 | AI2: ='0_Configuration'!$C$29 | AK2: =IF(Tab_Def_Flows[[#This Row],[ODYM_time_(t)]],"t,","")&IF(Tab_Def_Flows[[#This Row],[ODYM_Region_(r)]],"r,","")&IF(Tab_Def_Flows[[#This Row],[ODYM_process_(p)]],"p,","")&IF(Tab_Def_Flows[[#This Row],[ODYM_Good_(g)2]],"g,","")&IF(Tab_Def_Flows[[#This Row],[ODYM_material_(m)]],"m,","")&IF(Tab_Def_Flows[[#This Row],[ODYM_element_(e)]],"e","") | AL2: =IF(Tab_Def_Flows[[#This Row],[ODYM_time_(t)]],Tab_Def_Flows[[#This Row],[ODYM_Time_ID]]&",","")&IF(Tab_Def_Flows[[#This Row],[ODYM_Region_(r)]],Tab_Def_Flows[[#This Row],[ODYM_Region_ID]]&",","")&IF(Tab_Def_Flows[[#This Row],[ODYM_process_(p)]],Tab_Def_Flows[[#This Row],[ODYM_Process_ID]]&",","")&IF(Tab_Def_Flows[[#This Row],[ODYM_Good_(g)2]],Tab_Def_Flows[[#This Row],[ODYM_Good_ID]]&",","")&IF(Tab_Def_Flows[[#This Row],[ODYM_material_(m)]],Tab_Def_Flows[[#This Row],[ODYM_Material_ID]]&",","")&IF(Tab_Def_Flows[[#This Row],[ODYM_element_(e)]],Tab_Def_Flows[[#This Row],[ODYM_Element_ID]]&",","")
A3: FALSE | B3: =ROW()-1 | C3: ="F_"&LEFT(G3,2)&"_"&LEFT(I3,2) | D3: Environment_Input_Cultivation_E | E3: Product | F3: Environment | G3: =_xlfn.XLOOKUP(F3,Tab_Def_Processes[Process_Name],Tab_Def_Processes[Process_ID],,0,) | H3: Rye_Cultivation | I3: =_xlfn.XLOOKUP(H3,Tab_Def_Processes[Process_Name],Tab_Def_Processes[Process_ID],,0,) | J3: Yes | K3: Yes | M3: Yes | N3: =Tab_Def_Flows[[#This Row],[Flow_ID]]&"_WC" | O3: 0.23841962 | Q3: =Tab_Def_Flows[[#This Row],[Flow_ID]]&"_DM" | R3: 0.76158038 | T3: =Tab_Def_Flows[[#This Row],[Flow_ID]]&"_CC" | U3: 0 | W3: =Tab_Def_Flows[[#This Row],[Flow_CC_DM'[%']]]*Tab_Def_Flows[[#This Row],[Flow_DM'[%']]] | Y3: ='0_Configuration'!$C$2 | AA3: ='0_Configuration'!$C$6 | AC3: ='0_Configuration'!$C$10 | AE3: ='0_Configuration'!$C$17 | AF3: =_xlfn.XLOOKUP(Tab_Def_Flows[[#This Row],[ODYM_Good_Type]],Tab_Configuration[Value],Tab_Configuration[ODYM_ID],,0,) | AG3: ='0_Configuration'!$C$24 | AI3: ='0_Configuration'!$C$29 | AK3: =IF(Tab_Def_Flows[[#This Row],[ODYM_time_(t)]],"t,","")&IF(Tab_Def_Flows[[#This Row],[ODYM_Region_(r)]],"r,","")&IF(Tab_Def_Flows[[#This Row],[ODYM_process_(p)]],"p,","")&IF(Tab_Def_Flows[[#This Row],[ODYM_Good_(g)2]],"g,","")&IF(Tab_Def_Flows[[#This Row],[ODYM_material_(m)]],"m,","")&IF(Tab_Def_Flows[[#This Row],[ODYM_element_(e)]],"e","") | AL3: =IF(Tab_Def_Flows[[#This Row],[ODYM_time_(t)]],Tab_Def_Flows[[#This Row],[ODYM_Time_ID]]&",","")&IF(Tab_Def_Flows[[#This Row],[ODYM_Region_(r)]],Tab_Def_Flows[[#This Row],[ODYM_Region_ID]]&",","")&IF(Tab_Def_Flows[[#This Row],[ODYM_process_(p)]],Tab_Def_Flows[[#This Row],[ODYM_Process_ID]]&",","")&IF(Tab_Def_Flows[[#This Row],[ODYM_Good_(g)2]],Tab_Def_Flows[[#This Row],[ODYM_Good_ID]]&",","")&IF(Tab_Def_Flows[[#This Row],[ODYM_material_(m)]],Tab_Def_Flows[[#This Row],[ODYM_Material_ID]]&",","")&IF(Tab_Def_Flows[[#This Row],[ODYM_element_(e)]],Tab_Def_Flows[[#This Row],[ODYM_Element_ID]]&",","")
A4: FALSE | B4: =ROW()-1 | C4: ="F_"&LEFT(G4,2)&"_"&LEFT(I4,2) | D4: Atmosphere_Input_cow-manure_production_C | F4: Atmosphere | G4: =_xlfn.XLOOKUP(F4,Tab_Def_Processes[Process_Name],Tab_Def_Processes[Process_ID],,0,) | H4: Cow-Manure_Production | I4: =_xlfn.XLOOKUP(H4,Tab_Def_Processes[Process_Name],Tab_Def_Processes[Process_ID],,0,) | J4: Yes | K4: Yes | M4: Yes | N4: =Tab_Def_Flows[[#This Row],[Flow_ID]]&"_WC" | O4: 0 | Q4: =Tab_Def_Flows[[#This Row],[Flow_ID]]&"_DM" | R4: 1 | T4: =Tab_Def_Flows[[#This Row],[Flow_ID]]&"_CC" | U4: 1 | W4: =Tab_Def_Flows[[#This Row],[Flow_CC_DM'[%']]]*Tab_Def_Flows[[#This Row],[Flow_DM'[%']]] | Y4: ='0_Configuration'!$C$2 | AA4: ='0_Configuration'!$C$6 | AC4: ='0_Configuration'!$C$10 | AE4: ='0_Configuration'!$C$17 | AF4: =_xlfn.XLOOKUP(Tab_Def_Flows[[#This Row],[ODYM_Good_Type]],Tab_Configuration[Value],Tab_Configuration[ODYM_ID],,0,) | AG4: ='0_Configuration'!$C$24 | AI4: ='0_Configuration'!$C$29 | AK4: =IF(Tab_Def_Flows[[#This Row],[ODYM_time_(t)]],"t,","")&IF(Tab_Def_Flows[[#This Row],[ODYM_Region_(r)]],"r,","")&IF(Tab_Def_Flows[[#This Row],[ODYM_process_(p)]],"p,","")&IF(Tab_Def_Flows[[#This Row],[ODYM_Good_(g)2]],"g,","")&IF(Tab_Def_Flows[[#This Row],[ODYM_material_(m)]],"m,","")&IF(Tab_Def_Flows[[#This Row],[ODYM_element_(e)]],"e","") | AL4: =IF(Tab_Def_Flows[[#This Row],[ODYM_time_(t)]],Tab_Def_Flows[[#This Row],[ODYM_Time_ID]]&",","")&IF(Tab_Def_Flows[[#This Row],[ODYM_Region_(r)]],Tab_Def_Flows[[#This Row],[ODYM_Region_ID]]&",","")&IF(Tab_Def_Flows[[#This Row],[ODYM_process_(p)]],Tab_Def_Flows[[#This Row],[ODYM_Process_ID]]&",","")&IF(Tab_Def_Flows[[#This Row],[ODYM_Good_(g)2]],Tab_Def_Flows[[#This Row],[ODYM_Good_ID]]&",","")&IF(Tab_Def_Flows[[#This Row],[ODYM_material_(m)]],Tab_Def_Flows[[#This Row],[ODYM_Material_ID]]&",","")&IF(Tab_Def_Flows[[#This Row],[ODYM_element_(e)]],Tab_Def_Flows[[#This Row],[ODYM_Element_ID]]&",","")
A5: FALSE | B5: =ROW()-1 | C5: ="F_"&LEFT(G5,2)&"_"&LEFT(I5,2) | D5: Environment_Input_cow-manure_production_E | F5: Environment | G5: =_xlfn.XLOOKUP(F5,Tab_Def_Processes[Process_Name],Tab_Def_Processes[Process_ID],,0,) | H5: Cow-Manure_Production | I5: =_xlfn.XLOOKUP(H5,Tab_Def_Processes[Process_Name],Tab_Def_Processes[Process_ID],,0,) | J5: Yes | K5: Yes | M5: Yes | N5: =Tab_Def_Flows[[#This Row],[Flow_ID]]&"_WC" | O5: 0.96738929 | Q5: =Tab_Def_Flows[[#This Row],[Flow_ID]]&"_DM" | R5: 0.032610713 | T5: =Tab_Def_Flows[[#This Row],[Flow_ID]]&"_CC" | U5: 0 | W5: =Tab_Def_Flows[[#This Row],[Flow_CC_DM'[%']]]*Tab_Def_Flows[[#This Row],[Flow_DM'[%']]] | Y5: ='0_Configuration'!$C$2 | AA5: ='0_Configuration'!$C$6 | AC5: ='0_Configuration'!$C$10 | AE5: ='0_Configuration'!$C$17 | AF5: =_xlfn.XLOOKUP(Tab_Def_Flows[[#This Row],[ODYM_Good_Type]],Tab_Configuration[Value],Tab_Configuration[ODYM_ID],,0,) | AG5: ='0_Configuration'!$C$24 | AI5: ='0_Configuration'!$C$29 | AK5: =IF(Tab_Def_Flows[[#This Row],[ODYM_time_(t)]],"t,","")&IF(Tab_Def_Flows[[#This Row],[ODYM_Region_(r)]],"r,","")&IF(Tab_Def_Flows[[#This Row],[ODYM_process_(p)]],"p,","")&IF(Tab_Def_Flows[[#This Row],[ODYM_Good_(g)2]],"g,","")&IF(Tab_Def_Flows[[#This Row],[ODYM_material_(m)]],"m,","")&IF(Tab_Def_Flows[[#This Row],[ODYM_element_(e)]],"e","") | AL5: =IF(Tab_Def_Flows[[#This Row],[ODYM_time_(t)]],Tab_Def_Flows[[#This Row],[ODYM_Time_ID]]&",","")&IF(Tab_Def_Flows[[#This Row],[ODYM_Region_(r)]],Tab_Def_Flows[[#This Row],[ODYM_Region_ID]]&",","")&IF(Tab_Def_Flows[[#This Row],[ODYM_process_(p)]],Tab_Def_Flows[[#This Row],[ODYM_Process_ID]]&",","")&IF(Tab_Def_Flows[[#This Row],[ODYM_Good_(g)2]],Tab_Def_Flows[[#This Row],[ODYM_Good_ID]]&",","")&IF(Tab_Def_Flows[[#This Row],[ODYM_material_(m)]],Tab_Def_Flows[[#This Row],[ODYM_Material_ID]]&",","")&IF(Tab_Def_Flows[[#This Row],[ODYM_element_(e)]],Tab_Def_Flows[[#This Row],[ODYM_Element_ID]]&",","")
A6: FALSE | B6: =ROW()-1 | C6: ="F_"&LEFT(G6,2)&"_"&LEFT(I6,2) | D6: Atmosphere_Input_millet_production_C | F6: Atmosphere | G6: =_xlfn.XLOOKUP(F6,Tab_Def_Processes[Process_Name],Tab_Def_Processes[Process_ID],,0,) | H6: Millet_Production | I6: =_xlfn.XLOOKUP(H6,Tab_Def_Processes[Process_Name],Tab_Def_Processes[Process_ID],,0,) | J6: Yes | K6: Yes | M6: Yes | N6: =Tab_Def_Flows[[#This Row],[Flow_ID]]&"_WC" | O6: 0 | Q6: =Tab_Def_Flows[[#This Row],[Flow_ID]]&"_DM" | R6: 1 | T6: =Tab_Def_Flows[[#This Row],[Flow_ID]]&"_CC" | U6: 1 | W6: =Tab_Def_Flows[[#This Row],[Flow_CC_DM'[%']]]*Tab_Def_Flows[[#This Row],[Flow_DM'[%']]] | Y6: ='0_Configuration'!$C$2 | AA6: ='0_Configuration'!$C$6 | AC6: ='0_Configuration'!$C$10 | AE6: ='0_Configuration'!$C$17 | AF6: =_xlfn.XLOOKUP(Tab_Def_Flows[[#This Row],[ODYM_Good_Type]],Tab_Configuration[Value],Tab_Configuration[ODYM_ID],,0,) | AG6: ='0_Configuration'!$C$24 | AI6: ='0_Configuration'!$C$29 | AK6: =IF(Tab_Def_Flows[[#This Row],[ODYM_time_(t)]],"t,","")&IF(Tab_Def_Flows[[#This Row],[ODYM_Region_(r)]],"r,","")&IF(Tab_Def_Flows[[#This Row],[ODYM_process_(p)]],"p,","")&IF(Tab_Def_Flows[[#This Row],[ODYM_Good_(g)2]],"g,","")&IF(Tab_Def_Flows[[#This Row],[ODYM_material_(m)]],"m,","")&IF(Tab_Def_Flows[[#This Row],[ODYM_element_(e)]],"e","") | AL6: =IF(Tab_Def_Flows[[#This Row],[ODYM_time_(t)]],Tab_Def_Flows[[#This Row],[ODYM_Time_ID]]&",","")&IF(Tab_Def_Flows[[#This Row],[ODYM_Region_(r)]],Tab_Def_Flows[[#This Row],[ODYM_Region_ID]]&",","")&IF(Tab_Def_Flows[[#This Row],[ODYM_process_(p)]],Tab_Def_Flows[[#This Row],[ODYM_Process_ID]]&",","")&IF(Tab_Def_Flows[[#This Row],[ODYM_Good_(g)2]],Tab_Def_Flows[[#This Row],[ODYM_Good_ID]]&",","")&IF(Tab_Def_Flows[[#This Row],[ODYM_material_(m)]],Tab_Def_Flows[[#This Row],[ODYM_Material_ID]]&",","")&IF(Tab_Def_Flows[[#This Row],[ODYM_element_(e)]],Tab_Def_Flows[[#This Row],[ODYM_Element_ID]]&",","")
A7: FALSE | B7: =ROW()-1 | C7: ="F_"&LEFT(G7,2)&"_"&LEFT(I7,2) | D7: Environment_Input_millet_production_E | F7: Environment | G7: =_xlfn.XLOOKUP(F7,Tab_Def_Processes[Process_Name],Tab_Def_Processes[Process_ID],,0,) | H7: Millet_Production | I7: =_xlfn.XLOOKUP(H7,Tab_Def_Processes[Process_Name],Tab_Def_Processes[Process_ID],,0,) | J7: Yes | K7: Yes | M7: Yes | N7: =Tab_Def_Flows[[#This Row],[Flow_ID]]&"_WC" | O7: 0.15215687 | Q7: =Tab_Def_Flows[[#This Row],[Flow_ID]]&"_DM" | R7: 0.84784313 | T7: =Tab_Def_Flows[[#This Row],[Flow_ID]]&"_CC" | U7: 0 | W7: =Tab_Def_Flows[[#This Row],[Flow_CC_DM'[%']]]*Tab_Def_Flows[[#This Row],[Flow_DM'[%']]] | Y7: ='0_Configuration'!$C$2 | AA7: ='0_Configuration'!$C$6 | AC7: ='0_Configuration'!$C$10 | AE7: ='0_Configuration'!$C$17 | AF7: =_xlfn.XLOOKUP(Tab_Def_Flows[[#This Row],[ODYM_Good_Type]],Tab_Configuration[Value],Tab_Configuration[ODYM_ID],,0,) | AG7: ='0_Configuration'!$C$24 | AI7: ='0_Configuration'!$C$29 | AK7: =IF(Tab_Def_Flows[[#This Row],[ODYM_time_(t)]],"t,","")&IF(Tab_Def_Flows[[#This Row],[ODYM_Region_(r)]],"r,","")&IF(Tab_Def_Flows[[#This Row],[ODYM_process_(p)]],"p,","")&IF(Tab_Def_Flows[[#This Row],[ODYM_Good_(g)2]],"g,","")&IF(Tab_Def_Flows[[#This Row],[ODYM_material_(m)]],"m,","")&IF(Tab_Def_Flows[[#This Row],[ODYM_element_(e)]],"e","") | AL7: =IF(Tab_Def_Flows[[#This Row],[ODYM_time_(t)]],Tab_Def_Flows[[#This Row],[ODYM_Time_ID]]&",","")&IF(Tab_Def_Flows[[#This Row],[ODYM_Region_(r)]],Tab_Def_Flows[[#This Row],[ODYM_Region_ID]]&",","")&IF(Tab_Def_Flows[[#This Row],[ODYM_process_(p)]],Tab_Def_Flows[[#This Row],[ODYM_Process_ID]]&",","")&IF(Tab_Def_Flows[[#This Row],[ODYM_Good_(g)2]],Tab_Def_Flows[[#This Row],[ODYM_Good_ID]]&",","")&IF(Tab_Def_Flows[[#This Row],[ODYM_material_(m)]],Tab_Def_Flows[[#This Row],[ODYM_Material_ID]]&",","")&IF(Tab_Def_Flows[[#This Row],[ODYM_element_(e)]],Tab_Def_Flows[[#This Row],[ODYM_Element_ID]]&",","")
A8: FALSE | B8: =ROW()-1 | C8: ="F_"&LEFT(G8,2)&"_"&LEFT(I8,2) | D8: Environment_Input_MBC_production_E | F8: Environment | G8: =_xlfn.XLOOKUP(F8,Tab_Def_Processes[Process_Name],Tab_Def_Processes[Process_ID],,0,) | H8: MBC_Production | I8: =_xlfn.XLOOKUP(H8,Tab_Def_Processes[Process_Name],Tab_Def_Processes[Process_ID],,0,) | J8: Yes | K8: Yes | M8: Yes | N8: =Tab_Def_Flows[[#This Row],[Flow_ID]]&"_WC" | O8: 1 | Q8: =Tab_Def_Flows[[#This Row],[Flow_ID]]&"_DM" | R8: 0 | T8: =Tab_Def_Flows[[#This Row],[Flow_ID]]&"_CC" | U8: 0 | W8: =Tab_Def_Flows[[#This Row],[Flow_CC_DM'[%']]]*Tab_Def_Flows[[#This Row],[Flow_DM'[%']]] | Y8: ='0_Configuration'!$C$2 | AA8: ='0_Configuration'!$C$6 | AC8: ='0_Configuration'!$C$10 | AE8: ='0_Configuration'!$C$17 | AF8: =_xlfn.XLOOKUP(Tab_Def_Flows[[#This Row],[ODYM_Good_Type]],Tab_Configuration[Value],Tab_Configuration[ODYM_ID],,0,) | AG8: ='0_Configuration'!$C$24 | AI8: ='0_Configuration'!$C$29 | AK8: =IF(Tab_Def_Flows[[#This Row],[ODYM_time_(t)]],"t,","")&IF(Tab_Def_Flows[[#This Row],[ODYM_Region_(r)]],"r,","")&IF(Tab_Def_Flows[[#This Row],[ODYM_process_(p)]],"p,","")&IF(Tab_Def_Flows[[#This Row],[ODYM_Good_(g)2]],"g,","")&IF(Tab_Def_Flows[[#This Row],[ODYM_material_(m)]],"m,","")&IF(Tab_Def_Flows[[#This Row],[ODYM_element_(e)]],"e","") | AL8: =IF(Tab_Def_Flows[[#This Row],[ODYM_time_(t)]],Tab_Def_Flows[[#This Row],[ODYM_Time_ID]]&",","")&IF(Tab_Def_Flows[[#This Row],[ODYM_Region_(r)]],Tab_Def_Flows[[#This Row],[ODYM_Region_ID]]&",","")&IF(Tab_Def_Flows[[#This Row],[ODYM_process_(p)]],Tab_Def_Flows[[#This Row],[ODYM_Process_ID]]&",","")&IF(Tab_Def_Flows[[#This Row],[ODYM_Good_(g)2]],Tab_Def_Flows[[#This Row],[ODYM_Good_ID]]&",","")&IF(Tab_Def_Flows[[#This Row],[ODYM_material_(m)]],Tab_Def_Flows[[#This Row],[ODYM_Material_ID]]&",","")&IF(Tab_Def_Flows[[#This Row],[ODYM_element_(e)]],Tab_Def_Flows[[#This Row],[ODYM_Element_ID]]&",","")
A9: FALSE | B9: =ROW()-1 | C9: ="F_"&LEFT(G9,2)&"_"&LEFT(I9,2) | D9: Rye-Plant | F9: Rye_Cultivation | G9: =_xlfn.XLOOKUP(F9,Tab_Def_Processes[Process_Name],Tab_Def_Processes[Process_ID],,0,) | H9: Rye_Harvest | I9: =_xlfn.XLOOKUP(H9,Tab_Def_Processes[Process_Name],Tab_Def_Processes[Process_ID],,0,) | J9: Yes | K9: Yes | M9: Yes | N9: =Tab_Def_Flows[[#This Row],[Flow_ID]]&"_WC" | Q9: =Tab_Def_Flows[[#This Row],[Flow_ID]]&"_DM" | T9: =Tab_Def_Flows[[#This Row],[Flow_ID]]&"_CC" | W9: =Tab_Def_Flows[[#This Row],[Flow_CC_DM'[%']]]*Tab_Def_Flows[[#This Row],[Flow_DM'[%']]] | Y9: ='0_Configuration'!$C$2 | AA9: ='0_Configuration'!$C$6 | AC9: ='0_Configuration'!$C$10 | AE9: ='0_Configuration'!$C$17 | AF9: =_xlfn.XLOOKUP(Tab_Def_Flows[[#This Row],[ODYM_Good_Type]],Tab_Configuration[Value],Tab_Configuration[ODYM_ID],,0,) | AG9: ='0_Configuration'!$C$24 | AI9: ='0_Configuration'!$C$29 | AK9: =IF(Tab_Def_Flows[[#This Row],[ODYM_time_(t)]],"t,","")&IF(Tab_Def_Flows[[#This Row],[ODYM_Region_(r)]],"r,","")&IF(Tab_Def_Flows[[#This Row],[ODYM_process_(p)]],"p,","")&IF(Tab_Def_Flows[[#This Row],[ODYM_Good_(g)2]],"g,","")&IF(Tab_Def_Flows[[#This Row],[ODYM_material_(m)]],"m,","")&IF(Tab_Def_Flows[[#This Row],[ODYM_element_(e)]],"e","") | AL9: =IF(Tab_Def_Flows[[#This Row],[ODYM_time_(t)]],Tab_Def_Flows[[#This Row],[ODYM_Time_ID]]&",","")&IF(Tab_Def_Flows[[#This Row],[ODYM_Region_(r)]],Tab_Def_Flows[[#This Row],[ODYM_Region_ID]]&",","")&IF(Tab_Def_Flows[[#This Row],[ODYM_process_(p)]],Tab_Def_Flows[[#This Row],[ODYM_Process_ID]]&",","")&IF(Tab_Def_Flows[[#This Row],[ODYM_Good_(g)2]],Tab_Def_Flows[[#This Row],[ODYM_Good_ID]]&",","")&IF(Tab_Def_Flows[[#This Row],[ODYM_material_(m)]],Tab_Def_Flows[[#This Row],[ODYM_Material_ID]]&",","")&IF(Tab_Def_Flows[[#This Row],[ODYM_element_(e)]],Tab_Def_Flows[[#This Row],[ODYM_Element_ID]]&",","")
A10: FALSE | B10: =ROW()-1 | C10: ="F_"&LEFT(G10,2)&"_"&LEFT(I10,2) | D10: Rye-Grain | F10: Rye_Harvest | G10: =_xlfn.XLOOKUP(F10,Tab_Def_Processes[Process_Name],Tab_Def_Processes[Process_ID],,0,) | H10: Rye-Grain_Processing & Consumption | I10: =_xlfn.XLOOKUP(H10,Tab_Def_Processes[Process_Name],Tab_Def_Processes[Process_ID],,0,) | J10: Yes | K10: Yes | M10: Yes | N10: =Tab_Def_Flows[[#This Row],[Flow_ID]]&"_WC" | Q10: =Tab_Def_Flows[[#This Row],[Flow_ID]]&"_DM" | T10: =Tab_Def_Flows[[#This Row],[Flow_ID]]&"_CC" | W10: =Tab_Def_Flows[[#This Row],[Flow_CC_DM'[%']]]*Tab_Def_Flows[[#This Row],[Flow_DM'[%']]] | Y10: ='0_Configuration'!$C$2 | AA10: ='0_Configuration'!$C$6 | AC10: ='0_Configuration'!$C$10 | AE10: ='0_Configuration'!$C$17 | AF10: =_xlfn.XLOOKUP(Tab_Def_Flows[[#This Row],[ODYM_Good_Type]],Tab_Configuration[Value],Tab_Configuration[ODYM_ID],,0,) | AG10: ='0_Configuration'!$C$24 | AI10: ='0_Configuration'!$C$29 | AK10: =IF(Tab_Def_Flows[[#This Row],[ODYM_time_(t)]],"t,","")&IF(Tab_Def_Flows[[#This Row],[ODYM_Region_(r)]],"r,","")&IF(Tab_Def_Flows[[#This Row],[ODYM_process_(p)]],"p,","")&IF(Tab_Def_Flows[[#This Row],[ODYM_Good_(g)2]],"g,","")&IF(Tab_Def_Flows[[#This Row],[ODYM_material_(m)]],"m,","")&IF(Tab_Def_Flows[[#This Row],[ODYM_element_(e)]],"e","") | AL10: =IF(Tab_Def_Flows[[#This Row],[ODYM_time_(t)]],Tab_Def_Flows[[#This Row],[ODYM_Time_ID]]&",","")&IF(Tab_Def_Flows[[#This Row],[ODYM_Region_(r)]],Tab_Def_Flows[[#This Row],[ODYM_Region_ID]]&",","")&IF(Tab_Def_Flows[[#This Row],[ODYM_process_(p)]],Tab_Def_Flows[[#This Row],[ODYM_Process_ID]]&",","")&IF(Tab_Def_Flows[[#This Row],[ODYM_Good_(g)2]],Tab_Def_Flows[[#This Row],[ODYM_Good_ID]]&",","")&IF(Tab_Def_Flows[[#This Row],[ODYM_material_(m)]],Tab_Def_Flows[[#This Row],[ODYM_Material_ID]]&",","")&IF(Tab_Def_Flows[[#This Row],[ODYM_element_(e)]],Tab_Def_Flows[[#This Row],[ODYM_Element_ID]]&",","")
A11: FALSE | B11: =ROW()-1 | C11: ="F_"&LEFT(G11,2)&"_"&LEFT(I11,2) | D11: Rye-Grain_Processing & Consumption_Emissions_C | F11: Rye-Grain_Processing & Consumption | G11: =_xlfn.XLOOKUP(F11,Tab_Def_Processes[Process_Name],Tab_Def_Processes[Process_ID],,0,) | H11: Atmosphere | I11: =_xlfn.XLOOKUP(H11,Tab_Def_Processes[Process_Name],Tab_Def_Processes[Process_ID],,0,) | J11: Yes | K11: Yes | M11: Yes | N11: =Tab_Def_Flows[[#This Row],[Flow_ID]]&"_WC" | Q11: =Tab_Def_Flows[[#This Row],[Flow_ID]]&"_DM" | T11: =Tab_Def_Flows[[#This Row],[Flow_ID]]&"_CC" | W11: =Tab_Def_Flows[[#This Row],[Flow_CC_DM'[%']]]*Tab_Def_Flows[[#This Row],[Flow_DM'[%']]] | Y11: ='0_Configuration'!$C$2 | AA11: ='0_Configuration'!$C$6 | AC11: ='0_Configuration'!$C$10 | AE11: ='0_Configuration'!$C$17 | AF11: =_xlfn.XLOOKUP(Tab_Def_Flows[[#This Row],[ODYM_Good_Type]],Tab_Configuration[Value],Tab_Configuration[ODYM_ID],,0,) | AG11: ='0_Configuration'!$C$24 | AI11: ='0_Configuration'!$C$29 | AK11: =IF(Tab_Def_Flows[[#This Row],[ODYM_time_(t)]],"t,","")&IF(Tab_Def_Flows[[#This Row],[ODYM_Region_(r)]],"r,","")&IF(Tab_Def_Flows[[#This Row],[ODYM_process_(p)]],"p,","")&IF(Tab_Def_Flows[[#This Row],[ODYM_Good_(g)2]],"g,","")&IF(Tab_Def_Flows[[#This Row],[ODYM_material_(m)]],"m,","")&IF(Tab_Def_Flows[[#This Row],[ODYM_element_(e)]],"e","") | AL11: =IF(Tab_Def_Flows[[#This Row],[ODYM_time_(t)]],Tab_Def_Flows[[#This Row],[ODYM_Time_ID]]&",","")&IF(Tab_Def_Flows[[#This Row],[ODYM_Region_(r)]],Tab_Def_Flows[[#This Row],[ODYM_Region_ID]]&",","")&IF(Tab_Def_Flows[[#This Row],[ODYM_process_(p)]],Tab_Def_Flows[[#This Row],[ODYM_Process_ID]]&",","")&IF(Tab_Def_Flows[[#This Row],[ODYM_Good_(g)2]],Tab_Def_Flows[[#This Row],[ODYM_Good_ID]]&",","")&IF(Tab_Def_Flows[[#This Row],[ODYM_material_(m)]],Tab_Def_Flows[[#This Row],[ODYM_Material_ID]]&",","")&IF(Tab_Def_Flows[[#This Row],[ODYM_element_(e)]],Tab_Def_Flows[[#This Row],[ODYM_Element_ID]]&",","")
A12: FALSE | B12: =ROW()-1 | C12: ="F_"&LEFT(G12,2)&"_"&LEFT(I12,2) | D12: Rye-Grain_Processing & Consumption_Emissions_E | F12: Rye-Grain_Processing & Consumption | G12: =_xlfn.XLOOKUP(F12,Tab_Def_Processes[Process_Name],Tab_Def_Processes[Process_ID],,0,) | H12: Environment | I12: =_xlfn.XLOOKUP(H12,Tab_Def_Processes[Process_Name],Tab_Def_Processes[Process_ID],,0,) | J12: Yes | K12: Yes | M12: Yes | N12: =Tab_Def_Flows[[#This Row],[Flow_ID]]&"_WC" | Q12: =Tab_Def_Flows[[#This Row],[Flow_ID]]&"_DM" | T12: =Tab_Def_Flows[[#This Row],[Flow_ID]]&"_CC" | W12: =Tab_Def_Flows[[#This Row],[Flow_CC_DM'[%']]]*Tab_Def_Flows[[#This Row],[Flow_DM'[%']]] | Y12: ='0_Configuration'!$C$2 | AA12: ='0_Configuration'!$C$6 | AC12: ='0_Configuration'!$C$10 | AE12: ='0_Configuration'!$C$17 | AF12: =_xlfn.XLOOKUP(Tab_Def_Flows[[#This Row],[ODYM_Good_Type]],Tab_Configuration[Value],Tab_Configuration[ODYM_ID],,0,) | AG12: ='0_Configuration'!$C$24 | AI12: ='0_Configuration'!$C$29 | AK12: =IF(Tab_Def_Flows[[#This Row],[ODYM_time_(t)]],"t,","")&IF(Tab_Def_Flows[[#This Row],[ODYM_Region_(r)]],"r,","")&IF(Tab_Def_Flows[[#This Row],[ODYM_process_(p)]],"p,","")&IF(Tab_Def_Flows[[#This Row],[ODYM_Good_(g)2]],"g,","")&IF(Tab_Def_Flows[[#This Row],[ODYM_material_(m)]],"m,","")&IF(Tab_Def_Flows[[#This Row],[ODYM_element_(e)]],"e","") | AL12: =IF(Tab_Def_Flows[[#This Row],[ODYM_time_(t)]],Tab_Def_Flows[[#This Row],[ODYM_Time_ID]]&",","")&IF(Tab_Def_Flows[[#This Row],[ODYM_Region_(r)]],Tab_Def_Flows[[#This Row],[ODYM_Region_ID]]&",","")&IF(Tab_Def_Flows[[#This Row],[ODYM_process_(p)]],Tab_Def_Flows[[#This Row],[ODYM_Process_ID]]&",","")&IF(Tab_Def_Flows[[#This Row],[ODYM_Good_(g)2]],Tab_Def_Flows[[#This Row],[ODYM_Good_ID]]&",","")&IF(Tab_Def_Flows[[#This Row],[ODYM_material_(m)]],Tab_Def_Flows[[#This Row],[ODYM_Material_ID]]&",","")&IF(Tab_Def_Flows[[#This Row],[ODYM_element_(e)]],Tab_Def_Flows[[#This Row],[ODYM_Element_ID]]&",","")
A13: FALSE | B13: =ROW()-1 | C13: ="F_"&LEFT(G13,2)&"_"&LEFT(I13,2) | D13: Rye-Straw(mobilisable-used) | F13: Rye_Harvest | G13: =_xlfn.XLOOKUP(F13,Tab_Def_Processes[Process_Name],Tab_Def_Processes[Process_ID],,0,) | H13: Rye-Straw-mobilisable technical potential_Use | I13: =_xlfn.XLOOKUP(H13,Tab_Def_Processes[Process_Name],Tab_Def_Processes[Process_ID],,0,) | J13: Yes | K13: Yes | M13: Yes | N13: =Tab_Def_Flows[[#This Row],[Flow_ID]]&"_WC" | Q13: =Tab_Def_Flows[[#This Row],[Flow_ID]]&"_DM" | T13: =Tab_Def_Flows[[#This Row],[Flow_ID]]&"_CC" | W13: =Tab_Def_Flows[[#This Row],[Flow_CC_DM'[%']]]*Tab_Def_Flows[[#This Row],[Flow_DM'[%']]] | Y13: ='0_Configuration'!$C$2 | AA13: ='0_Configuration'!$C$6 | AC13: ='0_Configuration'!$C$10 | AE13: ='0_Configuration'!$C$17 | AF13: =_xlfn.XLOOKUP(Tab_Def_Flows[[#This Row],[ODYM_Good_Type]],Tab_Configuration[Value],Tab_Configuration[ODYM_ID],,0,) | AG13: ='0_Configuration'!$C$24 | AI13: ='0_Configuration'!$C$29 | AK13: =IF(Tab_Def_Flows[[#This Row],[ODYM_time_(t)]],"t,","")&IF(Tab_Def_Flows[[#This Row],[ODYM_Region_(r)]],"r,","")&IF(Tab_Def_Flows[[#This Row],[ODYM_process_(p)]],"p,","")&IF(Tab_Def_Flows[[#This Row],[ODYM_Good_(g)2]],"g,","")&IF(Tab_Def_Flows[[#This Row],[ODYM_material_(m)]],"m,","")&IF(Tab_Def_Flows[[#This Row],[ODYM_element_(e)]],"e","") | AL13: =IF(Tab_Def_Flows[[#This Row],[ODYM_time_(t)]],Tab_Def_Flows[[#This Row],[ODYM_Time_ID]]&",","")&IF(Tab_Def_Flows[[#This Row],[ODYM_Region_(r)]],Tab_Def_Flows[[#This Row],[ODYM_Region_ID]]&",","")&IF(Tab_Def_Flows[[#This Row],[ODYM_process_(p)]],Tab_Def_Flows[[#This Row],[ODYM_Process_ID]]&",","")&IF(Tab_Def_Flows[[#This Row],[ODYM_Good_(g)2]],Tab_Def_Flows[[#This Row],[ODYM_Good_ID]]&",","")&IF(Tab_Def_Flows[[#This Row],[ODYM_material_(m)]],Tab_Def_Flows[[#This Row],[ODYM_Material_ID]]&",","")&IF(Tab_Def_Flows[[#This Row],[ODYM_element_(e)]],Tab_Def_Flows[[#This Row],[ODYM_Element_ID]]&",","")
A14: FALSE | B14: =ROW()-1 | C14: ="F_"&LEFT(G14,2)&"_"&LEFT(I14,2) | D14: Rye-Straw(mobilisable) | F14: Rye_Harvest | G14: =_xlfn.XLOOKUP(F14,Tab_Def_Processes[Process_Name],Tab_Def_Processes[Process_ID],,0,) | H14: Biogas_Production | I14: =_xlfn.XLOOKUP(H14,Tab_Def_Processes[Process_Name],Tab_Def_Processes[Process_ID],,0,) | J14: Yes | K14: Yes | M14: Yes | N14: =Tab_Def_Flows[[#This Row],[Flow_ID]]&"_WC" | Q14: =Tab_Def_Flows[[#This Row],[Flow_ID]]&"_DM" | T14: =Tab_Def_Flows[[#This Row],[Flow_ID]]&"_CC" | W14: =Tab_Def_Flows[[#This Row],[Flow_CC_DM'[%']]]*Tab_Def_Flows[[#This Row],[Flow_DM'[%']]] | Y14: ='0_Configuration'!$C$2 | AA14: ='0_Configuration'!$C$6 | AC14: ='0_Configuration'!$C$10 | AE14: ='0_Configuration'!$C$17 | AF14: =_xlfn.XLOOKUP(Tab_Def_Flows[[#This Row],[ODYM_Good_Type]],Tab_Configuration[Value],Tab_Configuration[ODYM_ID],,0,) | AG14: ='0_Configuration'!$C$24 | AI14: ='0_Configuration'!$C$29 | AK14: =IF(Tab_Def_Flows[[#This Row],[ODYM_time_(t)]],"t,","")&IF(Tab_Def_Flows[[#This Row],[ODYM_Region_(r)]],"r,","")&IF(Tab_Def_Flows[[#This Row],[ODYM_process_(p)]],"p,","")&IF(Tab_Def_Flows[[#This Row],[ODYM_Good_(g)2]],"g,","")&IF(Tab_Def_Flows[[#This Row],[ODYM_material_(m)]],"m,","")&IF(Tab_Def_Flows[[#This Row],[ODYM_element_(e)]],"e","") | AL14: =IF(Tab_Def_Flows[[#This Row],[ODYM_time_(t)]],Tab_Def_Flows[[#This Row],[ODYM_Time_ID]]&",","")&IF(Tab_Def_Flows[[#This Row],[ODYM_Region_(r)]],Tab_Def_Flows[[#This Row],[ODYM_Region_ID]]&",","")&IF(Tab_Def_Flows[[#This Row],[ODYM_process_(p)]],Tab_Def_Flows[[#This Row],[ODYM_Process_ID]]&",","")&IF(Tab_Def_Flows[[#This Row],[ODYM_Good_(g)2]],Tab_Def_Flows[[#This Row],[ODYM_Good_ID]]&",","")&IF(Tab_Def_Flows[[#This Row],[ODYM_material_(m)]],Tab_Def_Flows[[#This Row],[ODYM_Material_ID]]&",","")&IF(Tab_Def_Flows[[#This Row],[ODYM_element_(e)]],Tab_Def_Flows[[#This Row],[ODYM_Element_ID]]&",","")
A15: FALSE | B15: =ROW()-1 | C15: ="F_"&LEFT(G15,2)&"_"&LEFT(I15,2) | D15: Rye-Straw(Not mobilisable) | F15: Rye_Harvest | G15: =_xlfn.XLOOKUP(F15,Tab_Def_Processes[Process_Name],Tab_Def_Processes[Process_ID],,0,) | H15: Rye-Straw(non-mobilizable)_Degradation | I15: =_xlfn.XLOOKUP(H15,Tab_Def_Processes[Process_Name],Tab_Def_Processes[Process_ID],,0,) | J15: Yes | K15: Yes | M15: Yes | N15: =Tab_Def_Flows[[#This Row],[Flow_ID]]&"_WC" | Q15: =Tab_Def_Flows[[#This Row],[Flow_ID]]&"_DM" | T15: =Tab_Def_Flows[[#This Row],[Flow_ID]]&"_CC" | W15: =Tab_Def_Flows[[#This Row],[Flow_CC_DM'[%']]]*Tab_Def_Flows[[#This Row],[Flow_DM'[%']]] | Y15: ='0_Configuration'!$C$2 | AA15: ='0_Configuration'!$C$6 | AC15: ='0_Configuration'!$C$10 | AE15: ='0_Configuration'!$C$17 | AF15: =_xlfn.XLOOKUP(Tab_Def_Flows[[#This Row],[ODYM_Good_Type]],Tab_Configuration[Value],Tab_Configuration[ODYM_ID],,0,) | AG15: ='0_Configuration'!$C$24 | AI15: ='0_Configuration'!$C$29 | AK15: =IF(Tab_Def_Flows[[#This Row],[ODYM_time_(t)]],"t,","")&IF(Tab_Def_Flows[[#This Row],[ODYM_Region_(r)]],"r,","")&IF(Tab_Def_Flows[[#This Row],[ODYM_process_(p)]],"p,","")&IF(Tab_Def_Flows[[#This Row],[ODYM_Good_(g)2]],"g,","")&IF(Tab_Def_Flows[[#This Row],[ODYM_material_(m)]],"m,","")&IF(Tab_Def_Flows[[#This Row],[ODYM_element_(e)]],"e","") | AL15: =IF(Tab_Def_Flows[[#This Row],[ODYM_time_(t)]],Tab_Def_Flows[[#This Row],[ODYM_Time_ID]]&",","")&IF(Tab_Def_Flows[[#This Row],[ODYM_Region_(r)]],Tab_Def_Flows[[#This Row],[ODYM_Region_ID]]&",","")&IF(Tab_Def_Flows[[#This Row],[ODYM_process_(p)]],Tab_Def_Flows[[#This Row],[ODYM_Process_ID]]&",","")&IF(Tab_Def_Flows[[#This Row],[ODYM_Good_(g)2]],Tab_Def_Flows[[#This Row],[ODYM_Good_ID]]&",","")&IF(Tab_Def_Flows[[#This Row],[ODYM_material_(m)]],Tab_Def_Flows[[#This Row],[ODYM_Material_ID]]&",","")&IF(Tab_Def_Flows[[#This Row],[ODYM_element_(e)]],Tab_Def_Flows[[#This Row],[ODYM_Element_ID]]&",","")
A16: FALSE | B16: =ROW()-1 | C16: ="F_"&LEFT(G16,2)&"_"&LEFT(I16,2) | D16: Rye-Straw(mobilisable-used)_Emissions_C | F16: Rye-Straw-mobilisable technical potential_Use | G16: =_xlfn.XLOOKUP(F16,Tab_Def_Processes[Process_Name],Tab_Def_Processes[Process_ID],,0,) | H16: Atmosphere | I16: =_xlfn.XLOOKUP(H16,Tab_Def_Processes[Process_Name],Tab_Def_Processes[Process_ID],,0,) | J16: Yes | K16: Yes | M16: Yes | N16: =Tab_Def_Flows[[#This Row],[Flow_ID]]&"_WC" | Q16: =Tab_Def_Flows[[#This Row],[Flow_ID]]&"_DM" | T16: =Tab_Def_Flows[[#This Row],[Flow_ID]]&"_CC" | W16: =Tab_Def_Flows[[#This Row],[Flow_CC_DM'[%']]]*Tab_Def_Flows[[#This Row],[Flow_DM'[%']]] | Y16: ='0_Configuration'!$C$2 | AA16: ='0_Configuration'!$C$6 | AC16: ='0_Configuration'!$C$10 | AE16: ='0_Configuration'!$C$17 | AF16: =_xlfn.XLOOKUP(Tab_Def_Flows[[#This Row],[ODYM_Good_Type]],Tab_Configuration[Value],Tab_Configuration[ODYM_ID],,0,) | AG16: ='0_Configuration'!$C$24 | AI16: ='0_Configuration'!$C$29 | AK16: =IF(Tab_Def_Flows[[#This Row],[ODYM_time_(t)]],"t,","")&IF(Tab_Def_Flows[[#This Row],[ODYM_Region_(r)]],"r,","")&IF(Tab_Def_Flows[[#This Row],[ODYM_process_(p)]],"p,","")&IF(Tab_Def_Flows[[#This Row],[ODYM_Good_(g)2]],"g,","")&IF(Tab_Def_Flows[[#This Row],[ODYM_material_(m)]],"m,","")&IF(Tab_Def_Flows[[#This Row],[ODYM_element_(e)]],"e","") | AL16: =IF(Tab_Def_Flows[[#This Row],[ODYM_time_(t)]],Tab_Def_Flows[[#This Row],[ODYM_Time_ID]]&",","")&IF(Tab_Def_Flows[[#This Row],[ODYM_Region_(r)]],Tab_Def_Flows[[#This Row],[ODYM_Region_ID]]&",","")&IF(Tab_Def_Flows[[#This Row],[ODYM_process_(p)]],Tab_Def_Flows[[#This Row],[ODYM_Process_ID]]&",","")&IF(Tab_Def_Flows[[#This Row],[ODYM_Good_(g)2]],Tab_Def_Flows[[#This Row],[ODYM_Good_ID]]&",","")&IF(Tab_Def_Flows[[#This Row],[ODYM_material_(m)]],Tab_Def_Flows[[#This Row],[ODYM_Material_ID]]&",","")&IF(Tab_Def_Flows[[#This Row],[ODYM_element_(e)]],Tab_Def_Flows[[#This Row],[ODYM_Element_ID]]&",","")
A17: FALSE | B17: =ROW()-1 | C17: ="F_"&LEFT(G17,2)&"_"&LEFT(I17,2) | D17: Rye-Straw(mobilisable-used)_Emissions_E | F17: Rye-Straw-mobilisable technical potential_Use | G17: =_xlfn.XLOOKUP(F17,Tab_Def_Processes[Process_Name],Tab_Def_Processes[Process_ID],,0,) | H17: Environment | I17: =_xlfn.XLOOKUP(H17,Tab_Def_Processes[Process_Name],Tab_Def_Processes[Process_ID],,0,) | J17: Yes | K17: Yes | M17: Yes | N17: =Tab_Def_Flows[[#This Row],[Flow_ID]]&"_WC" | Q17: =Tab_Def_Flows[[#This Row],[Flow_ID]]&"_DM" | T17: =Tab_Def_Flows[[#This Row],[Flow_ID]]&"_CC" | W17: =Tab_Def_Flows[[#This Row],[Flow_CC_DM'[%']]]*Tab_Def_Flows[[#This Row],[Flow_DM'[%']]] | Y17: ='0_Configuration'!$C$2 | AA17: ='0_Configuration'!$C$6 | AC17: ='0_Configuration'!$C$10 | AE17: ='0_Configuration'!$C$17 | AF17: =_xlfn.XLOOKUP(Tab_Def_Flows[[#This Row],[ODYM_Good_Type]],Tab_Configuration[Value],Tab_Configuration[ODYM_ID],,0,) | AG17: ='0_Configuration'!$C$24 | AI17: ='0_Configuration'!$C$29 | AK17: =IF(Tab_Def_Flows[[#This Row],[ODYM_time_(t)]],"t,","")&IF(Tab_Def_Flows[[#This Row],[ODYM_Region_(r)]],"r,","")&IF(Tab_Def_Flows[[#This Row],[ODYM_process_(p)]],"p,","")&IF(Tab_Def_Flows[[#This Row],[ODYM_Good_(g)2]],"g,","")&IF(Tab_Def_Flows[[#This Row],[ODYM_material_(m)]],"m,","")&IF(Tab_Def_Flows[[#This Row],[ODYM_element_(e)]],"e","") | AL17: =IF(Tab_Def_Flows[[#This Row],[ODYM_time_(t)]],Tab_Def_Flows[[#This Row],[ODYM_Time_ID]]&",","")&IF(Tab_Def_Flows[[#This Row],[ODYM_Region_(r)]],Tab_Def_Flows[[#This Row],[ODYM_Region_ID]]&",","")&IF(Tab_Def_Flows[[#This Row],[ODYM_process_(p)]],Tab_Def_Flows[[#This Row],[ODYM_Process_ID]]&",","")&IF(Tab_Def_Flows[[#This Row],[ODYM_Good_(g)2]],Tab_Def_Flows[[#This Row],[ODYM_Good_ID]]&",","")&IF(Tab_Def_Flows[[#This Row],[ODYM_material_(m)]],Tab_Def_Flows[[#This Row],[ODYM_Material_ID]]&",","")&IF(Tab_Def_Flows[[#This Row],[ODYM_element_(e)]],Tab_Def_Flows[[#This Row],[ODYM_Element_ID]]&",","")
A18: FALSE | B18: =ROW()-1 | C18: ="F_"&LEFT(G18,2)&"_"&LEFT(I18,2) | D18: Rye-Straw(Not mobilisable)_Emissions_C | F18: Rye-Straw(non-mobilizable)_Degradation | G18: =_xlfn.XLOOKUP(F18,Tab_Def_Processes[Process_Name],Tab_Def_Processes[Process_ID],,0,) | H18: Atmosphere | I18: =_xlfn.XLOOKUP(H18,Tab_Def_Processes[Process_Name],Tab_Def_Processes[Process_ID],,0,) | J18: Yes | K18: Yes | M18: Yes | N18: =Tab_Def_Flows[[#This Row],[Flow_ID]]&"_WC" | Q18: =Tab_Def_Flows[[#This Row],[Flow_ID]]&"_DM" | T18: =Tab_Def_Flows[[#This Row],[Flow_ID]]&"_CC" | W18: =Tab_Def_Flows[[#This Row],[Flow_CC_DM'[%']]]*Tab_Def_Flows[[#This Row],[Flow_DM'[%']]] | Y18: ='0_Configuration'!$C$2 | AA18: ='0_Configuration'!$C$6 | AC18: ='0_Configuration'!$C$10 | AE18: ='0_Configuration'!$C$17 | AF18: =_xlfn.XLOOKUP(Tab_Def_Flows[[#This Row],[ODYM_Good_Type]],Tab_Configuration[Value],Tab_Configuration[ODYM_ID],,0,) | AG18: ='0_Configuration'!$C$24 | AI18: ='0_Configuration'!$C$29 | AK18: =IF(Tab_Def_Flows[[#This Row],[ODYM_time_(t)]],"t,","")&IF(Tab_Def_Flows[[#This Row],[ODYM_Region_(r)]],"r,","")&IF(Tab_Def_Flows[[#This Row],[ODYM_process_(p)]],"p,","")&IF(Tab_Def_Flows[[#This Row],[ODYM_Good_(g)2]],"g,","")&IF(Tab_Def_Flows[[#This Row],[ODYM_material_(m)]],"m,","")&IF(Tab_Def_Flows[[#This Row],[ODYM_element_(e)]],"e","") | AL18: =IF(Tab_Def_Flows[[#This Row],[ODYM_time_(t)]],Tab_Def_Flows[[#This Row],[ODYM_Time_ID]]&",","")&IF(Tab_Def_Flows[[#This Row],[ODYM_Region_(r)]],Tab_Def_Flows[[#This Row],[ODYM_Region_ID]]&",","")&IF(Tab_Def_Flows[[#This Row],[ODYM_process_(p)]],Tab_Def_Flows[[#This Row],[ODYM_Process_ID]]&",","")&IF(Tab_Def_Flows[[#This Row],[ODYM_Good_(g)2]],Tab_Def_Flows[[#This Row],[ODYM_Good_ID]]&",","")&IF(Tab_Def_Flows[[#This Row],[ODYM_material_(m)]],Tab_Def_Flows[[#This Row],[ODYM_Material_ID]]&",","")&IF(Tab_Def_Flows[[#This Row],[ODYM_element_(e)]],Tab_Def_Flows[[#This Row],[ODYM_Element_ID]]&",","")
A19: FALSE | B19: =ROW()-1 | C19: ="F_"&LEFT(G19,2)&"_"&LEFT(I19,2) | D19: Rye-Straw(Not mobilisable)_Emissions_E | F19: Rye-Straw(non-mobilizable)_Degradation | G19: =_xlfn.XLOOKUP(F19,Tab_Def_Processes[Process_Name],Tab_Def_Processes[Process_ID],,0,) | H19: Environment | I19: =_xlfn.XLOOKUP(H19,Tab_Def_Processes[Process_Name],Tab_Def_Processes[Process_ID],,0,) | J19: Yes | K19: Yes | M19: Yes | N19: =Tab_Def_Flows[[#This Row],[Flow_ID]]&"_WC" | Q19: =Tab_Def_Flows[[#This Row],[Flow_ID]]&"_DM" | T19: =Tab_Def_Flows[[#This Row],[Flow_ID]]&"_CC" | W19: =Tab_Def_Flows[[#This Row],[Flow_CC_DM'[%']]]*Tab_Def_Flows[[#This Row],[Flow_DM'[%']]] | Y19: ='0_Configuration'!$C$2 | AA19: ='0_Configuration'!$C$6 | AC19: ='0_Configuration'!$C$10 | AE19: ='0_Configuration'!$C$17 | AF19: =_xlfn.XLOOKUP(Tab_Def_Flows[[#This Row],[ODYM_Good_Type]],Tab_Configuration[Value],Tab_Configuration[ODYM_ID],,0,) | AG19: ='0_Configuration'!$C$24 | AI19: ='0_Configuration'!$C$29 | AK19: =IF(Tab_Def_Flows[[#This Row],[ODYM_time_(t)]],"t,","")&IF(Tab_Def_Flows[[#This Row],[ODYM_Region_(r)]],"r,","")&IF(Tab_Def_Flows[[#This Row],[ODYM_process_(p)]],"p,","")&IF(Tab_Def_Flows[[#This Row],[ODYM_Good_(g)2]],"g,","")&IF(Tab_Def_Flows[[#This Row],[ODYM_material_(m)]],"m,","")&IF(Tab_Def_Flows[[#This Row],[ODYM_element_(e)]],"e","") | AL19: =IF(Tab_Def_Flows[[#This Row],[ODYM_time_(t)]],Tab_Def_Flows[[#This Row],[ODYM_Time_ID]]&",","")&IF(Tab_Def_Flows[[#This Row],[ODYM_Region_(r)]],Tab_Def_Flows[[#This Row],[ODYM_Region_ID]]&",","")&IF(Tab_Def_Flows[[#This Row],[ODYM_process_(p)]],Tab_Def_Flows[[#This Row],[ODYM_Process_ID]]&",","")&IF(Tab_Def_Flows[[#This Row],[ODYM_Good_(g)2]],Tab_Def_Flows[[#This Row],[ODYM_Good_ID]]&",","")&IF(Tab_Def_Flows[[#This Row],[ODYM_material_(m)]],Tab_Def_Flows[[#This Row],[ODYM_Material_ID]]&",","")&IF(Tab_Def_Flows[[#This Row],[ODYM_element_(e)]],Tab_Def_Flows[[#This Row],[ODYM_Element_ID]]&",","")
A20: FALSE | B20: =ROW()-1 | C20: ="F_"&LEFT(G20,2)&"_"&LEFT(I20,2) | D20: Cow-Manure | F20: Cow-Manure_Production | G20: =_xlfn.XLOOKUP(F20,Tab_Def_Processes[Process_Name],Tab_Def_Processes[Process_ID],,0,) | H20: MBC_Production | I20: =_xlfn.XLOOKUP(H20,Tab_Def_Processes[Process_Name],Tab_Def_Processes[Process_ID],,0,) | J20: Yes | K20: Yes | M20: Yes | N20: =Tab_Def_Flows[[#This Row],[Flow_ID]]&"_WC" | Q20: =Tab_Def_Flows[[#This Row],[Flow_ID]]&"_DM" | T20: =Tab_Def_Flows[[#This Row],[Flow_ID]]&"_CC" | W20: =Tab_Def_Flows[[#This Row],[Flow_CC_DM'[%']]]*Tab_Def_Flows[[#This Row],[Flow_DM'[%']]] | Y20: ='0_Configuration'!$C$2 | AA20: ='0_Configuration'!$C$6 | AC20: ='0_Configuration'!$C$10 | AE20: ='0_Configuration'!$C$17 | AF20: =_xlfn.XLOOKUP(Tab_Def_Flows[[#This Row],[ODYM_Good_Type]],Tab_Configuration[Value],Tab_Configuration[ODYM_ID],,0,) | AG20: ='0_Configuration'!$C$24 | AI20: ='0_Configuration'!$C$29 | AK20: =IF(Tab_Def_Flows[[#This Row],[ODYM_time_(t)]],"t,","")&IF(Tab_Def_Flows[[#This Row],[ODYM_Region_(r)]],"r,","")&IF(Tab_Def_Flows[[#This Row],[ODYM_process_(p)]],"p,","")&IF(Tab_Def_Flows[[#This Row],[ODYM_Good_(g)2]],"g,","")&IF(Tab_Def_Flows[[#This Row],[ODYM_material_(m)]],"m,","")&IF(Tab_Def_Flows[[#This Row],[ODYM_element_(e)]],"e","") | AL20: =IF(Tab_Def_Flows[[#This Row],[ODYM_time_(t)]],Tab_Def_Flows[[#This Row],[ODYM_Time_ID]]&",","")&IF(Tab_Def_Flows[[#This Row],[ODYM_Region_(r)]],Tab_Def_Flows[[#This Row],[ODYM_Region_ID]]&",","")&IF(Tab_Def_Flows[[#This Row],[ODYM_process_(p)]],Tab_Def_Flows[[#This Row],[ODYM_Process_ID]]&",","")&IF(Tab_Def_Flows[[#This Row],[ODYM_Good_(g)2]],Tab_Def_Flows[[#This Row],[ODYM_Good_ID]]&",","")&IF(Tab_Def_Flows[[#This Row],[ODYM_material_(m)]],Tab_Def_Flows[[#This Row],[ODYM_Material_ID]]&",","")&IF(Tab_Def_Flows[[#This Row],[ODYM_element_(e)]],Tab_Def_Flows[[#This Row],[ODYM_Element_ID]]&",","")
... A52: FALSE | B52: =ROW()-1 | C52: ="F_"&LEFT(G52,2)&"_"&LEFT(I52,2) | D52: Ash-Incineration_Emissions_E | F52: Ash_Treatment | G52: =_xlfn.XLOOKUP(F52,Tab_Def_Processes[Process_Name],Tab_Def_Processes[Process_ID],,0,) | H52: Environment | I52: =_xlfn.XLOOKUP(H52,Tab_Def_Processes[Process_Name],Tab_Def_Processes[Process_ID],,0,) | J52: Yes | K52: Yes | M52: Yes | N52: =Tab_Def_Flows[[#This Row],[Flow_ID]]&"_WC" | Q52: =Tab_Def_Flows[[#This Row],[Flow_ID]]&"_DM" | T52: =Tab_Def_Flows[[#This Row],[Flow_ID]]&"_CC" | W52: =Tab_Def_Flows[[#This Row],[Flow_CC_DM'[%']]]*Tab_Def_Flows[[#This Row],[Flow_DM'[%']]] | Y52: ='0_Configuration'!$C$2 | AA52: ='0_Configuration'!$C$6 | AC52: ='0_Configuration'!$C$10 | AE52: ='0_Configuration'!$C$17 | AF52: =_xlfn.XLOOKUP(Tab_Def_Flows[[#This Row],[ODYM_Good_Type]],Tab_Configuration[Value],Tab_Configuration[ODYM_ID],,0,) | AG52: ='0_Configuration'!$C$24 | AI52: ='0_Configuration'!$C$29 | AK52: =IF(Tab_Def_Flows[[#This Row],[ODYM_time_(t)]],"t,","")&IF(Tab_Def_Flows[[#This Row],[ODYM_Region_(r)]],"r,","")&IF(Tab_Def_Flows[[#This Row],[ODYM_process_(p)]],"p,","")&IF(Tab_Def_Flows[[#This Row],[ODYM_Good_(g)2]],"g,","")&IF(Tab_Def_Flows[[#This Row],[ODYM_material_(m)]],"m,","")&IF(Tab_Def_Flows[[#This Row],[ODYM_element_(e)]],"e","") | AL52: =IF(Tab_Def_Flows[[#This Row],[ODYM_time_(t)]],Tab_Def_Flows[[#This Row],[ODYM_Time_ID]]&",","")&IF(Tab_Def_Flows[[#This Row],[ODYM_Region_(r)]],Tab_Def_Flows[[#This Row],[ODYM_Region_ID]]&",","")&IF(Tab_Def_Flows[[#This Row],[ODYM_process_(p)]],Tab_Def_Flows[[#This Row],[ODYM_Process_ID]]&",","")&IF(Tab_Def_Flows[[#This Row],[ODYM_Good_(g)2]],Tab_Def_Flows[[#This Row],[ODYM_Good_ID]]&",","")&IF(Tab_Def_Flows[[#This Row],[ODYM_material_(m)]],Tab_Def_Flows[[#This Row],[ODYM_Material_ID]]&",","")&IF(Tab_Def_Flows[[#This Row],[ODYM_element_(e)]],Tab_Def_Flows[[#This Row],[ODYM_Element_ID]]&",","")
A53: FALSE | B53: =ROW()-1 | C53: ="F_"&LEFT(G53,2)&"_"&LEFT(I53,2) | G53: =_xlfn.XLOOKUP(F53,Tab_Def_Processes[Process_Name],Tab_Def_Processes[Process_ID],,0,) | I53: =_xlfn.XLOOKUP(H53,Tab_Def_Processes[Process_Name],Tab_Def_Processes[Process_ID],,0,) | J53: Yes | K53: Yes | M53: Yes | N53: =Tab_Def_Flows[[#This Row],[Flow_ID]]&"_WC" | Q53: =Tab_Def_Flows[[#This Row],[Flow_ID]]&"_DM" | T53: =Tab_Def_Flows[[#This Row],[Flow_ID]]&"_CC" | W53: =Tab_Def_Flows[[#This Row],[Flow_CC_DM'[%']]]*Tab_Def_Flows[[#This Row],[Flow_DM'[%']]] | Y53: ='0_Configuration'!$C$2 | AA53: ='0_Configuration'!$C$6 | AC53: ='0_Configuration'!$C$10 | AE53: ='0_Configuration'!$C$17 | AF53: =_xlfn.XLOOKUP(Tab_Def_Flows[[#This Row],[ODYM_Good_Type]],Tab_Configuration[Value],Tab_Configuration[ODYM_ID],,0,) | AG53: ='0_Configuration'!$C$24 | AI53: ='0_Configuration'!$C$29 | AK53: =IF(Tab_Def_Flows[[#This Row],[ODYM_time_(t)]],"t,","")&IF(Tab_Def_Flows[[#This Row],[ODYM_Region_(r)]],"r,","")&IF(Tab_Def_Flows[[#This Row],[ODYM_process_(p)]],"p,","")&IF(Tab_Def_Flows[[#This Row],[ODYM_Good_(g)2]],"g,","")&IF(Tab_Def_Flows[[#This Row],[ODYM_material_(m)]],"m,","")&IF(Tab_Def_Flows[[#This Row],[ODYM_element_(e)]],"e","") | AL53: =IF(Tab_Def_Flows[[#This Row],[ODYM_time_(t)]],Tab_Def_Flows[[#This Row],[ODYM_Time_ID]]&",","")&IF(Tab_Def_Flows[[#This Row],[ODYM_Region_(r)]],Tab_Def_Flows[[#This Row],[ODYM_Region_ID]]&",","")&IF(Tab_Def_Flows[[#This Row],[ODYM_process_(p)]],Tab_Def_Flows[[#This Row],[ODYM_Process_ID]]&",","")&IF(Tab_Def_Flows[[#This Row],[ODYM_Good_(g)2]],Tab_Def_Flows[[#This Row],[ODYM_Good_ID]]&",","")&IF(Tab_Def_Flows[[#This Row],[ODYM_material_(m)]],Tab_Def_Flows[[#This Row],[ODYM_Material_ID]]&",","")&IF(Tab_Def_Flows[[#This Row],[ODYM_element_(e)]],Tab_Def_Flows[[#This Row],[ODYM_Element_ID]]&",","")
A54: FALSE | B54: =ROW()-1 | C54: ="F_"&LEFT(G54,2)&"_"&LEFT(I54,2) | G54: =_xlfn.XLOOKUP(F54,Tab_Def_Processes[Process_Name],Tab_Def_Processes[Process_ID],,0,) | I54: =_xlfn.XLOOKUP(H54,Tab_Def_Processes[Process_Name],Tab_Def_Processes[Process_ID],,0,) | J54: Yes | K54: Yes | M54: Yes | N54: =Tab_Def_Flows[[#This Row],[Flow_ID]]&"_WC" | Q54: =Tab_Def_Flows[[#This Row],[Flow_ID]]&"_DM" | T54: =Tab_Def_Flows[[#This Row],[Flow_ID]]&"_CC" | W54: =Tab_Def_Flows[[#This Row],[Flow_CC_DM'[%']]]*Tab_Def_Flows[[#This Row],[Flow_DM'[%']]] | Y54: ='0_Configuration'!$C$2 | AA54: ='0_Configuration'!$C$6 | AC54: ='0_Configuration'!$C$10 | AE54: ='0_Configuration'!$C$17 | AF54: =_xlfn.XLOOKUP(Tab_Def_Flows[[#This Row],[ODYM_Good_Type]],Tab_Configuration[Value],Tab_Configuration[ODYM_ID],,0,) | AG54: ='0_Configuration'!$C$24 | AI54: ='0_Configuration'!$C$29 | AK54: =IF(Tab_Def_Flows[[#This Row],[ODYM_time_(t)]],"t,","")&IF(Tab_Def_Flows[[#This Row],[ODYM_Region_(r)]],"r,","")&IF(Tab_Def_Flows[[#This Row],[ODYM_process_(p)]],"p,","")&IF(Tab_Def_Flows[[#This Row],[ODYM_Good_(g)2]],"g,","")&IF(Tab_Def_Flows[[#This Row],[ODYM_material_(m)]],"m,","")&IF(Tab_Def_Flows[[#This Row],[ODYM_element_(e)]],"e","") | AL54: =IF(Tab_Def_Flows[[#This Row],[ODYM_time_(t)]],Tab_Def_Flows[[#This Row],[ODYM_Time_ID]]&",","")&IF(Tab_Def_Flows[[#This Row],[ODYM_Region_(r)]],Tab_Def_Flows[[#This Row],[ODYM_Region_ID]]&",","")&IF(Tab_Def_Flows[[#This Row],[ODYM_process_(p)]],Tab_Def_Flows[[#This Row],[ODYM_Process_ID]]&",","")&IF(Tab_Def_Flows[[#This Row],[ODYM_Good_(g)2]],Tab_Def_Flows[[#This Row],[ODYM_Good_ID]]&",","")&IF(Tab_Def_Flows[[#This Row],[ODYM_material_(m)]],Tab_Def_Flows[[#This Row],[ODYM_Material_ID]]&",","")&IF(Tab_Def_Flows[[#This Row],[ODYM_element_(e)]],Tab_Def_Flows[[#This Row],[ODYM_Element_ID]]&",","")
A55: FALSE | B55: =ROW()-1 | C55: ="F_"&LEFT(G55,2)&"_"&LEFT(I55,2) | G55: =_xlfn.XLOOKUP(F55,Tab_Def_Processes[Process_Name],Tab_Def_Processes[Process_ID],,0,) | I55: =_xlfn.XLOOKUP(H55,Tab_Def_Processes[Process_Name],Tab_Def_Processes[Process_ID],,0,) | J55: Yes | K55: Yes | M55: Yes | N55: =Tab_Def_Flows[[#This Row],[Flow_ID]]&"_WC" | Q55: =Tab_Def_Flows[[#This Row],[Flow_ID]]&"_DM" | T55: =Tab_Def_Flows[[#This Row],[Flow_ID]]&"_CC" | W55: =Tab_Def_Flows[[#This Row],[Flow_CC_DM'[%']]]*Tab_Def_Flows[[#This Row],[Flow_DM'[%']]] | Y55: ='0_Configuration'!$C$2 | AA55: ='0_Configuration'!$C$6 | AC55: ='0_Configuration'!$C$10 | AE55: ='0_Configuration'!$C$17 | AF55: =_xlfn.XLOOKUP(Tab_Def_Flows[[#This Row],[ODYM_Good_Type]],Tab_Configuration[Value],Tab_Configuration[ODYM_ID],,0,) | AG55: ='0_Configuration'!$C$24 | AI55: ='0_Configuration'!$C$29 | AK55: =IF(Tab_Def_Flows[[#This Row],[ODYM_time_(t)]],"t,","")&IF(Tab_Def_Flows[[#This Row],[ODYM_Region_(r)]],"r,","")&IF(Tab_Def_Flows[[#This Row],[ODYM_process_(p)]],"p,","")&IF(Tab_Def_Flows[[#This Row],[ODYM_Good_(g)2]],"g,","")&IF(Tab_Def_Flows[[#This Row],[ODYM_material_(m)]],"m,","")&IF(Tab_Def_Flows[[#This Row],[ODYM_element_(e)]],"e","") | AL55: =IF(Tab_Def_Flows[[#This Row],[ODYM_time_(t)]],Tab_Def_Flows[[#This Row],[ODYM_Time_ID]]&",","")&IF(Tab_Def_Flows[[#This Row],[ODYM_Region_(r)]],Tab_Def_Flows[[#This Row],[ODYM_Region_ID]]&",","")&IF(Tab_Def_Flows[[#This Row],[ODYM_process_(p)]],Tab_Def_Flows[[#This Row],[ODYM_Process_ID]]&",","")&IF(Tab_Def_Flows[[#This Row],[ODYM_Good_(g)2]],Tab_Def_Flows[[#This Row],[ODYM_Good_ID]]&",","")&IF(Tab_Def_Flows[[#This Row],[ODYM_material_(m)]],Tab_Def_Flows[[#This Row],[ODYM_Material_ID]]&",","")&IF(Tab_Def_Flows[[#This Row],[ODYM_element_(e)]],Tab_Def_Flows[[#This Row],[ODYM_Element_ID]]&",","")
A56: FALSE | B56: =ROW()-1 | C56: ="F_"&LEFT(G56,2)&"_"&LEFT(I56,2) | G56: =_xlfn.XLOOKUP(F56,Tab_Def_Processes[Process_Name],Tab_Def_Processes[Process_ID],,0,) | I56: =_xlfn.XLOOKUP(H56,Tab_Def_Processes[Process_Name],Tab_Def_Processes[Process_ID],,0,) | J56: Yes | K56: Yes | M56: Yes | N56: =Tab_Def_Flows[[#This Row],[Flow_ID]]&"_WC" | Q56: =Tab_Def_Flows[[#This Row],[Flow_ID]]&"_DM" | T56: =Tab_Def_Flows[[#This Row],[Flow_ID]]&"_CC" | W56: =Tab_Def_Flows[[#This Row],[Flow_CC_DM'[%']]]*Tab_Def_Flows[[#This Row],[Flow_DM'[%']]] | Y56: ='0_Configuration'!$C$2 | AA56: ='0_Configuration'!$C$6 | AC56: ='0_Configuration'!$C$10 | AE56: ='0_Configuration'!$C$17 | AF56: =_xlfn.XLOOKUP(Tab_Def_Flows[[#This Row],[ODYM_Good_Type]],Tab_Configuration[Value],Tab_Configuration[ODYM_ID],,0,) | AG56: ='0_Configuration'!$C$24 | AI56: ='0_Configuration'!$C$29 | AK56: =IF(Tab_Def_Flows[[#This Row],[ODYM_time_(t)]],"t,","")&IF(Tab_Def_Flows[[#This Row],[ODYM_Region_(r)]],"r,","")&IF(Tab_Def_Flows[[#This Row],[ODYM_process_(p)]],"p,","")&IF(Tab_Def_Flows[[#This Row],[ODYM_Good_(g)2]],"g,","")&IF(Tab_Def_Flows[[#This Row],[ODYM_material_(m)]],"m,","")&IF(Tab_Def_Flows[[#This Row],[ODYM_element_(e)]],"e","") | AL56: =IF(Tab_Def_Flows[[#This Row],[ODYM_time_(t)]],Tab_Def_Flows[[#This Row],[ODYM_Time_ID]]&",","")&IF(Tab_Def_Flows[[#This Row],[ODYM_Region_(r)]],Tab_Def_Flows[[#This Row],[ODYM_Region_ID]]&",","")&IF(Tab_Def_Flows[[#This Row],[ODYM_process_(p)]],Tab_Def_Flows[[#This Row],[ODYM_Process_ID]]&",","")&IF(Tab_Def_Flows[[#This Row],[ODYM_Good_(g)2]],Tab_Def_Flows[[#This Row],[ODYM_Good_ID]]&",","")&IF(Tab_Def_Flows[[#This Row],[ODYM_material_(m)]],Tab_Def_Flows[[#This Row],[ODYM_Material_ID]]&",","")&IF(Tab_Def_Flows[[#This Row],[ODYM_element_(e)]],Tab_Def_Flows[[#This Row],[ODYM_Element_ID]]&",","")
A57: FALSE | B57: =ROW()-1 | C57: ="F_"&LEFT(G57,2)&"_"&LEFT(I57,2) | G57: =_xlfn.XLOOKUP(F57,Tab_Def_Processes[Process_Name],Tab_Def_Processes[Process_ID],,0,) | I57: =_xlfn.XLOOKUP(H57,Tab_Def_Processes[Process_Name],Tab_Def_Processes[Process_ID],,0,) | J57: Yes | K57: Yes | M57: Yes | N57: =Tab_Def_Flows[[#This Row],[Flow_ID]]&"_WC" | Q57: =Tab_Def_Flows[[#This Row],[Flow_ID]]&"_DM" | T57: =Tab_Def_Flows[[#This Row],[Flow_ID]]&"_CC" | W57: =Tab_Def_Flows[[#This Row],[Flow_CC_DM'[%']]]*Tab_Def_Flows[[#This Row],[Flow_DM'[%']]] | Y57: ='0_Configuration'!$C$2 | AA57: ='0_Configuration'!$C$6 | AC57: ='0_Configuration'!$C$10 | AE57: ='0_Configuration'!$C$17 | AF57: =_xlfn.XLOOKUP(Tab_Def_Flows[[#This Row],[ODYM_Good_Type]],Tab_Configuration[Value],Tab_Configuration[ODYM_ID],,0,) | AG57: ='0_Configuration'!$C$24 | AI57: ='0_Configuration'!$C$29 | AK57: =IF(Tab_Def_Flows[[#This Row],[ODYM_time_(t)]],"t,","")&IF(Tab_Def_Flows[[#This Row],[ODYM_Region_(r)]],"r,","")&IF(Tab_Def_Flows[[#This Row],[ODYM_process_(p)]],"p,","")&IF(Tab_Def_Flows[[#This Row],[ODYM_Good_(g)2]],"g,","")&IF(Tab_Def_Flows[[#This Row],[ODYM_material_(m)]],"m,","")&IF(Tab_Def_Flows[[#This Row],[ODYM_element_(e)]],"e","") | AL57: =IF(Tab_Def_Flows[[#This Row],[ODYM_time_(t)]],Tab_Def_Flows[[#This Row],[ODYM_Time_ID]]&",","")&IF(Tab_Def_Flows[[#This Row],[ODYM_Region_(r)]],Tab_Def_Flows[[#This Row],[ODYM_Region_ID]]&",","")&IF(Tab_Def_Flows[[#This Row],[ODYM_process_(p)]],Tab_Def_Flows[[#This Row],[ODYM_Process_ID]]&",","")&IF(Tab_Def_Flows[[#This Row],[ODYM_Good_(g)2]],Tab_Def_Flows[[#This Row],[ODYM_Good_ID]]&",","")&IF(Tab_Def_Flows[[#This Row],[ODYM_material_(m)]],Tab_Def_Flows[[#This Row],[ODYM_Material_ID]]&",","")&IF(Tab_Def_Flows[[#This Row],[ODYM_element_(e)]],Tab_Def_Flows[[#This Row],[ODYM_Element_ID]]&",","")
A58: FALSE | B58: =ROW()-1 | C58: ="F_"&LEFT(G58,2)&"_"&LEFT(I58,2) | G58: =_xlfn.XLOOKUP(F58,Tab_Def_Processes[Process_Name],Tab_Def_Processes[Process_ID],,0,) | I58: =_xlfn.XLOOKUP(H58,Tab_Def_Processes[Process_Name],Tab_Def_Processes[Process_ID],,0,) | J58: Yes | K58: Yes | M58: Yes | N58: =Tab_Def_Flows[[#This Row],[Flow_ID]]&"_WC" | Q58: =Tab_Def_Flows[[#This Row],[Flow_ID]]&"_DM" | T58: =Tab_Def_Flows[[#This Row],[Flow_ID]]&"_CC" | W58: =Tab_Def_Flows[[#This Row],[Flow_CC_DM'[%']]]*Tab_Def_Flows[[#This Row],[Flow_DM'[%']]] | Y58: ='0_Configuration'!$C$2 | AA58: ='0_Configuration'!$C$6 | AC58: ='0_Configuration'!$C$10 | AE58: ='0_Configuration'!$C$17 | AF58: =_xlfn.XLOOKUP(Tab_Def_Flows[[#This Row],[ODYM_Good_Type]],Tab_Configuration[Value],Tab_Configuration[ODYM_ID],,0,) | AG58: ='0_Configuration'!$C$24 | AI58: ='0_Configuration'!$C$29 | AK58: =IF(Tab_Def_Flows[[#This Row],[ODYM_time_(t)]],"t,","")&IF(Tab_Def_Flows[[#This Row],[ODYM_Region_(r)]],"r,","")&IF(Tab_Def_Flows[[#This Row],[ODYM_process_(p)]],"p,","")&IF(Tab_Def_Flows[[#This Row],[ODYM_Good_(g)2]],"g,","")&IF(Tab_Def_Flows[[#This Row],[ODYM_material_(m)]],"m,","")&IF(Tab_Def_Flows[[#This Row],[ODYM_element_(e)]],"e","") | AL58: =IF(Tab_Def_Flows[[#This Row],[ODYM_time_(t)]],Tab_Def_Flows[[#This Row],[ODYM_Time_ID]]&",","")&IF(Tab_Def_Flows[[#This Row],[ODYM_Region_(r)]],Tab_Def_Flows[[#This Row],[ODYM_Region_ID]]&",","")&IF(Tab_Def_Flows[[#This Row],[ODYM_process_(p)]],Tab_Def_Flows[[#This Row],[ODYM_Process_ID]]&",","")&IF(Tab_Def_Flows[[#This Row],[ODYM_Good_(g)2]],Tab_Def_Flows[[#This Row],[ODYM_Good_ID]]&",","")&IF(Tab_Def_Flows[[#This Row],[ODYM_material_(m)]],Tab_Def_Flows[[#This Row],[ODYM_Material_ID]]&",","")&IF(Tab_Def_Flows[[#This Row],[ODYM_element_(e)]],Tab_Def_Flows[[#This Row],[ODYM_Element_ID]]&",","")
A59: FALSE | B59: =ROW()-1 | C59: ="F_"&LEFT(G59,2)&"_"&LEFT(I59,2) | G59: =_xlfn.XLOOKUP(F59,Tab_Def_Processes[Process_Name],Tab_Def_Processes[Process_ID],,0,) | I59: =_xlfn.XLOOKUP(H59,Tab_Def_Processes[Process_Name],Tab_Def_Processes[Process_ID],,0,) | J59: Yes | K59: Yes | M59: Yes | N59: =Tab_Def_Flows[[#This Row],[Flow_ID]]&"_WC" | Q59: =Tab_Def_Flows[[#This Row],[Flow_ID]]&"_DM" | T59: =Tab_Def_Flows[[#This Row],[Flow_ID]]&"_CC" | W59: =Tab_Def_Flows[[#This Row],[Flow_CC_DM'[%']]]*Tab_Def_Flows[[#This Row],[Flow_DM'[%']]] | Y59: ='0_Configuration'!$C$2 | AA59: ='0_Configuration'!$C$6 | AC59: ='0_Configuration'!$C$10 | AE59: ='0_Configuration'!$C$17 | AF59: =_xlfn.XLOOKUP(Tab_Def_Flows[[#This Row],[ODYM_Good_Type]],Tab_Configuration[Value],Tab_Configuration[ODYM_ID],,0,) | AG59: ='0_Configuration'!$C$24 | AI59: ='0_Configuration'!$C$29 | AK59: =IF(Tab_Def_Flows[[#This Row],[ODYM_time_(t)]],"t,","")&IF(Tab_Def_Flows[[#This Row],[ODYM_Region_(r)]],"r,","")&IF(Tab_Def_Flows[[#This Row],[ODYM_process_(p)]],"p,","")&IF(Tab_Def_Flows[[#This Row],[ODYM_Good_(g)2]],"g,","")&IF(Tab_Def_Flows[[#This Row],[ODYM_material_(m)]],"m,","")&IF(Tab_Def_Flows[[#This Row],[ODYM_element_(e)]],"e","") | AL59: =IF(Tab_Def_Flows[[#This Row],[ODYM_time_(t)]],Tab_Def_Flows[[#This Row],[ODYM_Time_ID]]&",","")&IF(Tab_Def_Flows[[#This Row],[ODYM_Region_(r)]],Tab_Def_Flows[[#This Row],[ODYM_Region_ID]]&",","")&IF(Tab_Def_Flows[[#This Row],[ODYM_process_(p)]],Tab_Def_Flows[[#This Row],[ODYM_Process_ID]]&",","")&IF(Tab_Def_Flows[[#This Row],[ODYM_Good_(g)2]],Tab_Def_Flows[[#This Row],[ODYM_Good_ID]]&",","")&IF(Tab_Def_Flows[[#This Row],[ODYM_material_(m)]],Tab_Def_Flows[[#This Row],[ODYM_Material_ID]]&",","")&IF(Tab_Def_Flows[[#This Row],[ODYM_element_(e)]],Tab_Def_Flows[[#This Row],[ODYM_Element_ID]]&",","")
A60: FALSE | B60: =ROW()-1 | C60: ="F_"&LEFT(G60,2)&"_"&LEFT(I60,2) | G60: =_xlfn.XLOOKUP(F60,Tab_Def_Processes[Process_Name],Tab_Def_Processes[Process_ID],,0,) | I60: =_xlfn.XLOOKUP(H60,Tab_Def_Processes[Process_Name],Tab_Def_Processes[Process_ID],,0,) | J60: Yes | K60: Yes | M60: Yes | N60: =Tab_Def_Flows[[#This Row],[Flow_ID]]&"_WC" | Q60: =Tab_Def_Flows[[#This Row],[Flow_ID]]&"_DM" | T60: =Tab_Def_Flows[[#This Row],[Flow_ID]]&"_CC" | W60: =Tab_Def_Flows[[#This Row],[Flow_CC_DM'[%']]]*Tab_Def_Flows[[#This Row],[Flow_DM'[%']]] | Y60: ='0_Configuration'!$C$2 | AA60: ='0_Configuration'!$C$6 | AC60: ='0_Configuration'!$C$10 | AE60: ='0_Configuration'!$C$17 | AF60: =_xlfn.XLOOKUP(Tab_Def_Flows[[#This Row],[ODYM_Good_Type]],Tab_Configuration[Value],Tab_Configuration[ODYM_ID],,0,) | AG60: ='0_Configuration'!$C$24 | AI60: ='0_Configuration'!$C$29 | AK60: =IF(Tab_Def_Flows[[#This Row],[ODYM_time_(t)]],"t,","")&IF(Tab_Def_Flows[[#This Row],[ODYM_Region_(r)]],"r,","")&IF(Tab_Def_Flows[[#This Row],[ODYM_process_(p)]],"p,","")&IF(Tab_Def_Flows[[#This Row],[ODYM_Good_(g)2]],"g,","")&IF(Tab_Def_Flows[[#This Row],[ODYM_material_(m)]],"m,","")&IF(Tab_Def_Flows[[#This Row],[ODYM_element_(e)]],"e","") | AL60: =IF(Tab_Def_Flows[[#This Row],[ODYM_time_(t)]],Tab_Def_Flows[[#This Row],[ODYM_Time_ID]]&",","")&IF(Tab_Def_Flows[[#This Row],[ODYM_Region_(r)]],Tab_Def_Flows[[#This Row],[ODYM_Region_ID]]&",","")&IF(Tab_Def_Flows[[#This Row],[ODYM_process_(p)]],Tab_Def_Flows[[#This Row],[ODYM_Process_ID]]&",","")&IF(Tab_Def_Flows[[#This Row],[ODYM_Good_(g)2]],Tab_Def_Flows[[#This Row],[ODYM_Good_ID]]&",","")&IF(Tab_Def_Flows[[#This Row],[ODYM_material_(m)]],Tab_Def_Flows[[#This Row],[ODYM_Material_ID]]&",","")&IF(Tab_Def_Flows[[#This Row],[ODYM_element_(e)]],Tab_Def_Flows[[#This Row],[ODYM_Element_ID]]&",","")
A61: FALSE | B61: =ROW()-1 | C61: ="F_"&LEFT(G61,2)&"_"&LEFT(I61,2) | G61: =_xlfn.XLOOKUP(F61,Tab_Def_Processes[Process_Name],Tab_Def_Processes[Process_ID],,0,) | I61: =_xlfn.XLOOKUP(H61,Tab_Def_Processes[Process_Name],Tab_Def_Processes[Process_ID],,0,) | J61: Yes | K61: Yes | M61: Yes | N61: =Tab_Def_Flows[[#This Row],[Flow_ID]]&"_WC" | Q61: =Tab_Def_Flows[[#This Row],[Flow_ID]]&"_DM" | T61: =Tab_Def_Flows[[#This Row],[Flow_ID]]&"_CC" | W61: =Tab_Def_Flows[[#This Row],[Flow_CC_DM'[%']]]*Tab_Def_Flows[[#This Row],[Flow_DM'[%']]] | Y61: ='0_Configuration'!$C$2 | AA61: ='0_Configuration'!$C$6 | AC61: ='0_Configuration'!$C$10 | AE61: ='0_Configuration'!$C$17 | AF61: =_xlfn.XLOOKUP(Tab_Def_Flows[[#This Row],[ODYM_Good_Type]],Tab_Configuration[Value],Tab_Configuration[ODYM_ID],,0,) | AG61: ='0_Configuration'!$C$24 | AI61: ='0_Configuration'!$C$29 | AK61: =IF(Tab_Def_Flows[[#This Row],[ODYM_time_(t)]],"t,","")&IF(Tab_Def_Flows[[#This Row],[ODYM_Region_(r)]],"r,","")&IF(Tab_Def_Flows[[#This Row],[ODYM_process_(p)]],"p,","")&IF(Tab_Def_Flows[[#This Row],[ODYM_Good_(g)2]],"g,","")&IF(Tab_Def_Flows[[#This Row],[ODYM_material_(m)]],"m,","")&IF(Tab_Def_Flows[[#This Row],[ODYM_element_(e)]],"e","") | AL61: =IF(Tab_Def_Flows[[#This Row],[ODYM_time_(t)]],Tab_Def_Flows[[#This Row],[ODYM_Time_ID]]&",","")&IF(Tab_Def_Flows[[#This Row],[ODYM_Region_(r)]],Tab_Def_Flows[[#This Row],[ODYM_Region_ID]]&",","")&IF(Tab_Def_Flows[[#This Row],[ODYM_process_(p)]],Tab_Def_Flows[[#This Row],[ODYM_Process_ID]]&",","")&IF(Tab_Def_Flows[[#This Row],[ODYM_Good_(g)2]],Tab_Def_Flows[[#This Row],[ODYM_Good_ID]]&",","")&IF(Tab_Def_Flows[[#This Row],[ODYM_material_(m)]],Tab_Def_Flows[[#This Row],[ODYM_Material_ID]]&",","")&IF(Tab_Def_Flows[[#This Row],[ODYM_element_(e)]],Tab_Def_Flows[[#This Row],[ODYM_Element_ID]]&",","")
